Workbook
Name a: #REF!
Name aa: #REF!
Name b: #REF!
Name br: #REF!
Name condition: [1]Data!$B:$C
Name Monthdata: [2]!Month_Table[Monthlist]
Name pop: #REF!
Name tc: #REF!
Name បញ្ជីអនុគណនី: [3]!Table2[[អនុគណនី]:[ឈ្មោះគណនី]]
Name ល.រ: '[4]Costing(ដំបូង)'!$B$283:$B$1048576
Name សរុប: '[4]Costing(ដំបូង)'!$K$283:$K$1048576
Name អនុគណនី: '[4]Costing(ដំបូង)'!$E$283:$E$1048576

Sheet Sheet1
A1: id | B1: name_en | C1: name_kh
A2: 1 | B2: name | C2: name

Sheet PB1Revenue
A1: id | B1: planning_id | C1: chapter_id | D1: account_id | E1: sub_account_id | F1: 1 | G1: 2 | H1: 3 | I1: 4 | J1: imple_income_budget | K1: rule_basic_income_plan | L1: rule_qty_income_plan | M1: rule_budget_credit | N1: imple_budget_semester_1 | O1: imple_budget_semester_2 | P1: annual_estimate | Q1: percentage_rule | R1: basic_income_plan | S1: qty_income_plan | T1: total_income_plan | U1: percentage_income_plan
A2: 1 | B2: 4 | C2: 18 | D2: 90 | E2: =MATCH(H2,'[5]Sub Account'!$E$2:$E$503,0) -> 318 | H2: 70011 | I2: ពន្ធលើប្រាក់ចំណូល (រូបវន្តបុគ្គល) | K2: 2 | L2: 4 | M2: 2 | N2: 2 | O2: 2 | P2: 1 | Q2: =IFERROR(P2/M2,"-") -> 0.5 | R2: 2 | S2: 2 | U2: =IFERROR(T2/M2,"-") -> 0 | V2: =IF(OR(M2>0,T2>0),"ok","-") -> ok
A3: 2 | B3: 4 | C3: 18 | D3: 90 | E3: =MATCH(H3,'[5]Sub Account'!$E$2:$E$503,0) -> 319 | H3: 70012 | I3: ពន្ធលើប្រាក់ចំណូល (នីតិបុគ្គល) | P3: =SUM(N3:O3) -> 0 | Q3: =IFERROR(P3/M3,"-") -> - | U3: =IFERROR(T3/M3,"-") -> - | V3: =IF(OR(M3>0,T3>0),"ok","-") -> -
A4: 3 | B4: 4 | C4: 18 | D4: 90 | E4: =MATCH(H4,'[5]Sub Account'!$E$2:$E$503,0) -> 320 | H4: 70013 | I4: ពន្ធលើប្រាក់បៀវត្ស | P4: =SUM(N4:O4) -> 0 | Q4: =IFERROR(P4/M4,"-") -> - | U4: =IFERROR(T4/M4,"-") -> - | V4: =IF(OR(M4>0,T4>0),"ok","-") -> -
A5: 4 | B5: 4 | C5: 18 | D5: 90 | E5: =MATCH(H5,'[5]Sub Account'!$E$2:$E$503,0) -> 321 | H5: 70014 | I5: ពន្ធលើឈ្នួលចលននិងអចលនទ្រព្យ (រូបវន្តបុគ្គល) | P5: =SUM(N5:O5) -> 0 | Q5: =IFERROR(P5/M5,"-") -> - | U5: =IFERROR(T5/M5,"-") -> - | V5: =IF(OR(M5>0,T5>0),"ok","-") -> -
A6: 5 | B6: 4 | C6: 18 | D6: 90 | E6: =MATCH(H6,'[5]Sub Account'!$E$2:$E$503,0) -> 322 | H6: 70015 | I6: ពន្ធលើឈ្នួលចលននិងអចលនទ្រព្យ (នីតិបុគ្គល) | P6: =SUM(N6:O6) -> 0 | Q6: =IFERROR(P6/M6,"-") -> - | U6: =IFERROR(T6/M6,"-") -> - | V6: =IF(OR(M6>0,T6>0),"ok","-") -> -
A7: 6 | B7: 4 | C7: 18 | D7: 90 | E7: =MATCH(H7,'[5]Sub Account'!$E$2:$E$503,0) -> 323 | H7: 70016 | I7: ពន្ធលើប្រាក់ចំណូលនីតិបុគ្គលជាបន្ទុករបស់រដ្ឋ | P7: =SUM(N7:O7) -> 0 | Q7: =IFERROR(P7/M7,"-") -> - | U7: =IFERROR(T7/M7,"-") -> - | V7: =IF(OR(M7>0,T7>0),"ok","-") -> -
G8: 7002 | I8: ពន្ធប្រយោល | J8: =SUM(J9:J15) -> 0 | K8: =SUM(K9:K15) -> 0 | L8: =SUM(L9:L15) -> 0 | M8: =SUM(M9:M15) -> 0 | N8: =SUM(N9:N15) -> 0 | O8: =SUM(O9:O15) -> 0 | P8: =SUM(P9:P15) -> 0 | Q8: =IFERROR(P8/M8,"-") -> - | R8: =SUM(R9:R15) -> 0 | S8: =SUM(S9:S15) -> 0 | T8: =SUM(T9:T15) -> 0 | U8: =IFERROR(T8/M8,"-") -> - | V8: =IF(OR(M8>0,T8>0),"ok","-") -> -
A9: 8 | B9: 4 | C9: 18 | D9: 91 | E9: =MATCH(H9,'[5]Sub Account'!$E$2:$E$503,0) -> 324 | H9: 70021 | I9: អាករលើផលរបរ | P9: =SUM(N9:O9) -> 0 | Q9: =IFERROR(P9/M9,"-") -> - | U9: =IFERROR(T9/M9,"-") -> - | V9: =IF(OR(M9>0,T9>0),"ok","-") -> -
A10: 9 | B10: 4 | C10: 18 | D10: 91 | E10: =MATCH(H10,'[5]Sub Account'!$E$2:$E$503,0) -> 325 | H10: 70022 | I10: អាករលើតម្លៃបន្ថែម | P10: =SUM(N10:O10) -> 0 | Q10: =IFERROR(P10/M10,"-") -> - | U10: =IFERROR(T10/M10,"-") -> - | V10: =IF(OR(M10>0,T10>0),"ok","-") -> -
A11: 10 | B11: 4 | C11: 18 | D11: 91 | E11: =MATCH(H11,'[5]Sub Account'!$E$2:$E$503,0) -> 326 | H11: 70023 | I11: អាករលើតម្លៃបន្ថែម​លើទំនិញជាបន្ទុករបស់​រដ្ឋ | P11: =SUM(N11:O11) -> 0 | Q11: =IFERROR(P11/M11,"-") -> - | U11: =IFERROR(T11/M11,"-") -> - | V11: =IF(OR(M11>0,T11>0),"ok","-") -> -
A12: 11 | B12: 4 | C12: 18 | D12: 91 | E12: =MATCH(H12,'[5]Sub Account'!$E$2:$E$503,0) -> 327 | H12: 70024 | I12: អាករលើតម្លៃបន្ថែម​លើសេវាជាបន្ទុករបស់​រដ្ឋ | P12: =SUM(N12:O12) -> 0 | Q12: =IFERROR(P12/M12,"-") -> - | U12: =IFERROR(T12/M12,"-") -> - | V12: =IF(OR(M12>0,T12>0),"ok","-") -> -
A13: 12 | B13: 4 | C13: 18 | D13: 91 | E13: =MATCH(H13,'[5]Sub Account'!$E$2:$E$503,0) -> 328 | H13: 70025 | I13: អាករលើតម្លៃបន្ថែម របបនាំចូល (សហគ្រាសប្រេងឥន្ធនៈ) | P13: =SUM(N13:O13) -> 0 | Q13: =IFERROR(P13/M13,"-") -> - | U13: =IFERROR(T13/M13,"-") -> - | V13: =IF(OR(M13>0,T13>0),"ok","-") -> -
A14: 13 | B14: 4 | C14: 18 | D14: 91 | E14: =MATCH(H14,'[5]Sub Account'!$E$2:$E$503,0) -> 329 | H14: 70026 | I14: អាករលើតម្លៃបន្ថែម របបនាំចូល (សហគ្រាសផ្សេងៗទៀត) | P14: =SUM(N14:O14) -> 0 | Q14: =IFERROR(P14/M14,"-") -> - | U14: =IFERROR(T14/M14,"-") -> - | V14: =IF(OR(M14>0,T14>0),"ok","-") -> -
A15: 14 | B15: 4 | C15: 18 | D15: 91 | E15: =MATCH(H15,'[5]Sub Account'!$E$2:$E$503,0) -> 330 | H15: 70027 | I15: អាករលើតម្លៃបន្ថែម របបនាំចូល (ជាបន្ទុករបស់រដ្ឋ) | P15: =SUM(N15:O15) -> 0 | Q15: =IFERROR(P15/M15,"-") -> - | U15: =IFERROR(T15/M15,"-") -> - | V15: =IF(OR(M15>0,T15>0),"ok","-") -> -
G16: 7003 | I16: អាករពិសេស | J16: =SUM(J17:J22) -> 0 | K16: =SUM(K17:K22) -> 0 | L16: =SUM(L17:L22) -> 0 | M16: =SUM(M17:M22) -> 0 | N16: =SUM(N17:N22) -> 0 | O16: =SUM(O17:O22) -> 0 | P16: =SUM(P17:P22) -> 0 | Q16: =IFERROR(P16/M16,"-") -> - | R16: =SUM(R17:R22) -> 0 | S16: =SUM(S17:S22) -> 0 | T16: =SUM(T17:T22) -> 0 | U16: =IFERROR(T16/M16,"-") -> - | V16: =IF(OR(M16>0,T16>0),"ok","-") -> -
A17: 16 | B17: 4 | C17: 18 | D17: 92 | E17: =MATCH(H17,'[5]Sub Account'!$E$2:$E$503,0) -> 331 | H17: 70031 | I17: អាករពិសេសលើទំនិញមួយចំនួន | P17: =SUM(N17:O17) -> 0 | Q17: =IFERROR(P17/M17,"-") -> - | U17: =IFERROR(T17/M17,"-") -> - | V17: =IF(OR(M17>0,T17>0),"ok","-") -> -
A18: 17 | B18: 4 | C18: 18 | D18: 92 | E18: =MATCH(H18,'[5]Sub Account'!$E$2:$E$503,0) -> 332 | H18: 70032 | I18: អាករពិសេសលើទំនិញមួយចំនួន របបនាំចូល (សហគ្រាសប្រេងឥន្ធនៈ) | P18: =SUM(N18:O18) -> 0 | Q18: =IFERROR(P18/M18,"-") -> - | U18: =IFERROR(T18/M18,"-") -> - | V18: =IF(OR(M18>0,T18>0),"ok","-") -> -
A19: 18 | B19: 4 | C19: 18 | D19: 92 | E19: =MATCH(H19,'[5]Sub Account'!$E$2:$E$503,0) -> 333 | H19: 70033 | I19: អាករពិសេសលើទំនិញមួយចំនួន របបនាំចូល (សហគ្រាសផ្សេងៗទៀត) | P19: =SUM(N19:O19) -> 0 | Q19: =IFERROR(P19/M19,"-") -> - | U19: =IFERROR(T19/M19,"-") -> - | V19: =IF(OR(M19>0,T19>0),"ok","-") -> -
A20: 19 | B20: 4 | C20: 18 | D20: 92 | E20: =MATCH(H20,'[5]Sub Account'!$E$2:$E$503,0) -> 334 | H20: 70034 | I20: អាករពិសេសលើសេវាមួយចំនួន | P20: =SUM(N20:O20) -> 0 | Q20: =IFERROR(P20/M20,"-") -> - | U20: =IFERROR(T20/M20,"-") -> - | V20: =IF(OR(M20>0,T20>0),"ok","-") -> -
A21: 20 | B21: 4 | C21: 18 | D21: 92 | E21: =MATCH(H21,'[5]Sub Account'!$E$2:$E$503,0) -> 335 | H21: 70035 | I21: អាករសម្រាប់បំភ្លឺសាធារណៈ | P21: =SUM(N21:O21) -> 0 | Q21: =IFERROR(P21/M21,"-") -> - | U21: =IFERROR(T21/M21,"-") -> - | V21: =IF(OR(M21>0,T21>0),"ok","-") -> -
A22: 21 | B22: 4 | C22: 18 | D22: 92 | E22: =MATCH(H22,'[5]Sub Account'!$E$2:$E$503,0) -> 336 | H22: 70038 | I22: ផ្សេងៗ | P22: =SUM(N22:O22) -> 0 | Q22: =IFERROR(P22/M22,"-") -> - | U22: =IFERROR(T22/M22,"-") -> - | V22: =IF(OR(M22>0,T22>0),"ok","-") -> -
G23: 7004 | I23: អាករលើសេវាដែលបានកំណត់ | J23: =SUM(J24:J25) -> 0 | K23: =SUM(K24:K25) -> 0 | L23: =SUM(L24:L25) -> 0 | M23: =SUM(M24:M25) -> 0 | N23: =SUM(N24:N25) -> 0 | O23: =SUM(O24:O25) -> 0 | P23: =SUM(P24:P25) -> 0 | Q23: =IFERROR(P23/M23,"-") -> - | R23: =SUM(R24:R25) -> 0 | S23: =SUM(S24:S25) -> 0 | T23: =SUM(T24:T25) -> 0 | U23: =IFERROR(T23/M23,"-") -> - | V23: =IF(OR(M23>0,T23>0),"ok","-") -> -
A24: 23 | B24: 4 | C24: 18 | D24: 93 | E24: =MATCH(H24,'[5]Sub Account'!$E$2:$E$503,0) -> 337 | H24: 70045 | I24: អាករលើការស្នាក់នៅ | P24: =SUM(N24:O24) -> 0 | Q24: =IFERROR(P24/M24,"-") -> - | U24: =IFERROR(T24/M24,"-") -> - | V24: =IF(OR(M24>0,T24>0),"ok","-") -> -
A25: 24 | B25: 4 | C25: 18 | D25: 93 | E25: =MATCH(H25,'[5]Sub Account'!$E$2:$E$503,0) -> 338 | H25: 70046 | I25: ពន្ធសត្តឃាត | P25: =SUM(N25:O25) -> 0 | Q25: =IFERROR(P25/M25,"-") -> - | U25: =IFERROR(T25/M25,"-") -> - | V25: =IF(OR(M25>0,T25>0),"ok","-") -> -
G26: 7005 | I26: អាករលើការប្រើប្រាស់ទ្រព្យសម្បត្តិ ឬ ការអនុវត្តសកម្មភាព | J26: =SUM(J27:J29) -> 0 | K26: =SUM(K27:K29) -> 0 | L26: =SUM(L27:L29) -> 0 | M26: =SUM(M27:M29) -> 0 | N26: =SUM(N27:N29) -> 0 | O26: =SUM(O27:O29) -> 0 | P26: =SUM(P27:P29) -> 0 | Q26: =IFERROR(P26/M26,"-") -> - | R26: =SUM(R27:R29) -> 0 | S26: =SUM(S27:S29) -> 0 | T26: =SUM(T27:T29) -> 0 | U26: =IFERROR(T26/M26,"-") -> - | V26: =IF(OR(M26>0,T26>0),"ok","-") -> -
A27: 26 | B27: 4 | C27: 18 | D27: 94 | E27: =MATCH(H27,'[5]Sub Account'!$E$2:$E$503,0) -> 339 | H27: 70053 | I27: ពន្ធប៉ាតង់ | P27: =SUM(N27:O27) -> 0 | Q27: =IFERROR(P27/M27,"-") -> - | U27: =IFERROR(T27/M27,"-") -> - | V27: =IF(OR(M27>0,T27>0),"ok","-") -> -
A28: 27 | B28: 4 | C28: 18 | D28: 94 | E28: =MATCH(H28,'[5]Sub Account'!$E$2:$E$503,0) -> 340 | H28: 70054 | I28: ពន្ធលើមធ្យោបាយដឹកជញ្ជូន និងយានជំនិះគ្រប់ប្រភេទ | P28: =SUM(N28:O28) -> 0 | Q28: =IFERROR(P28/M28,"-") -> - | U28: =IFERROR(T28/M28,"-") -> - | V28: =IF(OR(M28>0,T28>0),"ok","-") -> -
A29: 28 | B29: 4 | C29: 18 | D29: 94 | E29: =MATCH(H29,'[5]Sub Account'!$E$2:$E$503,0) -> 341 | H29: 70055 | I29: ពន្ធលើមធ្យោបាយដឹកជញ្ជូន និង​យានជំនិះគ្រប់ប្រភេទជាបន្ទុករបស់រដ្ឋ | P29: =SUM(N29:O29) -> 0 | Q29: =IFERROR(P29/M29,"-") -> - | U29: =IFERROR(T29/M29,"-") -> - | V29: =IF(OR(M29>0,T29>0),"ok","-") -> -
G30: 7006 | I30: ពន្ធប្រថាប់ត្រា | J30: =SUM(J31:J36) -> 0 | K30: =SUM(K31:K36) -> 0 | L30: =SUM(L31:L36) -> 0 | M30: =SUM(M31:M36) -> 0 | N30: =SUM(N31:N36) -> 0 | O30: =SUM(O31:O36) -> 0 | P30: =SUM(P31:P36) -> 0 | Q30: =IFERROR(P30/M30,"-") -> - | R30: =SUM(R31:R36) -> 0 | S30: =SUM(S31:S36) -> 0 | T30: =SUM(T31:T36) -> 0 | U30: =IFERROR(T30/M30,"-") -> - | V30: =IF(OR(M30>0,T30>0),"ok","-") -> -
A31: 30 | B31: 4 | C31: 18 | D31: 95 | E31: =MATCH(H31,'[5]Sub Account'!$E$2:$E$503,0) -> 342 | H31: 70061 | I31: ពន្ធប្រថាប់ត្រា លើតម្លៃអចលនទ្រព្យចំពោះការផ្ទេរកម្មសិទ្ធិ ឬ សិទ្ធិកាន់កាប់ | P31: =SUM(N31:O31) -> 0 | Q31: =IFERROR(P31/M31,"-") -> - | U31: =IFERROR(T31/M31,"-") -> - | V31: =IF(OR(M31>0,T31>0),"ok","-") -> -
A32: 31 | B32: 4 | C32: 18 | D32: 95 | E32: =MATCH(H32,'[5]Sub Account'!$E$2:$E$503,0) -> 343 | H32: 70062 | I32: ពន្ធប្រថាប់ត្រា លើតម្លៃមធ្យោបាយដឹកជញ្ជូន ឬ យានយន្តចំពោះការផ្ទេរកម្មសិទ្ធិ | P32: =SUM(N32:O32) -> 0 | Q32: =IFERROR(P32/M32,"-") -> - | U32: =IFERROR(T32/M32,"-") -> - | V32: =IF(OR(M32>0,T32>0),"ok","-") -> -
A33: 32 | B33: 4 | C33: 18 | D33: 95 | E33: =MATCH(H33,'[5]Sub Account'!$E$2:$E$503,0) -> 344 | H33: 70063 | I33: ពន្ធប្រថាប់ត្រា លើតម្លៃភាគហ៊ុនចំពោះការផ្ទេរភាគហ៊ុន | P33: =SUM(N33:O33) -> 0 | Q33: =IFERROR(P33/M33,"-") -> - | U33: =IFERROR(T33/M33,"-") -> - | V33: =IF(OR(M33>0,T33>0),"ok","-") -> -
A34: 33 | B34: 4 | C34: 18 | D34: 95 | E34: =MATCH(H34,'[5]Sub Account'!$E$2:$E$503,0) -> 345 | H34: 70064 | I34: ពន្ធប្រថាប់ត្រា លើតម្លៃកិច្ចសន្យាចំពោះការផ្គត់ផ្គង់ទំនិញ ឬ សេវា | P34: =SUM(N34:O34) -> 0 | Q34: =IFERROR(P34/M34,"-") -> - | U34: =IFERROR(T34/M34,"-") -> - | V34: =IF(OR(M34>0,T34>0),"ok","-") -> -
A35: 34 | B35: 4 | C35: 18 | D35: 95 | E35: =MATCH(H35,'[5]Sub Account'!$E$2:$E$503,0) -> 346 | H35: 70065 | I35: ពន្ធប្រថាប់ត្រា លើលិខិតមានលក្ខណៈគតិយុត្ដ | P35: =SUM(N35:O35) -> 0 | Q35: =IFERROR(P35/M35,"-") -> - | U35: =IFERROR(T35/M35,"-") -> - | V35: =IF(OR(M35>0,T35>0),"ok","-") -> -
A36: 35 | B36: 4 | C36: 18 | D36: 95 | E36: =MATCH(H36,'[5]Sub Account'!$E$2:$E$503,0) -> 347 | H36: 70066 | I36: ពន្ធប្រថាប់ត្រាលើការផ្ទេរកម្មសិទ្ធិ ឬ សិទ្ធិ​កាន់កាប់​អចលនទ្រព្យ​ក្នុង​រង្វង់ញាតិ និង​ការអនុគ្រោះពន្ធ ជាបន្ទុករបស់រដ្ឋ | P36: =SUM(N36:O36) -> 0 | Q36: =IFERROR(P36/M36,"-") -> - | U36: =IFERROR(T36/M36,"-") -> - | V36: =IF(OR(M36>0,T36>0),"ok","-") -> -
G37: 7007 | I37: ពន្ធលើអចលនទ្រព្យ | J37: =SUM(J38:J41) -> 0 | K37: =SUM(K38:K41) -> 0 | L37: =SUM(L38:L41) -> 0 | M37: =SUM(M38:M41) -> 0 | N37: =SUM(N38:N41) -> 0 | O37: =SUM(O38:O41) -> 0 | P37: =SUM(P38:P41) -> 0 | Q37: =IFERROR(P37/M37,"-") -> - | R37: =SUM(R38:R41) -> 0 | S37: =SUM(S38:S41) -> 0 | T37: =SUM(T38:T41) -> 0 | U37: =IFERROR(T37/M37,"-") -> - | V37: =IF(OR(M37>0,T37>0),"ok","-") -> -
A38: 37 | B38: 4 | C38: 18 | D38: 96 | E38: =MATCH(H38,'[5]Sub Account'!$E$2:$E$503,0) -> 348 | H38: 70071 | I38: ពន្ធលើអចលនទ្រព្យ (រូបវន្តបុគ្គល) | P38: =SUM(N38:O38) -> 0 | Q38: =IFERROR(P38/M38,"-") -> - | U38: =IFERROR(T38/M38,"-") -> - | V38: =IF(OR(M38>0,T38>0),"ok","-") -> -
A39: 38 | B39: 4 | C39: 18 | D39: 96 | E39: =MATCH(H39,'[5]Sub Account'!$E$2:$E$503,0) -> 349 | H39: 70072 | I39: ពន្ធលើអចលនទ្រព្យ (នីតិបុគ្គល) | P39: =SUM(N39:O39) -> 0 | Q39: =IFERROR(P39/M39,"-") -> - | U39: =IFERROR(T39/M39,"-") -> - | V39: =IF(OR(M39>0,T39>0),"ok","-") -> -
A40: 39 | B40: 4 | C40: 18 | D40: 96 | E40: =MATCH(H40,'[5]Sub Account'!$E$2:$E$503,0) -> 350 | H40: 70073 | I40: ពន្ធលើដីធ្លីមិនបានប្រើប្រាស់ | P40: =SUM(N40:O40) -> 0 | Q40: =IFERROR(P40/M40,"-") -> - | U40: =IFERROR(T40/M40,"-") -> - | V40: =IF(OR(M40>0,T40>0),"ok","-") -> -
...

Sheet BSP4B
C5: តារាង ៤ ខ : ពណ៌នាអំពីការគ្រោងចំណាយមូលធនសម្រាប់អនុកម្មវិធី
J6: តារាង ៤"ខ"
D7: កូដអនុកម្មវិធី | E7: =Costing!$G$11 -> 10101 | J7: ឯកតា៖ លានរៀល
A10: Check | B10: កូដអង្គភាព | C10: ឈ្មោះគម្រោង តាមកម្មវិធី | D10: លេខ អនុកម្មវិធី | E10: បរិយាយគម្រោង | F10: ពន្យល់អំពីនិន្នាការមូលនិធិ លើសពីឆ្នាំថវិកា | G10: ច្បាប់ហិរញ្ញវត្ថុឆ្នាំ២០២២ | I10: គ្រោងឆ្នាំ២០២៣
G11: ថវិការដ្ឋ | H11: ថវិកាដៃគូអភិវឌ្ឍន៍ | I11: ថវិការដ្ឋ | J11: ថវិកាដៃគូអភិវឌ្ឍន៍
C12: សរុបរួមចំណាយមូលធន | G12: =G13 -> 0 | H12: =H13 -> 0 | I12: =I13 -> 0 | J12: =J13 -> 0 | K12: =IF(SUM(G12:J12)>0,"ok","-") -> -
C13: =Costing!$H$11 -> អនុកម្មវិធីទី១.១ | D13: =Costing!$G$11 -> 10101 | G13: =SUM(G14:G19) -> 0 | H13: =SUM(H14:H19) -> 0 | I13: =SUM(I14:I19) -> 0 | J13: =SUM(J14:J19) -> 0 | K13: =IF(SUM(G13:J13)>0,"ok","-") -> -
C14: ឈ្មោះគម្រោង : ... | D14: =$D$13 -> 10101 | K14: =IF(SUM(G14:J14)>0,"ok","-") -> -
C15: ឈ្មោះគម្រោង : ... | D15: =$D$13 -> 10101 | K15: =IF(SUM(G15:J15)>0,"ok","-") -> -
C16: ឈ្មោះគម្រោង : ... | D16: =$D$13 -> 10101 | K16: =IF(SUM(G16:J16)>0,"ok","-") -> -
C17: ឈ្មោះគម្រោង : ... | D17: =$D$13 -> 10101 | K17: =IF(SUM(G17:J17)>0,"ok","-") -> -
C18: ឈ្មោះគម្រោង : ... | D18: =$D$13 -> 10101 | K18: =IF(SUM(G18:J18)>0,"ok","-") -> -
C19: ឈ្មោះគម្រោង : ... | D19: =$D$13 -> 10101 | K19: =IF(SUM(G19:J19)>0,"ok","-") -> -

Sheet PB1-Rev
A5: គម្រោងថវិកាឆ្នាំ២០២៣
A6: គម្រោងចំណូលថវិកាតាមចំណាត់ថ្នាក់សេដ្ឋកិច្ច
A7: =Costing!$K$11 -> អគ្គនាយកដ្ឋានគោលនយោបាយ
P8: តារាងទី១ (តារាង ១"ក" ក្នុងសារាចររៀបចំគម្រោងថវិកាប្រចាំឆ្នាំ)
P9: ឯកតា៖ លានរៀល
A12: ជំពូក | B12: គណនី | C12: អនុគណនី | D12: ចំណាត់ថ្នាក់ចំណាយ (តាមតារាងមាតិកាថវិកា ) | E12: ចំណូលឆ្នាំ២០២១ (អនុវត្ត) | F12: ច្បាប់ហិរញ្ញវត្ថុឆ្នាំ២០២២ | I12: ប៉ាន់ស្មាន​អនុវត្ត​ឆ្នាំ​២០២២ | M12: គម្រោង​ឆ្នាំ​២០២៣
F13: មូលដ្ឋាន គិតចំណូល | G13: បរិមាណ | H13: សរុប​ ឥណទានថវិកា | I13: អនុវត្ដ ឆមាសទី១ | J13: ប៉ាន់ស្មាន ឆមាសទី២ | K13: ប៉ាន់​ស្មាន​ប្រចាំ​ឆ្នាំ | M13: មូលដ្ឋាន គិតចំណូល | N13: បរិមាណ | O13: សរុប​ការ​គ្រោ​ង​ចំណូល
K14: សរុប | L14: %ច្ប.២២ | O14: សរុប​ | P14: %ច្ប.២២ | Q14: ok
A15: សរុប​រួមចំណូល​ (ក+ខ) | E15: =E17+E261 -> 0 | F15: =F17+F261 -> 0 | G15: =G17+G261 -> 0 | H15: =H17+H261 -> 0 | I15: =I17+I261 -> 0 | J15: =J17+J261 -> 0 | K15: =K17+K261 -> 0 | L15: =IFERROR(K15/H15,"-") -> - | M15: =M17+M261 -> 0 | N15: =N17+N261 -> 0 | O15: =O17+O261 -> 0 | P15: =IFERROR(O15/H15,"-") -> - | Q15: =IF(OR(H15>0,O15>0),"ok","-") -> -
A16: ក្នុងនោះចំណូល​ក្នុងប្រទេស | E16: =E17+E264 -> 0 | F16: =F17+F264 -> 0 | G16: =G17+G264 -> 0 | H16: =H17+H264 -> 0 | I16: =I17+I264 -> 0 | J16: =J17+J264 -> 0 | K16: =K17+K264 -> 0 | L16: =IFERROR(K16/H16,"-") -> - | M16: =M17+M264 -> 0 | N16: =N17+N264 -> 0 | O16: =O17+O264 -> 0 | P16: =IFERROR(O16/H16,"-") -> - | Q16: =IF(OR(H16>0,O16>0),"ok","-") -> -
A17: ក. សរុបចំណូល​ចរន្ត (ក្រុមទី១+ក្រុមទី២) | E17: =E18+E259 -> 0 | F17: =F18+F259 -> 0 | G17: =G18+G259 -> 0 | H17: =H18+H259 -> 0 | I17: =I18+I259 -> 0 | J17: =J18+J259 -> 0 | K17: =K18+K259 -> 0 | L17: =IFERROR(K17/H17,"-") -> - | M17: =M18+M259 -> 0 | N17: =N18+N259 -> 0 | O17: =O18+O259 -> 0 | P17: =IFERROR(O17/H17,"-") -> - | Q17: =IF(OR(H17>0,O17>0),"ok","-") -> -
A18: ក្រុមទី១: ចំណូល​ពិត (ប្រភេទទី១+ប្រភេទទី២) | E18: =E19+E82 -> 0 | F18: =F19+F82 -> 0 | G18: =G19+G82 -> 0 | H18: =H19+H82 -> 0 | I18: =I19+I82 -> 0 | J18: =J19+J82 -> 0 | K18: =K19+K82 -> 0 | L18: =IFERROR(K18/H18,"-") -> - | M18: =M19+M82 -> 0 | N18: =N19+N82 -> 0 | O18: =O19+O82 -> 0 | P18: =IFERROR(O18/H18,"-") -> - | Q18: =IF(OR(H18>0,O18>0),"ok","-") -> -
A19: ប្រភេទទី១: ចំណូល​សារពើពន្ធ | E19: =E20+E65 -> 0 | F19: =F20+F65 -> 0 | G19: =G20+G65 -> 0 | H19: =H20+H65 -> 0 | I19: =I20+I65 -> 0 | J19: =J20+J65 -> 0 | K19: =K20+K65 -> 0 | L19: =IFERROR(K19/H19,"-") -> - | M19: =M20+M65 -> 0 | N19: =N20+N65 -> 0 | O19: =O20+O65 -> 0 | P19: =IFERROR(O19/H19,"-") -> - | Q19: =IF(OR(H19>0,O19>0),"ok","-") -> -
A20: 70 | D20: ចំណូលសារពើពន្ធក្នុងស្រុក | E20: =E21+E28+E36+E43+E46+E50+E57+E62 -> 0 | F20: =F21+F28+F36+F43+F46+F50+F57+F62 -> 0 | G20: =G21+G28+G36+G43+G46+G50+G57+G62 -> 0 | H20: =H21+H28+H36+H43+H46+H50+H57+H62 -> 0 | I20: =I21+I28+I36+I43+I46+I50+I57+I62 -> 0 | J20: =J21+J28+J36+J43+J46+J50+J57+J62 -> 0 | K20: =K21+K28+K36+K43+K46+K50+K57+K62 -> 0 | L20: =IFERROR(K20/H20,"-") -> - | M20: =M21+M28+M36+M43+M46+M50+M57+M62 -> 0 | N20: =N21+N28+N36+N43+N46+N50+N57+N62 -> 0 | O20: =O21+O28+O36+O43+O46+O50+O57+O62 -> 0 | P20: =IFERROR(O20/H20,"-") -> - | Q20: =IF(OR(H20>0,O20>0),"ok","-") -> -
B21: 7001 | D21: ពន្ធផ្ទាល់ (ពន្ធលើផលទុន ប្រាក់ចំណូល) | E21: =SUM(E22:E27) -> 0 | F21: =SUM(F22:F27) -> 0 | G21: =SUM(G22:G27) -> 0 | H21: =SUM(H22:H27) -> 0 | I21: =SUM(I22:I27) -> 0 | J21: =SUM(J22:J27) -> 0 | K21: =SUM(K22:K27) -> 0 | L21: =IFERROR(K21/H21,"-") -> - | M21: =SUM(M22:M27) -> 0 | N21: =SUM(N22:N27) -> 0 | O21: =SUM(O22:O27) -> 0 | P21: =IFERROR(O21/H21,"-") -> - | Q21: =IF(OR(H21>0,O21>0),"ok","-") -> -
C22: 70011 | D22: ពន្ធលើប្រាក់ចំណូល (រូបវន្តបុគ្គល) | K22: =SUM(I22:J22) -> 0 | L22: =IFERROR(K22/H22,"-") -> - | P22: =IFERROR(O22/H22,"-") -> - | Q22: =IF(OR(H22>0,O22>0),"ok","-") -> -
C23: 70012 | D23: ពន្ធលើប្រាក់ចំណូល (នីតិបុគ្គល) | K23: =SUM(I23:J23) -> 0 | L23: =IFERROR(K23/H23,"-") -> - | P23: =IFERROR(O23/H23,"-") -> - | Q23: =IF(OR(H23>0,O23>0),"ok","-") -> -
C24: 70013 | D24: ពន្ធលើប្រាក់បៀវត្ស | K24: =SUM(I24:J24) -> 0 | L24: =IFERROR(K24/H24,"-") -> - | P24: =IFERROR(O24/H24,"-") -> - | Q24: =IF(OR(H24>0,O24>0),"ok","-") -> -
C25: 70014 | D25: ពន្ធលើឈ្នួលចលននិងអចលនទ្រព្យ (រូបវន្តបុគ្គល) | K25: =SUM(I25:J25) -> 0 | L25: =IFERROR(K25/H25,"-") -> - | P25: =IFERROR(O25/H25,"-") -> - | Q25: =IF(OR(H25>0,O25>0),"ok","-") -> -
C26: 70015 | D26: ពន្ធលើឈ្នួលចលននិងអចលនទ្រព្យ (នីតិបុគ្គល) | K26: =SUM(I26:J26) -> 0 | L26: =IFERROR(K26/H26,"-") -> - | P26: =IFERROR(O26/H26,"-") -> - | Q26: =IF(OR(H26>0,O26>0),"ok","-") -> -
C27: 70016 | D27: ពន្ធលើប្រាក់ចំណូលនីតិបុគ្គលជាបន្ទុករបស់រដ្ឋ | K27: =SUM(I27:J27) -> 0 | L27: =IFERROR(K27/H27,"-") -> - | P27: =IFERROR(O27/H27,"-") -> - | Q27: =IF(OR(H27>0,O27>0),"ok","-") -> -
B28: 7002 | D28: ពន្ធប្រយោល | E28: =SUM(E29:E35) -> 0 | F28: =SUM(F29:F35) -> 0 | G28: =SUM(G29:G35) -> 0 | H28: =SUM(H29:H35) -> 0 | I28: =SUM(I29:I35) -> 0 | J28: =SUM(J29:J35) -> 0 | K28: =SUM(K29:K35) -> 0 | L28: =IFERROR(K28/H28,"-") -> - | M28: =SUM(M29:M35) -> 0 | N28: =SUM(N29:N35) -> 0 | O28: =SUM(O29:O35) -> 0 | P28: =IFERROR(O28/H28,"-") -> - | Q28: =IF(OR(H28>0,O28>0),"ok","-") -> -
C29: 70021 | D29: អាករលើផលរបរ | K29: =SUM(I29:J29) -> 0 | L29: =IFERROR(K29/H29,"-") -> - | P29: =IFERROR(O29/H29,"-") -> - | Q29: =IF(OR(H29>0,O29>0),"ok","-") -> -
C30: 70022 | D30: អាករលើតម្លៃបន្ថែម | K30: =SUM(I30:J30) -> 0 | L30: =IFERROR(K30/H30,"-") -> - | P30: =IFERROR(O30/H30,"-") -> - | Q30: =IF(OR(H30>0,O30>0),"ok","-") -> -
C31: 70023 | D31: អាករលើតម្លៃបន្ថែម​លើទំនិញជាបន្ទុករបស់​រដ្ឋ | K31: =SUM(I31:J31) -> 0 | L31: =IFERROR(K31/H31,"-") -> - | P31: =IFERROR(O31/H31,"-") -> - | Q31: =IF(OR(H31>0,O31>0),"ok","-") -> -
C32: 70024 | D32: អាករលើតម្លៃបន្ថែម​លើសេវាជាបន្ទុករបស់​រដ្ឋ | K32: =SUM(I32:J32) -> 0 | L32: =IFERROR(K32/H32,"-") -> - | P32: =IFERROR(O32/H32,"-") -> - | Q32: =IF(OR(H32>0,O32>0),"ok","-") -> -
C33: 70025 | D33: អាករលើតម្លៃបន្ថែម របបនាំចូល (សហគ្រាសប្រេងឥន្ធនៈ) | K33: =SUM(I33:J33) -> 0 | L33: =IFERROR(K33/H33,"-") -> - | P33: =IFERROR(O33/H33,"-") -> - | Q33: =IF(OR(H33>0,O33>0),"ok","-") -> -
C34: 70026 | D34: អាករលើតម្លៃបន្ថែម របបនាំចូល (សហគ្រាសផ្សេងៗទៀត) | K34: =SUM(I34:J34) -> 0 | L34: =IFERROR(K34/H34,"-") -> - | P34: =IFERROR(O34/H34,"-") -> - | Q34: =IF(OR(H34>0,O34>0),"ok","-") -> -
C35: 70027 | D35: អាករលើតម្លៃបន្ថែម របបនាំចូល (ជាបន្ទុករបស់រដ្ឋ) | K35: =SUM(I35:J35) -> 0 | L35: =IFERROR(K35/H35,"-") -> - | P35: =IFERROR(O35/H35,"-") -> - | Q35: =IF(OR(H35>0,O35>0),"ok","-") -> -
B36: 7003 | D36: អាករពិសេស | E36: =SUM(E37:E42) -> 0 | F36: =SUM(F37:F42) -> 0 | G36: =SUM(G37:G42) -> 0 | H36: =SUM(H37:H42) -> 0 | I36: =SUM(I37:I42) -> 0 | J36: =SUM(J37:J42) -> 0 | K36: =SUM(K37:K42) -> 0 | L36: =IFERROR(K36/H36,"-") -> - | M36: =SUM(M37:M42) -> 0 | N36: =SUM(N37:N42) -> 0 | O36: =SUM(O37:O42) -> 0 | P36: =IFERROR(O36/H36,"-") -> - | Q36: =IF(OR(H36>0,O36>0),"ok","-") -> -
C37: 70031 | D37: អាករពិសេសលើទំនិញមួយចំនួន | K37: =SUM(I37:J37) -> 0 | L37: =IFERROR(K37/H37,"-") -> - | P37: =IFERROR(O37/H37,"-") -> - | Q37: =IF(OR(H37>0,O37>0),"ok","-") -> -
C38: 70032 | D38: អាករពិសេសលើទំនិញមួយចំនួន របបនាំចូល (សហគ្រាសប្រេងឥន្ធនៈ) | K38: =SUM(I38:J38) -> 0 | L38: =IFERROR(K38/H38,"-") -> - | P38: =IFERROR(O38/H38,"-") -> - | Q38: =IF(OR(H38>0,O38>0),"ok","-") -> -
C39: 70033 | D39: អាករពិសេសលើទំនិញមួយចំនួន របបនាំចូល (សហគ្រាសផ្សេងៗទៀត) | K39: =SUM(I39:J39) -> 0 | L39: =IFERROR(K39/H39,"-") -> - | P39: =IFERROR(O39/H39,"-") -> - | Q39: =IF(OR(H39>0,O39>0),"ok","-") -> -
C40: 70034 | D40: អាករពិសេសលើសេវាមួយចំនួន | K40: =SUM(I40:J40) -> 0 | L40: =IFERROR(K40/H40,"-") -> - | P40: =IFERROR(O40/H40,"-") -> - | Q40: =IF(OR(H40>0,O40>0),"ok","-") -> -
C41: 70035 | D41: អាករសម្រាប់បំភ្លឺសាធារណៈ | K41: =SUM(I41:J41) -> 0 | L41: =IFERROR(K41/H41,"-") -> - | P41: =IFERROR(O41/H41,"-") -> - | Q41: =IF(OR(H41>0,O41>0),"ok","-") -> -
C42: 70038 | D42: ផ្សេងៗ | K42: =SUM(I42:J42) -> 0 | L42: =IFERROR(K42/H42,"-") -> - | P42: =IFERROR(O42/H42,"-") -> - | Q42: =IF(OR(H42>0,O42>0),"ok","-") -> -
B43: 7004 | D43: អាករលើសេវាដែលបានកំណត់ | E43: =SUM(E44:E45) -> 0 | F43: =SUM(F44:F45) -> 0 | G43: =SUM(G44:G45) -> 0 | H43: =SUM(H44:H45) -> 0 | I43: =SUM(I44:I45) -> 0 | J43: =SUM(J44:J45) -> 0 | K43: =SUM(K44:K45) -> 0 | L43: =IFERROR(K43/H43,"-") -> - | M43: =SUM(M44:M45) -> 0 | N43: =SUM(N44:N45) -> 0 | O43: =SUM(O44:O45) -> 0 | P43: =IFERROR(O43/H43,"-") -> - | Q43: =IF(OR(H43>0,O43>0),"ok","-") -> -
C44: 70045 | D44: អាករលើការស្នាក់នៅ | K44: =SUM(I44:J44) -> 0 | L44: =IFERROR(K44/H44,"-") -> - | P44: =IFERROR(O44/H44,"-") -> - | Q44: =IF(OR(H44>0,O44>0),"ok","-") -> -
C45: 70046 | D45: ពន្ធសត្តឃាត | K45: =SUM(I45:J45) -> 0 | L45: =IFERROR(K45/H45,"-") -> - | P45: =IFERROR(O45/H45,"-") -> - | Q45: =IF(OR(H45>0,O45>0),"ok","-") -> -
B46: 7005 | D46: អាករលើការប្រើប្រាស់ទ្រព្យសម្បត្តិ ឬ ការអនុវត្តសកម្មភាព | E46: =SUM(E47:E49) -> 0 | F46: =SUM(F47:F49) -> 0 | G46: =SUM(G47:G49) -> 0 | H46: =SUM(H47:H49) -> 0 | I46: =SUM(I47:I49) -> 0 | J46: =SUM(J47:J49) -> 0 | K46: =SUM(K47:K49) -> 0 | L46: =IFERROR(K46/H46,"-") -> - | M46: =SUM(M47:M49) -> 0 | N46: =SUM(N47:N49) -> 0 | O46: =SUM(O47:O49) -> 0 | P46: =IFERROR(O46/H46,"-") -> - | Q46: =IF(OR(H46>0,O46>0),"ok","-") -> -
...

Sheet PB2-Exp
A5: គម្រោងថវិកាឆ្នាំ២០២៣
A6: គម្រោងចំណាយថវិកាតាមចំណាត់ថ្នាក់សេដ្ឋកិច្ច
A7: =Costing!$K$11 -> អគ្គនាយកដ្ឋានគោលនយោបាយ
T8: តារាងទី២ (តារាង ២"ក" ក្នុងសារាចររៀបចំគម្រោងថវិកាប្រចាំឆ្នាំ)
T9: ឯកតា៖ លានរៀល
D10: កូដអនុកម្មវិធី
A12: ជំពូក | B12: គណនី | C12: អនុគណនី | D12: ចំណាត់ថ្នាក់ចំណាយ (តាមតារាងមាតិកាថវិកា ) | E12: ចំណាយ ឆ្នាំ២០២១ (អនុវត្ត) | F12: ច្បាប់ហិរញ្ញវត្ថុឆ្នាំ២០២២ | I12: ប៉ាន់ស្មានអនុវត្តឆ្នាំ២០២២ | N12: គម្រោងថវិកាឆ្នាំ២០២៣ | Q12: កើន/ថយធៀប'២២ | S12: ចំណាយមិនប្រចាំ | T12: សង្ខេបបរិយាយមូលហេតុកើន/ថយ​ តាមគណនី ឬអនុគណនី
F13: ឥណទានដើមឆ្នាំ | G13: ឥណទាន វិចារណកម្ម | H13: ឥណទានថ្មី | I13: អនុវត្ដជាក់ស្ដែង ឆមាសទី១ | J13: ប៉ាន់ស្មានឆមាសទី២ | K13: ប៉ាន់​ស្មាន​ប្រចាំ​ឆ្នាំ | N13: ទឹកប្រាក់ | O13: %ឥ.ច្ប ២០២២ | P13: %ឥ.ថ្មី ២០២២ | Q13: ទឹកប្រាក់ | R13: %ឥ.ច្ប ២០២២
K14: ទឹកប្រាក់ | L14: %ឥ.ច្ប | M14: %ឥ.ថ្មី
A15: សរុបចំណាយថវិកាទូទៅរបស់រដ្ឋ (ក+ខ) | E15: =E16+E343 -> 21633.013 | F15: =F16+F343 -> 2069.399 | G15: =G16+G343 -> 0 | H15: =H16+H343 -> 2069.399 | I15: =I16+I343 -> 992.87 | J15: =J16+J343 -> 1076.529 | K15: =K16+K343 -> 2069.399 | L15: =IFERROR(K15/F15,"-") -> 1 | M15: =IFERROR(K15/H15,"-") -> 1 | N15: =N16+N343 -> #REF! | O15: =IFERROR(N15/F15,"-") -> - | P15: =IFERROR(N15/H15,"-") -> - | Q15: =Q16+Q343 -> #REF! | R15: =IFERROR(Q15/F15,"-") -> - | S15: =S16+S343 -> #REF! | U15: =IF(OR(F15>0,H15>0,N15>0),"ok","-") -> #REF!
A16: ក/.សរុបចំណាយចរន្ត (ក្រុមទី១+ក្រុមទី២) | E16: =E17+E324 -> 21633.013 | F16: =F17+F324 -> 2069.399 | G16: =G17+G324 -> 0 | H16: =H17+H324 -> 2069.399 | I16: =I17+I324 -> 992.87 | J16: =J17+J324 -> 1076.529 | K16: =K17+K324 -> 2069.399 | L16: =IFERROR(K16/F16,"-") -> 1 | M16: =IFERROR(K16/H16,"-") -> 1 | N16: =N17+N324 -> #REF! | O16: =IFERROR(N16/F16,"-") -> - | P16: =IFERROR(N16/H16,"-") -> - | Q16: =Q17+Q324 -> #REF! | R16: =IFERROR(Q16/F16,"-") -> - | S16: =S17+S324 -> #REF! | U16: =IF(OR(F16>0,H16>0,N16>0),"ok","-") -> #REF!
A17: ក្រុមទី១:ចំណាយពិត (ប្រភេទ១+២+៣+៤) | E17: =E18+E201+E215+E295 -> 21633.013 | F17: =F18+F201+F215+F295 -> 2069.399 | G17: =G18+G201+G215+G295 -> 0 | H17: =H18+H201+H215+H295 -> 2069.399 | I17: =I18+I201+I215+I295 -> 992.87 | J17: =J18+J201+J215+J295 -> 1076.529 | K17: =K18+K201+K215+K295 -> 2069.399 | L17: =IFERROR(K17/F17,"-") -> 1 | M17: =IFERROR(K17/H17,"-") -> 1 | N17: =N18+N201+N215+N295 -> #REF! | O17: =IFERROR(N17/F17,"-") -> - | P17: =IFERROR(N17/H17,"-") -> - | Q17: =Q18+Q201+Q215+Q295 -> #REF! | R17: =IFERROR(Q17/F17,"-") -> - | S17: =S18+S201+S215+S295 -> #REF! | U17: =IF(OR(F17>0,H17>0,N17>0),"ok","-") -> #REF!
A18: ប្រភេទទី១:មធ្យោបាយសេវា | E18: =E19+E63+E148 -> 1633.013 | F18: =F19+F63+F148 -> 2069.399 | G18: =G19+G63+G148 -> 0 | H18: =H19+H63+H148 -> 2069.399 | I18: =I19+I63+I148 -> 992.87 | J18: =J19+J63+J148 -> 1076.529 | K18: =K19+K63+K148 -> 2069.399 | L18: =IFERROR(K18/F18,"-") -> 1 | M18: =IFERROR(K18/H18,"-") -> 1 | N18: =N19+N63+N148 -> #REF! | O18: =IFERROR(N18/F18,"-") -> - | P18: =IFERROR(N18/H18,"-") -> - | Q18: =Q19+Q63+Q148 -> #REF! | R18: =IFERROR(Q18/F18,"-") -> - | S18: =S19+S63+S148 -> #REF! | U18: =IF(OR(F18>0,H18>0,N18>0),"ok","-") -> #REF!
A19: 60 | D19: ការទិញ | E19: =E20+E27+E32+E41+E46+E53+E57+E61 -> 247.847 | F19: =F20+F27+F32+F41+F46+F53+F57+F61 -> 322 | G19: =G20+G27+G32+G41+G46+G53+G57+G61 -> 0 | H19: =H20+H27+H32+H41+H46+H53+H57+H61 -> 322 | I19: =I20+I27+I32+I41+I46+I53+I57+I61 -> 279.97 | J19: =J20+J27+J32+J41+J46+J53+J57+J61 -> 42.03 | K19: =K20+K27+K32+K41+K46+K53+K57+K61 -> 322 | L19: =IFERROR(K19/F19,"-") -> 1 | M19: =IFERROR(K19/H19,"-") -> 1 | N19: =N20+N27+N32+N41+N46+N53+N57+N61 -> #REF! | O19: =IFERROR(N19/F19,"-") -> - | P19: =IFERROR(N19/H19,"-") -> - | Q19: =Q20+Q27+Q32+Q41+Q46+Q53+Q57+Q61 -> #REF! | R19: =IFERROR(Q19/F19,"-") -> - | S19: =S20+S27+S32+S41+S46+S53+S57+S61 -> #REF! | U19: =IF(OR(F19>0,H19>0,N19>0),"ok","-") -> #REF!
B20: 6001 | D20: សម្ភារផ្គត់ផ្គង់ថែទាំ | E20: =SUM(E21:E26) -> 86.662 | F20: =SUM(F21:F26) -> 104.3 | G20: =SUM(G21:G26) -> 0 | H20: =SUM(H21:H26) -> 104.3 | I20: =SUM(I21:I26) -> 96.81 | J20: =SUM(J21:J26) -> 7.49 | K20: =SUM(K21:K26) -> 104.3 | L20: =IFERROR(K20/F20,"-") -> 1 | M20: =IFERROR(K20/H20,"-") -> 1 | N20: =SUM(N21:N26) -> #REF! | O20: =IFERROR(N20/F20,"-") -> - | P20: =IFERROR(N20/H20,"-") -> - | Q20: =SUM(Q21:Q26) -> #REF! | R20: =IFERROR(Q20/F20,"-") -> - | S20: =SUM(S21:S26) -> #REF! | U20: =IF(OR(F20>0,H20>0,N20>0),"ok","-") -> #REF!
C21: 60011 | D21: សម្ភារផ្គត់ផ្គង់សម្អាតនិងអនាម័យ | E21: 33.355 | F21: 48.4 | H21: 48.4 | I21: 40.92 | J21: =H21-I21 -> 7.48 | K21: =SUM(I21:J21) -> 48.4 | L21: =IFERROR(K21/F21,"-") -> 1 | M21: =IFERROR(K21/H21,"-") -> 1 | N21: =#REF! -> #REF! | O21: =IFERROR(N21/F21,"-") -> - | P21: =IFERROR(N21/H21,"-") -> - | Q21: =N21-F21 -> #REF! | R21: =IFERROR(Q21/F21,"-") -> - | S21: =#REF! -> #REF! | T21: កើនលើការបន្ថែមសម្ភារៈអនាម័យសម្រាប់នាយកដ្ឋានថ្មី២ | U21: =IF(OR(F21>0,H21>0,N21>0),"ok","-") -> #REF!
C22: 60012 | D22: សម្ភារផ្គត់ផ្គង់សម្រាប់ថែទាំអគារ ប្រាសាទ និងសំណង់ផ្សេងៗ | J22: =H22-I22 -> 0 | K22: =SUM(I22:J22) -> 0 | L22: =IFERROR(K22/F22,"-") -> - | M22: =IFERROR(K22/H22,"-") -> - | N22: =#REF! -> #REF! | O22: =IFERROR(N22/F22,"-") -> - | P22: =IFERROR(N22/H22,"-") -> - | Q22: =N22-F22 -> #REF! | R22: =IFERROR(Q22/F22,"-") -> - | S22: =#REF! -> #REF! | U22: =IF(OR(F22>0,H22>0,N22>0),"ok","-") -> #REF!
C23: 60013 | D23: សម្ភារផ្គត់ផ្គង់សម្រាប់ថែទាំផ្លូវថ្នល់ ស្ពាន និងលូ | J23: =H23-I23 -> 0 | K23: =SUM(I23:J23) -> 0 | L23: =IFERROR(K23/F23,"-") -> - | M23: =IFERROR(K23/H23,"-") -> - | N23: =#REF! -> #REF! | O23: =IFERROR(N23/F23,"-") -> - | P23: =IFERROR(N23/H23,"-") -> - | Q23: =N23-F23 -> #REF! | R23: =IFERROR(Q23/F23,"-") -> - | S23: =#REF! -> #REF! | U23: =IF(OR(F23>0,H23>0,N23>0),"ok","-") -> #REF!
C24: 60014 | D24: សម្ភារផ្គត់ផ្គង់សម្រាប់ថែទាំសម្ភារ ឧបករណ៍ | E24: 26.207 | F24: 28.8 | H24: 28.8 | I24: 28.79 | J24: =H24-I24 -> 0.01 | K24: =SUM(I24:J24) -> 28.8 | L24: =IFERROR(K24/F24,"-") -> 1 | M24: =IFERROR(K24/H24,"-") -> 1 | N24: =#REF! -> #REF! | O24: =IFERROR(N24/F24,"-") -> - | P24: =IFERROR(N24/H24,"-") -> - | Q24: =N24-F24 -> #REF! | R24: =IFERROR(Q24/F24,"-") -> - | S24: =#REF! -> #REF! | T24: កើនលើការបន្ថែមការទិញសំបកកង់រថយន្តជូនថ្នាក់ដឹកនាំសម្រាប់នាយកដ្ឋានថ្មី២ | U24: =IF(OR(F24>0,H24>0,N24>0),"ok","-") -> #REF!
C25: 60015 | D25: ប្រេងឥន្ធនៈនិងប្រេងរំអិល | E25: =54.2/2 -> 27.1 | F25: 27.1 | H25: 27.1 | I25: 27.1 | J25: =H25-I25 -> 0 | K25: =SUM(I25:J25) -> 27.1 | L25: =IFERROR(K25/F25,"-") -> 1 | M25: =IFERROR(K25/H25,"-") -> 1 | N25: =#REF! -> #REF! | O25: =IFERROR(N25/F25,"-") -> - | P25: =IFERROR(N25/H25,"-") -> - | Q25: =N25-F25 -> #REF! | R25: =IFERROR(Q25/F25,"-") -> - | S25: =#REF! -> #REF! | T25: កើនដោយសារតម្លៃប្រេងលើទីផ្សារកើនឡើង និងលើការបន្ថែមថវិកាសម្រាប់នាយកដ្ឋានថ្មី២ | U25: =IF(OR(F25>0,H25>0,N25>0),"ok","-") -> #REF!
C26: 60018 | D26: សម្ភារផ្គត់ផ្គង់ថែទាំផ្សេងៗ | J26: =H26-I26 -> 0 | K26: =SUM(I26:J26) -> 0 | L26: =IFERROR(K26/F26,"-") -> - | M26: =IFERROR(K26/H26,"-") -> - | N26: =#REF! -> #REF! | O26: =IFERROR(N26/F26,"-") -> - | P26: =IFERROR(N26/H26,"-") -> - | Q26: =N26-F26 -> #REF! | R26: =IFERROR(Q26/F26,"-") -> - | S26: =#REF! -> #REF! | U26: =IF(OR(F26>0,H26>0,N26>0),"ok","-") -> #REF!
B27: 6002 | D27: សម្ភារផ្គត់ផ្គង់ផ្នែករដ្ឋបាល | E27: =SUM(E28:E31) -> 98.34 | F27: =SUM(F28:F31) -> 106 | G27: =SUM(G28:G31) -> 0 | H27: =SUM(H28:H31) -> 106 | I27: =SUM(I28:I31) -> 88.29 | J27: =SUM(J28:J31) -> 17.71 | K27: =SUM(K28:K31) -> 106 | L27: =IFERROR(K27/F27,"-") -> 1 | M27: =IFERROR(K27/H27,"-") -> 1 | N27: =SUM(N28:N31) -> #REF! | O27: =IFERROR(N27/F27,"-") -> - | P27: =IFERROR(N27/H27,"-") -> - | Q27: =SUM(Q28:Q31) -> #REF! | R27: =IFERROR(Q27/F27,"-") -> - | S27: =SUM(S28:S31) -> #REF! | U27: =IF(OR(F27>0,H27>0,N27>0),"ok","-") -> #REF!
C28: 60021 | D28: សម្ភារការិយាល័យ | E28: 73.468 | F28: 106 | H28: 106 | I28: 88.29 | J28: =H28-I28 -> 17.71 | K28: =SUM(I28:J28) -> 106 | L28: =IFERROR(K28/F28,"-") -> 1 | M28: =IFERROR(K28/H28,"-") -> 1 | N28: =#REF! -> #REF! | O28: =IFERROR(N28/F28,"-") -> - | P28: =IFERROR(N28/H28,"-") -> - | Q28: =N28-F28 -> #REF! | R28: =IFERROR(Q28/F28,"-") -> - | S28: =#REF! -> #REF! | T28: កើនលើការបន្ថែមសម្ភារៈការិយាល័យសម្រាប់នាយកដ្ឋានថ្មី២ | U28: =IF(OR(F28>0,H28>0,N28>0),"ok","-") -> #REF!
C29: 60022 | D29: សៀវភៅមើលនិងឯកសារ | J29: =I29-H29 -> 0 | K29: =SUM(I29:J29) -> 0 | L29: =IFERROR(K29/F29,"-") -> - | M29: =IFERROR(K29/H29,"-") -> - | N29: =#REF! -> #REF! | O29: =IFERROR(N29/F29,"-") -> - | P29: =IFERROR(N29/H29,"-") -> - | Q29: =N29-F29 -> #REF! | R29: =IFERROR(Q29/F29,"-") -> - | S29: =#REF! -> #REF! | U29: =IF(OR(F29>0,H29>0,N29>0),"ok","-") -> #REF!
C30: 60023 | D30: ការបោះពុម្ព | E30: 24.872 | J30: =I30-H30 -> 0 | K30: =SUM(I30:J30) -> 0 | L30: =IFERROR(K30/F30,"-") -> - | M30: =IFERROR(K30/H30,"-") -> - | N30: =#REF! -> #REF! | O30: =IFERROR(N30/F30,"-") -> - | P30: =IFERROR(N30/H30,"-") -> - | Q30: =N30-F30 -> #REF! | R30: =IFERROR(Q30/F30,"-") -> - | S30: =#REF! -> #REF! | U30: =IF(OR(F30>0,H30>0,N30>0),"ok","-") -> #REF!
C31: 60028 | D31: សម្ភារផ្គត់ផ្គង់ផ្នែករដ្ឋបាលផ្សេងៗ | J31: =I31-H31 -> 0 | K31: =SUM(I31:J31) -> 0 | L31: =IFERROR(K31/F31,"-") -> - | M31: =IFERROR(K31/H31,"-") -> - | N31: =#REF! -> #REF! | O31: =IFERROR(N31/F31,"-") -> - | P31: =IFERROR(N31/H31,"-") -> - | Q31: =N31-F31 -> #REF! | R31: =IFERROR(Q31/F31,"-") -> - | S31: =#REF! -> #REF! | U31: =IF(OR(F31>0,H31>0,N31>0),"ok","-") -> #REF!
B32: 6003 | D32: ស្បៀងអាហារនិងផលិតផលកសិកម្ម | E32: =SUM(E33:E40) -> 42.934 | F32: =SUM(F33:F40) -> 56.8 | G32: =SUM(G33:G40) -> 0 | H32: =SUM(H33:H40) -> 56.8 | I32: =SUM(I33:I40) -> 47.36 | J32: =SUM(J33:J40) -> 9.44 | K32: =SUM(K33:K40) -> 56.8 | L32: =IFERROR(K32/F32,"-") -> 1 | M32: =IFERROR(K32/H32,"-") -> 1 | N32: =SUM(N33:N40) -> #REF! | O32: =IFERROR(N32/F32,"-") -> - | P32: =IFERROR(N32/H32,"-") -> - | Q32: =SUM(Q33:Q40) -> #REF! | R32: =IFERROR(Q32/F32,"-") -> - | S32: =SUM(S33:S40) -> #REF! | U32: =IF(OR(F32>0,H32>0,N32>0),"ok","-") -> #REF!
C33: 60031 | D33: ស្បៀង | K33: =SUM(I33:J33) -> 0 | L33: =IFERROR(K33/F33,"-") -> - | M33: =IFERROR(K33/H33,"-") -> - | N33: =#REF! -> #REF! | O33: =IFERROR(N33/F33,"-") -> - | P33: =IFERROR(N33/H33,"-") -> - | Q33: =N33-F33 -> #REF! | R33: =IFERROR(Q33/F33,"-") -> - | S33: =#REF! -> #REF! | U33: =IF(OR(F33>0,H33>0,N33>0),"ok","-") -> #REF!
C34: 60032 | D34: ចំណីសត្វ | K34: =SUM(I34:J34) -> 0 | L34: =IFERROR(K34/F34,"-") -> - | M34: =IFERROR(K34/H34,"-") -> - | N34: =#REF! -> #REF! | O34: =IFERROR(N34/F34,"-") -> - | P34: =IFERROR(N34/H34,"-") -> - | Q34: =N34-F34 -> #REF! | R34: =IFERROR(Q34/F34,"-") -> - | S34: =#REF! -> #REF! | U34: =IF(OR(F34>0,H34>0,N34>0),"ok","-") -> #REF!
C35: 60033 | D35: ពូជនិងកូនរុក្ខជាតិ | K35: =SUM(I35:J35) -> 0 | L35: =IFERROR(K35/F35,"-") -> - | M35: =IFERROR(K35/H35,"-") -> - | N35: =#REF! -> #REF! | O35: =IFERROR(N35/F35,"-") -> - | P35: =IFERROR(N35/H35,"-") -> - | Q35: =N35-F35 -> #REF! | R35: =IFERROR(Q35/F35,"-") -> - | S35: =#REF! -> #REF! | U35: =IF(OR(F35>0,H35>0,N35>0),"ok","-") -> #REF!
C36: 60034 | D36: ផលិតផលការពារសុខុមាលភាពរុក្ខជាតិនិងជី | K36: =SUM(I36:J36) -> 0 | L36: =IFERROR(K36/F36,"-") -> - | M36: =IFERROR(K36/H36,"-") -> - | N36: =#REF! -> #REF! | O36: =IFERROR(N36/F36,"-") -> - | P36: =IFERROR(N36/H36,"-") -> - | Q36: =N36-F36 -> #REF! | R36: =IFERROR(Q36/F36,"-") -> - | S36: =#REF! -> #REF! | U36: =IF(OR(F36>0,H36>0,N36>0),"ok","-") -> #REF!
C37: 60035 | D37: ពូជសត្វ | K37: =SUM(I37:J37) -> 0 | L37: =IFERROR(K37/F37,"-") -> - | M37: =IFERROR(K37/H37,"-") -> - | N37: =#REF! -> #REF! | O37: =IFERROR(N37/F37,"-") -> - | P37: =IFERROR(N37/H37,"-") -> - | Q37: =N37-F37 -> #REF! | R37: =IFERROR(Q37/F37,"-") -> - | S37: =#REF! -> #REF! | U37: =IF(OR(F37>0,H37>0,N37>0),"ok","-") -> #REF!
C38: 60036 | D38: ឱសថ និងវត្ថុធាតុសម្រាប់បសុពេទ្យ | K38: =SUM(I38:J38) -> 0 | L38: =IFERROR(K38/F38,"-") -> - | M38: =IFERROR(K38/H38,"-") -> - | N38: =#REF! -> #REF! | O38: =IFERROR(N38/F38,"-") -> - | P38: =IFERROR(N38/H38,"-") -> - | Q38: =N38-F38 -> #REF! | R38: =IFERROR(Q38/F38,"-") -> - | S38: =#REF! -> #REF! | U38: =IF(OR(F38>0,H38>0,N38>0),"ok","-") -> #REF!
C39: 60037 | D39: ស្បៀងសម្រាប់រដ្ឋបាល | E39: 42.934 | F39: 56.8 | H39: 56.8 | I39: 47.36 | J39: =H39-I39 -> 9.44 | K39: =SUM(I39:J39) -> 56.8 | L39: =IFERROR(K39/F39,"-") -> 1 | M39: =IFERROR(K39/H39,"-") -> 1 | N39: =#REF! -> #REF! | O39: =IFERROR(N39/F39,"-") -> - | P39: =IFERROR(N39/H39,"-") -> - | Q39: =N39-F39 -> #REF! | R39: =IFERROR(Q39/F39,"-") -> - | S39: =#REF! -> #REF! | T39: កើនលើការបន្ថែមស្បៀងសម្រាប់ប្រើប្រាស់លើនាយកដ្ឋានថ្មី២ | U39: =IF(OR(F39>0,H39>0,N39>0),"ok","-") -> #REF!
C40: 60038 | D40: ស្បៀងអាហារ និងផលិតផលកសិកម្មផ្សេងៗ | K40: =SUM(I40:J40) -> 0 | L40: =IFERROR(K40/F40,"-") -> - | M40: =IFERROR(K40/H40,"-") -> - | N40: =#REF! -> #REF! | O40: =IFERROR(N40/F40,"-") -> - | P40: =IFERROR(N40/H40,"-") -> - | Q40: =N40-F40 -> #REF! | R40: =IFERROR(Q40/F40,"-") -> - | S40: =#REF! -> #REF! | U40: =IF(OR(F40>0,H40>0,N40>0),"ok","-") -> #REF!
B41: 6004 | D41: សំលៀកបំពាក់និងការតុបតែង | E41: =SUM(E42:E45) -> 0 | F41: =SUM(F42:F45) -> 0 | G41: =SUM(G42:G45) -> 0 | H41: =SUM(H42:H45) -> 0 | I41: =SUM(I42:I45) -> 0 | J41: =SUM(J42:J45) -> 0 | K41: =SUM(K42:K45) -> 0 | L41: =IFERROR(K41/F41,"-") -> - | M41: =IFERROR(K41/H41,"-") -> - | N41: =SUM(N42:N45) -> #REF! | O41: =IFERROR(N41/F41,"-") -> - | P41: =IFERROR(N41/H41,"-") -> - | Q41: =SUM(Q42:Q45) -> #REF! | R41: =IFERROR(Q41/F41,"-") -> - | S41: =SUM(S42:S45) -> #REF! | U41: =IF(OR(F41>0,H41>0,N41>0),"ok","-") -> #REF!
C42: 60041 | D42: ឯកសណ្ឋាន | K42: =SUM(I42:J42) -> 0 | L42: =IFERROR(K42/F42,"-") -> - | M42: =IFERROR(K42/H42,"-") -> - | N42: =#REF! -> #REF! | O42: =IFERROR(N42/F42,"-") -> - | P42: =IFERROR(N42/H42,"-") -> - | Q42: =N42-F42 -> #REF! | R42: =IFERROR(Q42/F42,"-") -> - | S42: =#REF! -> #REF! | U42: =IF(OR(F42>0,H42>0,N42>0),"ok","-") -> #REF!
C43: 60042 | D43: សំលៀកបំពាក់ការពារសុវត្ថិភាព | K43: =SUM(I43:J43) -> 0 | L43: =IFERROR(K43/F43,"-") -> - | M43: =IFERROR(K43/H43,"-") -> - | N43: =#REF! -> #REF! | O43: =IFERROR(N43/F43,"-") -> - | P43: =IFERROR(N43/H43,"-") -> - | Q43: =N43-F43 -> #REF! | R43: =IFERROR(Q43/F43,"-") -> - | S43: =#REF! -> #REF! | U43: =IF(OR(F43>0,H43>0,N43>0),"ok","-") -> #REF!
C44: 60043 | D44: មេដាយ (គ្រឿងឥស្សរិយយស) | K44: =SUM(I44:J44) -> 0 | L44: =IFERROR(K44/F44,"-") -> - | M44: =IFERROR(K44/H44,"-") -> - | N44: =#REF! -> #REF! | O44: =IFERROR(N44/F44,"-") -> - | P44: =IFERROR(N44/H44,"-") -> - | Q44: =N44-F44 -> #REF! | R44: =IFERROR(Q44/F44,"-") -> - | S44: =#REF! -> #REF! | U44: =IF(OR(F44>0,H44>0,N44>0),"ok","-") -> #REF!
C45: 60048 | D45: សំលៀកបំពាក់និងការតុបតែងផ្សេងៗ | K45: =SUM(I45:J45) -> 0 | L45: =IFERROR(K45/F45,"-") -> - | M45: =IFERROR(K45/H45,"-") -> - | N45: =#REF! -> #REF! | O45: =IFERROR(N45/F45,"-") -> - | P45: =IFERROR(N45/H45,"-") -> - | Q45: =N45-F45 -> #REF! | R45: =IFERROR(Q45/F45,"-") -> - | S45: =#REF! -> #REF! | U45: =IF(OR(F45>0,H45>0,N45>0),"ok","-") -> #REF!
...

Sheet Prog
C5: គម្រោងថវិកាឆ្នាំ២០២៣
C6: គោលបំណង និងការទទួលខុសត្រូវលើអនុកម្មវិធី
C7: =Costing!$K$11 -> អគ្គនាយកដ្ឋានគោលនយោបាយ
E8: តារាងទី៥ (តារាង ៥"ក" ក្នុងសារាចររៀបចំគម្រោងថវិកាប្រចាំឆ្នាំ)
E9: ឯកតា៖ លានរៀល
A12: Check | B12: កូដកម្មវិធី | C12: បរិយាយកម្មវិធី និងអនុកម្មវិធី | D12: អង្គភាពទទួលខុសត្រូវ | E12: ការពណ៌នាគោលបំណង (អនុកម្មវិធី) (អាចដកស្រង់ចេញពីផែនការយុទ្ធសាស្ត្រថវិកា២០២២-២០២៤)
B13: =A14 -> 101 | C13: =#REF! -> #REF! | F13: =IF(AND(C13<>"",D13<>""),"ok","-") -> #REF!
A14: =LEFT(B14,3) -> 101 | B14: =Costing!$G$11 -> 10101 | C14: =IF(#REF!<>"",#REF!,"") -> #REF! | D14: =IF(#REF!<>"",#REF!,"") -> #REF! | F14: =IF(AND(C14<>"",D14<>""),"ok","-") -> #REF!
A15: =LEFT(B15,5) -> 10101 | B15: =$B$14&"01" -> 1010101 | C15: =IF(#REF!<>"",#REF!,"") -> #REF! | D15: =IF(#REF!<>"",#REF!,"") -> #REF! | F15: =IF(AND(C15<>"",D15<>""),"ok","-") -> #REF!
A16: =LEFT(B16,7) -> 1010101 | B16: =B15&"01" -> 101010101 | C16: =IF(#REF!<>"",#REF!,"") -> #REF! | D16: =IF(#REF!<>"",#REF!,"") -> #REF! | F16: =IF(AND(C16<>"",D16<>""),"ok","-") -> #REF!
A17: =LEFT(B17,7) -> 1010101 | B17: =B15&"02" -> 101010102 | C17: =IF(#REF!<>"",#REF!,"") -> #REF! | D17: =IF(#REF!<>"",#REF!,"") -> #REF! | F17: =IF(AND(C17<>"",D17<>""),"ok","-") -> #REF!
A18: =LEFT(B18,7) -> 1010101 | B18: =B15&"03" -> 101010103 | C18: =IF(#REF!<>"",#REF!,"") -> #REF! | D18: =IF(#REF!<>"",#REF!,"") -> #REF! | F18: =IF(AND(C18<>"",D18<>""),"ok","-") -> #REF!
A19: =LEFT(B19,7) -> 1010101 | B19: =B15&"04" -> 101010104 | C19: =IF(#REF!<>"",#REF!,"") -> #REF! | D19: =IF(#REF!<>"",#REF!,"") -> #REF! | F19: =IF(AND(C19<>"",D19<>""),"ok","-") -> #REF!
A20: =LEFT(B20,7) -> 1010101 | B20: =B15&"05" -> 101010105 | C20: =IF(#REF!<>"",#REF!,"") -> #REF! | D20: =IF(#REF!<>"",#REF!,"") -> #REF! | F20: =IF(AND(C20<>"",D20<>""),"ok","-") -> #REF!
A21: =LEFT(B21,7) -> 1010101 | B21: =B15&"06" -> 101010106 | C21: =IF(#REF!<>"",#REF!,"") -> #REF! | D21: =IF(#REF!<>"",#REF!,"") -> #REF! | F21: =IF(AND(C21<>"",D21<>""),"ok","-") -> #REF!
A22: =LEFT(B22,7) -> 1010101 | B22: =B15&"07" -> 101010107 | C22: =IF(#REF!<>"",#REF!,"") -> #REF! | D22: =IF(#REF!<>"",#REF!,"") -> #REF! | F22: =IF(AND(C22<>"",D22<>""),"ok","-") -> #REF!
A23: =LEFT(B23,7) -> 1010101 | B23: =B15&"08" -> 101010108 | C23: =IF(#REF!<>"",#REF!,"") -> #REF! | D23: =IF(#REF!<>"",#REF!,"") -> #REF! | F23: =IF(AND(C23<>"",D23<>""),"ok","-") -> #REF!
A24: =LEFT(B24,7) -> 1010101 | B24: =B15&"09" -> 101010109 | C24: =IF(#REF!<>"",#REF!,"") -> #REF! | D24: =IF(#REF!<>"",#REF!,"") -> #REF! | F24: =IF(AND(C24<>"",D24<>""),"ok","-") -> #REF!
A25: =LEFT(B25,7) -> 1010101 | B25: =B15&"10" -> 101010110 | C25: =IF(#REF!<>"",#REF!,"") -> #REF! | D25: =IF(#REF!<>"",#REF!,"") -> #REF! | F25: =IF(AND(C25<>"",D25<>""),"ok","-") -> #REF!
A26: =LEFT(B26,7) -> 1010101 | B26: =B15&"11" -> 101010111 | C26: =IF(#REF!<>"",#REF!,"") -> #REF! | D26: =IF(#REF!<>"",#REF!,"") -> #REF! | F26: =IF(AND(C26<>"",D26<>""),"ok","-") -> #REF!
A27: =LEFT(B27,7) -> 1010101 | B27: =B15&"12" -> 101010112 | C27: =IF(#REF!<>"",#REF!,"") -> #REF! | D27: =IF(#REF!<>"",#REF!,"") -> #REF! | F27: =IF(AND(C27<>"",D27<>""),"ok","-") -> #REF!
A28: =LEFT(B28,5) -> 10101 | B28: =$B$14&"02" -> 1010102 | C28: =IF(#REF!<>"",#REF!,"") -> #REF! | D28: =IF(#REF!<>"",#REF!,"") -> #REF! | F28: =IF(AND(C28<>"",D28<>""),"ok","-") -> #REF!
A29: =LEFT(B29,7) -> 1010102 | B29: =B28&"01" -> 101010201 | C29: =IF(#REF!<>"",#REF!,"") -> #REF! | D29: =IF(#REF!<>"",#REF!,"") -> #REF! | F29: =IF(AND(C29<>"",D29<>""),"ok","-") -> #REF!
A30: =LEFT(B30,7) -> 1010102 | B30: =B28&"02" -> 101010202 | C30: =IF(#REF!<>"",#REF!,"") -> #REF! | D30: =IF(#REF!<>"",#REF!,"") -> #REF! | F30: =IF(AND(C30<>"",D30<>""),"ok","-") -> #REF!
A31: =LEFT(B31,7) -> 1010102 | B31: =B28&"03" -> 101010203 | C31: =IF(#REF!<>"",#REF!,"") -> #REF! | D31: =IF(#REF!<>"",#REF!,"") -> #REF! | F31: =IF(AND(C31<>"",D31<>""),"ok","-") -> #REF!
A32: =LEFT(B32,7) -> 1010102 | B32: =B28&"04" -> 101010204 | C32: =IF(#REF!<>"",#REF!,"") -> #REF! | D32: =IF(#REF!<>"",#REF!,"") -> #REF! | F32: =IF(AND(C32<>"",D32<>""),"ok","-") -> #REF!
A33: =LEFT(B33,7) -> 1010102 | B33: =B28&"05" -> 101010205 | C33: =IF(#REF!<>"",#REF!,"") -> #REF! | D33: =IF(#REF!<>"",#REF!,"") -> #REF! | F33: =IF(AND(C33<>"",D33<>""),"ok","-") -> #REF!
A34: =LEFT(B34,7) -> 1010102 | B34: =B28&"06" -> 101010206 | C34: =IF(#REF!<>"",#REF!,"") -> #REF! | D34: =IF(#REF!<>"",#REF!,"") -> #REF! | F34: =IF(AND(C34<>"",D34<>""),"ok","-") -> #REF!
A35: =LEFT(B35,7) -> 1010102 | B35: =B28&"07" -> 101010207 | C35: =IF(#REF!<>"",#REF!,"") -> #REF! | D35: =IF(#REF!<>"",#REF!,"") -> #REF! | F35: =IF(AND(C35<>"",D35<>""),"ok","-") -> #REF!
A36: =LEFT(B36,7) -> 1010102 | B36: =B28&"08" -> 101010208 | C36: =IF(#REF!<>"",#REF!,"") -> #REF! | D36: =IF(#REF!<>"",#REF!,"") -> #REF! | F36: =IF(AND(C36<>"",D36<>""),"ok","-") -> #REF!
A37: =LEFT(B37,7) -> 1010102 | B37: =B28&"09" -> 101010209 | C37: =IF(#REF!<>"",#REF!,"") -> #REF! | D37: =IF(#REF!<>"",#REF!,"") -> #REF! | F37: =IF(AND(C37<>"",D37<>""),"ok","-") -> #REF!
A38: =LEFT(B38,7) -> 1010102 | B38: =B28&"10" -> 101010210 | C38: =IF(#REF!<>"",#REF!,"") -> #REF! | D38: =IF(#REF!<>"",#REF!,"") -> #REF! | F38: =IF(AND(C38<>"",D38<>""),"ok","-") -> #REF!
A39: =LEFT(B39,7) -> 1010102 | B39: =B28&"11" -> 101010211 | C39: =IF(#REF!<>"",#REF!,"") -> #REF! | D39: =IF(#REF!<>"",#REF!,"") -> #REF! | F39: =IF(AND(C39<>"",D39<>""),"ok","-") -> #REF!
A40: =LEFT(B40,7) -> 1010102 | B40: =B28&"12" -> 101010212 | C40: =IF(#REF!<>"",#REF!,"") -> #REF! | D40: =IF(#REF!<>"",#REF!,"") -> #REF! | F40: =IF(AND(C40<>"",D40<>""),"ok","-") -> #REF!
A41: =LEFT(B41,5) -> 10101 | B41: =$B$14&"03" -> 1010103 | C41: =IF(#REF!<>"",#REF!,"") -> #REF! | D41: =IF(#REF!<>"",#REF!,"") -> #REF! | F41: =IF(AND(C41<>"",D41<>""),"ok","-") -> #REF!
A42: =LEFT(B42,7) -> 1010103 | B42: =B41&"01" -> 101010301 | C42: =IF(#REF!<>"",#REF!,"") -> #REF! | D42: =IF(#REF!<>"",#REF!,"") -> #REF! | F42: =IF(AND(C42<>"",D42<>""),"ok","-") -> #REF!
A43: =LEFT(B43,7) -> 1010103 | B43: =B41&"02" -> 101010302 | C43: =IF(#REF!<>"",#REF!,"") -> #REF! | D43: =IF(#REF!<>"",#REF!,"") -> #REF! | F43: =IF(AND(C43<>"",D43<>""),"ok","-") -> #REF!
A44: =LEFT(B44,7) -> 1010103 | B44: =B41&"03" -> 101010303 | C44: =IF(#REF!<>"",#REF!,"") -> #REF! | D44: =IF(#REF!<>"",#REF!,"") -> #REF! | F44: =IF(AND(C44<>"",D44<>""),"ok","-") -> #REF!
A45: =LEFT(B45,7) -> 1010103 | B45: =B41&"04" -> 101010304 | C45: =IF(#REF!<>"",#REF!,"") -> #REF! | D45: =IF(#REF!<>"",#REF!,"") -> #REF! | F45: =IF(AND(C45<>"",D45<>""),"ok","-") -> #REF!
A46: =LEFT(B46,7) -> 1010103 | B46: =B41&"05" -> 101010305 | C46: =IF(#REF!<>"",#REF!,"") -> #REF! | D46: =IF(#REF!<>"",#REF!,"") -> #REF! | F46: =IF(AND(C46<>"",D46<>""),"ok","-") -> #REF!
...

Sheet Costing
D6: តារាងឧបសម្ព័ន្ធ
D7: ការគណនាតម្រូវការចំណាយលម្អិតឆ្នាំ២០២៣ តាមសកម្មភាព ចង្កោមសកម្មភាព អនុកម្មវិធី
D8: ="របស់"&K11 -> របស់អគ្គនាយកដ្ឋានគោលនយោបាយ
S9: តារាងទី១០
S10: ឯកតា៖ រៀល
D11: រចនាសម្ព័ន្ធកម្មវិធី | G11: 10101 | H11: អនុកម្មវិធីទី១.១ | I11: អង្គភាព | J11: 1002 | K11: អគ្គនាយកដ្ឋានគោលនយោបាយ
D13: សង្ខេបគម្រោងចំណាយ | I13: ប្រចាំ/មិនប្រចាំ | O13: ចំណាយតាមខែ | R13: ចំណាយតាមមុខសញ្ញា | W13: ប្រចាំ/មិនប្រចាំ | X13: រូបិយបណ្ណ | Y13: ខែ | Z13: មុខសញ្ញា
D14: ជំពូក | E14: ចំណាត់ថ្នាក់ចំណាយ | H14: គ្រោងឆ្នាំ២០២៣ | I14: ប្រចាំ | J14: មិនប្រចាំ | K14: row | O14: ខែ | P14: សរុបចំណាយ | R14: មុខសញ្ញា | S14: សរុបចំណាយ | W14: Regular | X14: KHR | Y14: 1 | Z14: លទ្ធកម្ម
D15: 60 | E15: ការទិញ | H15: =SUMIFS($P$32:$P$6606,$B$32:$B$6606,D15,$A$32:$A$6606,$G$11) -> 446300000 | I15: =SUMIFS($P$32:$P$6606,$B$32:$B$6606,$D15,$A$32:$A$6606,$G$11,$I$32:$I$6606,$W$14) -> 394100000 | J15: =SUMIFS($P$32:$P$6606,$B$32:$B$6606,$D15,$A$32:$A$6606,$G$11,$I$32:$I$6606,$W$15) -> 52200000 | K15: =MATCH(D15,#REF!,0) -> #REF! | O15: 1 | P15: =SUMIFS($P$32:$P$6606,$A$32:$A$6606,$G$11,$Q$32:$Q$6606,$O15) -> 0 | R15: លទ្ធកម្ម | S15: =SUMIFS($P$32:$P$6606,$A$32:$A$6606,$G$11,$R$32:$R$6606,$R15) -> 0 | W15: Irregular | Y15: 2 | Z15: រជ្ជទេយ្យ
D16: 61 | E16: សេវាកម្ម | H16: =SUMIFS($P$32:$P$6606,$B$32:$B$6606,D16,$A$32:$A$6606,$G$11) -> 1402600000 | I16: =SUMIFS($P$32:$P$6606,$B$32:$B$6606,$D16,$A$32:$A$6606,$G$11,$I$32:$I$6606,$W$14) -> 1402600000 | J16: =SUMIFS($P$32:$P$6606,$B$32:$B$6606,$D16,$A$32:$A$6606,$G$11,$I$32:$I$6606,$W$15) -> 0 | K16: =MATCH(D16,#REF!,0) -> #REF! | O16: 2 | P16: =SUMIFS($P$32:$P$6606,$A$32:$A$6606,$G$11,$Q$32:$Q$6606,$O16) -> 0 | R16: រជ្ជទេយ្យ | S16: =SUMIFS($P$32:$P$6606,$A$32:$A$6606,$G$11,$R$32:$R$6606,$R16) -> 0 | Y16: 3 | Z16: បើកប្រាក់មុន
D17: 62 | E17: អត្ថប្រយោជន៍សង្គម | H17: =SUMIFS($P$32:$P$6606,$B$32:$B$6606,D17,$A$32:$A$6606,$G$11) -> 0 | I17: =SUMIFS($P$32:$P$6606,$B$32:$B$6606,$D17,$A$32:$A$6606,$G$11,$I$32:$I$6606,$W$14) -> 0 | J17: =SUMIFS($P$32:$P$6606,$B$32:$B$6606,$D17,$A$32:$A$6606,$G$11,$I$32:$I$6606,$W$15) -> 0 | K17: =MATCH(D17,#REF!,0) -> #REF! | O17: 3 | P17: =SUMIFS($P$32:$P$6606,$A$32:$A$6606,$G$11,$Q$32:$Q$6606,$O17) -> 0 | R17: បើកប្រាក់មុន | S17: =SUMIFS($P$32:$P$6606,$A$32:$A$6606,$G$11,$R$32:$R$6606,$R17) -> 0 | Y17: 4 | Z17: បុរេប្រទាន
D18: 63 | E18: ពន្ធនិងអាករ | H18: =SUMIFS($P$32:$P$6606,$B$32:$B$6606,D18,$A$32:$A$6606,$G$11) -> 0 | I18: =SUMIFS($P$32:$P$6606,$B$32:$B$6606,$D18,$A$32:$A$6606,$G$11,$I$32:$I$6606,$W$14) -> 0 | J18: =SUMIFS($P$32:$P$6606,$B$32:$B$6606,$D18,$A$32:$A$6606,$G$11,$I$32:$I$6606,$W$15) -> 0 | K18: =MATCH(D18,#REF!,0) -> #REF! | O18: 4 | P18: =SUMIFS($P$32:$P$6606,$A$32:$A$6606,$G$11,$Q$32:$Q$6606,$O18) -> 0 | R18: បុរេប្រទាន | S18: =SUMIFS($P$32:$P$6606,$A$32:$A$6606,$G$11,$R$32:$R$6606,$R18) -> 0 | Y18: 5 | Z18: ផ្សេងៗ
D19: 64 | E19: បន្ទុកបុគ្គលិក | H19: =SUMIFS($P$32:$P$6606,$B$32:$B$6606,D19,$A$32:$A$6606,$G$11) -> 1261800000 | I19: =SUMIFS($P$32:$P$6606,$B$32:$B$6606,$D19,$A$32:$A$6606,$G$11,$I$32:$I$6606,$W$14) -> 1261800000 | J19: =SUMIFS($P$32:$P$6606,$B$32:$B$6606,$D19,$A$32:$A$6606,$G$11,$I$32:$I$6606,$W$15) -> 0 | K19: =MATCH(D19,#REF!,0) -> #REF! | O19: 5 | P19: =SUMIFS($P$32:$P$6606,$A$32:$A$6606,$G$11,$Q$32:$Q$6606,$O19) -> 0 | R19: ផ្សេងៗ | S19: =SUMIFS($P$32:$P$6606,$A$32:$A$6606,$G$11,$R$32:$R$6606,$R19) -> 0 | Y19: 6
D20: 65 | E20: ឧបត្ថម្ភធន | H20: =SUMIFS($P$32:$P$6606,$B$32:$B$6606,D20,$A$32:$A$6606,$G$11) -> 0 | I20: =SUMIFS($P$32:$P$6606,$B$32:$B$6606,$D20,$A$32:$A$6606,$G$11,$I$32:$I$6606,$W$14) -> 0 | J20: =SUMIFS($P$32:$P$6606,$B$32:$B$6606,$D20,$A$32:$A$6606,$G$11,$I$32:$I$6606,$W$15) -> 0 | K20: =MATCH(D20,#REF!,0) -> #REF! | O20: 6 | P20: =SUMIFS($P$32:$P$6606,$A$32:$A$6606,$G$11,$Q$32:$Q$6606,$O20) -> 0 | R20: សរុប | S20: =SUM(S15:S19) -> 0 | Y20: 7
D21: 66 | E21: បន្ទុកហិរញ្ញវត្ថុ | H21: =SUMIFS($P$32:$P$6606,$B$32:$B$6606,D21,$A$32:$A$6606,$G$11) -> 0 | I21: =SUMIFS($P$32:$P$6606,$B$32:$B$6606,$D21,$A$32:$A$6606,$G$11,$I$32:$I$6606,$W$14) -> 0 | J21: =SUMIFS($P$32:$P$6606,$B$32:$B$6606,$D21,$A$32:$A$6606,$G$11,$I$32:$I$6606,$W$15) -> 0 | K21: =MATCH(D21,#REF!,0) -> #REF! | O21: 7 | P21: =SUMIFS($P$32:$P$6606,$A$32:$A$6606,$G$11,$Q$32:$Q$6606,$O21) -> 0 | Y21: 8
D22: 67 | E22: បន្ទុកពិសេស | H22: =SUMIFS($P$32:$P$6606,$B$32:$B$6606,D22,$A$32:$A$6606,$G$11) -> 0 | I22: =SUMIFS($P$32:$P$6606,$B$32:$B$6606,$D22,$A$32:$A$6606,$G$11,$I$32:$I$6606,$W$14) -> 0 | J22: =SUMIFS($P$32:$P$6606,$B$32:$B$6606,$D22,$A$32:$A$6606,$G$11,$I$32:$I$6606,$W$15) -> 0 | K22: =MATCH(D22,#REF!,0) -> #REF! | O22: 8 | P22: =SUMIFS($P$32:$P$6606,$A$32:$A$6606,$G$11,$Q$32:$Q$6606,$O22) -> 0 | Y22: 9
D23: 68 | E23: ទាយជ្ជទានឱ្យដល់រំលស់អចលកម្ម | H23: =SUMIFS($P$32:$P$6606,$B$32:$B$6606,D23,$A$32:$A$6606,$G$11) -> 0 | I23: =SUMIFS($P$32:$P$6606,$B$32:$B$6606,$D23,$A$32:$A$6606,$G$11,$I$32:$I$6606,$W$14) -> 0 | J23: =SUMIFS($P$32:$P$6606,$B$32:$B$6606,$D23,$A$32:$A$6606,$G$11,$I$32:$I$6606,$W$15) -> 0 | K23: =MATCH(D23,#REF!,0) -> #REF! | O23: 9 | P23: =SUMIFS($P$32:$P$6606,$A$32:$A$6606,$G$11,$Q$32:$Q$6606,$O23) -> 0 | Y23: 10
D24: 69 | E24: ចំណាយមិនបានគ្រោងទុក | H24: =SUMIFS($P$32:$P$6606,$B$32:$B$6606,D24,$A$32:$A$6606,$G$11) -> 0 | I24: =SUMIFS($P$32:$P$6606,$B$32:$B$6606,$D24,$A$32:$A$6606,$G$11,$I$32:$I$6606,$W$14) -> 0 | J24: =SUMIFS($P$32:$P$6606,$B$32:$B$6606,$D24,$A$32:$A$6606,$G$11,$I$32:$I$6606,$W$15) -> 0 | K24: =MATCH(D24,#REF!,0) -> #REF! | O24: 10 | P24: =SUMIFS($P$32:$P$6606,$A$32:$A$6606,$G$11,$Q$32:$Q$6606,$O24) -> 0 | Y24: 11
D25: សរុប | H25: =SUM(H15:H24) -> 3110700000 | I25: =SUM(I15:I24) -> 3058500000 | J25: =SUM(J15:J24) -> 52200000 | O25: 11 | P25: =SUMIFS($P$32:$P$6606,$A$32:$A$6606,$G$11,$Q$32:$Q$6606,$O25) -> 0 | Y25: 12
O26: 12 | P26: =SUMIFS($P$32:$P$6606,$A$32:$A$6606,$G$11,$Q$32:$Q$6606,$O26) -> 0
O27: សរុប | P27: =SUM(P15:P26) -> 0
A29: កូដកម្មវិធី | B29: ជំពូក | C29: លេខ | D29: ល.រ. | E29: កូដច.ស. | F29: កូដសកម្មភាព | G29: អនុគណនី | H29: បរិយាយមុខសញ្ញា | I29: ប្រចាំ/មិនប្រចាំ | J29: ឯកតា | K29: បរិមាណ | L29: រូបិយបណ្ណ | M29: តម្លៃឯកតា | N29: តម្លៃ១លើក | O29: លើក/ឆ្នាំ | P29: សរុបប្រចាំឆ្នាំ | Q29: ខែ | R29: មុខសញ្ញា | S29: ផ្សេងៗ | U29: Check | V29: Check | W29: Check
D30: Line # | E30: Act. Cluster | F30: Prog. Activity | G30: Sub-Account | H30: Item Description | I30: Ir/Regular | J30: Unit Measure | K30: # of Units | L30: Currency | M30: Unit Price | N30: Total Amount | O30: # Times | P30: Total Annual Amount | Q30: Month | R30: Expense Type | S30: Misc. | U30: បរិមាណ | V30: តម្លៃឯកតា | W30: ចំនួនលើក
D31: 1 | E31: 2 | F31: 3 | G31: 4 | H31: 5 | I31: 6 | J31: 7 | K31: 8 | L31: 9 | M31: 10 | N31: 11=8*10 | O31: 12 | P31: 13=11*12 | Q31: 14 | R31: 15 | S31: 16
A32: =IF(AND(F32<>"",G32<>""),LEFT(E32,5),"") | B32: =IF(AND(F32<>"",G32<>""),LEFT(G32,2),"") | C32: =IF(AND(F32<>"",G32<>""),COUNT($C31:C$32)+1,"") | D32: =IF(C32<>"","LN"&TEXT(C32,"0000"),"") | E32: =IF(AND(F32<>"",G32<>""),LEFT(F32,7),"") | F32: =$G$11 -> 10101 | H32: =$H$11&" : "&$K$11 -> អនុកម្មវិធីទី១.១ : អគ្គនាយកដ្ឋានគោលនយោបាយ | N32: =IF(AND(F32<>"",G32<>""),K32*M32,"") | P32: =SUMIF($A33:$A$6606,F32,$P33:$P$6606) -> 3110700000 | T32: =IF(AND(F32<>"",G32<>""),"ok","-") -> -
A33: =IF(AND(F33<>"",G33<>""),LEFT(E33,5),"") | B33: =IF(AND(F33<>"",G33<>""),LEFT(G33,2),"") | C33: =IF(AND(F33<>"",G33<>""),COUNT($C$32:C32)+1,"") | D33: =IF(C33<>"","LN"&TEXT(C33,"0000"),"") | E33: =IF(AND(F33<>"",G33<>""),LEFT(F33,7),"") | F33: 1010101 | H33: ចង្កោមសកម្មភាពទី១៖ លេខាធិការដ្ឋាន | N33: =IF(AND(F33<>"",G33<>""),K33*M33,"") | P33: =SUMIF($E34:$E$6606,F33,$P34:$P$6606) -> 1211100000 | T33: =IF(AND(F33<>"",G33<>""),"ok","-") -> -
A34: =IF(AND(F34<>"",G34<>""),LEFT(E34,5),"") | B34: =IF(AND(F34<>"",G34<>""),LEFT(G34,2),"") | C34: =IF(AND(F34<>"",G34<>""),COUNT($C$32:C33)+1,"") | D34: =IF(C34<>"","LN"&TEXT(C34,"0000"),"") | E34: =IF(AND(F34<>"",G34<>""),LEFT(F34,7),"") | F34: 101010101 | H34: សកម្មភាពទី១ នៃចង្កោមសកម្មភាពទី១៖ បំពេញមុខងារជាលេខាធិការដ្ឋាន | N34: =IF(AND(F34<>"",G34<>""),K34*M34,"") | P34: =SUMIF($F35:$F$6606,F34,$P35:$P$6606) -> 1185100000 | T34: =IF(AND(F34<>"",G34<>""),"ok","-") -> -
A35: =IF(AND(F35<>"",G35<>""),LEFT(E35,5),"") | B35: =IF(AND(F35<>"",G35<>""),LEFT(G35,2),"") | C35: =IF(AND(F35<>"",G35<>""),COUNT($C$32:C34)+1,"") | D35: =IF(C35<>"","LN"&TEXT(C35,"0000"),"") | E35: =IF(AND(F35<>"",G35<>""),LEFT(F35,7),"") | H35: ១.បន្ទុកបុគ្គលិក | N35: =IF(AND(F35<>"",G35<>""),K35*M35,"") | P35: =SUM(P36:P46) -> 1114200000 | T35: =IF(AND(F35<>"",G35<>""),"ok","-") -> -
A36: =IF(AND(F36<>"",G36<>""),LEFT(E36,5),"") -> 10101 | B36: =IF(AND(F36<>"",G36<>""),LEFT(G36,2),"") -> 64 | C36: =IF(AND(F36<>"",G36<>""),COUNT($C$32:C35)+1,"") -> 1 | D36: =IF(C36<>"","LN"&TEXT(C36,"0000"),"") -> LN0001 | E36: =IF(AND(F36<>"",G36<>""),LEFT(F36,7),"") -> 1010101 | F36: 101010101 | G36: 64021 | H36: ប្រាក់បៀវត្សមូលដ្ឋានមន្ត្រីរាជការ ចំនួន ៥៦នាក់ | I36: Regular | J36: ខែ | K36: 1 | L36: KHR | M36: 50216000 | N36: =IF(AND(F36<>"",G36<>""),K36*M36,"") -> 50216000 | O36: 12 | P36: =IF(AND(F36<>"",G36<>""),N36*O36,"") -> 602592000 | T36: =IF(AND(F36<>"",G36<>""),"ok","-") -> ok | U36: =MOD(K36,1) -> 0 | V36: =MOD(M36,1) -> 0 | W36: =MOD(O36,1) -> 0
A37: =IF(AND(F37<>"",G37<>""),LEFT(E37,5),"") -> 10101 | B37: =IF(AND(F37<>"",G37<>""),LEFT(G37,2),"") -> 64 | C37: =IF(AND(F37<>"",G37<>""),COUNT($C$32:C36)+1,"") -> 2 | D37: =IF(C37<>"","LN"&TEXT(C37,"0000"),"") -> LN0002 | E37: =IF(AND(F37<>"",G37<>""),LEFT(F37,7),"") -> 1010101 | F37: 101010101 | G37: 64021 | H37: បង្រ្គប់ប្រាក់បៀវត្សមូលដ្ឋានមន្ត្រីរាជការ ចំនួន ៥៦នាក់ | I37: Regular | J37: ខែ | K37: 1 | L37: KHR | M37: 8000 | N37: =IF(AND(F37<>"",G37<>""),K37*M37,"") -> 8000 | O37: 1 | P37: =IF(AND(F37<>"",G37<>""),N37*O37,"") -> 8000 | T37: =IF(AND(F37<>"",G37<>""),"ok","-") -> ok | U37: =MOD(K37,1) -> 0 | V37: =MOD(M37,1) -> 0 | W37: =MOD(O37,1) -> 0
A38: =IF(AND(F38<>"",G38<>""),LEFT(E38,5),"") -> 10101 | B38: =IF(AND(F38<>"",G38<>""),LEFT(G38,2),"") -> 64 | C38: =IF(AND(F38<>"",G38<>""),COUNT($C$32:C37)+1,"") -> 3 | D38: =IF(C38<>"","LN"&TEXT(C38,"0000"),"") -> LN0003 | E38: =IF(AND(F38<>"",G38<>""),LEFT(F38,7),"") -> 1010101 | F38: 101010101 | G38: 64022 | H38: ប្រាក់បំណាច់មុខងារ ចំនួន ៥៦ នាក់ | I38: Regular | J38: ខែ | K38: 1 | L38: KHR | M38: 40050000 | N38: =IF(AND(F38<>"",G38<>""),K38*M38,"") -> 40050000 | O38: 12 | P38: =IF(AND(F38<>"",G38<>""),N38*O38,"") -> 480600000 | T38: =IF(AND(F38<>"",G38<>""),"ok","-") -> ok | U38: =MOD(K38,1) -> 0 | V38: =MOD(M38,1) -> 0 | W38: =MOD(O38,1) -> 0
A39: =IF(AND(F39<>"",G39<>""),LEFT(E39,5),"") -> 10101 | B39: =IF(AND(F39<>"",G39<>""),LEFT(G39,2),"") -> 64 | C39: =IF(AND(F39<>"",G39<>""),COUNT($C$32:C38)+1,"") -> 4 | D39: =IF(C39<>"","LN"&TEXT(C39,"0000"),"") -> LN0004 | E39: =IF(AND(F39<>"",G39<>""),LEFT(F39,7),"") -> 1010101 | F39: 101010101 | G39: 64022 | H39: បង្រ្គប់ប្រាក់បំណាច់មុខងារ ចំនួន ៥៦ នាក់ | I39: Regular | J39: ខែ | K39: 1 | L39: KHR | M39: 400000 | N39: =IF(AND(F39<>"",G39<>""),K39*M39,"") -> 400000 | O39: 1 | P39: =IF(AND(F39<>"",G39<>""),N39*O39,"") -> 400000 | T39: =IF(AND(F39<>"",G39<>""),"ok","-") -> ok | U39: =MOD(K39,1) -> 0 | V39: =MOD(M39,1) -> 0 | W39: =MOD(O39,1) -> 0
A40: =IF(AND(F40<>"",G40<>""),LEFT(E40,5),"") -> 10101 | B40: =IF(AND(F40<>"",G40<>""),LEFT(G40,2),"") -> 64 | C40: =IF(AND(F40<>"",G40<>""),COUNT($C$32:C39)+1,"") -> 5 | D40: =IF(C40<>"","LN"&TEXT(C40,"0000"),"") -> LN0005 | E40: =IF(AND(F40<>"",G40<>""),LEFT(F40,7),"") -> 1010101 | F40: 101010101 | G40: 64052 | H40: អ្នកសំរាលកូន (មាតុភាព) | I40: Regular | J40: នាក់ | K40: 3 | L40: KHR | M40: 800000 | N40: =IF(AND(F40<>"",G40<>""),K40*M40,"") -> 2400000 | O40: 1 | P40: =IF(AND(F40<>"",G40<>""),N40*O40,"") -> 2400000 | T40: =IF(AND(F40<>"",G40<>""),"ok","-") -> ok | U40: =MOD(K40,1) -> 0 | V40: =MOD(M40,1) -> 0 | W40: =MOD(O40,1) -> 0
A41: =IF(AND(F41<>"",G41<>""),LEFT(E41,5),"") -> 10101 | B41: =IF(AND(F41<>"",G41<>""),LEFT(G41,2),"") -> 64 | C41: =IF(AND(F41<>"",G41<>""),COUNT($C$32:C40)+1,"") -> 6 | D41: =IF(C41<>"","LN"&TEXT(C41,"0000"),"") -> LN0006 | E41: =IF(AND(F41<>"",G41<>""),LEFT(F41,7),"") -> 1010101 | F41: 101010101 | G41: 64061 | H41: កូនមានអាយុក្រោម 20ឆ្នាំ | I41: Regular | J41: នាក់ | K41: 32 | L41: KHR | M41: 10000 | N41: =IF(AND(F41<>"",G41<>""),K41*M41,"") -> 320000 | O41: 12 | P41: =IF(AND(F41<>"",G41<>""),N41*O41,"") -> 3840000 | T41: =IF(AND(F41<>"",G41<>""),"ok","-") -> ok | U41: =MOD(K41,1) -> 0 | V41: =MOD(M41,1) -> 0 | W41: =MOD(O41,1) -> 0
A42: =IF(AND(F42<>"",G42<>""),LEFT(E42,5),"") -> 10101 | B42: =IF(AND(F42<>"",G42<>""),LEFT(G42,2),"") -> 64 | C42: =IF(AND(F42<>"",G42<>""),COUNT($C$32:C39)+1,"") -> 5 | D42: =IF(C42<>"","LN"&TEXT(C42,"0000"),"") -> LN0005 | E42: =IF(AND(F42<>"",G42<>""),LEFT(F42,7),"") -> 1010101 | F42: 101010101 | G42: 64061 | H42: បង្គ្រប់កូនមានអាយុក្រោម 20ឆ្នាំ | I42: Regular | J42: នាក់ | K42: 1 | L42: KHR | M42: 60000 | N42: =IF(AND(F42<>"",G42<>""),K42*M42,"") -> 60000 | O42: 1 | P42: =IF(AND(F42<>"",G42<>""),N42*O42,"") -> 60000 | T42: =IF(AND(F42<>"",G42<>""),"ok","-") -> ok | U42: =MOD(K42,1) -> 0 | V42: =MOD(M42,1) -> 0 | W42: =MOD(O42,1) -> 0 | AA42: =AA49+AA219+AA382+AA383+AA617+AA768+AA872+AA873 -> 17664500
A43: =IF(AND(F43<>"",G43<>""),LEFT(E43,5),"") -> 10101 | B43: =IF(AND(F43<>"",G43<>""),LEFT(G43,2),"") -> 64 | C43: =IF(AND(F43<>"",G43<>""),COUNT($C$32:C42)+1,"") -> 8 | D43: =IF(C43<>"","LN"&TEXT(C43,"0000"),"") -> LN0008 | E43: =IF(AND(F43<>"",G43<>""),LEFT(F43,7),"") -> 1010101 | F43: 101010101 | G43: 64063 | H43: ប្រាក់បំណាច់អ្នកក្នុងបន្ទុក | I43: Regular | J43: នាក់ | K43: 10 | L43: KHR | M43: 15000 | N43: =IF(AND(F43<>"",G43<>""),K43*M43,"") -> 150000 | O43: 12 | P43: =IF(AND(F43<>"",G43<>""),N43*O43,"") -> 1800000 | T43: =IF(AND(F43<>"",G43<>""),"ok","-") -> ok | U43: =MOD(K43,1) -> 0 | V43: =MOD(M43,1) -> 0 | W43: =MOD(O43,1) -> 0
A44: =IF(AND(F44<>"",G44<>""),LEFT(E44,5),"") -> 10101 | B44: =IF(AND(F44<>"",G44<>""),LEFT(G44,2),"") -> 64 | C44: =IF(AND(F44<>"",G44<>""),COUNT($C$32:C41)+1,"") -> 7 | D44: =IF(C44<>"","LN"&TEXT(C44,"0000"),"") -> LN0007 | E44: =IF(AND(F44<>"",G44<>""),LEFT(F44,7),"") -> 1010101 | F44: 101010101 | G44: 64981 | H44: បន្ទុកផ្សេងៗទៀត | I44: Regular | J44: នាក់ | K44: 54 | L44: KHR | M44: 50000 | N44: =IF(AND(F44<>"",G44<>""),K44*M44,"") -> 2700000 | O44: 2 | P44: =IF(AND(F44<>"",G44<>""),N44*O44,"") -> 5400000 | T44: =IF(AND(F44<>"",G44<>""),"ok","-") -> ok | U44: =MOD(K44,1) -> 0 | V44: =MOD(M44,1) -> 0 | W44: =MOD(O44,1) -> 0 | AA44: =AA51+AA221+AA384+AA385+AA619+AA770+AA874+AA875 -> 0
A45: =IF(AND(F45<>"",G45<>""),LEFT(E45,5),"") -> 10101 | B45: =IF(AND(F45<>"",G45<>""),LEFT(G45,2),"") -> 64 | C45: =IF(AND(F45<>"",G45<>""),COUNT($C$32:C42)+1,"") -> 8 | D45: =IF(C45<>"","LN"&TEXT(C45,"0000"),"") -> LN0008 | E45: =IF(AND(F45<>"",G45<>""),LEFT(F45,7),"") -> 1010101 | F45: 101010101 | G45: 64041 | H45: ភ្នាក់ងារជាប់កិច្ចសន្យា ចំនួន ២នាក់ | I45: Regular | J45: នាក់ | K45: 2 | L45: KHR | M45: 710000 | N45: =IF(AND(F45<>"",G45<>""),K45*M45,"") -> 1420000 | O45: 12 | P45: =IF(AND(F45<>"",G45<>""),N45*O45,"") -> 17040000 | T45: =IF(AND(F45<>"",G45<>""),"ok","-") -> ok | U45: =MOD(K45,1) -> 0 | V45: =MOD(M45,1) -> 0 | W45: =MOD(O45,1) -> 0
