Workbook

Sheet Sheet1
A1: id | B1: rev_pro_id | C1: entity_id | D1: account_group_id | E1: account_id | F1: sub_account_id | H1: col1 | I1: col2 | J1: col3 | K1: finance_law | L1: annual_program_plan | M1: annual_percentage_law | N1: s1_total_bp | O1: s1_bp_jan | P1: s1_bp_feb | Q1: s1_bp_mar | R1: s1_total_est_imp | S1: s1_est_imp_jan | T1: s1_est_imp_feb | U1: s1_est_imp_mar | V1: s2_total_bp | W1: s2_bp_apr | X1: s2_bp_may | Y1: s2_bp_jun | Z1: s2_total_adj | AA1: s2_adj_apr | AB1: s2_adj_may | AC1: s2_adj_jun | AD1: s3_total_pb | AE1: s3_bp_jul | AF1: s3_bp_aug | AG1: s3_bp_sep | AH1: s3_total_est_imp | AI1: s3_est_imp_jul | AJ1: s3_est_imp_aug | AK1: s3_est_imp_sep | AL1: s4_total_bp | AM1: s4_bp_oct | AN1: s4_bp_nov | AO1: s4_bp_dec | AP1: s4_total_adj | AQ1: s4_adj_oct | AR1: s4_adj_nov | AS1: s4_adj_dec | AT1: remark
A2: 1 | B2: 0 | C2: 6 | J2: អគ្គនាយកដ្ឋានគយនិងរដ្ឋាករកម្ពុជា | K2: 0 | L2: 0 | M2: - | N2: 0 | O2: 0 | P2: 0 | Q2: 0 | R2: 0 | S2: 0 | T2: 0 | U2: 0 | V2: 0 | W2: 0 | X2: 0 | Y2: 0 | Z2: 0 | AA2: 0 | AB2: 0 | AC2: 0 | AD2: 0 | AE2: 0 | AF2: 0 | AG2: 0 | AH2: 0 | AI2: 0 | AJ2: 0 | AK2: 0 | AL2: 0 | AM2: 0 | AN2: 0 | AO2: 0 | AP2: 0 | AQ2: 0 | AR2: 0 | AS2: 0
A3: 2 | B3: 1 | D3: 18 | E3: 91 | F3: 482 | G3: 70 | H3: 7002 | I3: 70025 | J3: អាករលើតម្លៃបន្ថែម របបនាំចូល (សហគ្រាសប្រេងឥន្ធនៈ) | M3: - | N3: 0 | R3: 0 | V3: 0 | Z3: 0 | AD3: 0 | AH3: 0 | AL3: 0 | AP3: 0
A4: 3 | B4: 1 | D4: 18 | E4: 91 | F4: 483 | G4: 70 | H4: 7002 | I4: 70026 | J4: អាករលើតម្លៃបន្ថែម របបនាំចូល (សហគ្រាសផ្សេងៗទៀត) | M4: - | N4: 0 | R4: 0 | V4: 0 | Z4: 0 | AD4: 0 | AH4: 0 | AL4: 0 | AP4: 0
A5: 4 | B5: 1 | D5: 18 | E5: 91 | F5: 484 | G5: 70 | H5: 7002 | I5: 70027 | J5: អាករលើតម្លៃបន្ថែម របបនាំចូល (ជាបន្ទុករបស់រដ្ឋ) | M5: - | N5: 0 | R5: 0 | V5: 0 | Z5: 0 | AD5: 0 | AH5: 0 | AL5: 0 | AP5: 0
A6: 5 | B6: 1 | D6: 18 | E6: 92 | F6: 485 | G6: 70 | H6: 7003 | I6: 70032 | J6: អាករពិសេសលើទំនិញមួយចំនួន របបនាំចូល (សហគ្រាសប្រេងឥន្ធនៈ) | M6: - | N6: 0 | R6: 0 | V6: 0 | Z6: 0 | AD6: 0 | AH6: 0 | AL6: 0 | AP6: 0
A7: 6 | B7: 1 | D7: 18 | E7: 92 | F7: 486 | G7: 70 | H7: 7003 | I7: 70033 | J7: អាករពិសេសលើទំនិញមួយចំនួន របបនាំចូល (សហគ្រាសផ្សេងៗទៀត) | M7: - | N7: 0 | R7: 0 | V7: 0 | Z7: 0 | AD7: 0 | AH7: 0 | AL7: 0 | AP7: 0
A8: 7 | B8: 1 | D8: 19 | E8: 98 | F8: 487 | G8: 71 | H8: 7100 | I8: 71001 | J8: ពន្ធគយពីការនាំចូល | M8: - | N8: 0 | R8: 0 | V8: 0 | Z8: 0 | AD8: 0 | AH8: 0 | AL8: 0 | AP8: 0
A9: 8 | B9: 1 | D9: 19 | E9: 98 | F9: 488 | G9: 71 | H9: 7100 | I9: 71002 | J9: កម្រៃពីការងារគយ | M9: - | N9: 0 | R9: 0 | V9: 0 | Z9: 0 | AD9: 0 | AH9: 0 | AL9: 0 | AP9: 0
A10: 9 | B10: 1 | D10: 19 | E10: 98 | F10: 489 | G10: 71 | H10: 7100 | I10: 71003 | J10: ពន្ធគយលើផលិតផលតេលសីលា | M10: - | N10: 0 | R10: 0 | V10: 0 | Z10: 0 | AD10: 0 | AH10: 0 | AL10: 0 | AP10: 0
A11: 10 | B11: 1 | D11: 19 | E11: 98 | F11: 490 | G11: 71 | H11: 7100 | I11: 71004 | J11: អាករបន្ថែមលើផលិតផលតែលសិលាសំរាប់ថែទាំផ្លូវថ្នល់ | M11: - | N11: 0 | R11: 0 | V11: 0 | Z11: 0 | AD11: 0 | AH11: 0 | AL11: 0 | AP11: 0
A12: 11 | B12: 1 | D12: 19 | E12: 98 | F12: 491 | G12: 71 | H12: 7100 | I12: 71005 | J12: ផលពីការលក់ទំនិញរឹបអូស និងទំនិញគ្មានការទាមទារ | M12: - | N12: 0 | R12: 0 | V12: 0 | Z12: 0 | AD12: 0 | AH12: 0 | AL12: 0 | AP12: 0
A13: 12 | B13: 1 | D13: 19 | E13: 98 | F13: 492 | G13: 71 | H13: 7100 | I13: 71006 | J13: ពិន័យផ្សេងៗលើការនាំចូល | M13: - | N13: 0 | R13: 0 | V13: 0 | Z13: 0 | AD13: 0 | AH13: 0 | AL13: 0 | AP13: 0
A14: 13 | B14: 1 | D14: 19 | E14: 98 | F14: 493 | G14: 71 | H14: 7100 | I14: 71007 | J14: ពន្ធនាំចូល (ជាបន្ទុករបស់រដ្ឋ) | M14: - | N14: 0 | R14: 0 | V14: 0 | Z14: 0 | AD14: 0 | AH14: 0 | AL14: 0 | AP14: 0
... A24: 23 | B24: 1 | D24: 21 | E24: 109 | F24: 500 | G24: 73 | H24: 7308 | I24: 73087 | J24: ផលពីការត្រួតពិនិត្យគុណភាពផលិតផល និងការគោរពបទដ្ឋាន | M24: - | N24: 0 | R24: 0 | V24: 0 | Z24: 0 | AD24: 0 | AH24: 0 | AL24: 0 | AP24: 0
A25: 24 | B25: 0 | C25: 7 | F25: #N/A | J25: អគ្គនាយកដ្ឋានពន្ធដារ | K25: 0 | L25: 0 | M25: - | N25: 0 | O25: 0 | P25: 0 | Q25: 0 | R25: 0 | S25: 0 | T25: 0 | U25: 0 | V25: 0 | W25: 0 | X25: 0 | Y25: 0 | Z25: 0 | AA25: 0 | AB25: 0 | AC25: 0 | AD25: 0 | AE25: 0 | AF25: 0 | AG25: 0 | AH25: 0 | AI25: 0 | AJ25: 0 | AK25: 0 | AL25: 0 | AM25: 0 | AN25: 0 | AO25: 0 | AP25: 0 | AQ25: 0 | AR25: 0 | AS25: 0
A26: 25 | B26: 24 | D26: 18 | E26: 90 | F26: 457 | G26: 70 | H26: 7001 | I26: 70011 | J26: ពន្ធលើប្រាក់ចំណូល (រូបវន្តបុគ្គល) | L26: 0 | M26: - | N26: 0 | R26: 0 | V26: 0 | Z26: 0 | AD26: 0 | AH26: 0 | AL26: 0 | AP26: 0
A27: 26 | B27: 24 | D27: 18 | E27: 90 | F27: 458 | G27: 70 | H27: 7001 | I27: 70012 | J27: ពន្ធលើប្រាក់ចំណូល (នីតិបុគ្គល) | L27: 0 | M27: - | N27: 0 | R27: 0 | V27: 0 | Z27: 0 | AD27: 0 | AH27: 0 | AL27: 0 | AP27: 0
A28: 27 | B28: 24 | D28: 18 | E28: 90 | F28: 459 | G28: 70 | H28: 7001 | I28: 70013 | J28: ពន្ធលើប្រាក់បៀវត្ស | L28: 0 | M28: - | N28: 0 | R28: 0 | V28: 0 | Z28: 0 | AD28: 0 | AH28: 0 | AL28: 0 | AP28: 0
A29: 28 | B29: 24 | D29: 18 | E29: 90 | F29: 460 | G29: 70 | H29: 7001 | I29: 70014 | J29: ពន្ធលើឈ្នួលចលននិងអចលនទ្រព្យ (រូបវន្តបុគ្គល) | L29: 0 | M29: - | N29: 0 | R29: 0 | V29: 0 | Z29: 0 | AD29: 0 | AH29: 0 | AL29: 0 | AP29: 0
A30: 29 | B30: 24 | D30: 18 | E30: 90 | F30: 461 | G30: 70 | H30: 7001 | I30: 70015 | J30: ពន្ធលើឈ្នួលចលននិងអចលនទ្រព្យ (នីតិបុគ្គល) | L30: 0 | M30: - | N30: 0 | R30: 0 | V30: 0 | Z30: 0 | AD30: 0 | AH30: 0 | AL30: 0 | AP30: 0
A31: 30 | B31: 24 | D31: 18 | E31: 91 | F31: 462 | G31: 70 | H31: 7002 | I31: 70022 | J31: អាករលើតម្លៃបន្ថែម | L31: 0 | M31: - | N31: 0 | R31: 0 | V31: 0 | Z31: 0 | AD31: 0 | AH31: 0 | AL31: 0 | AP31: 0
A32: 31 | B32: 24 | D32: 18 | E32: 92 | F32: 463 | G32: 70 | H32: 7003 | I32: 70031 | J32: អាករពិសេសលើទំនិញមួយចំនួន | L32: 0 | M32: - | N32: 0 | R32: 0 | V32: 0 | Z32: 0 | AD32: 0 | AH32: 0 | AL32: 0 | AP32: 0
A33: 32 | B33: 24 | D33: 18 | E33: 92 | F33: 464 | G33: 70 | H33: 7003 | I33: 70034 | J33: អាករពិសេសលើសេវាមួយចំនួន | L33: 0 | M33: - | N33: 0 | R33: 0 | V33: 0 | Z33: 0 | AD33: 0 | AH33: 0 | AL33: 0 | AP33: 0
A34: 33 | B34: 24 | D34: 18 | E34: 97 | F34: 465 | G34: 70 | H34: 7008 | I34: 70081 | J34: ពន្ធតែមប្រិ៍ | L34: 0 | M34: - | N34: 0 | R34: 0 | V34: 0 | Z34: 0 | AD34: 0 | AH34: 0 | AL34: 0 | AP34: 0
A35: 34 | B35: 24 | D35: 18 | E35: 97 | F35: 466 | G35: 70 | H35: 7008 | I35: 70082 | J35: ប្រាក់ទោសទណ្ឌសារពើពន្ធ | L35: 0 | M35: - | N35: 0 | R35: 0 | V35: 0 | Z35: 0 | AD35: 0 | AH35: 0 | AL35: 0 | AP35: 0
A36: 35 | B36: 24 | D36: 21 | E36: 103 | F36: 467 | G36: 73 | H36: 7301 | I36: 73012 | J36: លក់ឯកសារ លតាប័ត្រ និង លិខិតបោះពុម្ភផ្សេងៗ | L36: 0 | M36: - | N36: 0 | R36: 0 | V36: 0 | Z36: 0 | AD36: 0 | AH36: 0 | AL36: 0 | AP36: 0
A37: 36 | B37: 24 | D37: 21 | E37: 104 | F37: 468 | G37: 73 | H37: 7302 | I37: 73023 | J37: ផលពីការបង្កើតសហគ្រាស | L37: 0 | M37: - | N37: 0 | R37: 0 | V37: 0 | Z37: 0 | AD37: 0 | AH37: 0 | AL37: 0 | AP37: 0
... A40: 39 | B40: 24 | D40: 21 | E40: 91 | F40: 471 | G40: 73 | H40: 7002 | I40: 70021 | J40: អាករលើផលរបរ | L40: 0 | M40: - | N40: 0 | R40: 0 | V40: 0 | Z40: 0 | AD40: 0 | AH40: 0 | AL40: 0 | AP40: 0
A41: 40 | B41: 0 | C41: 24 | F41: #N/A | J41: និយ័តករធានារ៉ាប់រងកម្ពុជា | K41: 0 | L41: 0 | M41: - | N41: 0 | O41: 0 | P41: 0 | Q41: 0 | R41: 0 | S41: 0 | T41: 0 | U41: 0 | V41: 0 | W41: 0 | X41: 0 | Y41: 0 | Z41: 0 | AA41: 0 | AB41: 0 | AC41: 0 | AD41: 0 | AE41: 0 | AF41: 0 | AG41: 0 | AH41: 0 | AI41: 0 | AJ41: 0 | AK41: 0 | AL41: 0 | AM41: 0 | AN41: 0 | AO41: 0 | AP41: 0 | AQ41: 0 | AR41: 0 | AS41: 0
A42: 41 | B42: 40 | D42: 21 | E42: 104 | F42: 472 | G42: 73 | H42: 7302 | I42: 73048 | J42: ផលពីសេវាផ្សេងៗទៀត | M42: - | N42: 0 | R42: 0 | V42: 0 | Z42: 0 | AD42: 0 | AH42: 0 | AL42: 0 | AP42: 0
A43: 42 | B43: 40 | D43: 21 | E43: 105 | F43: 473 | G43: 73 | H43: 7304 | I43: 73066 | J43: ចំណូលពីអាជ្ញាប័ណ្ណក្នុងស្រុក | M43: - | N43: 0 | R43: 0 | V43: 0 | Z43: 0 | AD43: 0 | AH43: 0 | AL43: 0 | AP43: 0
A44: 43 | B44: 0 | C44: 25 | F44: #N/A | J44: និយ័តករបរធនបាលកិច្ច | K44: 0 | L44: 0 | M44: - | N44: 0 | O44: 0 | P44: 0 | Q44: 0 | R44: 0 | S44: 0 | T44: 0 | U44: 0 | V44: 0 | W44: 0 | X44: 0 | Y44: 0 | Z44: 0 | AA44: 0 | AB44: 0 | AC44: 0 | AD44: 0 | AE44: 0 | AF44: 0 | AG44: 0 | AH44: 0 | AI44: 0 | AJ44: 0 | AK44: 0 | AL44: 0 | AM44: 0 | AN44: 0 | AO44: 0 | AP44: 0 | AQ44: 0 | AR44: 0 | AS44: 0
A45: 44 | B45: 43 | D45: 21 | E45: 104 | F45: 468 | G45: 73 | H45: 7302 | I45: 73023 | J45: ផលពីការបង្កើតសហគ្រាស | M45: - | N45: 0 | R45: 0 | V45: 0 | Z45: 0 | AD45: 0 | AH45: 0 | AL45: 0 | AP45: 0
A46: 45 | B46: 0 | C46: 26 | F46: #N/A | J46: និយ័តករអាជីវកម្មអចលនវត្ថុនិងបញ្ចាំ | K46: 0 | L46: 0 | M46: - | N46: 0 | O46: 0 | P46: 0 | Q46: 0 | R46: 0 | S46: 0 | T46: 0 | U46: 0 | V46: 0 | W46: 0 | X46: 0 | Y46: 0 | Z46: 0 | AA46: 0 | AB46: 0 | AC46: 0 | AD46: 0 | AE46: 0 | AF46: 0 | AG46: 0 | AH46: 0 | AI46: 0 | AJ46: 0 | AK46: 0 | AL46: 0 | AM46: 0 | AN46: 0 | AO46: 0 | AP46: 0 | AQ46: 0 | AR46: 0 | AS46: 0
A47: 46 | B47: 45 | D47: 21 | E47: 104 | F47: 468 | G47: 73 | H47: 7302 | I47: 73023 | J47: ផលពីការបង្កើតសហគ្រាស | L47: 0 | M47: - | N47: 0 | R47: 0 | V47: 0 | Z47: 0 | AD47: 0 | AH47: 0 | AL47: 0 | AP47: 0
A48: 47 | B48: 45 | D48: 21 | E48: 105 | F48: 472 | G48: 73 | H48: 7304 | I48: 73048 | J48: ផលពីសេវាផ្សេងៗទៀត | L48: 0 | M48: - | N48: 0 | R48: 0 | V48: 0 | Z48: 0 | AD48: 0 | AH48: 0 | AL48: 0 | AP48: 0
A49: 48 | B49: 45 | D49: 21 | E49: 107 | F49: 473 | G49: 73 | H49: 7306 | I49: 73066 | J49: ចំណូលពីអាជ្ញាប័ណ្ណក្នុងស្រុក | L49: 0 | M49: - | N49: 0 | R49: 0 | V49: 0 | Z49: 0 | AD49: 0 | AH49: 0 | AL49: 0 | AP49: 0
A50: 49 | B50: 0 | C50: 27 | F50: #N/A | J50: អគ្គលេខាធិការដ្ឋានគណៈកម្មការគ្រប់គ្រងល្បែងពាណិជ្ជកម្មកម្ពុជា | K50: 0 | L50: 0 | M50: - | N50: 0 | O50: 0 | P50: 0 | Q50: 0 | R50: 0 | S50: 0 | T50: 0 | U50: 0 | V50: 0 | W50: 0 | X50: 0 | Y50: 0 | Z50: 0 | AA50: 0 | AB50: 0 | AC50: 0 | AD50: 0 | AE50: 0 | AF50: 0 | AG50: 0 | AH50: 0 | AI50: 0 | AJ50: 0 | AK50: 0 | AL50: 0 | AM50: 0 | AN50: 0 | AO50: 0 | AP50: 0 | AQ50: 0 | AR50: 0 | AS50: 0
A51: 50 | B51: 49 | D51: 21 | E51: 107 | F51: 474 | G51: 73 | H51: 7306 | I51: 73061 | J51: ចំណូលពីកាតព្វកិច្ចកាស៊ីណូ | L51: 0 | M51: - | N51: 0 | R51: 0 | V51: 0 | Z51: 0 | AD51: 0 | AH51: 0 | AL51: 0 | AP51: 0
...

Sheet by Min.
AB2: ព្រះរាជាណាចក្រកម្ពុជា | AN2: ព្រះរាជាណាចក្រកម្ពុជា
G3: ក្រសួងសេដ្ឋកិច្ច​និងហិរញ្ញវត្ថុ | AB3: ជាតិ សាសនា ព្រះមហាក្សត្រ | AN3: ជាតិ សាសនា ព្រះមហាក្សត្រ
G4: អគ្គលេខាធិការដ្ឋាន | Y4: ​
G7: គម្រោងកម្មវិធីចំណូល​ថវិកាថ្នាក់ជាតិ-ប្រចាំឆ្នាំ២០២២
G8: របស់ក្រសួងសេដ្ឋកិច្ចនិងហិរញ្ញវត្ថុ
A9: id | B9: rev_pro_id | C9: entity_id | D9: account_group_id | E9: account_id | F9: sub_account_id | K9: finance_law | L9: annual_program_plan | M9: annual_percentage_law | N9: s1_total_bp | O9: s1_bp_jan | P9: s1_bp_feb | Q9: s1_bp_mar | R9: s1_total_est_imp | S9: s1_est_imp_jan | T9: s1_est_imp_feb | U9: s1_est_imp_mar | V9: s2_total_bp | W9: s2_bp_apr | X9: s2_bp_may | Y9: s2_bp_jun | Z9: s2_total_adj | AA9: s2_adj_apr | AB9: s2_adj_may | AC9: s2_adj_jun | AD9: s3_total_pb | AE9: s3_bp_jul | AF9: s3_bp_aug | AG9: s3_bp_sep | AH9: s3_total_est_imp | AI9: s3_est_imp_jul | AJ9: s3_est_imp_aug | AK9: s3_est_imp_sep | AL9: s4_total_bp | AM9: s4_bp_oct | AN9: s4_bp_nov | AO9: s4_bp_dec | AP9: s4_total_adj | AQ9: s4_adj_oct | AR9: s4_adj_nov | AS9: s4_adj_dec | AT9: remark | AU9: ឯកតា៖ ពាន់រៀល
G10: ជំពូក | H10: គណនី | I10: អនុគណនី | J10: ក្រសួង-ស្ថាប័ន | K10: ច្បាប់ ហិរញ្ញវត្ថុ | L10: សរុបគម្រោង កម្មវិធីប្រចាំឆ្នំា | N10: ត្រីមាសទី១ | V10: ត្រីមាសទី២ | AD10: ត្រីមាសទី៣ | AL10: ត្រីមាសទី៤ | AT10: ផ្សេងៗ
N11: គ្រោងដើមឆ្នាំ | R11: ប៉ាន់ស្មានអនុវត្ត | V11: គ្រោងដើមឆ្នាំ | Z11: ស្នើសុំកែតម្រូវ | AD11: គ្រោងដើមឆ្នាំ | AH11: ប៉ាន់ស្មានអនុវត្ត | AL11: គ្រោង​ដើមឆ្នាំ | AP11: ស្នើសុំ​កែតម្រូវ
L12: ទឹកប្រាក់ | M12: %ច្បាប់ | N12: សរុប | O12: ខែ១ | P12: ខែ​២ | Q12: ខែ​៣ | R12: សរុប | S12: អនុ.ខែ១ | T12: អនុ.ខែ​២ | U12: អនុ.ខែ​៣ | V12: សរុប | W12: ខែ៤ | X12: ខែ​៥ | Y12: ខែ​៦ | Z12: សរុប | AA12: ខែ៤ | AB12: ខែ​៥ | AC12: ខែ​៦ | AD12: សរុប | AE12: ខែ៧ | AF12: ខែ​៨ | AG12: ខែ​៩ | AH12: សរុប | AI12: អនុ.ខែ៧ | AJ12: អនុ.ខែ​៨ | AK12: ប៉ាន់អនុ.ខែ​៩ | AL12: សរុប | AM12: ខែ១០ | AN12: ខែ​១១ | AO12: ខែ​១២ | AP12: សរុប | AQ12: ខែ១០ | AR12: ខែ​១១ | AS12: ខែ​១២
J13: ក្រសួងសេដ្ឋកិច្ច និងហិរញ្ញវត្ថុ | K13: =K14+K87 -> 0 | L13: =L14+L87 -> 0 | M13: =IFERROR(L13/K13, "-") -> - | N13: =N14+N87 -> 0 | O13: =O14+O87 -> 0 | P13: =P14+P87 -> 0 | Q13: =Q14+Q87 -> 0 | R13: =R14+R87 -> 0 | S13: =S14+S87 -> 0 | T13: =T14+T87 -> 0 | U13: =U14+U87 -> 0 | ... AS13: =AS14+AS87 -> 0 | AU13: =IF(SUM(K13:L13)<>0, "OK", "-") -> -
G14: ១.សរុបរួមថ្នាក់កណ្តាល (បូកបញ្ចូលចំណូលមិនឆ្លងកាត់រតនាគារជាតិ) | K14: =K16+K39+K55+K58+K60+K64+K67 -> 0 | L14: =L16+L39+L55+L58+L60+L64+L67 -> 0 | M14: =IFERROR(L14/K14, "-") -> - | N14: =N16+N39+N55+N58+N60+N64+N67 -> 0 | O14: =O16+O39+O55+O58+O60+O64+O67 -> 0 | P14: =P16+P39+P55+P58+P60+P64+P67 -> 0 | Q14: =Q16+Q39+Q55+Q58+Q60+Q64+Q67 -> 0 | R14: =R16+R39+R55+R58+R60+R64+R67 -> 0 | S14: =S16+S39+S55+S58+S60+S64+S67 -> 0 | T14: =T16+T39+T55+T58+T60+T64+T67 -> 0 | U14: =U16+U39+U55+U58+U60+U64+U67 -> 0 | ... AS14: =AS16+AS39+AS55+AS58+AS60+AS64+AS67 -> 0 | AU14: =IF(SUM(K14:L14)<>0, "OK", "-") -> -
G15: ១.សរុបរួមថ្នាក់កណ្តាល (មិនបូកបញ្ចូលចំណូលមិនឆ្លងកាត់រតនាគារជាតិ) | K15: =K16+K39+K55+K58+K60+K64+K68 -> 0 | L15: =L16+L39+L55+L58+L60+L64+L68 -> 0 | M15: =IFERROR(L15/K15, "-") -> - | N15: =N16+N39+N55+N58+N60+N64+N68 -> 0 | O15: =O16+O39+O55+O58+O60+O64+O68 -> 0 | P15: =P16+P39+P55+P58+P60+P64+P68 -> 0 | Q15: =Q16+Q39+Q55+Q58+Q60+Q64+Q68 -> 0 | R15: =R16+R39+R55+R58+R60+R64+R68 -> 0 | S15: =S16+S39+S55+S58+S60+S64+S68 -> 0 | T15: =T16+T39+T55+T58+T60+T64+T68 -> 0 | U15: =U16+U39+U55+U58+U60+U64+U68 -> 0 | ... AS15: =AS16+AS39+AS55+AS58+AS60+AS64+AS68 -> 0 | AU15: =IF(SUM(K15:L15)<>0, "OK", "-") -> -
A16: 1 | C16: =IFERROR(INDEX([1]Entity!$A$2:$A$503,MATCH($J16,[1]Entity!$E$2:$E$503,0)),"") -> 6 | J16: អគ្គនាយកដ្ឋានគយនិងរដ្ឋាករកម្ពុជា | K16: =SUM(K17:K38) -> 0 | L16: =SUM(L17:L38) -> 0 | M16: =IFERROR(L16/K16, "-") -> - | N16: =SUM(N17:N38) -> 0 | O16: =SUM(O17:O38) -> 0 | P16: =SUM(P17:P38) -> 0 | Q16: =SUM(Q17:Q38) -> 0 | R16: =SUM(R17:R38) -> 0 | S16: =SUM(S17:S38) -> 0 | T16: =SUM(T17:T38) -> 0 | U16: =SUM(U17:U38) -> 0 | ... AS16: =SUM(AS17:AS38) -> 0 | AU16: =IF(SUM(K16:L16)<>0, "OK", "-") -> -
A17: 2 | B17: 1 | C17: =IFERROR(INDEX([1]Entity!$A$2:$A$503,MATCH($J17,[1]Entity!$E$2:$E$503,0)),"") | D17: =IFERROR(INDEX('[2]Account Group'!$A:$A,MATCH(G17,'[2]Account Group'!$B:$B,0)),"") -> 18 | E17: =IFERROR(INDEX([3]Account!$A:$A,MATCH(H17,[3]Account!$D:$D,0)),"") -> 91 | F17: =INDEX('[4]Sub Account'!$A:$A,MATCH(I17,'[4]Sub Account'!$D:$D,0)) -> 482 | G17: 70 | H17: 7002 | I17: 70025 | J17: អាករលើតម្លៃបន្ថែម របបនាំចូល (សហគ្រាសប្រេងឥន្ធនៈ) | M17: =IFERROR(L17/K17, "-") -> - | N17: =SUM(O17:Q17) -> 0 | R17: =SUM(S17:U17) -> 0 | V17: =SUM(W17:Y17) -> 0 | Z17: =SUM(AA17:AC17) -> 0 | AD17: =SUM(AE17:AG17) -> 0 | AH17: =SUM(AI17:AK17) -> 0 | AL17: =SUM(AM17:AO17) -> 0 | AP17: =SUM(AQ17:AS17) -> 0 | AU17: =IF(SUM(K17:L17)<>0, "OK", "-") -> -
A18: 3 | B18: 1 | C18: =IFERROR(INDEX([1]Entity!$A$2:$A$503,MATCH($J18,[1]Entity!$E$2:$E$503,0)),"") | D18: =IFERROR(INDEX('[2]Account Group'!$A:$A,MATCH(G18,'[2]Account Group'!$B:$B,0)),"") -> 18 | E18: =IFERROR(INDEX([3]Account!$A:$A,MATCH(H18,[3]Account!$D:$D,0)),"") -> 91 | F18: =INDEX('[4]Sub Account'!$A:$A,MATCH(I18,'[4]Sub Account'!$D:$D,0)) -> 483 | G18: 70 | H18: 7002 | I18: 70026 | J18: អាករលើតម្លៃបន្ថែម របបនាំចូល (សហគ្រាសផ្សេងៗទៀត) | M18: =IFERROR(L18/K18, "-") -> - | N18: =SUM(O18:Q18) -> 0 | R18: =SUM(S18:U18) -> 0 | V18: =SUM(W18:Y18) -> 0 | Z18: =SUM(AA18:AC18) -> 0 | AD18: =SUM(AE18:AG18) -> 0 | AH18: =SUM(AI18:AK18) -> 0 | AL18: =SUM(AM18:AO18) -> 0 | AP18: =SUM(AQ18:AS18) -> 0 | AU18: =IF(SUM(K18:L18)<>0, "OK", "-") -> -
A19: 4 | B19: 1 | C19: =IFERROR(INDEX([1]Entity!$A$2:$A$503,MATCH($J19,[1]Entity!$E$2:$E$503,0)),"") | D19: =IFERROR(INDEX('[2]Account Group'!$A:$A,MATCH(G19,'[2]Account Group'!$B:$B,0)),"") -> 18 | E19: =IFERROR(INDEX([3]Account!$A:$A,MATCH(H19,[3]Account!$D:$D,0)),"") -> 91 | F19: =INDEX('[4]Sub Account'!$A:$A,MATCH(I19,'[4]Sub Account'!$D:$D,0)) -> 484 | G19: 70 | H19: 7002 | I19: 70027 | J19: អាករលើតម្លៃបន្ថែម របបនាំចូល (ជាបន្ទុករបស់រដ្ឋ) | M19: =IFERROR(L19/K19, "-") -> - | N19: =SUM(O19:Q19) -> 0 | R19: =SUM(S19:U19) -> 0 | V19: =SUM(W19:Y19) -> 0 | Z19: =SUM(AA19:AC19) -> 0 | AD19: =SUM(AE19:AG19) -> 0 | AH19: =SUM(AI19:AK19) -> 0 | AL19: =SUM(AM19:AO19) -> 0 | AP19: =SUM(AQ19:AS19) -> 0 | AU19: =IF(SUM(K19:L19)<>0, "OK", "-") -> -
A20: 5 | B20: 1 | C20: =IFERROR(INDEX([1]Entity!$A$2:$A$503,MATCH($J20,[1]Entity!$E$2:$E$503,0)),"") | D20: =IFERROR(INDEX('[2]Account Group'!$A:$A,MATCH(G20,'[2]Account Group'!$B:$B,0)),"") -> 18 | E20: =IFERROR(INDEX([3]Account!$A:$A,MATCH(H20,[3]Account!$D:$D,0)),"") -> 92 | F20: =INDEX('[4]Sub Account'!$A:$A,MATCH(I20,'[4]Sub Account'!$D:$D,0)) -> 485 | G20: 70 | H20: 7003 | I20: 70032 | J20: អាករពិសេសលើទំនិញមួយចំនួន របបនាំចូល (សហគ្រាសប្រេងឥន្ធនៈ) | M20: =IFERROR(L20/K20, "-") -> - | N20: =SUM(O20:Q20) -> 0 | R20: =SUM(S20:U20) -> 0 | V20: =SUM(W20:Y20) -> 0 | Z20: =SUM(AA20:AC20) -> 0 | AD20: =SUM(AE20:AG20) -> 0 | AH20: =SUM(AI20:AK20) -> 0 | AL20: =SUM(AM20:AO20) -> 0 | AP20: =SUM(AQ20:AS20) -> 0 | AU20: =IF(SUM(K20:L20)<>0, "OK", "-") -> -
A21: 6 | B21: 1 | C21: =IFERROR(INDEX([1]Entity!$A$2:$A$503,MATCH($J21,[1]Entity!$E$2:$E$503,0)),"") | D21: =IFERROR(INDEX('[2]Account Group'!$A:$A,MATCH(G21,'[2]Account Group'!$B:$B,0)),"") -> 18 | E21: =IFERROR(INDEX([3]Account!$A:$A,MATCH(H21,[3]Account!$D:$D,0)),"") -> 92 | F21: =INDEX('[4]Sub Account'!$A:$A,MATCH(I21,'[4]Sub Account'!$D:$D,0)) -> 486 | G21: 70 | H21: 7003 | I21: 70033 | J21: អាករពិសេសលើទំនិញមួយចំនួន របបនាំចូល (សហគ្រាសផ្សេងៗទៀត) | M21: =IFERROR(L21/K21, "-") -> - | N21: =SUM(O21:Q21) -> 0 | R21: =SUM(S21:U21) -> 0 | V21: =SUM(W21:Y21) -> 0 | Z21: =SUM(AA21:AC21) -> 0 | AD21: =SUM(AE21:AG21) -> 0 | AH21: =SUM(AI21:AK21) -> 0 | AL21: =SUM(AM21:AO21) -> 0 | AP21: =SUM(AQ21:AS21) -> 0 | AU21: =IF(SUM(K21:L21)<>0, "OK", "-") -> -
A22: 7 | B22: 1 | C22: =IFERROR(INDEX([1]Entity!$A$2:$A$503,MATCH($J22,[1]Entity!$E$2:$E$503,0)),"") | D22: =IFERROR(INDEX('[2]Account Group'!$A:$A,MATCH(G22,'[2]Account Group'!$B:$B,0)),"") -> 19 | E22: =IFERROR(INDEX([3]Account!$A:$A,MATCH(H22,[3]Account!$D:$D,0)),"") -> 98 | F22: =INDEX('[4]Sub Account'!$A:$A,MATCH(I22,'[4]Sub Account'!$D:$D,0)) -> 487 | G22: 71 | H22: 7100 | I22: 71001 | J22: ពន្ធគយពីការនាំចូល | M22: =IFERROR(L22/K22, "-") -> - | N22: =SUM(O22:Q22) -> 0 | R22: =SUM(S22:U22) -> 0 | V22: =SUM(W22:Y22) -> 0 | Z22: =SUM(AA22:AC22) -> 0 | AD22: =SUM(AE22:AG22) -> 0 | AH22: =SUM(AI22:AK22) -> 0 | AL22: =SUM(AM22:AO22) -> 0 | AP22: =SUM(AQ22:AS22) -> 0 | AU22: =IF(SUM(K22:L22)<>0, "OK", "-") -> -
A23: 8 | B23: 1 | C23: =IFERROR(INDEX([1]Entity!$A$2:$A$503,MATCH($J23,[1]Entity!$E$2:$E$503,0)),"") | D23: =IFERROR(INDEX('[2]Account Group'!$A:$A,MATCH(G23,'[2]Account Group'!$B:$B,0)),"") -> 19 | E23: =IFERROR(INDEX([3]Account!$A:$A,MATCH(H23,[3]Account!$D:$D,0)),"") -> 98 | F23: =INDEX('[4]Sub Account'!$A:$A,MATCH(I23,'[4]Sub Account'!$D:$D,0)) -> 488 | G23: 71 | H23: 7100 | I23: 71002 | J23: កម្រៃពីការងារគយ | M23: =IFERROR(L23/K23, "-") -> - | N23: =SUM(O23:Q23) -> 0 | R23: =SUM(S23:U23) -> 0 | V23: =SUM(W23:Y23) -> 0 | Z23: =SUM(AA23:AC23) -> 0 | AD23: =SUM(AE23:AG23) -> 0 | AH23: =SUM(AI23:AK23) -> 0 | AL23: =SUM(AM23:AO23) -> 0 | AP23: =SUM(AQ23:AS23) -> 0 | AU23: =IF(SUM(K23:L23)<>0, "OK", "-") -> -
A24: 9 | B24: 1 | C24: =IFERROR(INDEX([1]Entity!$A$2:$A$503,MATCH($J24,[1]Entity!$E$2:$E$503,0)),"") | D24: =IFERROR(INDEX('[2]Account Group'!$A:$A,MATCH(G24,'[2]Account Group'!$B:$B,0)),"") -> 19 | E24: =IFERROR(INDEX([3]Account!$A:$A,MATCH(H24,[3]Account!$D:$D,0)),"") -> 98 | F24: =INDEX('[4]Sub Account'!$A:$A,MATCH(I24,'[4]Sub Account'!$D:$D,0)) -> 489 | G24: 71 | H24: 7100 | I24: 71003 | J24: ពន្ធគយលើផលិតផលតេលសីលា | M24: =IFERROR(L24/K24, "-") -> - | N24: =SUM(O24:Q24) -> 0 | R24: =SUM(S24:U24) -> 0 | V24: =SUM(W24:Y24) -> 0 | Z24: =SUM(AA24:AC24) -> 0 | AD24: =SUM(AE24:AG24) -> 0 | AH24: =SUM(AI24:AK24) -> 0 | AL24: =SUM(AM24:AO24) -> 0 | AP24: =SUM(AQ24:AS24) -> 0 | AU24: =IF(SUM(K24:L24)<>0, "OK", "-") -> -
A25: 10 | B25: 1 | C25: =IFERROR(INDEX([1]Entity!$A$2:$A$503,MATCH($J25,[1]Entity!$E$2:$E$503,0)),"") | D25: =IFERROR(INDEX('[2]Account Group'!$A:$A,MATCH(G25,'[2]Account Group'!$B:$B,0)),"") -> 19 | E25: =IFERROR(INDEX([3]Account!$A:$A,MATCH(H25,[3]Account!$D:$D,0)),"") -> 98 | F25: =INDEX('[4]Sub Account'!$A:$A,MATCH(I25,'[4]Sub Account'!$D:$D,0)) -> 490 | G25: 71 | H25: 7100 | I25: 71004 | J25: អាករបន្ថែមលើផលិតផលតែលសិលាសំរាប់ថែទាំផ្លូវថ្នល់ | M25: =IFERROR(L25/K25, "-") -> - | N25: =SUM(O25:Q25) -> 0 | R25: =SUM(S25:U25) -> 0 | V25: =SUM(W25:Y25) -> 0 | Z25: =SUM(AA25:AC25) -> 0 | AD25: =SUM(AE25:AG25) -> 0 | AH25: =SUM(AI25:AK25) -> 0 | AL25: =SUM(AM25:AO25) -> 0 | AP25: =SUM(AQ25:AS25) -> 0 | AU25: =IF(SUM(K25:L25)<>0, "OK", "-") -> -
A26: 11 | B26: 1 | C26: =IFERROR(INDEX([1]Entity!$A$2:$A$503,MATCH($J26,[1]Entity!$E$2:$E$503,0)),"") | D26: =IFERROR(INDEX('[2]Account Group'!$A:$A,MATCH(G26,'[2]Account Group'!$B:$B,0)),"") -> 19 | E26: =IFERROR(INDEX([3]Account!$A:$A,MATCH(H26,[3]Account!$D:$D,0)),"") -> 98 | F26: =INDEX('[4]Sub Account'!$A:$A,MATCH(I26,'[4]Sub Account'!$D:$D,0)) -> 491 | G26: 71 | H26: 7100 | I26: 71005 | J26: ផលពីការលក់ទំនិញរឹបអូស និងទំនិញគ្មានការទាមទារ | M26: =IFERROR(L26/K26, "-") -> - | N26: =SUM(O26:Q26) -> 0 | R26: =SUM(S26:U26) -> 0 | V26: =SUM(W26:Y26) -> 0 | Z26: =SUM(AA26:AC26) -> 0 | AD26: =SUM(AE26:AG26) -> 0 | AH26: =SUM(AI26:AK26) -> 0 | AL26: =SUM(AM26:AO26) -> 0 | AP26: =SUM(AQ26:AS26) -> 0 | AU26: =IF(SUM(K26:L26)<>0, "OK", "-") -> -
A27: 12 | B27: 1 | C27: =IFERROR(INDEX([1]Entity!$A$2:$A$503,MATCH($J27,[1]Entity!$E$2:$E$503,0)),"") | D27: =IFERROR(INDEX('[2]Account Group'!$A:$A,MATCH(G27,'[2]Account Group'!$B:$B,0)),"") -> 19 | E27: =IFERROR(INDEX([3]Account!$A:$A,MATCH(H27,[3]Account!$D:$D,0)),"") -> 98 | F27: =INDEX('[4]Sub Account'!$A:$A,MATCH(I27,'[4]Sub Account'!$D:$D,0)) -> 492 | G27: 71 | H27: 7100 | I27: 71006 | J27: ពិន័យផ្សេងៗលើការនាំចូល | M27: =IFERROR(L27/K27, "-") -> - | N27: =SUM(O27:Q27) -> 0 | R27: =SUM(S27:U27) -> 0 | V27: =SUM(W27:Y27) -> 0 | Z27: =SUM(AA27:AC27) -> 0 | AD27: =SUM(AE27:AG27) -> 0 | AH27: =SUM(AI27:AK27) -> 0 | AL27: =SUM(AM27:AO27) -> 0 | AP27: =SUM(AQ27:AS27) -> 0 | AU27: =IF(SUM(K27:L27)<>0, "OK", "-") -> -
A28: 13 | B28: 1 | C28: =IFERROR(INDEX([1]Entity!$A$2:$A$503,MATCH($J28,[1]Entity!$E$2:$E$503,0)),"") | D28: =IFERROR(INDEX('[2]Account Group'!$A:$A,MATCH(G28,'[2]Account Group'!$B:$B,0)),"") -> 19 | E28: =IFERROR(INDEX([3]Account!$A:$A,MATCH(H28,[3]Account!$D:$D,0)),"") -> 98 | F28: =INDEX('[4]Sub Account'!$A:$A,MATCH(I28,'[4]Sub Account'!$D:$D,0)) -> 493 | G28: 71 | H28: 7100 | I28: 71007 | J28: ពន្ធនាំចូល (ជាបន្ទុករបស់រដ្ឋ) | M28: =IFERROR(L28/K28, "-") -> - | N28: =SUM(O28:Q28) -> 0 | R28: =SUM(S28:U28) -> 0 | V28: =SUM(W28:Y28) -> 0 | Z28: =SUM(AA28:AC28) -> 0 | AD28: =SUM(AE28:AG28) -> 0 | AH28: =SUM(AI28:AK28) -> 0 | AL28: =SUM(AM28:AO28) -> 0 | AP28: =SUM(AQ28:AS28) -> 0 | AU28: =IF(SUM(K28:L28)<>0, "OK", "-") -> -
... A38: 23 | B38: 1 | C38: =IFERROR(INDEX([1]Entity!$A$2:$A$503,MATCH($J38,[1]Entity!$E$2:$E$503,0)),"") | D38: =IFERROR(INDEX('[2]Account Group'!$A:$A,MATCH(G38,'[2]Account Group'!$B:$B,0)),"") -> 21 | E38: =IFERROR(INDEX([3]Account!$A:$A,MATCH(H38,[3]Account!$D:$D,0)),"") -> 109 | F38: =INDEX('[4]Sub Account'!$A:$A,MATCH(I38,'[4]Sub Account'!$D:$D,0)) -> 500 | G38: 73 | H38: 7308 | I38: 73087 | J38: ផលពីការត្រួតពិនិត្យគុណភាពផលិតផល និងការគោរពបទដ្ឋាន | M38: =IFERROR(L38/K38, "-") -> - | N38: =SUM(O38:Q38) -> 0 | R38: =SUM(S38:U38) -> 0 | V38: =SUM(W38:Y38) -> 0 | Z38: =SUM(AA38:AC38) -> 0 | AD38: =SUM(AE38:AG38) -> 0 | AH38: =SUM(AI38:AK38) -> 0 | AL38: =SUM(AM38:AO38) -> 0 | AP38: =SUM(AQ38:AS38) -> 0 | AU38: =IF(SUM(K38:L38)<>0, "OK", "-") -> -
A39: 24 | C39: =IFERROR(INDEX([1]Entity!$A$2:$A$503,MATCH(TRIM($J39),[1]Entity!$E$2:$E$503,0)),"") -> 7 | D39: =IFERROR(INDEX('[2]Account Group'!$A:$A,MATCH(G39,'[2]Account Group'!$B:$B,0)),"") | E39: =IFERROR(INDEX([3]Account!$A:$A,MATCH(H39,[3]Account!$D:$D,0)),"") | F39: =INDEX('[4]Sub Account'!$A:$A,MATCH(I39,'[4]Sub Account'!$D:$D,0)) -> #N/A | J39: អគ្គនាយកដ្ឋានពន្ធដារ | K39: =SUM(K40:K54) -> 0 | L39: =SUM(L40:L54) -> 0 | M39: =IFERROR(L39/K39, "-") -> - | N39: =SUM(N40:N54) -> 0 | O39: =SUM(O40:O54) -> 0 | P39: =SUM(P40:P54) -> 0 | Q39: =SUM(Q40:Q54) -> 0 | R39: =SUM(R40:R54) -> 0 | S39: =SUM(S40:S54) -> 0 | T39: =SUM(T40:T54) -> 0 | U39: =SUM(U40:U54) -> 0 | ... AS39: =SUM(AS40:AS54) -> 0 | AU39: =IF(SUM(K39:L39)<>0, "OK", "-") -> -
A40: 25 | B40: 24 | D40: =IFERROR(INDEX('[2]Account Group'!$A:$A,MATCH(G40,'[2]Account Group'!$B:$B,0)),"") -> 18 | E40: =IFERROR(INDEX([3]Account!$A:$A,MATCH(H40,[3]Account!$D:$D,0)),"") -> 90 | F40: =INDEX('[4]Sub Account'!$A:$A,MATCH(I40,'[4]Sub Account'!$D:$D,0)) -> 457 | G40: 70 | H40: 7001 | I40: 70011 | J40: ពន្ធលើប្រាក់ចំណូល (រូបវន្តបុគ្គល) | L40: =N40+V40+AD40+AL40 -> 0 | M40: =IFERROR(L40/K40, "-") -> - | N40: =SUM(O40:Q40) -> 0 | R40: =SUM(S40:U40) -> 0 | V40: =SUM(W40:Y40) -> 0 | Z40: =SUM(AA40:AC40) -> 0 | AD40: =SUM(AE40:AG40) -> 0 | AH40: =SUM(AI40:AK40) -> 0 | AL40: =SUM(AM40:AO40) -> 0 | AP40: =SUM(AQ40:AS40) -> 0 | AU40: =IF(SUM(K40:L40)<>0, "OK", "-") -> -
A41: 26 | B41: 24 | D41: =IFERROR(INDEX('[2]Account Group'!$A:$A,MATCH(G41,'[2]Account Group'!$B:$B,0)),"") -> 18 | E41: =IFERROR(INDEX([3]Account!$A:$A,MATCH(H41,[3]Account!$D:$D,0)),"") -> 90 | F41: =INDEX('[4]Sub Account'!$A:$A,MATCH(I41,'[4]Sub Account'!$D:$D,0)) -> 458 | G41: 70 | H41: 7001 | I41: 70012 | J41: ពន្ធលើប្រាក់ចំណូល (នីតិបុគ្គល) | L41: =N41+V41+AD41+AL41 -> 0 | M41: =IFERROR(L41/K41, "-") -> - | N41: =SUM(O41:Q41) -> 0 | R41: =SUM(S41:U41) -> 0 | V41: =SUM(W41:Y41) -> 0 | Z41: =SUM(AA41:AC41) -> 0 | AD41: =SUM(AE41:AG41) -> 0 | AH41: =SUM(AI41:AK41) -> 0 | AL41: =SUM(AM41:AO41) -> 0 | AP41: =SUM(AQ41:AS41) -> 0 | AU41: =IF(SUM(K41:L41)<>0, "OK", "-") -> -
A42: 27 | B42: 24 | D42: =IFERROR(INDEX('[2]Account Group'!$A:$A,MATCH(G42,'[2]Account Group'!$B:$B,0)),"") -> 18 | E42: =IFERROR(INDEX([3]Account!$A:$A,MATCH(H42,[3]Account!$D:$D,0)),"") -> 90 | F42: =INDEX('[4]Sub Account'!$A:$A,MATCH(I42,'[4]Sub Account'!$D:$D,0)) -> 459 | G42: 70 | H42: 7001 | I42: 70013 | J42: ពន្ធលើប្រាក់បៀវត្ស | L42: =N42+V42+AD42+AL42 -> 0 | M42: =IFERROR(L42/K42, "-") -> - | N42: =SUM(O42:Q42) -> 0 | R42: =SUM(S42:U42) -> 0 | V42: =SUM(W42:Y42) -> 0 | Z42: =SUM(AA42:AC42) -> 0 | AD42: =SUM(AE42:AG42) -> 0 | AH42: =SUM(AI42:AK42) -> 0 | AL42: =SUM(AM42:AO42) -> 0 | AP42: =SUM(AQ42:AS42) -> 0 | AU42: =IF(SUM(K42:L42)<>0, "OK", "-") -> -
A43: 28 | B43: 24 | D43: =IFERROR(INDEX('[2]Account Group'!$A:$A,MATCH(G43,'[2]Account Group'!$B:$B,0)),"") -> 18 | E43: =IFERROR(INDEX([3]Account!$A:$A,MATCH(H43,[3]Account!$D:$D,0)),"") -> 90 | F43: =INDEX('[4]Sub Account'!$A:$A,MATCH(I43,'[4]Sub Account'!$D:$D,0)) -> 460 | G43: 70 | H43: 7001 | I43: 70014 | J43: ពន្ធលើឈ្នួលចលននិងអចលនទ្រព្យ (រូបវន្តបុគ្គល) | L43: =N43+V43+AD43+AL43 -> 0 | M43: =IFERROR(L43/K43, "-") -> - | N43: =SUM(O43:Q43) -> 0 | R43: =SUM(S43:U43) -> 0 | V43: =SUM(W43:Y43) -> 0 | Z43: =SUM(AA43:AC43) -> 0 | AD43: =SUM(AE43:AG43) -> 0 | AH43: =SUM(AI43:AK43) -> 0 | AL43: =SUM(AM43:AO43) -> 0 | AP43: =SUM(AQ43:AS43) -> 0 | AU43: =IF(SUM(K43:L43)<>0, "OK", "-") -> -
A44: 29 | B44: 24 | D44: =IFERROR(INDEX('[2]Account Group'!$A:$A,MATCH(G44,'[2]Account Group'!$B:$B,0)),"") -> 18 | E44: =IFERROR(INDEX([3]Account!$A:$A,MATCH(H44,[3]Account!$D:$D,0)),"") -> 90 | F44: =INDEX('[4]Sub Account'!$A:$A,MATCH(I44,'[4]Sub Account'!$D:$D,0)) -> 461 | G44: 70 | H44: 7001 | I44: 70015 | J44: ពន្ធលើឈ្នួលចលននិងអចលនទ្រព្យ (នីតិបុគ្គល) | L44: =N44+V44+AD44+AL44 -> 0 | M44: =IFERROR(L44/K44, "-") -> - | N44: =SUM(O44:Q44) -> 0 | R44: =SUM(S44:U44) -> 0 | V44: =SUM(W44:Y44) -> 0 | Z44: =SUM(AA44:AC44) -> 0 | AD44: =SUM(AE44:AG44) -> 0 | AH44: =SUM(AI44:AK44) -> 0 | AL44: =SUM(AM44:AO44) -> 0 | AP44: =SUM(AQ44:AS44) -> 0 | AU44: =IF(SUM(K44:L44)<>0, "OK", "-") -> -
A45: 30 | B45: 24 | D45: =IFERROR(INDEX('[2]Account Group'!$A:$A,MATCH(G45,'[2]Account Group'!$B:$B,0)),"") -> 18 | E45: =IFERROR(INDEX([3]Account!$A:$A,MATCH(H45,[3]Account!$D:$D,0)),"") -> 91 | F45: =INDEX('[4]Sub Account'!$A:$A,MATCH(I45,'[4]Sub Account'!$D:$D,0)) -> 462 | G45: 70 | H45: 7002 | I45: 70022 | J45: អាករលើតម្លៃបន្ថែម | L45: =N45+V45+AD45+AL45 -> 0 | M45: =IFERROR(L45/K45, "-") -> - | N45: =SUM(O45:Q45) -> 0 | R45: =SUM(S45:U45) -> 0 | V45: =SUM(W45:Y45) -> 0 | Z45: =SUM(AA45:AC45) -> 0 | AD45: =SUM(AE45:AG45) -> 0 | AH45: =SUM(AI45:AK45) -> 0 | AL45: =SUM(AM45:AO45) -> 0 | AP45: =SUM(AQ45:AS45) -> 0 | AU45: =IF(SUM(K45:L45)<>0, "OK", "-") -> -
A46: 31 | B46: 24 | D46: =IFERROR(INDEX('[2]Account Group'!$A:$A,MATCH(G46,'[2]Account Group'!$B:$B,0)),"") -> 18 | E46: =IFERROR(INDEX([3]Account!$A:$A,MATCH(H46,[3]Account!$D:$D,0)),"") -> 92 | F46: =INDEX('[4]Sub Account'!$A:$A,MATCH(I46,'[4]Sub Account'!$D:$D,0)) -> 463 | G46: 70 | H46: 7003 | I46: 70031 | J46: អាករពិសេសលើទំនិញមួយចំនួន | L46: =N46+V46+AD46+AL46 -> 0 | M46: =IFERROR(L46/K46, "-") -> - | N46: =SUM(O46:Q46) -> 0 | R46: =SUM(S46:U46) -> 0 | V46: =SUM(W46:Y46) -> 0 | Z46: =SUM(AA46:AC46) -> 0 | AD46: =SUM(AE46:AG46) -> 0 | AH46: =SUM(AI46:AK46) -> 0 | AL46: =SUM(AM46:AO46) -> 0 | AP46: =SUM(AQ46:AS46) -> 0 | AU46: =IF(SUM(K46:L46)<>0, "OK", "-") -> -
A47: 32 | B47: 24 | D47: =IFERROR(INDEX('[2]Account Group'!$A:$A,MATCH(G47,'[2]Account Group'!$B:$B,0)),"") -> 18 | E47: =IFERROR(INDEX([3]Account!$A:$A,MATCH(H47,[3]Account!$D:$D,0)),"") -> 92 | F47: =INDEX('[4]Sub Account'!$A:$A,MATCH(I47,'[4]Sub Account'!$D:$D,0)) -> 464 | G47: 70 | H47: 7003 | I47: 70034 | J47: អាករពិសេសលើសេវាមួយចំនួន | L47: =N47+V47+AD47+AL47 -> 0 | M47: =IFERROR(L47/K47, "-") -> - | N47: =SUM(O47:Q47) -> 0 | R47: =SUM(S47:U47) -> 0 | V47: =SUM(W47:Y47) -> 0 | Z47: =SUM(AA47:AC47) -> 0 | AD47: =SUM(AE47:AG47) -> 0 | AH47: =SUM(AI47:AK47) -> 0 | AL47: =SUM(AM47:AO47) -> 0 | AP47: =SUM(AQ47:AS47) -> 0 | AU47: =IF(SUM(K47:L47)<>0, "OK", "-") -> -
A48: 33 | B48: 24 | D48: =IFERROR(INDEX('[2]Account Group'!$A:$A,MATCH(G48,'[2]Account Group'!$B:$B,0)),"") -> 18 | E48: =IFERROR(INDEX([3]Account!$A:$A,MATCH(H48,[3]Account!$D:$D,0)),"") -> 97 | F48: =INDEX('[4]Sub Account'!$A:$A,MATCH(I48,'[4]Sub Account'!$D:$D,0)) -> 465 | G48: 70 | H48: 7008 | I48: 70081 | J48: ពន្ធតែមប្រិ៍ | L48: =N48+V48+AD48+AL48 -> 0 | M48: =IFERROR(L48/K48, "-") -> - | N48: =SUM(O48:Q48) -> 0 | R48: =SUM(S48:U48) -> 0 | V48: =SUM(W48:Y48) -> 0 | Z48: =SUM(AA48:AC48) -> 0 | AD48: =SUM(AE48:AG48) -> 0 | AH48: =SUM(AI48:AK48) -> 0 | AL48: =SUM(AM48:AO48) -> 0 | AP48: =SUM(AQ48:AS48) -> 0 | AU48: =IF(SUM(K48:L48)<>0, "OK", "-") -> -
A49: 34 | B49: 24 | D49: =IFERROR(INDEX('[2]Account Group'!$A:$A,MATCH(G49,'[2]Account Group'!$B:$B,0)),"") -> 18 | E49: =IFERROR(INDEX([3]Account!$A:$A,MATCH(H49,[3]Account!$D:$D,0)),"") -> 97 | F49: =INDEX('[4]Sub Account'!$A:$A,MATCH(I49,'[4]Sub Account'!$D:$D,0)) -> 466 | G49: 70 | H49: 7008 | I49: 70082 | J49: ប្រាក់ទោសទណ្ឌសារពើពន្ធ | L49: =N49+V49+AD49+AL49 -> 0 | M49: =IFERROR(L49/K49, "-") -> - | N49: =SUM(O49:Q49) -> 0 | R49: =SUM(S49:U49) -> 0 | V49: =SUM(W49:Y49) -> 0 | Z49: =SUM(AA49:AC49) -> 0 | AD49: =SUM(AE49:AG49) -> 0 | AH49: =SUM(AI49:AK49) -> 0 | AL49: =SUM(AM49:AO49) -> 0 | AP49: =SUM(AQ49:AS49) -> 0 | AU49: =IF(SUM(K49:L49)<>0, "OK", "-") -> -
A50: 35 | B50: 24 | D50: =IFERROR(INDEX('[2]Account Group'!$A:$A,MATCH(G50,'[2]Account Group'!$B:$B,0)),"") -> 21 | E50: =IFERROR(INDEX([3]Account!$A:$A,MATCH(H50,[3]Account!$D:$D,0)),"") -> 103 | F50: =INDEX('[4]Sub Account'!$A:$A,MATCH(I50,'[4]Sub Account'!$D:$D,0)) -> 467 | G50: 73 | H50: 7301 | I50: 73012 | J50: លក់ឯកសារ លតាប័ត្រ និង លិខិតបោះពុម្ភផ្សេងៗ | L50: =N50+V50+AD50+AL50 -> 0 | M50: =IFERROR(L50/K50, "-") -> - | N50: =SUM(O50:Q50) -> 0 | R50: =SUM(S50:U50) -> 0 | V50: =SUM(W50:Y50) -> 0 | Z50: =SUM(AA50:AC50) -> 0 | AD50: =SUM(AE50:AG50) -> 0 | AH50: =SUM(AI50:AK50) -> 0 | AL50: =SUM(AM50:AO50) -> 0 | AP50: =SUM(AQ50:AS50) -> 0 | AU50: =IF(SUM(K50:L50)<>0, "OK", "-") -> -
A51: 36 | B51: 24 | D51: =IFERROR(INDEX('[2]Account Group'!$A:$A,MATCH(G51,'[2]Account Group'!$B:$B,0)),"") -> 21 | E51: =IFERROR(INDEX([3]Account!$A:$A,MATCH(H51,[3]Account!$D:$D,0)),"") -> 104 | F51: =INDEX('[4]Sub Account'!$A:$A,MATCH(I51,'[4]Sub Account'!$D:$D,0)) -> 468 | G51: 73 | H51: 7302 | I51: 73023 | J51: ផលពីការបង្កើតសហគ្រាស | L51: =N51+V51+AD51+AL51 -> 0 | M51: =IFERROR(L51/K51, "-") -> - | N51: =SUM(O51:Q51) -> 0 | R51: =SUM(S51:U51) -> 0 | V51: =SUM(W51:Y51) -> 0 | Z51: =SUM(AA51:AC51) -> 0 | AD51: =SUM(AE51:AG51) -> 0 | AH51: =SUM(AI51:AK51) -> 0 | AL51: =SUM(AM51:AO51) -> 0 | AP51: =SUM(AQ51:AS51) -> 0 | AU51: =IF(SUM(K51:L51)<>0, "OK", "-") -> -
... A54: 39 | B54: 24 | D54: =IFERROR(INDEX('[2]Account Group'!$A:$A,MATCH(G54,'[2]Account Group'!$B:$B,0)),"") -> 21 | E54: =IFERROR(INDEX([3]Account!$A:$A,MATCH(H54,[3]Account!$D:$D,0)),"") -> 91 | F54: =INDEX('[4]Sub Account'!$A:$A,MATCH(I54,'[4]Sub Account'!$D:$D,0)) -> 471 | G54: 73 | H54: 7002 | I54: 70021 | J54: អាករលើផលរបរ | L54: =N54+V54+AD54+AL54 -> 0 | M54: =IFERROR(L54/K54, "-") -> - | N54: =SUM(O54:Q54) -> 0 | R54: =SUM(S54:U54) -> 0 | V54: =SUM(W54:Y54) -> 0 | Z54: =SUM(AA54:AC54) -> 0 | AD54: =SUM(AE54:AG54) -> 0 | AH54: =SUM(AI54:AK54) -> 0 | AL54: =SUM(AM54:AO54) -> 0 | AP54: =SUM(AQ54:AS54) -> 0 | AU54: =IF(SUM(K54:L54)<>0, "OK", "-") -> -
...

Sheet By Pro.
V1: ព្រះរាជាណាចក្រកម្ពុជា | AH1: ព្រះរាជាណាចក្រកម្ពុជា
A2: ក្រសួងសេដ្ឋកិច្ច​និងហិរញ្ញវត្ថុ | V2: ជាតិ សាសនា ព្រះមហាក្សត្រ | AH2: ជាតិ សាសនា ព្រះមហាក្សត្រ
A3: អគ្គលេខាធិការដ្ឋាន
A6: គម្រោងកម្មវិធីចំណូល​ថវិកាថ្នាក់ជាតិ-ប្រចាំឆ្នាំ​២០២២
A7: របស់មន្ទីរសេដ្ឋកិច្ចនិងហិរញ្ញវត្ថុរាជធានី ខេត្ត
AN8: ឯកតា៖ ពាន់រៀល
A9: ជំពូក | B9: គណនី | C9: អនុគណនី | D9: ក្រសួង-ស្ថាប័ន | E9: ច្បាប់ ហិរញ្ញវត្ថុ | F9: សរុបគម្រោង កម្មវិធីប្រចាំឆ្នំា | H9: ត្រីមាសទី១ | P9: ត្រីមាសទី២ | X9: ត្រីមាសទី៣ | AF9: ត្រីមាសទី៤ | AN9: ផ្សេងៗ
H10: គ្រោងដើមឆ្នាំ | L10: ប៉ាន់ស្មានអនុវត្ត | P10: គ្រោងដើមឆ្នាំ | T10: ស្នើសុំកែតម្រូវ | X10: គ្រោងដើមឆ្នាំ | AB10: ប៉ាន់ស្មានអនុវត្ត | AF10: គ្រោង​ដើមឆ្នាំ | AJ10: ស្នើសុំ​កែតម្រូវ
F11: ទឹកប្រាក់ | G11: %ច្បាប់ | H11: សរុប | I11: ខែ១ | J11: ខែ​២ | K11: ខែ​៣ | L11: សរុប | M11: អនុ.ខែ១ | N11: អនុ.ខែ​២ | O11: ប៉ាន់អនុ.ខែ​៣ | P11: សរុប | Q11: ខែ៤ | R11: ខែ​៥ | S11: ខែ​៦ | T11: សរុប | U11: ខែ៤ | V11: ខែ​៥ | W11: ខែ​៦ | X11: សរុប | Y11: ខែ៧ | Z11: ខែ​៨ | AA11: ខែ​៩ | AB11: សរុប | AC11: អនុ.ខែ៧ | AD11: អនុ.ខែ​៨ | AE11: ប៉ាន់អនុ.ខែ​៩ | AF11: សរុប | AG11: ខែ១០ | AH11: ខែ​១១ | AI11: ខែ​១២ | AJ11: សរុប | AK11: ខែ១០ | AL11: ខែ​១១ | AM11: ខែ​១២
D12: មន្ទីរសេដ្ឋកិច្ចនិងហិរញ្ញវត្ថុ | E12: =SUM(E13:E16) -> 0 | F12: =SUM(F13:F16) -> 0 | G12: =IFERROR(F12/E12, "-") -> - | H12: =SUM(H13:H16) -> 0 | I12: =SUM(I13:I16) -> 0 | J12: =SUM(J13:J16) -> 0 | K12: =SUM(K13:K16) -> 0 | L12: =SUM(L13:L16) -> 0 | M12: =SUM(M13:M16) -> 0 | N12: =SUM(N13:N16) -> 0 | O12: =SUM(O13:O16) -> 0 | ... AM12: =SUM(AM13:AM16) -> 0 | AO12: =IF(SUM(E12:F12)<>0, "OK", "-") -> -
A13: 73 | B13: 7302 | C13: 73023 | D13: ផលពីការបង្កើតសហគ្រាស | F13: =H13+P13+X13+AF13 -> 0 | G13: =IFERROR(F13/E13, "-") -> - | H13: =SUM(I13:K13) -> 0 | L13: =SUM(M13:O13) -> 0 | P13: =SUM(Q13:S13) -> 0 | T13: =SUM(U13:W13) -> 0 | X13: =SUM(Y13:AA13) -> 0 | AB13: =SUM(AC13:AE13) -> 0 | AF13: =SUM(AG13:AI13) -> 0 | AJ13: =SUM(AK13:AM13) -> 0 | AO13: =IF(SUM(E13:F13)<>0, "OK", "-") -> -
A14: 73 | B14: 7306 | C14: 73066 | D14: ចំណូលពីអាជ្ញាប័ណ្ណក្នុងស្រុក | F14: =H14+P14+X14+AF14 -> 0 | G14: =IFERROR(F14/E14, "-") -> - | H14: =SUM(I14:K14) -> 0 | L14: =SUM(M14:O14) -> 0 | P14: =SUM(Q14:S14) -> 0 | T14: =SUM(U14:W14) -> 0 | X14: =SUM(Y14:AA14) -> 0 | AB14: =SUM(AC14:AE14) -> 0 | AF14: =SUM(AG14:AI14) -> 0 | AJ14: =SUM(AK14:AM14) -> 0 | AO14: =IF(SUM(E14:F14)<>0, "OK", "-") -> -
A15: 73 | B15: 7307 | C15: 73071 | D15: ការជួលដីទំនេរ | F15: =H15+P15+X15+AF15 -> 0 | G15: =IFERROR(F15/E15, "-") -> - | H15: =SUM(I15:K15) -> 0 | L15: =SUM(M15:O15) -> 0 | P15: =SUM(Q15:S15) -> 0 | T15: =SUM(U15:W15) -> 0 | X15: =SUM(Y15:AA15) -> 0 | AB15: =SUM(AC15:AE15) -> 0 | AF15: =SUM(AG15:AI15) -> 0 | AJ15: =SUM(AK15:AM15) -> 0 | AO15: =IF(SUM(E15:F15)<>0, "OK", "-") -> -
A16: 73 | B16: 7307 | C16: 73072 | D16: ការជួលដីមានអគារ | F16: =H16+P16+X16+AF16 -> 0 | G16: =IFERROR(F16/E16, "-") -> - | H16: =SUM(I16:K16) -> 0 | L16: =SUM(M16:O16) -> 0 | P16: =SUM(Q16:S16) -> 0 | T16: =SUM(U16:W16) -> 0 | X16: =SUM(Y16:AA16) -> 0 | AB16: =SUM(AC16:AE16) -> 0 | AF16: =SUM(AG16:AI16) -> 0 | AJ16: =SUM(AK16:AM16) -> 0 | AO16: =IF(SUM(E16:F16)<>0, "OK", "-") -> -
D17: មន្ទីរសេដ្ឋកិច្ចនិងហិរញ្ញវត្ថុខេត្តបន្ទាយមានជ័យ | E17: =SUM(E18:E21) -> 5000 | F17: =SUM(F18:F21) -> 5000 | G17: =IFERROR(F17/E17, "-") -> 1 | H17: =SUM(H18:H21) -> 1500 | I17: =SUM(I18:I21) -> 0 | J17: =SUM(J18:J21) -> 0 | K17: =SUM(K18:K21) -> 1500 | L17: =SUM(L18:L21) -> 0 | M17: =SUM(M18:M21) -> 0 | N17: =SUM(N18:N21) -> 0 | O17: =SUM(O18:O21) -> 0 | ... AM17: =SUM(AM18:AM21) -> 0 | AO17: =IF(SUM(E17:F17)<>0, "OK", "-") -> OK
A18: 73 | B18: 7302 | C18: 73023 | D18: ផលពីការបង្កើតសហគ្រាស | E18: ='[5]01.BMC'!E13 -> 5000 | F18: =H18+P18+X18+AF18 -> 5000 | G18: =IFERROR(F18/E18, "-") -> 1 | H18: =SUM(I18:K18) -> 1500 | I18: ='[5]01.BMC'!I13 -> 0 | J18: ='[5]01.BMC'!J13 -> 0 | K18: ='[5]01.BMC'!K13 -> 1500 | L18: =SUM(M18:O18) -> 0 | M18: ='[5]01.BMC'!M13 -> 0 | N18: ='[5]01.BMC'!N13 -> 0 | O18: ='[5]01.BMC'!O13 -> 0 | P18: =SUM(Q18:S18) -> 1500 | Q18: ='[5]01.BMC'!Q13 -> 0 | R18: ='[5]01.BMC'!R13 -> 0 | S18: ='[5]01.BMC'!S13 -> 1500 | T18: =SUM(U18:W18) -> 0 | U18: ='[5]01.BMC'!U13 -> 0 | V18: ='[5]01.BMC'!V13 -> 0 | W18: ='[5]01.BMC'!W13 -> 0 | X18: =SUM(Y18:AA18) -> 1000 | Y18: ='[5]01.BMC'!Y13 -> 0 | Z18: ='[5]01.BMC'!Z13 -> 0 | AA18: ='[5]01.BMC'!AA13 -> 1000 | AB18: =SUM(AC18:AE18) -> 0 | AF18: =SUM(AG18:AI18) -> 1000 | AG18: ='[5]01.BMC'!AG13 -> 0 | AH18: ='[5]01.BMC'!AH13 -> 1000 | AI18: ='[5]01.BMC'!AI13 -> 0 | AJ18: =SUM(AK18:AM18) -> 0 | AO18: =IF(SUM(E18:F18)<>0, "OK", "-") -> OK
A19: 73 | B19: 7306 | C19: 73066 | D19: ចំណូលពីអាជ្ញាប័ណ្ណក្នុងស្រុក | E19: ='[5]01.BMC'!E14 -> 0 | F19: =H19+P19+X19+AF19 -> 0 | G19: =IFERROR(F19/E19, "-") -> - | H19: =SUM(I19:K19) -> 0 | I19: ='[5]01.BMC'!I14 -> 0 | J19: ='[5]01.BMC'!J14 -> 0 | K19: ='[5]01.BMC'!K14 -> 0 | L19: =SUM(M19:O19) -> 0 | M19: ='[5]01.BMC'!M14 -> 0 | N19: ='[5]01.BMC'!N14 -> 0 | O19: ='[5]01.BMC'!O14 -> 0 | P19: =SUM(Q19:S19) -> 0 | Q19: ='[5]01.BMC'!Q14 -> 0 | R19: ='[5]01.BMC'!R14 -> 0 | S19: ='[5]01.BMC'!S14 -> 0 | T19: =SUM(U19:W19) -> 0 | U19: ='[5]01.BMC'!U14 -> 0 | V19: ='[5]01.BMC'!V14 -> 0 | W19: ='[5]01.BMC'!W14 -> 0 | X19: =SUM(Y19:AA19) -> 0 | Y19: ='[5]01.BMC'!Y14 -> 0 | Z19: ='[5]01.BMC'!Z14 -> 0 | AA19: ='[5]01.BMC'!AA14 -> 0 | AB19: =SUM(AC19:AE19) -> 0 | AF19: =SUM(AG19:AI19) -> 0 | AG19: ='[5]01.BMC'!AG14 -> 0 | AH19: ='[5]01.BMC'!AH14 -> 0 | AI19: ='[5]01.BMC'!AI14 -> 0 | AJ19: =SUM(AK19:AM19) -> 0 | AO19: =IF(SUM(E19:F19)<>0, "OK", "-") -> -
A20: 73 | B20: 7307 | C20: 73071 | D20: ការជួលដីទំនេរ | E20: =E147 -> 0 | F20: =H20+P20+X20+AF20 -> 0 | G20: =IFERROR(F20/E20, "-") -> - | H20: =SUM(I20:K20) -> 0 | I20: =I147 -> 0 | J20: =J147 -> 0 | K20: =K147 -> 0 | L20: =SUM(M20:O20) -> 0 | M20: =M147 -> 0 | N20: =N147 -> 0 | O20: =O147 -> 0 | P20: =SUM(Q20:S20) -> 0 | Q20: =Q147 -> 0 | R20: =R147 -> 0 | S20: =S147 -> 0 | T20: =SUM(U20:W20) -> 0 | U20: =U147 -> 0 | V20: =V147 -> 0 | W20: =W147 -> 0 | X20: =SUM(Y20:AA20) -> 0 | Y20: =Y147 -> 0 | Z20: =Z147 -> 0 | AA20: =AA147 -> 0 | AB20: =SUM(AC20:AE20) -> 0 | AC20: =AC147 -> 0 | AD20: =AD147 -> 0 | AE20: =AE147 -> 0 | AF20: =SUM(AG20:AI20) -> 0 | AG20: =AG147 -> 0 | AH20: =AH147 -> 0 | AI20: =AI147 -> 0 | AJ20: =SUM(AK20:AM20) -> 0 | AK20: =AK147 -> 0 | AL20: =AL147 -> 0 | AM20: =AM147 -> 0 | AO20: =IF(SUM(E20:F20)<>0, "OK", "-") -> -
A21: 73 | B21: 7307 | C21: 73072 | D21: ការជួលដីមានអគារ | E21: =E143+E148 -> 0 | F21: =H21+P21+X21+AF21 -> 0 | G21: =IFERROR(F21/E21, "-") -> - | H21: =SUM(I21:K21) -> 0 | I21: =I143+I148 -> 0 | J21: =J143+J148 -> 0 | K21: =K143+K148 -> 0 | L21: =SUM(M21:O21) -> 0 | M21: =M143+M148 -> 0 | N21: =N143+N148 -> 0 | O21: =O143+O148 -> 0 | P21: =SUM(Q21:S21) -> 0 | Q21: =Q143+Q148 -> 0 | R21: =R143+R148 -> 0 | S21: =S143+S148 -> 0 | T21: =SUM(U21:W21) -> 0 | U21: =U143+U148 -> 0 | V21: =V143+V148 -> 0 | W21: =W143+W148 -> 0 | X21: =SUM(Y21:AA21) -> 0 | Y21: =Y143+Y148 -> 0 | Z21: =Z143+Z148 -> 0 | AA21: =AA143+AA148 -> 0 | AB21: =SUM(AC21:AE21) -> 0 | AC21: =AC143+AC148 -> 0 | AD21: =AD143+AD148 -> 0 | AE21: =AE143+AE148 -> 0 | AF21: =SUM(AG21:AI21) -> 0 | AG21: =AG143+AG148 -> 0 | AH21: =AH143+AH148 -> 0 | AI21: =AI143+AI148 -> 0 | AJ21: =SUM(AK21:AM21) -> 0 | AK21: =AK143+AK148 -> 0 | AL21: =AL143+AL148 -> 0 | AM21: =AM143+AM148 -> 0 | AO21: =IF(SUM(E21:F21)<>0, "OK", "-") -> -
D22: មន្ទីរសេដ្ឋកិច្ចនិងហិរញ្ញវត្ថុខេត្តបាត់ដំបង | E22: =SUM(E23:E26) -> 0 | F22: =SUM(F23:F26) -> 7000 | G22: =IFERROR(F22/E22, "-") -> - | H22: =SUM(H23:H26) -> 3000 | I22: =SUM(I23:I26) -> 0 | J22: =SUM(J23:J26) -> 0 | K22: =SUM(K23:K26) -> 3000 | L22: =SUM(L23:L26) -> 0 | M22: =SUM(M23:M26) -> 0 | N22: =SUM(N23:N26) -> 0 | O22: =SUM(O23:O26) -> 0 | ... AM22: =SUM(AM23:AM26) -> 0 | AO22: =IF(SUM(E22:F22)<>0, "OK", "-") -> OK
A23: 73 | B23: 7302 | C23: 73023 | D23: ផលពីការបង្កើតសហគ្រាស | E23: ='[5]01.BMC'!E18 -> 0 | F23: =H23+P23+X23+AF23 -> 7000 | G23: =IFERROR(F23/E23, "-") -> - | H23: =SUM(I23:K23) -> 3000 | I23: ='[5]02.BTB'!I13 -> 0 | J23: ='[5]02.BTB'!J13 -> 0 | K23: ='[5]02.BTB'!K13 -> 3000 | L23: =SUM(M23:O23) -> 0 | M23: ='[5]02.BTB'!M13 -> 0 | N23: ='[5]02.BTB'!N13 -> 0 | O23: ='[5]02.BTB'!O13 -> 0 | P23: =SUM(Q23:S23) -> 2000 | Q23: ='[5]02.BTB'!Q13 -> 0 | R23: ='[5]02.BTB'!R13 -> 0 | S23: ='[5]02.BTB'!S13 -> 2000 | T23: =SUM(U23:W23) -> 0 | U23: ='[5]02.BTB'!U13 -> 0 | V23: ='[5]02.BTB'!V13 -> 0 | W23: ='[5]02.BTB'!W13 -> 0 | X23: =SUM(Y23:AA23) -> 1000 | Y23: ='[5]02.BTB'!Y13 -> 0 | Z23: ='[5]02.BTB'!Z13 -> 0 | AA23: ='[5]02.BTB'!AA13 -> 1000 | AB23: =SUM(AC23:AE23) -> 0 | AC23: ='[5]02.BTB'!AC13 -> 0 | AD23: ='[5]02.BTB'!AD13 -> 0 | AE23: ='[5]02.BTB'!AE13 -> 0 | AF23: =SUM(AG23:AI23) -> 1000 | AG23: ='[5]02.BTB'!AG13 -> 0 | AH23: ='[5]02.BTB'!AH13 -> 0 | AI23: ='[5]02.BTB'!AI13 -> 1000 | AJ23: =SUM(AK23:AM23) -> 0 | AK23: ='[5]02.BTB'!AK13 -> 0 | AL23: ='[5]02.BTB'!AL13 -> 0 | AM23: ='[5]02.BTB'!AM13 -> 0 | AO23: =IF(SUM(E23:F23)<>0, "OK", "-") -> OK
A24: 73 | B24: 7306 | C24: 73066 | D24: ចំណូលពីអាជ្ញាប័ណ្ណក្នុងស្រុក | E24: ='[5]01.BMC'!E19 -> 0 | F24: =H24+P24+X24+AF24 -> 0 | G24: =IFERROR(F24/E24, "-") -> - | H24: =SUM(I24:K24) -> 0 | I24: ='[5]02.BTB'!I14 -> 0 | J24: ='[5]02.BTB'!J14 -> 0 | K24: ='[5]02.BTB'!K14 -> 0 | L24: =SUM(M24:O24) -> 0 | M24: ='[5]02.BTB'!M14 -> 0 | N24: ='[5]02.BTB'!N14 -> 0 | O24: ='[5]02.BTB'!O14 -> 0 | P24: =SUM(Q24:S24) -> 0 | Q24: ='[5]02.BTB'!Q14 -> 0 | R24: ='[5]02.BTB'!R14 -> 0 | S24: ='[5]02.BTB'!S14 -> 0 | T24: =SUM(U24:W24) -> 0 | U24: ='[5]02.BTB'!U14 -> 0 | V24: ='[5]02.BTB'!V14 -> 0 | W24: ='[5]02.BTB'!W14 -> 0 | X24: =SUM(Y24:AA24) -> 0 | Y24: ='[5]02.BTB'!Y14 -> 0 | Z24: ='[5]02.BTB'!Z14 -> 0 | AA24: ='[5]02.BTB'!AA14 -> 0 | AB24: =SUM(AC24:AE24) -> 0 | AC24: ='[5]02.BTB'!AC14 -> 0 | AD24: ='[5]02.BTB'!AD14 -> 0 | AE24: ='[5]02.BTB'!AE14 -> 0 | AF24: =SUM(AG24:AI24) -> 0 | AG24: ='[5]02.BTB'!AG14 -> 0 | AH24: ='[5]02.BTB'!AH14 -> 0 | AI24: ='[5]02.BTB'!AI14 -> 0 | AJ24: =SUM(AK24:AM24) -> 0 | AK24: ='[5]02.BTB'!AK14 -> 0 | AL24: ='[5]02.BTB'!AL14 -> 0 | AM24: ='[5]02.BTB'!AM14 -> 0 | AO24: =IF(SUM(E24:F24)<>0, "OK", "-") -> -
A25: 73 | B25: 7307 | C25: 73071 | D25: ការជួលដីទំនេរ | E25: =E152 -> 0 | F25: =H25+P25+X25+AF25 -> 0 | G25: =IFERROR(F25/E25, "-") -> - | H25: =SUM(I25:K25) -> 0 | I25: ='[5]02.BTB'!I15 -> 0 | J25: ='[5]02.BTB'!J15 -> 0 | K25: ='[5]02.BTB'!K15 -> 0 | L25: =SUM(M25:O25) -> 0 | M25: ='[5]02.BTB'!M15 -> 0 | N25: ='[5]02.BTB'!N15 -> 0 | O25: ='[5]02.BTB'!O15 -> 0 | P25: =SUM(Q25:S25) -> 0 | Q25: ='[5]02.BTB'!Q15 -> 0 | R25: ='[5]02.BTB'!R15 -> 0 | S25: ='[5]02.BTB'!S15 -> 0 | T25: =SUM(U25:W25) -> 0 | U25: ='[5]02.BTB'!U15 -> 0 | V25: ='[5]02.BTB'!V15 -> 0 | W25: ='[5]02.BTB'!W15 -> 0 | X25: =SUM(Y25:AA25) -> 0 | Y25: ='[5]02.BTB'!Y15 -> 0 | Z25: ='[5]02.BTB'!Z15 -> 0 | AA25: ='[5]02.BTB'!AA15 -> 0 | AB25: =SUM(AC25:AE25) -> 0 | AC25: ='[5]02.BTB'!AC15 -> 0 | AD25: ='[5]02.BTB'!AD15 -> 0 | AE25: ='[5]02.BTB'!AE15 -> 0 | AF25: =SUM(AG25:AI25) -> 0 | AG25: ='[5]02.BTB'!AG15 -> 0 | AH25: ='[5]02.BTB'!AH15 -> 0 | AI25: ='[5]02.BTB'!AI15 -> 0 | AJ25: =SUM(AK25:AM25) -> 0 | AK25: ='[5]02.BTB'!AK15 -> 0 | AL25: ='[5]02.BTB'!AL15 -> 0 | AM25: ='[5]02.BTB'!AM15 -> 0 | AO25: =IF(SUM(E25:F25)<>0, "OK", "-") -> -
A26: 73 | B26: 7307 | C26: 73072 | D26: ការជួលដីមានអគារ | E26: =E148+E153 -> 0 | F26: =H26+P26+X26+AF26 -> 0 | G26: =IFERROR(F26/E26, "-") -> - | H26: =SUM(I26:K26) -> 0 | I26: ='[5]02.BTB'!I16 -> 0 | J26: ='[5]02.BTB'!J16 -> 0 | K26: ='[5]02.BTB'!K16 -> 0 | L26: =SUM(M26:O26) -> 0 | M26: ='[5]02.BTB'!M16 -> 0 | N26: ='[5]02.BTB'!N16 -> 0 | O26: ='[5]02.BTB'!O16 -> 0 | P26: =SUM(Q26:S26) -> 0 | Q26: ='[5]02.BTB'!Q16 -> 0 | R26: ='[5]02.BTB'!R16 -> 0 | S26: ='[5]02.BTB'!S16 -> 0 | T26: =SUM(U26:W26) -> 0 | U26: ='[5]02.BTB'!U16 -> 0 | V26: ='[5]02.BTB'!V16 -> 0 | W26: ='[5]02.BTB'!W16 -> 0 | X26: =SUM(Y26:AA26) -> 0 | Y26: ='[5]02.BTB'!Y16 -> 0 | Z26: ='[5]02.BTB'!Z16 -> 0 | AA26: ='[5]02.BTB'!AA16 -> 0 | AB26: =SUM(AC26:AE26) -> 0 | AC26: ='[5]02.BTB'!AC16 -> 0 | AD26: ='[5]02.BTB'!AD16 -> 0 | AE26: ='[5]02.BTB'!AE16 -> 0 | AF26: =SUM(AG26:AI26) -> 0 | AG26: ='[5]02.BTB'!AG16 -> 0 | AH26: ='[5]02.BTB'!AH16 -> 0 | AI26: ='[5]02.BTB'!AI16 -> 0 | AJ26: =SUM(AK26:AM26) -> 0 | AK26: ='[5]02.BTB'!AK16 -> 0 | AL26: ='[5]02.BTB'!AL16 -> 0 | AM26: ='[5]02.BTB'!AM16 -> 0 | AO26: =IF(SUM(E26:F26)<>0, "OK", "-") -> -
D27: មន្ទីរសេដ្ឋកិច្ចនិងហិរញ្ញវត្ថុខេត្តកំពង់ចាម | E27: =SUM(E28:E31) -> 0 | F27: =SUM(F28:F31) -> 0 | G27: =IFERROR(F27/E27, "-") -> - | H27: =SUM(H28:H31) -> 0 | I27: =SUM(I28:I31) -> 0 | J27: =SUM(J28:J31) -> 0 | K27: =SUM(K28:K31) -> 0 | L27: =SUM(L28:L31) -> 0 | M27: =SUM(M28:M31) -> 0 | N27: =SUM(N28:N31) -> 0 | O27: =SUM(O28:O31) -> 0 | ... AM27: =SUM(AM28:AM31) -> 0 | AO27: =IF(SUM(E27:F27)<>0, "OK", "-") -> -
A28: 73 | B28: 7302 | C28: 73023 | D28: ផលពីការបង្កើតសហគ្រាស | E28: ='[5]01.BMC'!E23 -> 0 | F28: =H28+P28+X28+AF28 -> 0 | G28: =IFERROR(F28/E28, "-") -> - | H28: =SUM(I28:K28) -> 0 | I28: ='[5]01.BMC'!I23 -> 0 | J28: ='[5]01.BMC'!J23 -> 0 | K28: ='[5]01.BMC'!K23 -> 0 | L28: =SUM(M28:O28) -> 0 | M28: ='[5]01.BMC'!M23 -> 0 | N28: ='[5]01.BMC'!N23 -> 0 | O28: ='[5]01.BMC'!O23 -> 0 | P28: =SUM(Q28:S28) -> 0 | Q28: ='[5]01.BMC'!Q23 -> 0 | R28: ='[5]01.BMC'!R23 -> 0 | S28: ='[5]01.BMC'!S23 -> 0 | T28: =SUM(U28:W28) -> 0 | U28: ='[5]01.BMC'!U23 -> 0 | V28: ='[5]01.BMC'!V23 -> 0 | W28: ='[5]01.BMC'!W23 -> 0 | X28: =SUM(Y28:AA28) -> 0 | Y28: ='[5]01.BMC'!Y23 -> 0 | Z28: ='[5]01.BMC'!Z23 -> 0 | AA28: ='[5]01.BMC'!AA23 -> 0 | AB28: =SUM(AC28:AE28) -> 0 | AF28: =SUM(AG28:AI28) -> 0 | AG28: ='[5]01.BMC'!AG23 -> 0 | AH28: ='[5]01.BMC'!AH23 -> 0 | AI28: ='[5]01.BMC'!AI23 -> 0 | AJ28: =SUM(AK28:AM28) -> 0 | AO28: =IF(SUM(E28:F28)<>0, "OK", "-") -> -
A29: 73 | B29: 7306 | C29: 73066 | D29: ចំណូលពីអាជ្ញាប័ណ្ណក្នុងស្រុក | E29: ='[5]01.BMC'!E24 -> 0 | F29: =H29+P29+X29+AF29 -> 0 | G29: =IFERROR(F29/E29, "-") -> - | H29: =SUM(I29:K29) -> 0 | I29: ='[5]01.BMC'!I24 -> 0 | J29: ='[5]01.BMC'!J24 -> 0 | K29: ='[5]01.BMC'!K24 -> 0 | L29: =SUM(M29:O29) -> 0 | M29: ='[5]01.BMC'!M24 -> 0 | N29: ='[5]01.BMC'!N24 -> 0 | O29: ='[5]01.BMC'!O24 -> 0 | P29: =SUM(Q29:S29) -> 0 | Q29: ='[5]01.BMC'!Q24 -> 0 | R29: ='[5]01.BMC'!R24 -> 0 | S29: ='[5]01.BMC'!S24 -> 0 | T29: =SUM(U29:W29) -> 0 | U29: ='[5]01.BMC'!U24 -> 0 | V29: ='[5]01.BMC'!V24 -> 0 | W29: ='[5]01.BMC'!W24 -> 0 | X29: =SUM(Y29:AA29) -> 0 | Y29: ='[5]01.BMC'!Y24 -> 0 | Z29: ='[5]01.BMC'!Z24 -> 0 | AA29: ='[5]01.BMC'!AA24 -> 0 | AB29: =SUM(AC29:AE29) -> 0 | AF29: =SUM(AG29:AI29) -> 0 | AG29: ='[5]01.BMC'!AG24 -> 0 | AH29: ='[5]01.BMC'!AH24 -> 0 | AI29: ='[5]01.BMC'!AI24 -> 0 | AJ29: =SUM(AK29:AM29) -> 0 | AO29: =IF(SUM(E29:F29)<>0, "OK", "-") -> -
A30: 73 | B30: 7307 | C30: 73071 | D30: ការជួលដីទំនេរ | E30: =E157 -> 0 | F30: =H30+P30+X30+AF30 -> 0 | G30: =IFERROR(F30/E30, "-") -> - | H30: =SUM(I30:K30) -> 0 | I30: =I157 -> 0 | J30: =J157 -> 0 | K30: =K157 -> 0 | L30: =SUM(M30:O30) -> 0 | M30: =M157 -> 0 | N30: =N157 -> 0 | O30: =O157 -> 0 | P30: =SUM(Q30:S30) -> 0 | Q30: =Q157 -> 0 | R30: =R157 -> 0 | S30: =S157 -> 0 | T30: =SUM(U30:W30) -> 0 | U30: =U157 -> 0 | V30: =V157 -> 0 | W30: =W157 -> 0 | X30: =SUM(Y30:AA30) -> 0 | Y30: =Y157 -> 0 | Z30: =Z157 -> 0 | AA30: =AA157 -> 0 | AB30: =SUM(AC30:AE30) -> 0 | AC30: =AC157 -> 0 | AD30: =AD157 -> 0 | AE30: =AE157 -> 0 | AF30: =SUM(AG30:AI30) -> 0 | AG30: =AG157 -> 0 | AH30: =AH157 -> 0 | AI30: =AI157 -> 0 | AJ30: =SUM(AK30:AM30) -> 0 | AK30: =AK157 -> 0 | AL30: =AL157 -> 0 | AM30: =AM157 -> 0 | AO30: =IF(SUM(E30:F30)<>0, "OK", "-") -> -
A31: 73 | B31: 7307 | C31: 73072 | D31: ការជួលដីមានអគារ | E31: =E153+E158 -> 0 | F31: =H31+P31+X31+AF31 -> 0 | G31: =IFERROR(F31/E31, "-") -> - | H31: =SUM(I31:K31) -> 0 | I31: =I153+I158 -> 0 | J31: =J153+J158 -> 0 | K31: =K153+K158 -> 0 | L31: =SUM(M31:O31) -> 0 | M31: =M153+M158 -> 0 | N31: =N153+N158 -> 0 | O31: =O153+O158 -> 0 | P31: =SUM(Q31:S31) -> 0 | Q31: =Q153+Q158 -> 0 | R31: =R153+R158 -> 0 | S31: =S153+S158 -> 0 | T31: =SUM(U31:W31) -> 0 | U31: =U153+U158 -> 0 | V31: =V153+V158 -> 0 | W31: =W153+W158 -> 0 | X31: =SUM(Y31:AA31) -> 0 | Y31: =Y153+Y158 -> 0 | Z31: =Z153+Z158 -> 0 | AA31: =AA153+AA158 -> 0 | AB31: =SUM(AC31:AE31) -> 0 | AC31: =AC153+AC158 -> 0 | AD31: =AD153+AD158 -> 0 | AE31: =AE153+AE158 -> 0 | AF31: =SUM(AG31:AI31) -> 0 | AG31: =AG153+AG158 -> 0 | AH31: =AH153+AH158 -> 0 | AI31: =AI153+AI158 -> 0 | AJ31: =SUM(AK31:AM31) -> 0 | AK31: =AK153+AK158 -> 0 | AL31: =AL153+AL158 -> 0 | AM31: =AM153+AM158 -> 0 | AO31: =IF(SUM(E31:F31)<>0, "OK", "-") -> -
D32: មន្ទីរសេដ្ឋកិច្ចនិងហិរញ្ញវត្ថុខេត្តកំពង់ឆ្នំាង | E32: =SUM(E33:E36) -> 0 | F32: =SUM(F33:F36) -> 0 | G32: =IFERROR(F32/E32, "-") -> - | H32: =SUM(H33:H36) -> 0 | I32: =SUM(I33:I36) -> 0 | J32: =SUM(J33:J36) -> 0 | K32: =SUM(K33:K36) -> 0 | L32: =SUM(L33:L36) -> 0 | M32: =SUM(M33:M36) -> 0 | N32: =SUM(N33:N36) -> 0 | O32: =SUM(O33:O36) -> 0 | ... AM32: =SUM(AM33:AM36) -> 0 | AO32: =IF(SUM(E32:F32)<>0, "OK", "-") -> -
A33: 73 | B33: 7302 | C33: 73023 | D33: ផលពីការបង្កើតសហគ្រាស | E33: ='[5]01.BMC'!E28 -> 0 | F33: =H33+P33+X33+AF33 -> 0 | G33: =IFERROR(F33/E33, "-") -> - | H33: =SUM(I33:K33) -> 0 | I33: ='[5]01.BMC'!I28 -> 0 | J33: ='[5]01.BMC'!J28 -> 0 | K33: ='[5]01.BMC'!K28 -> 0 | L33: =SUM(M33:O33) -> 0 | M33: ='[5]01.BMC'!M28 -> 0 | N33: ='[5]01.BMC'!N28 -> 0 | O33: ='[5]01.BMC'!O28 -> 0 | P33: =SUM(Q33:S33) -> 0 | Q33: ='[5]01.BMC'!Q28 -> 0 | R33: ='[5]01.BMC'!R28 -> 0 | S33: ='[5]01.BMC'!S28 -> 0 | T33: =SUM(U33:W33) -> 0 | U33: ='[5]01.BMC'!U28 -> 0 | V33: ='[5]01.BMC'!V28 -> 0 | W33: ='[5]01.BMC'!W28 -> 0 | X33: =SUM(Y33:AA33) -> 0 | Y33: ='[5]01.BMC'!Y28 -> 0 | Z33: ='[5]01.BMC'!Z28 -> 0 | AA33: ='[5]01.BMC'!AA28 -> 0 | AB33: =SUM(AC33:AE33) -> 0 | AF33: =SUM(AG33:AI33) -> 0 | AG33: ='[5]01.BMC'!AG28 -> 0 | AH33: ='[5]01.BMC'!AH28 -> 0 | AI33: ='[5]01.BMC'!AI28 -> 0 | AJ33: =SUM(AK33:AM33) -> 0 | AO33: =IF(SUM(E33:F33)<>0, "OK", "-") -> -
A34: 73 | B34: 7306 | C34: 73066 | D34: ចំណូលពីអាជ្ញាប័ណ្ណក្នុងស្រុក | E34: ='[5]01.BMC'!E29 -> 0 | F34: =H34+P34+X34+AF34 -> 0 | G34: =IFERROR(F34/E34, "-") -> - | H34: =SUM(I34:K34) -> 0 | I34: ='[5]01.BMC'!I29 -> 0 | J34: ='[5]01.BMC'!J29 -> 0 | K34: ='[5]01.BMC'!K29 -> 0 | L34: =SUM(M34:O34) -> 0 | M34: ='[5]01.BMC'!M29 -> 0 | N34: ='[5]01.BMC'!N29 -> 0 | O34: ='[5]01.BMC'!O29 -> 0 | P34: =SUM(Q34:S34) -> 0 | Q34: ='[5]01.BMC'!Q29 -> 0 | R34: ='[5]01.BMC'!R29 -> 0 | S34: ='[5]01.BMC'!S29 -> 0 | T34: =SUM(U34:W34) -> 0 | U34: ='[5]01.BMC'!U29 -> 0 | V34: ='[5]01.BMC'!V29 -> 0 | W34: ='[5]01.BMC'!W29 -> 0 | X34: =SUM(Y34:AA34) -> 0 | Y34: ='[5]01.BMC'!Y29 -> 0 | Z34: ='[5]01.BMC'!Z29 -> 0 | AA34: ='[5]01.BMC'!AA29 -> 0 | AB34: =SUM(AC34:AE34) -> 0 | AF34: =SUM(AG34:AI34) -> 0 | AG34: ='[5]01.BMC'!AG29 -> 0 | AH34: ='[5]01.BMC'!AH29 -> 0 | AI34: ='[5]01.BMC'!AI29 -> 0 | AJ34: =SUM(AK34:AM34) -> 0 | AO34: =IF(SUM(E34:F34)<>0, "OK", "-") -> -
A35: 73 | B35: 7307 | C35: 73071 | D35: ការជួលដីទំនេរ | E35: =E162 -> 0 | F35: =H35+P35+X35+AF35 -> 0 | G35: =IFERROR(F35/E35, "-") -> - | H35: =SUM(I35:K35) -> 0 | I35: =I162 -> 0 | J35: =J162 -> 0 | K35: =K162 -> 0 | L35: =SUM(M35:O35) -> 0 | M35: =M162 -> 0 | N35: =N162 -> 0 | O35: =O162 -> 0 | P35: =SUM(Q35:S35) -> 0 | Q35: =Q162 -> 0 | R35: =R162 -> 0 | S35: =S162 -> 0 | T35: =SUM(U35:W35) -> 0 | U35: =U162 -> 0 | V35: =V162 -> 0 | W35: =W162 -> 0 | X35: =SUM(Y35:AA35) -> 0 | Y35: =Y162 -> 0 | Z35: =Z162 -> 0 | AA35: =AA162 -> 0 | AB35: =SUM(AC35:AE35) -> 0 | AC35: =AC162 -> 0 | AD35: =AD162 -> 0 | AE35: =AE162 -> 0 | AF35: =SUM(AG35:AI35) -> 0 | AG35: =AG162 -> 0 | AH35: =AH162 -> 0 | AI35: =AI162 -> 0 | AJ35: =SUM(AK35:AM35) -> 0 | AK35: =AK162 -> 0 | AL35: =AL162 -> 0 | AM35: =AM162 -> 0 | AO35: =IF(SUM(E35:F35)<>0, "OK", "-") -> -
A36: 73 | B36: 7307 | C36: 73072 | D36: ការជួលដីមានអគារ | E36: =E158+E163 -> 0 | F36: =H36+P36+X36+AF36 -> 0 | G36: =IFERROR(F36/E36, "-") -> - | H36: =SUM(I36:K36) -> 0 | I36: =I158+I163 -> 0 | J36: =J158+J163 -> 0 | K36: =K158+K163 -> 0 | L36: =SUM(M36:O36) -> 0 | M36: =M158+M163 -> 0 | N36: =N158+N163 -> 0 | O36: =O158+O163 -> 0 | P36: =SUM(Q36:S36) -> 0 | Q36: =Q158+Q163 -> 0 | R36: =R158+R163 -> 0 | S36: =S158+S163 -> 0 | T36: =SUM(U36:W36) -> 0 | U36: =U158+U163 -> 0 | V36: =V158+V163 -> 0 | W36: =W158+W163 -> 0 | X36: =SUM(Y36:AA36) -> 0 | Y36: =Y158+Y163 -> 0 | Z36: =Z158+Z163 -> 0 | AA36: =AA158+AA163 -> 0 | AB36: =SUM(AC36:AE36) -> 0 | AC36: =AC158+AC163 -> 0 | AD36: =AD158+AD163 -> 0 | AE36: =AE158+AE163 -> 0 | AF36: =SUM(AG36:AI36) -> 0 | AG36: =AG158+AG163 -> 0 | AH36: =AH158+AH163 -> 0 | AI36: =AI158+AI163 -> 0 | AJ36: =SUM(AK36:AM36) -> 0 | AK36: =AK158+AK163 -> 0 | AL36: =AL158+AL163 -> 0 | AM36: =AM158+AM163 -> 0 | AO36: =IF(SUM(E36:F36)<>0, "OK", "-") -> -
D37: មន្ទីរសេដ្ឋកិច្ចនិងហិរញ្ញវត្ថុខេត្តកំពង់ស្ពឺ | E37: =SUM(E38:E41) -> 0 | F37: =SUM(F38:F41) -> 0 | G37: =IFERROR(F37/E37, "-") -> - | H37: =SUM(H38:H41) -> 0 | I37: =SUM(I38:I41) -> 0 | J37: =SUM(J38:J41) -> 0 | K37: =SUM(K38:K41) -> 0 | L37: =SUM(L38:L41) -> 0 | M37: =SUM(M38:M41) -> 0 | N37: =SUM(N38:N41) -> 0 | O37: =SUM(O38:O41) -> 0 | ... AM37: =SUM(AM38:AM41) -> 0 | AO37: =IF(SUM(E37:F37)<>0, "OK", "-") -> -
A38: 73 | B38: 7302 | C38: 73023 | D38: ផលពីការបង្កើតសហគ្រាស | E38: ='[5]01.BMC'!E33 -> 0 | F38: =H38+P38+X38+AF38 -> 0 | G38: =IFERROR(F38/E38, "-") -> - | H38: =SUM(I38:K38) -> 0 | I38: ='[5]01.BMC'!I33 -> 0 | J38: ='[5]01.BMC'!J33 -> 0 | K38: ='[5]01.BMC'!K33 -> 0 | L38: =SUM(M38:O38) -> 0 | M38: ='[5]01.BMC'!M33 -> 0 | N38: ='[5]01.BMC'!N33 -> 0 | O38: ='[5]01.BMC'!O33 -> 0 | P38: =SUM(Q38:S38) -> 0 | Q38: ='[5]01.BMC'!Q33 -> 0 | R38: ='[5]01.BMC'!R33 -> 0 | S38: ='[5]01.BMC'!S33 -> 0 | T38: =SUM(U38:W38) -> 0 | U38: ='[5]01.BMC'!U33 -> 0 | V38: ='[5]01.BMC'!V33 -> 0 | W38: ='[5]01.BMC'!W33 -> 0 | X38: =SUM(Y38:AA38) -> 0 | Y38: ='[5]01.BMC'!Y33 -> 0 | Z38: ='[5]01.BMC'!Z33 -> 0 | AA38: ='[5]01.BMC'!AA33 -> 0 | AB38: =SUM(AC38:AE38) -> 0 | AF38: =SUM(AG38:AI38) -> 0 | AG38: ='[5]01.BMC'!AG33 -> 0 | AH38: ='[5]01.BMC'!AH33 -> 0 | AI38: ='[5]01.BMC'!AI33 -> 0 | AJ38: =SUM(AK38:AM38) -> 0 | AO38: =IF(SUM(E38:F38)<>0, "OK", "-") -> -
A39: 73 | B39: 7306 | C39: 73066 | D39: ចំណូលពីអាជ្ញាប័ណ្ណក្នុងស្រុក | E39: ='[5]01.BMC'!E34 -> 0 | F39: =H39+P39+X39+AF39 -> 0 | G39: =IFERROR(F39/E39, "-") -> - | H39: =SUM(I39:K39) -> 0 | I39: ='[5]01.BMC'!I34 -> 0 | J39: ='[5]01.BMC'!J34 -> 0 | K39: ='[5]01.BMC'!K34 -> 0 | L39: =SUM(M39:O39) -> 0 | M39: ='[5]01.BMC'!M34 -> 0 | N39: ='[5]01.BMC'!N34 -> 0 | O39: ='[5]01.BMC'!O34 -> 0 | P39: =SUM(Q39:S39) -> 0 | Q39: ='[5]01.BMC'!Q34 -> 0 | R39: ='[5]01.BMC'!R34 -> 0 | S39: ='[5]01.BMC'!S34 -> 0 | T39: =SUM(U39:W39) -> 0 | U39: ='[5]01.BMC'!U34 -> 0 | V39: ='[5]01.BMC'!V34 -> 0 | W39: ='[5]01.BMC'!W34 -> 0 | X39: =SUM(Y39:AA39) -> 0 | Y39: ='[5]01.BMC'!Y34 -> 0 | Z39: ='[5]01.BMC'!Z34 -> 0 | AA39: ='[5]01.BMC'!AA34 -> 0 | AB39: =SUM(AC39:AE39) -> 0 | AF39: =SUM(AG39:AI39) -> 0 | AG39: ='[5]01.BMC'!AG34 -> 0 | AH39: ='[5]01.BMC'!AH34 -> 0 | AI39: ='[5]01.BMC'!AI34 -> 0 | AJ39: =SUM(AK39:AM39) -> 0 | AO39: =IF(SUM(E39:F39)<>0, "OK", "-") -> -
A40: 73 | B40: 7307 | C40: 73071 | D40: ការជួលដីទំនេរ | E40: =E167 -> 0 | F40: =H40+P40+X40+AF40 -> 0 | G40: =IFERROR(F40/E40, "-") -> - | H40: =SUM(I40:K40) -> 0 | I40: =I167 -> 0 | J40: =J167 -> 0 | K40: =K167 -> 0 | L40: =SUM(M40:O40) -> 0 | M40: =M167 -> 0 | N40: =N167 -> 0 | O40: =O167 -> 0 | P40: =SUM(Q40:S40) -> 0 | Q40: =Q167 -> 0 | R40: =R167 -> 0 | S40: =S167 -> 0 | T40: =SUM(U40:W40) -> 0 | U40: =U167 -> 0 | V40: =V167 -> 0 | W40: =W167 -> 0 | X40: =SUM(Y40:AA40) -> 0 | Y40: =Y167 -> 0 | Z40: =Z167 -> 0 | AA40: =AA167 -> 0 | AB40: =SUM(AC40:AE40) -> 0 | AC40: =AC167 -> 0 | AD40: =AD167 -> 0 | AE40: =AE167 -> 0 | AF40: =SUM(AG40:AI40) -> 0 | AG40: =AG167 -> 0 | AH40: =AH167 -> 0 | AI40: =AI167 -> 0 | AJ40: =SUM(AK40:AM40) -> 0 | AK40: =AK167 -> 0 | AL40: =AL167 -> 0 | AM40: =AM167 -> 0 | AO40: =IF(SUM(E40:F40)<>0, "OK", "-") -> -
A41: 73 | B41: 7307 | C41: 73072 | D41: ការជួលដីមានអគារ | E41: =E163+E168 -> 0 | F41: =H41+P41+X41+AF41 -> 0 | G41: =IFERROR(F41/E41, "-") -> - | H41: =SUM(I41:K41) -> 0 | I41: =I163+I168 -> 0 | J41: =J163+J168 -> 0 | K41: =K163+K168 -> 0 | L41: =SUM(M41:O41) -> 0 | M41: =M163+M168 -> 0 | N41: =N163+N168 -> 0 | O41: =O163+O168 -> 0 | P41: =SUM(Q41:S41) -> 0 | Q41: =Q163+Q168 -> 0 | R41: =R163+R168 -> 0 | S41: =S163+S168 -> 0 | T41: =SUM(U41:W41) -> 0 | U41: =U163+U168 -> 0 | V41: =V163+V168 -> 0 | W41: =W163+W168 -> 0 | X41: =SUM(Y41:AA41) -> 0 | Y41: =Y163+Y168 -> 0 | Z41: =Z163+Z168 -> 0 | AA41: =AA163+AA168 -> 0 | AB41: =SUM(AC41:AE41) -> 0 | AC41: =AC163+AC168 -> 0 | AD41: =AD163+AD168 -> 0 | AE41: =AE163+AE168 -> 0 | AF41: =SUM(AG41:AI41) -> 0 | AG41: =AG163+AG168 -> 0 | AH41: =AH163+AH168 -> 0 | AI41: =AI163+AI168 -> 0 | AJ41: =SUM(AK41:AM41) -> 0 | AK41: =AK163+AK168 -> 0 | AL41: =AL163+AL168 -> 0 | AM41: =AM163+AM168 -> 0 | AO41: =IF(SUM(E41:F41)<>0, "OK", "-") -> -
D42: មន្ទីរសេដ្ឋកិច្ចនិងហិរញ្ញវត្ថុខេត្តកំពង់ធំ | E42: =SUM(E43:E46) -> 0 | F42: =SUM(F43:F46) -> 0 | G42: =IFERROR(F42/E42, "-") -> - | H42: =SUM(H43:H46) -> 0 | I42: =SUM(I43:I46) -> 0 | J42: =SUM(J43:J46) -> 0 | K42: =SUM(K43:K46) -> 0 | L42: =SUM(L43:L46) -> 0 | M42: =SUM(M43:M46) -> 0 | N42: =SUM(N43:N46) -> 0 | O42: =SUM(O43:O46) -> 0 | ... AM42: =SUM(AM43:AM46) -> 0 | AO42: =IF(SUM(E42:F42)<>0, "OK", "-") -> -
...
