Workbook

Sheet PIP-Status 2017 (2)
A4: សម្រង់ស្ថានភាព​គម្រោងវិនិយោគសាធារណៈ ឆ្នាំ២០១៧-២០១៨ នៃក្រសួងសេដ្ឋកិច្ចនិងហិរញ្ញវត្ថុ
U6: ឯកតា៖លានរៀល
A7: ឈ្មោះគម្រោង | B7: តម្លៃគម្រោង | C7: ឆ្នាំ២០១៧ | L7: ឆ្នាំ២០១៨ | R7: ឆ្នាំ២០១៩ | U7: ផ្សេងៗ
C8: គម្រោងស្នើសុំ | F8: គម្រោងអនុម័ត | I8: ចំណាយ​អនុវត្តជាក់ស្ដែង | L8: គម្រោងស្នើសុំ | O8: គម្រោងអនុម័ត | R8: គម្រោងស្នើសុំ
C9: សរុប | D9: ហិរ.ក្នុងប្រ/ទ | E9: ហិរ.ក្រៅប្រ/ទ | F9: សរុប | G9: ហិរ.ក្នុងប្រ/ទ | H9: ហិរ.ក្រៅប្រ/ទ | I9: សរុប | J9: ហិរ.ក្នុងប្រ/ទ | K9: ហិរ.ក្រៅប្រ/ទ | L9: សរុប | M9: ហិរ.ក្នុងប្រ/ទ | N9: ហិរ.ក្រៅប្រ/ទ | O9: សរុប | P9: ហិរ.ក្នុងប្រ/ទ | Q9: ហិរ.ក្រៅប្រ/ទ | R9: សរុប | S9: ហិរ.ក្នុងប្រ/ទ | T9: ហិរ.ក្រៅប្រ/ទ
A10: សរុបក្រសួងសេដ្ឋកិច្ចនិងហិរញ្ញវត្ថុ | B10: =B11 -> 0 | C10: =D10+E10 -> 20414.8 | D10: =D11+D104 -> 1184.8 | E10: =E11+E104 -> 19230 | F10: =G10+H10 -> 14690.5 | G10: =G11+G104 -> 5703.3 | H10: =H11+H104 -> 8987.2 | I10: =J10+K10 -> 0 | J10: =J11+J104 -> 0 | K10: =K11+K104 -> 0 | L10: =M10+N10 -> 12000 | M10: =M11+M104 -> 0 | N10: =N11+N104 -> 12000 | O10: =P10+Q10 -> 4518.5 | P10: =P11+P104 -> 4518.5 | Q10: =Q11+Q104 -> 0 | R10: =S10+T10 -> 0 | S10: =S11+S104 -> 0 | T10: =T11+T104 -> 0 | V10: =IF((B10+C10+F10+L10+O10)<>0,"ok","-") -> ok
A11: គោលបំណងគោលនយោបាយទី១ | B11: =B12 -> 0 | C11: =D11+E11 -> 0 | D11: =D12+D58 -> 0 | E11: =E12+E58 -> 0 | F11: =G11+H11 -> 0 | G11: =G12+G58 -> 0 | H11: =H12+H58 -> 0 | I11: =J11+K11 -> 0 | J11: =J12+J58 -> 0 | K11: =K12+K58 -> 0 | L11: =M11+N11 -> 0 | M11: =M12+M58 -> 0 | N11: =N12+N58 -> 0 | O11: =P11+Q11 -> 0 | P11: =P12+P58 -> 0 | Q11: =Q12+Q58 -> 0 | R11: =S11+T11 -> 0 | S11: =S12+S58 -> 0 | T11: =T12+T58 -> 0 | V11: =IF((B11+C11+F11+L11+O11)<>0,"ok","-") -> -
A12: កម្មវិធីទី១ | B12: =B13 -> 0 | C12: =D12+E12 -> 0 | D12: =D13+D28+D43 -> 0 | E12: =E13+E28+E43 -> 0 | F12: =G12+H12 -> 0 | G12: =G13+G28+G43 -> 0 | H12: =H13+H28+H43 -> 0 | I12: =J12+K12 -> 0 | J12: =J13+J28+J43 -> 0 | K12: =K13+K28+K43 -> 0 | L12: =M12+N12 -> 0 | M12: =M13+M28+M43 -> 0 | N12: =N13+N28+N43 -> 0 | O12: =P12+Q12 -> 0 | P12: =P13+P28+P43 -> 0 | Q12: =Q13+Q28+Q43 -> 0 | R12: =S12+T12 -> 0 | S12: =S13+S28+S43 -> 0 | T12: =T13+T28+T43 -> 0 | V12: =IF((B12+C12+F12+L12+O12)<>0,"ok","-") -> -
A13: អនុកម្មវិធីទី១.១ (អគ្គនាយកដ្ឋានគោលនយោបាយ) | B13: =B14+B21 -> 0 | C13: =D13+E13 -> 0 | D13: =D14+D21 -> 0 | E13: =E14+E21 -> 0 | F13: =G13+H13 -> 0 | G13: =G14+G21 -> 0 | H13: =H14+H21 -> 0 | I13: =J13+K13 -> 0 | J13: =J14+J21 -> 0 | K13: =K14+K21 -> 0 | L13: =M13+N13 -> 0 | M13: =M14+M21 -> 0 | N13: =N14+N21 -> 0 | O13: =P13+Q13 -> 0 | P13: =P14+P21 -> 0 | Q13: =Q14+Q21 -> 0 | R13: =S13+T13 -> 0 | S13: =S14+S21 -> 0 | T13: =T14+T21 -> 0 | V13: =IF((B13+C13+F13+L13+O13)<>0,"ok","-") -> -
A14: I. សរុបគម្រោងកំពុងដំណើរការ | B14: =B15+B18 -> 0 | C14: =D14+E14 -> 0 | D14: =D15+D18 -> 0 | E14: =E15+E18 -> 0 | F14: =G14+H14 -> 0 | G14: =G15+G18 -> 0 | H14: =H15+H18 -> 0 | I14: =J14+K14 -> 0 | J14: =J15+J18 -> 0 | K14: =K15+K18 -> 0 | L14: =M14+N14 -> 0 | M14: =M15+M18 -> 0 | N14: =N15+N18 -> 0 | O14: =P14+Q14 -> 0 | P14: =P15+P18 -> 0 | Q14: =Q15+Q18 -> 0 | R14: =S14+T14 -> 0 | S14: =S15+S18 -> 0 | T14: =T15+T18 -> 0 | V14: =IF((B14+C14+F14+L14+O14)<>0,"ok","-") -> -
A15: -គម្រោងវិនិយោគជាទុន | B15: =SUM(B16:B17) -> 0 | C15: =D15+E15 -> 0 | D15: =SUM(D16:D17) -> 0 | E15: =SUM(E16:E17) -> 0 | F15: =G15+H15 -> 0 | G15: =SUM(G16:G17) -> 0 | H15: =SUM(H16:H17) -> 0 | I15: =J15+K15 -> 0 | J15: =SUM(J16:J17) -> 0 | K15: =SUM(K16:K17) -> 0 | L15: =M15+N15 -> 0 | M15: =SUM(M16:M17) -> 0 | N15: =SUM(N16:N17) -> 0 | O15: =P15+Q15 -> 0 | P15: =SUM(P16:P17) -> 0 | Q15: =SUM(Q16:Q17) -> 0 | R15: =S15+T15 -> 0 | S15: =SUM(S16:S17) -> 0 | T15: =SUM(T16:T17) -> 0 | V15: =IF((B15+C15+F15+L15+O15)<>0,"ok","-") -> -
A16: ១.គម្រោង...... | C16: =D16+E16 -> 0 | F16: =G16+H16 -> 0 | I16: =J16+K16 -> 0 | L16: =M16+N16 -> 0 | O16: =P16+Q16 -> 0 | R16: =S16+T16 -> 0 | V16: =IF((B16+C16+F16+L16+O16)<>0,"ok","-") -> -
A17: ២.គម្រោង...... | C17: =D17+E17 -> 0 | F17: =G17+H17 -> 0 | I17: =J17+K17 -> 0 | L17: =M17+N17 -> 0 | O17: =P17+Q17 -> 0 | R17: =S17+T17 -> 0 | V17: =IF((B17+C17+F17+L17+O17)<>0,"ok","-") -> -
A18: -គម្រោងជំនួយបច្ចេកទេស | B18: =SUM(B19:B20) -> 0 | C18: =D18+E18 -> 0 | D18: =SUM(D19:D20) -> 0 | E18: =SUM(E19:E20) -> 0 | F18: =G18+H18 -> 0 | G18: =SUM(G19:G20) -> 0 | H18: =SUM(H19:H20) -> 0 | I18: =J18+K18 -> 0 | J18: =SUM(J19:J20) -> 0 | K18: =SUM(K19:K20) -> 0 | L18: =M18+N18 -> 0 | M18: =SUM(M19:M20) -> 0 | N18: =SUM(N19:N20) -> 0 | O18: =P18+Q18 -> 0 | P18: =SUM(P19:P20) -> 0 | Q18: =SUM(Q19:Q20) -> 0 | R18: =S18+T18 -> 0 | S18: =SUM(S19:S20) -> 0 | T18: =SUM(T19:T20) -> 0 | V18: =IF((B18+C18+F18+L18+O18)<>0,"ok","-") -> -
A19: ៣.គម្រោង...... | C19: =D19+E19 -> 0 | F19: =G19+H19 -> 0 | I19: =J19+K19 -> 0 | L19: =M19+N19 -> 0 | O19: =P19+Q19 -> 0 | R19: =S19+T19 -> 0 | V19: =IF((B19+C19+F19+L19+O19)<>0,"ok","-") -> -
A20: ៤.គម្រោង...... | C20: =D20+E20 -> 0 | F20: =G20+H20 -> 0 | I20: =J20+K20 -> 0 | L20: =M20+N20 -> 0 | O20: =P20+Q20 -> 0 | R20: =S20+T20 -> 0 | V20: =IF((B20+C20+F20+L20+O20)<>0,"ok","-") -> -
A21: II. សរុបគម្រោងស្នើសុំថ្មី (ដើម្បីអនុវត្ត ផ.យ.អ.ជ) | B21: =B22+B25 -> 0 | C21: =D21+E21 -> 0 | D21: =D22+D25 -> 0 | E21: =E22+E25 -> 0 | F21: =G21+H21 -> 0 | G21: =G22+G25 -> 0 | H21: =H22+H25 -> 0 | I21: =J21+K21 -> 0 | J21: =J22+J25 -> 0 | K21: =K22+K25 -> 0 | L21: =M21+N21 -> 0 | M21: =M22+M25 -> 0 | N21: =N22+N25 -> 0 | O21: =P21+Q21 -> 0 | P21: =P22+P25 -> 0 | Q21: =Q22+Q25 -> 0 | R21: =S21+T21 -> 0 | S21: =S22+S25 -> 0 | T21: =T22+T25 -> 0 | V21: =IF((B21+C21+F21+L21+O21)<>0,"ok","-") -> -
A22: -គម្រោងវិនិយោគជាទុន | B22: =SUM(B23:B24) -> 0 | C22: =D22+E22 -> 0 | D22: =SUM(D23:D24) -> 0 | E22: =SUM(E23:E24) -> 0 | F22: =G22+H22 -> 0 | G22: =SUM(G23:G24) -> 0 | H22: =SUM(H23:H24) -> 0 | I22: =J22+K22 -> 0 | J22: =SUM(J23:J24) -> 0 | K22: =SUM(K23:K24) -> 0 | L22: =M22+N22 -> 0 | M22: =SUM(M23:M24) -> 0 | N22: =SUM(N23:N24) -> 0 | O22: =P22+Q22 -> 0 | P22: =SUM(P23:P24) -> 0 | Q22: =SUM(Q23:Q24) -> 0 | R22: =S22+T22 -> 0 | S22: =SUM(S23:S24) -> 0 | T22: =SUM(T23:T24) -> 0 | V22: =IF((B22+C22+F22+L22+O22)<>0,"ok","-") -> -
A23: ១.គម្រោង...... | C23: =D23+E23 -> 0 | F23: =G23+H23 -> 0 | I23: =J23+K23 -> 0 | L23: =M23+N23 -> 0 | O23: =P23+Q23 -> 0 | R23: =S23+T23 -> 0 | V23: =IF((B23+C23+F23+L23+O23)<>0,"ok","-") -> -
A24: ២.គម្រោង...... | C24: =D24+E24 -> 0 | F24: =G24+H24 -> 0 | I24: =J24+K24 -> 0 | L24: =M24+N24 -> 0 | O24: =P24+Q24 -> 0 | R24: =S24+T24 -> 0 | V24: =IF((B24+C24+F24+L24+O24)<>0,"ok","-") -> -
A25: -គម្រោងជំនួយបច្ចេកទេស | B25: =SUM(B26:B27) -> 0 | C25: =D25+E25 -> 0 | D25: =SUM(D26:D27) -> 0 | E25: =SUM(E26:E27) -> 0 | F25: =G25+H25 -> 0 | G25: =SUM(G26:G27) -> 0 | H25: =SUM(H26:H27) -> 0 | I25: =J25+K25 -> 0 | J25: =SUM(J26:J27) -> 0 | K25: =SUM(K26:K27) -> 0 | L25: =M25+N25 -> 0 | M25: =SUM(M26:M27) -> 0 | N25: =SUM(N26:N27) -> 0 | O25: =P25+Q25 -> 0 | P25: =SUM(P26:P27) -> 0 | Q25: =SUM(Q26:Q27) -> 0 | R25: =S25+T25 -> 0 | S25: =SUM(S26:S27) -> 0 | T25: =SUM(T26:T27) -> 0 | V25: =IF((B25+C25+F25+L25+O25)<>0,"ok","-") -> -
A26: ៣.គម្រោង...... | C26: =D26+E26 -> 0 | F26: =G26+H26 -> 0 | I26: =J26+K26 -> 0 | L26: =M26+N26 -> 0 | O26: =P26+Q26 -> 0 | R26: =S26+T26 -> 0 | V26: =IF((B26+C26+F26+L26+O26)<>0,"ok","-") -> -
A27: ៤.គម្រោង...... | C27: =D27+E27 -> 0 | F27: =G27+H27 -> 0 | I27: =J27+K27 -> 0 | L27: =M27+N27 -> 0 | O27: =P27+Q27 -> 0 | R27: =S27+T27 -> 0 | V27: =IF((B27+C27+F27+L27+O27)<>0,"ok","-") -> -
A28: អនុកម្មវិធីទី១.២ (ឧត្តមក្រុមប្រឹក្សាសេដ្ឋកិច្ចជាតិ) | B28: =B29+B36 -> 0 | C28: =D28+E28 -> 0 | D28: =D29+D36 -> 0 | E28: =E29+E36 -> 0 | F28: =G28+H28 -> 0 | G28: =G29+G36 -> 0 | H28: =H29+H36 -> 0 | I28: =J28+K28 -> 0 | J28: =J29+J36 -> 0 | K28: =K29+K36 -> 0 | L28: =M28+N28 -> 0 | M28: =M29+M36 -> 0 | N28: =N29+N36 -> 0 | O28: =P28+Q28 -> 0 | P28: =P29+P36 -> 0 | Q28: =Q29+Q36 -> 0 | R28: =S28+T28 -> 0 | S28: =S29+S36 -> 0 | T28: =T29+T36 -> 0 | V28: =IF((B28+C28+F28+L28+O28)<>0,"ok","-") -> -
A29: I. សរុបគម្រោងកំពុងដំណើរការ | B29: =B30+B33 -> 0 | C29: =D29+E29 -> 0 | D29: =D30+D33 -> 0 | E29: =E30+E33 -> 0 | F29: =G29+H29 -> 0 | G29: =G30+G33 -> 0 | H29: =H30+H33 -> 0 | I29: =J29+K29 -> 0 | J29: =J30+J33 -> 0 | K29: =K30+K33 -> 0 | L29: =M29+N29 -> 0 | M29: =M30+M33 -> 0 | N29: =N30+N33 -> 0 | O29: =P29+Q29 -> 0 | P29: =P30+P33 -> 0 | Q29: =Q30+Q33 -> 0 | R29: =S29+T29 -> 0 | S29: =S30+S33 -> 0 | T29: =T30+T33 -> 0 | V29: =IF((B29+C29+F29+L29+O29)<>0,"ok","-") -> -
A30: -គម្រោងវិនិយោគជាទុន | B30: =SUM(B31:B32) -> 0 | C30: =D30+E30 -> 0 | D30: =SUM(D31:D32) -> 0 | E30: =SUM(E31:E32) -> 0 | F30: =G30+H30 -> 0 | G30: =SUM(G31:G32) -> 0 | H30: =SUM(H31:H32) -> 0 | I30: =J30+K30 -> 0 | J30: =SUM(J31:J32) -> 0 | K30: =SUM(K31:K32) -> 0 | L30: =M30+N30 -> 0 | M30: =SUM(M31:M32) -> 0 | N30: =SUM(N31:N32) -> 0 | O30: =P30+Q30 -> 0 | P30: =SUM(P31:P32) -> 0 | Q30: =SUM(Q31:Q32) -> 0 | R30: =S30+T30 -> 0 | S30: =SUM(S31:S32) -> 0 | T30: =SUM(T31:T32) -> 0 | V30: =IF((B30+C30+F30+L30+O30)<>0,"ok","-") -> -
A31: ១.គម្រោង...... | C31: =D31+E31 -> 0 | F31: =G31+H31 -> 0 | I31: =J31+K31 -> 0 | L31: =M31+N31 -> 0 | O31: =P31+Q31 -> 0 | R31: =S31+T31 -> 0 | V31: =IF((B31+C31+F31+L31+O31)<>0,"ok","-") -> -
A32: ២.គម្រោង...... | C32: =D32+E32 -> 0 | F32: =G32+H32 -> 0 | I32: =J32+K32 -> 0 | L32: =M32+N32 -> 0 | O32: =P32+Q32 -> 0 | R32: =S32+T32 -> 0 | V32: =IF((B32+C32+F32+L32+O32)<>0,"ok","-") -> -
A33: -គម្រោងជំនួយបច្ចេកទេស | B33: =SUM(B34:B35) -> 0 | C33: =D33+E33 -> 0 | D33: =SUM(D34:D35) -> 0 | E33: =SUM(E34:E35) -> 0 | F33: =G33+H33 -> 0 | G33: =SUM(G34:G35) -> 0 | H33: =SUM(H34:H35) -> 0 | I33: =J33+K33 -> 0 | J33: =SUM(J34:J35) -> 0 | K33: =SUM(K34:K35) -> 0 | L33: =M33+N33 -> 0 | M33: =SUM(M34:M35) -> 0 | N33: =SUM(N34:N35) -> 0 | O33: =P33+Q33 -> 0 | P33: =SUM(P34:P35) -> 0 | Q33: =SUM(Q34:Q35) -> 0 | R33: =S33+T33 -> 0 | S33: =SUM(S34:S35) -> 0 | T33: =SUM(T34:T35) -> 0 | V33: =IF((B33+C33+F33+L33+O33)<>0,"ok","-") -> -
A34: ៣.គម្រោង...... | C34: =D34+E34 -> 0 | F34: =G34+H34 -> 0 | I34: =J34+K34 -> 0 | L34: =M34+N34 -> 0 | O34: =P34+Q34 -> 0 | R34: =S34+T34 -> 0 | V34: =IF((B34+C34+F34+L34+O34)<>0,"ok","-") -> -
A35: ៤.គម្រោង...... | C35: =D35+E35 -> 0 | F35: =G35+H35 -> 0 | I35: =J35+K35 -> 0 | L35: =M35+N35 -> 0 | O35: =P35+Q35 -> 0 | R35: =S35+T35 -> 0 | V35: =IF((B35+C35+F35+L35+O35)<>0,"ok","-") -> -
A36: II. សរុបគម្រោងស្នើសុំថ្មី (ដើម្បីអនុវត្ត ផ.យ.អ.ជ) | B36: =B37+B40 -> 0 | C36: =D36+E36 -> 0 | D36: =D37+D40 -> 0 | E36: =E37+E40 -> 0 | F36: =G36+H36 -> 0 | G36: =G37+G40 -> 0 | H36: =H37+H40 -> 0 | I36: =J36+K36 -> 0 | J36: =J37+J40 -> 0 | K36: =K37+K40 -> 0 | L36: =M36+N36 -> 0 | M36: =M37+M40 -> 0 | N36: =N37+N40 -> 0 | O36: =P36+Q36 -> 0 | P36: =P37+P40 -> 0 | Q36: =Q37+Q40 -> 0 | R36: =S36+T36 -> 0 | S36: =S37+S40 -> 0 | T36: =T37+T40 -> 0 | V36: =IF((B36+C36+F36+L36+O36)<>0,"ok","-") -> -
A37: -គម្រោងវិនិយោគជាទុន | B37: =SUM(B38:B39) -> 0 | C37: =D37+E37 -> 0 | D37: =SUM(D38:D39) -> 0 | E37: =SUM(E38:E39) -> 0 | F37: =G37+H37 -> 0 | G37: =SUM(G38:G39) -> 0 | H37: =SUM(H38:H39) -> 0 | I37: =J37+K37 -> 0 | J37: =SUM(J38:J39) -> 0 | K37: =SUM(K38:K39) -> 0 | L37: =M37+N37 -> 0 | M37: =SUM(M38:M39) -> 0 | N37: =SUM(N38:N39) -> 0 | O37: =P37+Q37 -> 0 | P37: =SUM(P38:P39) -> 0 | Q37: =SUM(Q38:Q39) -> 0 | R37: =S37+T37 -> 0 | S37: =SUM(S38:S39) -> 0 | T37: =SUM(T38:T39) -> 0 | V37: =IF((B37+C37+F37+L37+O37)<>0,"ok","-") -> -
A38: ១.គម្រោង...... | C38: =D38+E38 -> 0 | F38: =G38+H38 -> 0 | I38: =J38+K38 -> 0 | L38: =M38+N38 -> 0 | O38: =P38+Q38 -> 0 | R38: =S38+T38 -> 0 | V38: =IF((B38+C38+F38+L38+O38)<>0,"ok","-") -> -
A39: ២.គម្រោង...... | C39: =D39+E39 -> 0 | F39: =G39+H39 -> 0 | I39: =J39+K39 -> 0 | L39: =M39+N39 -> 0 | O39: =P39+Q39 -> 0 | R39: =S39+T39 -> 0 | V39: =IF((B39+C39+F39+L39+O39)<>0,"ok","-") -> -
A40: -គម្រោងជំនួយបច្ចេកទេស | B40: =SUM(B41:B42) -> 0 | C40: =D40+E40 -> 0 | D40: =SUM(D41:D42) -> 0 | E40: =SUM(E41:E42) -> 0 | F40: =G40+H40 -> 0 | G40: =SUM(G41:G42) -> 0 | H40: =SUM(H41:H42) -> 0 | I40: =J40+K40 -> 0 | J40: =SUM(J41:J42) -> 0 | K40: =SUM(K41:K42) -> 0 | L40: =M40+N40 -> 0 | M40: =SUM(M41:M42) -> 0 | N40: =SUM(N41:N42) -> 0 | O40: =P40+Q40 -> 0 | P40: =SUM(P41:P42) -> 0 | Q40: =SUM(Q41:Q42) -> 0 | R40: =S40+T40 -> 0 | S40: =SUM(S41:S42) -> 0 | T40: =SUM(T41:T42) -> 0 | V40: =IF((B40+C40+F40+L40+O40)<>0,"ok","-") -> -
A41: ៣.គម្រោង...... | C41: =D41+E41 -> 0 | F41: =G41+H41 -> 0 | I41: =J41+K41 -> 0 | L41: =M41+N41 -> 0 | O41: =P41+Q41 -> 0 | R41: =S41+T41 -> 0 | V41: =IF((B41+C41+F41+L41+O41)<>0,"ok","-") -> -
A42: ៤.គម្រោង...... | C42: =D42+E42 -> 0 | F42: =G42+H42 -> 0 | I42: =J42+K42 -> 0 | L42: =M42+N42 -> 0 | O42: =P42+Q42 -> 0 | R42: =S42+T42 -> 0 | V42: =IF((B42+C42+F42+L42+O42)<>0,"ok","-") -> -
A43: អនុកម្មវិធីទី១.៣ (លេខាធិការដ្ឋាន គ.ផ.ក) | B43: =B44+B51 -> 0 | C43: =D43+E43 -> 0 | D43: =D44+D51 -> 0 | E43: =E44+E51 -> 0 | F43: =G43+H43 -> 0 | G43: =G44+G51 -> 0 | H43: =H44+H51 -> 0 | I43: =J43+K43 -> 0 | J43: =J44+J51 -> 0 | K43: =K44+K51 -> 0 | L43: =M43+N43 -> 0 | M43: =M44+M51 -> 0 | N43: =N44+N51 -> 0 | O43: =P43+Q43 -> 0 | P43: =P44+P51 -> 0 | Q43: =Q44+Q51 -> 0 | R43: =S43+T43 -> 0 | S43: =S44+S51 -> 0 | T43: =T44+T51 -> 0 | V43: =IF((B43+C43+F43+L43+O43)<>0,"ok","-") -> -
A44: I. សរុបគម្រោងកំពុងដំណើរការ | B44: =B45+B48 -> 0 | C44: =D44+E44 -> 0 | D44: =D45+D48 -> 0 | E44: =E45+E48 -> 0 | F44: =G44+H44 -> 0 | G44: =G45+G48 -> 0 | H44: =H45+H48 -> 0 | I44: =J44+K44 -> 0 | J44: =J45+J48 -> 0 | K44: =K45+K48 -> 0 | L44: =M44+N44 -> 0 | M44: =M45+M48 -> 0 | N44: =N45+N48 -> 0 | O44: =P44+Q44 -> 0 | P44: =P45+P48 -> 0 | Q44: =Q45+Q48 -> 0 | R44: =S44+T44 -> 0 | S44: =S45+S48 -> 0 | T44: =T45+T48 -> 0 | V44: =IF((B44+C44+F44+L44+O44)<>0,"ok","-") -> -
...

Sheet PIP-Status 2017-18 
A4: សម្រង់ស្ថានភាព​គម្រោងវិនិយោគសាធារណៈ ឆ្នាំ២០១៧-២០១៨ នៃក្រសួងសេដ្ឋកិច្ចនិងហិរញ្ញវត្ថុ
U6: ឯកតា៖លានរៀល
A7: ឈ្មោះគម្រោង | B7: តម្លៃគម្រោង | C7: ឆ្នាំ២០១៧ | L7: ឆ្នាំ២០១៨ | R7: ឆ្នាំ២០១៩ | U7: ផ្សេងៗ
C8: គម្រោងស្នើសុំ | F8: គម្រោងអនុម័ត | I8: ចំណាយ​អនុវត្តជាក់ស្ដែង | L8: គម្រោងស្នើសុំ | O8: គម្រោងអនុម័ត | R8: គម្រោងស្នើសុំ
C9: សរុប | D9: ហិរ.ក្នុងប្រ/ទ | E9: ហិរ.ក្រៅប្រ/ទ | F9: សរុប | G9: ហិរ.ក្នុងប្រ/ទ | H9: ហិរ.ក្រៅប្រ/ទ | I9: សរុប | J9: ហិរ.ក្នុងប្រ/ទ | K9: ហិរ.ក្រៅប្រ/ទ | L9: សរុប | M9: ហិរ.ក្នុងប្រ/ទ | N9: ហិរ.ក្រៅប្រ/ទ | O9: សរុប | P9: ហិរ.ក្នុងប្រ/ទ | Q9: ហិរ.ក្រៅប្រ/ទ | R9: សរុប | S9: ហិរ.ក្នុងប្រ/ទ | T9: ហិរ.ក្រៅប្រ/ទ
A10: សរុបក្រសួងសេដ្ឋកិច្ចនិងហិរញ្ញវត្ថុ | B10: =B11 -> 0 | C10: =D10+E10 -> 20414.8 | D10: =D11+D104 -> 1184.8 | E10: =E11+E104 -> 19230 | F10: =G10+H10 -> 14690.5 | G10: =G11+G104 -> 5703.3 | H10: =H11+H104 -> 8987.2 | I10: =J10+K10 -> 0 | J10: =J11+J104 -> 0 | K10: =K11+K104 -> 0 | L10: =M10+N10 -> 55378.2 | M10: =M11+M104 -> 46878.2 | N10: =N11+N104 -> 8500 | O10: =P10+Q10 -> 0 | P10: =P11+P104 -> 0 | Q10: =Q11+Q104 -> 0 | R10: =S10+T10 -> 0 | S10: =S11+S104 -> 0 | T10: =T11+T104 -> 0 | V10: =IF((B10+C10+F10+L10+O10)<>0,"ok","-") -> ok
A11: គោលបំណងគោលនយោបាយទី១ | B11: =B12 -> 0 | C11: =D11+E11 -> 0 | D11: =D12+D58 -> 0 | E11: =E12+E58 -> 0 | F11: =G11+H11 -> 0 | G11: =G12+G58 -> 0 | H11: =H12+H58 -> 0 | I11: =J11+K11 -> 0 | J11: =J12+J58 -> 0 | K11: =K12+K58 -> 0 | L11: =M11+N11 -> 1500 | M11: =M12+M58 -> 1500 | N11: =N12+N58 -> 0 | O11: =P11+Q11 -> 0 | P11: =P12+P58 -> 0 | Q11: =Q12+Q58 -> 0 | R11: =S11+T11 -> 0 | S11: =S12+S58 -> 0 | T11: =T12+T58 -> 0 | V11: =IF((B11+C11+F11+L11+O11)<>0,"ok","-") -> ok
A12: កម្មវិធីទី១ | B12: =B13 -> 0 | C12: =D12+E12 -> 0 | D12: =D13+D28+D43 -> 0 | E12: =E13+E28+E43 -> 0 | F12: =G12+H12 -> 0 | G12: =G13+G28+G43 -> 0 | H12: =H13+H28+H43 -> 0 | I12: =J12+K12 -> 0 | J12: =J13+J28+J43 -> 0 | K12: =K13+K28+K43 -> 0 | L12: =M12+N12 -> 0 | M12: =M13+M28+M43 -> 0 | N12: =N13+N28+N43 -> 0 | O12: =P12+Q12 -> 0 | P12: =P13+P28+P43 -> 0 | Q12: =Q13+Q28+Q43 -> 0 | R12: =S12+T12 -> 0 | S12: =S13+S28+S43 -> 0 | T12: =T13+T28+T43 -> 0 | V12: =IF((B12+C12+F12+L12+O12)<>0,"ok","-") -> -
A13: អនុកម្មវិធីទី១.១ (អគ្គនាយកដ្ឋានគោលនយោបាយ) | B13: =B14+B21 -> 0 | C13: =D13+E13 -> 0 | D13: =D14+D21 -> 0 | E13: =E14+E21 -> 0 | F13: =G13+H13 -> 0 | G13: =G14+G21 -> 0 | H13: =H14+H21 -> 0 | I13: =J13+K13 -> 0 | J13: =J14+J21 -> 0 | K13: =K14+K21 -> 0 | L13: =M13+N13 -> 0 | M13: =M14+M21 -> 0 | N13: =N14+N21 -> 0 | O13: =P13+Q13 -> 0 | P13: =P14+P21 -> 0 | Q13: =Q14+Q21 -> 0 | R13: =S13+T13 -> 0 | S13: =S14+S21 -> 0 | T13: =T14+T21 -> 0 | V13: =IF((B13+C13+F13+L13+O13)<>0,"ok","-") -> -
A14: I. សរុបគម្រោងកំពុងដំណើរការ | B14: =B15+B18 -> 0 | C14: =D14+E14 -> 0 | D14: =D15+D18 -> 0 | E14: =E15+E18 -> 0 | F14: =G14+H14 -> 0 | G14: =G15+G18 -> 0 | H14: =H15+H18 -> 0 | I14: =J14+K14 -> 0 | J14: =J15+J18 -> 0 | K14: =K15+K18 -> 0 | L14: =M14+N14 -> 0 | M14: =M15+M18 -> 0 | N14: =N15+N18 -> 0 | O14: =P14+Q14 -> 0 | P14: =P15+P18 -> 0 | Q14: =Q15+Q18 -> 0 | R14: =S14+T14 -> 0 | S14: =S15+S18 -> 0 | T14: =T15+T18 -> 0 | V14: =IF((B14+C14+F14+L14+O14)<>0,"ok","-") -> -
A15: -គម្រោងវិនិយោគជាទុន | B15: =SUM(B16:B17) -> 0 | C15: =D15+E15 -> 0 | D15: =SUM(D16:D17) -> 0 | E15: =SUM(E16:E17) -> 0 | F15: =G15+H15 -> 0 | G15: =SUM(G16:G17) -> 0 | H15: =SUM(H16:H17) -> 0 | I15: =J15+K15 -> 0 | J15: =SUM(J16:J17) -> 0 | K15: =SUM(K16:K17) -> 0 | L15: =M15+N15 -> 0 | M15: =SUM(M16:M17) -> 0 | N15: =SUM(N16:N17) -> 0 | O15: =P15+Q15 -> 0 | P15: =SUM(P16:P17) -> 0 | Q15: =SUM(Q16:Q17) -> 0 | R15: =S15+T15 -> 0 | S15: =SUM(S16:S17) -> 0 | T15: =SUM(T16:T17) -> 0 | V15: =IF((B15+C15+F15+L15+O15)<>0,"ok","-") -> -
A16: ១.គម្រោង...... | C16: =D16+E16 -> 0 | F16: =G16+H16 -> 0 | I16: =J16+K16 -> 0 | L16: =M16+N16 -> 0 | O16: =P16+Q16 -> 0 | R16: =S16+T16 -> 0 | V16: =IF((B16+C16+F16+L16+O16)<>0,"ok","-") -> -
A17: ២.គម្រោង...... | C17: =D17+E17 -> 0 | F17: =G17+H17 -> 0 | I17: =J17+K17 -> 0 | L17: =M17+N17 -> 0 | O17: =P17+Q17 -> 0 | R17: =S17+T17 -> 0 | V17: =IF((B17+C17+F17+L17+O17)<>0,"ok","-") -> -
A18: -គម្រោងជំនួយបច្ចេកទេស | B18: =SUM(B19:B20) -> 0 | C18: =D18+E18 -> 0 | D18: =SUM(D19:D20) -> 0 | E18: =SUM(E19:E20) -> 0 | F18: =G18+H18 -> 0 | G18: =SUM(G19:G20) -> 0 | H18: =SUM(H19:H20) -> 0 | I18: =J18+K18 -> 0 | J18: =SUM(J19:J20) -> 0 | K18: =SUM(K19:K20) -> 0 | L18: =M18+N18 -> 0 | M18: =SUM(M19:M20) -> 0 | N18: =SUM(N19:N20) -> 0 | O18: =P18+Q18 -> 0 | P18: =SUM(P19:P20) -> 0 | Q18: =SUM(Q19:Q20) -> 0 | R18: =S18+T18 -> 0 | S18: =SUM(S19:S20) -> 0 | T18: =SUM(T19:T20) -> 0 | V18: =IF((B18+C18+F18+L18+O18)<>0,"ok","-") -> -
A19: ៣.គម្រោង...... | C19: =D19+E19 -> 0 | F19: =G19+H19 -> 0 | I19: =J19+K19 -> 0 | L19: =M19+N19 -> 0 | O19: =P19+Q19 -> 0 | R19: =S19+T19 -> 0 | V19: =IF((B19+C19+F19+L19+O19)<>0,"ok","-") -> -
A20: ៤.គម្រោង...... | C20: =D20+E20 -> 0 | F20: =G20+H20 -> 0 | I20: =J20+K20 -> 0 | L20: =M20+N20 -> 0 | O20: =P20+Q20 -> 0 | R20: =S20+T20 -> 0 | V20: =IF((B20+C20+F20+L20+O20)<>0,"ok","-") -> -
A21: II. សរុបគម្រោងស្នើសុំថ្មី (ដើម្បីអនុវត្ត ផ.យ.អ.ជ) | B21: =B22+B25 -> 0 | C21: =D21+E21 -> 0 | D21: =D22+D25 -> 0 | E21: =E22+E25 -> 0 | F21: =G21+H21 -> 0 | G21: =G22+G25 -> 0 | H21: =H22+H25 -> 0 | I21: =J21+K21 -> 0 | J21: =J22+J25 -> 0 | K21: =K22+K25 -> 0 | L21: =M21+N21 -> 0 | M21: =M22+M25 -> 0 | N21: =N22+N25 -> 0 | O21: =P21+Q21 -> 0 | P21: =P22+P25 -> 0 | Q21: =Q22+Q25 -> 0 | R21: =S21+T21 -> 0 | S21: =S22+S25 -> 0 | T21: =T22+T25 -> 0 | V21: =IF((B21+C21+F21+L21+O21)<>0,"ok","-") -> -
A22: -គម្រោងវិនិយោគជាទុន | B22: =SUM(B23:B24) -> 0 | C22: =D22+E22 -> 0 | D22: =SUM(D23:D24) -> 0 | E22: =SUM(E23:E24) -> 0 | F22: =G22+H22 -> 0 | G22: =SUM(G23:G24) -> 0 | H22: =SUM(H23:H24) -> 0 | I22: =J22+K22 -> 0 | J22: =SUM(J23:J24) -> 0 | K22: =SUM(K23:K24) -> 0 | L22: =M22+N22 -> 0 | M22: =SUM(M23:M24) -> 0 | N22: =SUM(N23:N24) -> 0 | O22: =P22+Q22 -> 0 | P22: =SUM(P23:P24) -> 0 | Q22: =SUM(Q23:Q24) -> 0 | R22: =S22+T22 -> 0 | S22: =SUM(S23:S24) -> 0 | T22: =SUM(T23:T24) -> 0 | V22: =IF((B22+C22+F22+L22+O22)<>0,"ok","-") -> -
A23: ១.គម្រោង...... | C23: =D23+E23 -> 0 | F23: =G23+H23 -> 0 | I23: =J23+K23 -> 0 | L23: =M23+N23 -> 0 | O23: =P23+Q23 -> 0 | R23: =S23+T23 -> 0 | V23: =IF((B23+C23+F23+L23+O23)<>0,"ok","-") -> -
A24: ២.គម្រោង...... | C24: =D24+E24 -> 0 | F24: =G24+H24 -> 0 | I24: =J24+K24 -> 0 | L24: =M24+N24 -> 0 | O24: =P24+Q24 -> 0 | R24: =S24+T24 -> 0 | V24: =IF((B24+C24+F24+L24+O24)<>0,"ok","-") -> -
A25: -គម្រោងជំនួយបច្ចេកទេស | B25: =SUM(B26:B27) -> 0 | C25: =D25+E25 -> 0 | D25: =SUM(D26:D27) -> 0 | E25: =SUM(E26:E27) -> 0 | F25: =G25+H25 -> 0 | G25: =SUM(G26:G27) -> 0 | H25: =SUM(H26:H27) -> 0 | I25: =J25+K25 -> 0 | J25: =SUM(J26:J27) -> 0 | K25: =SUM(K26:K27) -> 0 | L25: =M25+N25 -> 0 | M25: =SUM(M26:M27) -> 0 | N25: =SUM(N26:N27) -> 0 | O25: =P25+Q25 -> 0 | P25: =SUM(P26:P27) -> 0 | Q25: =SUM(Q26:Q27) -> 0 | R25: =S25+T25 -> 0 | S25: =SUM(S26:S27) -> 0 | T25: =SUM(T26:T27) -> 0 | V25: =IF((B25+C25+F25+L25+O25)<>0,"ok","-") -> -
A26: ៣.គម្រោង...... | C26: =D26+E26 -> 0 | F26: =G26+H26 -> 0 | I26: =J26+K26 -> 0 | L26: =M26+N26 -> 0 | O26: =P26+Q26 -> 0 | R26: =S26+T26 -> 0 | V26: =IF((B26+C26+F26+L26+O26)<>0,"ok","-") -> -
A27: ៤.គម្រោង...... | C27: =D27+E27 -> 0 | F27: =G27+H27 -> 0 | I27: =J27+K27 -> 0 | L27: =M27+N27 -> 0 | O27: =P27+Q27 -> 0 | R27: =S27+T27 -> 0 | V27: =IF((B27+C27+F27+L27+O27)<>0,"ok","-") -> -
A28: អនុកម្មវិធីទី១.២ (ឧត្តមក្រុមប្រឹក្សាសេដ្ឋកិច្ចជាតិ) | B28: =B29+B36 -> 0 | C28: =D28+E28 -> 0 | D28: =D29+D36 -> 0 | E28: =E29+E36 -> 0 | F28: =G28+H28 -> 0 | G28: =G29+G36 -> 0 | H28: =H29+H36 -> 0 | I28: =J28+K28 -> 0 | J28: =J29+J36 -> 0 | K28: =K29+K36 -> 0 | L28: =M28+N28 -> 0 | M28: =M29+M36 -> 0 | N28: =N29+N36 -> 0 | O28: =P28+Q28 -> 0 | P28: =P29+P36 -> 0 | Q28: =Q29+Q36 -> 0 | R28: =S28+T28 -> 0 | S28: =S29+S36 -> 0 | T28: =T29+T36 -> 0 | V28: =IF((B28+C28+F28+L28+O28)<>0,"ok","-") -> -
A29: I. សរុបគម្រោងកំពុងដំណើរការ | B29: =B30+B33 -> 0 | C29: =D29+E29 -> 0 | D29: =D30+D33 -> 0 | E29: =E30+E33 -> 0 | F29: =G29+H29 -> 0 | G29: =G30+G33 -> 0 | H29: =H30+H33 -> 0 | I29: =J29+K29 -> 0 | J29: =J30+J33 -> 0 | K29: =K30+K33 -> 0 | L29: =M29+N29 -> 0 | M29: =M30+M33 -> 0 | N29: =N30+N33 -> 0 | O29: =P29+Q29 -> 0 | P29: =P30+P33 -> 0 | Q29: =Q30+Q33 -> 0 | R29: =S29+T29 -> 0 | S29: =S30+S33 -> 0 | T29: =T30+T33 -> 0 | V29: =IF((B29+C29+F29+L29+O29)<>0,"ok","-") -> -
A30: -គម្រោងវិនិយោគជាទុន | B30: =SUM(B31:B32) -> 0 | C30: =D30+E30 -> 0 | D30: =SUM(D31:D32) -> 0 | E30: =SUM(E31:E32) -> 0 | F30: =G30+H30 -> 0 | G30: =SUM(G31:G32) -> 0 | H30: =SUM(H31:H32) -> 0 | I30: =J30+K30 -> 0 | J30: =SUM(J31:J32) -> 0 | K30: =SUM(K31:K32) -> 0 | L30: =M30+N30 -> 0 | M30: =SUM(M31:M32) -> 0 | N30: =SUM(N31:N32) -> 0 | O30: =P30+Q30 -> 0 | P30: =SUM(P31:P32) -> 0 | Q30: =SUM(Q31:Q32) -> 0 | R30: =S30+T30 -> 0 | S30: =SUM(S31:S32) -> 0 | T30: =SUM(T31:T32) -> 0 | V30: =IF((B30+C30+F30+L30+O30)<>0,"ok","-") -> -
A31: ១.គម្រោង...... | C31: =D31+E31 -> 0 | F31: =G31+H31 -> 0 | I31: =J31+K31 -> 0 | L31: =M31+N31 -> 0 | O31: =P31+Q31 -> 0 | R31: =S31+T31 -> 0 | V31: =IF((B31+C31+F31+L31+O31)<>0,"ok","-") -> -
A32: ២.គម្រោង...... | C32: =D32+E32 -> 0 | F32: =G32+H32 -> 0 | I32: =J32+K32 -> 0 | L32: =M32+N32 -> 0 | O32: =P32+Q32 -> 0 | R32: =S32+T32 -> 0 | V32: =IF((B32+C32+F32+L32+O32)<>0,"ok","-") -> -
A33: -គម្រោងជំនួយបច្ចេកទេស | B33: =SUM(B34:B35) -> 0 | C33: =D33+E33 -> 0 | D33: =SUM(D34:D35) -> 0 | E33: =SUM(E34:E35) -> 0 | F33: =G33+H33 -> 0 | G33: =SUM(G34:G35) -> 0 | H33: =SUM(H34:H35) -> 0 | I33: =J33+K33 -> 0 | J33: =SUM(J34:J35) -> 0 | K33: =SUM(K34:K35) -> 0 | L33: =M33+N33 -> 0 | M33: =SUM(M34:M35) -> 0 | N33: =SUM(N34:N35) -> 0 | O33: =P33+Q33 -> 0 | P33: =SUM(P34:P35) -> 0 | Q33: =SUM(Q34:Q35) -> 0 | R33: =S33+T33 -> 0 | S33: =SUM(S34:S35) -> 0 | T33: =SUM(T34:T35) -> 0 | V33: =IF((B33+C33+F33+L33+O33)<>0,"ok","-") -> -
A34: ៣.គម្រោង...... | C34: =D34+E34 -> 0 | F34: =G34+H34 -> 0 | I34: =J34+K34 -> 0 | L34: =M34+N34 -> 0 | O34: =P34+Q34 -> 0 | R34: =S34+T34 -> 0 | V34: =IF((B34+C34+F34+L34+O34)<>0,"ok","-") -> -
A35: ៤.គម្រោង...... | C35: =D35+E35 -> 0 | F35: =G35+H35 -> 0 | I35: =J35+K35 -> 0 | L35: =M35+N35 -> 0 | O35: =P35+Q35 -> 0 | R35: =S35+T35 -> 0 | V35: =IF((B35+C35+F35+L35+O35)<>0,"ok","-") -> -
A36: II. សរុបគម្រោងស្នើសុំថ្មី (ដើម្បីអនុវត្ត ផ.យ.អ.ជ) | B36: =B37+B40 -> 0 | C36: =D36+E36 -> 0 | D36: =D37+D40 -> 0 | E36: =E37+E40 -> 0 | F36: =G36+H36 -> 0 | G36: =G37+G40 -> 0 | H36: =H37+H40 -> 0 | I36: =J36+K36 -> 0 | J36: =J37+J40 -> 0 | K36: =K37+K40 -> 0 | L36: =M36+N36 -> 0 | M36: =M37+M40 -> 0 | N36: =N37+N40 -> 0 | O36: =P36+Q36 -> 0 | P36: =P37+P40 -> 0 | Q36: =Q37+Q40 -> 0 | R36: =S36+T36 -> 0 | S36: =S37+S40 -> 0 | T36: =T37+T40 -> 0 | V36: =IF((B36+C36+F36+L36+O36)<>0,"ok","-") -> -
A37: -គម្រោងវិនិយោគជាទុន | B37: =SUM(B38:B39) -> 0 | C37: =D37+E37 -> 0 | D37: =SUM(D38:D39) -> 0 | E37: =SUM(E38:E39) -> 0 | F37: =G37+H37 -> 0 | G37: =SUM(G38:G39) -> 0 | H37: =SUM(H38:H39) -> 0 | I37: =J37+K37 -> 0 | J37: =SUM(J38:J39) -> 0 | K37: =SUM(K38:K39) -> 0 | L37: =M37+N37 -> 0 | M37: =SUM(M38:M39) -> 0 | N37: =SUM(N38:N39) -> 0 | O37: =P37+Q37 -> 0 | P37: =SUM(P38:P39) -> 0 | Q37: =SUM(Q38:Q39) -> 0 | R37: =S37+T37 -> 0 | S37: =SUM(S38:S39) -> 0 | T37: =SUM(T38:T39) -> 0 | V37: =IF((B37+C37+F37+L37+O37)<>0,"ok","-") -> -
A38: ១.គម្រោង...... | C38: =D38+E38 -> 0 | F38: =G38+H38 -> 0 | I38: =J38+K38 -> 0 | L38: =M38+N38 -> 0 | O38: =P38+Q38 -> 0 | R38: =S38+T38 -> 0 | V38: =IF((B38+C38+F38+L38+O38)<>0,"ok","-") -> -
A39: ២.គម្រោង...... | C39: =D39+E39 -> 0 | F39: =G39+H39 -> 0 | I39: =J39+K39 -> 0 | L39: =M39+N39 -> 0 | O39: =P39+Q39 -> 0 | R39: =S39+T39 -> 0 | V39: =IF((B39+C39+F39+L39+O39)<>0,"ok","-") -> -
A40: -គម្រោងជំនួយបច្ចេកទេស | B40: =SUM(B41:B42) -> 0 | C40: =D40+E40 -> 0 | D40: =SUM(D41:D42) -> 0 | E40: =SUM(E41:E42) -> 0 | F40: =G40+H40 -> 0 | G40: =SUM(G41:G42) -> 0 | H40: =SUM(H41:H42) -> 0 | I40: =J40+K40 -> 0 | J40: =SUM(J41:J42) -> 0 | K40: =SUM(K41:K42) -> 0 | L40: =M40+N40 -> 0 | M40: =SUM(M41:M42) -> 0 | N40: =SUM(N41:N42) -> 0 | O40: =P40+Q40 -> 0 | P40: =SUM(P41:P42) -> 0 | Q40: =SUM(Q41:Q42) -> 0 | R40: =S40+T40 -> 0 | S40: =SUM(S41:S42) -> 0 | T40: =SUM(T41:T42) -> 0 | V40: =IF((B40+C40+F40+L40+O40)<>0,"ok","-") -> -
A41: ៣.គម្រោង...... | C41: =D41+E41 -> 0 | F41: =G41+H41 -> 0 | I41: =J41+K41 -> 0 | L41: =M41+N41 -> 0 | O41: =P41+Q41 -> 0 | R41: =S41+T41 -> 0 | V41: =IF((B41+C41+F41+L41+O41)<>0,"ok","-") -> -
A42: ៤.គម្រោង...... | C42: =D42+E42 -> 0 | F42: =G42+H42 -> 0 | I42: =J42+K42 -> 0 | L42: =M42+N42 -> 0 | O42: =P42+Q42 -> 0 | R42: =S42+T42 -> 0 | V42: =IF((B42+C42+F42+L42+O42)<>0,"ok","-") -> -
A43: អនុកម្មវិធីទី១.៣ (លេខាធិការដ្ឋាន គ.ផ.ក) | B43: =B44+B51 -> 0 | C43: =D43+E43 -> 0 | D43: =D44+D51 -> 0 | E43: =E44+E51 -> 0 | F43: =G43+H43 -> 0 | G43: =G44+G51 -> 0 | H43: =H44+H51 -> 0 | I43: =J43+K43 -> 0 | J43: =J44+J51 -> 0 | K43: =K44+K51 -> 0 | L43: =M43+N43 -> 0 | M43: =M44+M51 -> 0 | N43: =N44+N51 -> 0 | O43: =P43+Q43 -> 0 | P43: =P44+P51 -> 0 | Q43: =Q44+Q51 -> 0 | R43: =S43+T43 -> 0 | S43: =S44+S51 -> 0 | T43: =T44+T51 -> 0 | V43: =IF((B43+C43+F43+L43+O43)<>0,"ok","-") -> -
A44: I. សរុបគម្រោងកំពុងដំណើរការ | B44: =B45+B48 -> 0 | C44: =D44+E44 -> 0 | D44: =D45+D48 -> 0 | E44: =E45+E48 -> 0 | F44: =G44+H44 -> 0 | G44: =G45+G48 -> 0 | H44: =H45+H48 -> 0 | I44: =J44+K44 -> 0 | J44: =J45+J48 -> 0 | K44: =K45+K48 -> 0 | L44: =M44+N44 -> 0 | M44: =M45+M48 -> 0 | N44: =N45+N48 -> 0 | O44: =P44+Q44 -> 0 | P44: =P45+P48 -> 0 | Q44: =Q45+Q48 -> 0 | R44: =S44+T44 -> 0 | S44: =S45+S48 -> 0 | T44: =T45+T48 -> 0 | V44: =IF((B44+C44+F44+L44+O44)<>0,"ok","-") -> -
...

Sheet PIP 2019 by Fund-status
B5: ឧបសម្ព័ន្ធទី១៖ តារាងសរុបគម្រោងវិនិយោគរបស់ក្រសួងសេដ្ឋកិច្ចនិងហិរញ្ញវត្ថុ សម្រាប់ដាក់បញ្ជូលក្នុង ក.វ.ស ៣ឆ្នាំរកិល ២០១៩-២០២១ (តាមប្រភេទគម្រោង/ប្រភពហិរញ្ញប្បទាន)
R6: ឯកតា៖ពាន់ដុល្លារអាមេរិក
B7: ឈ្មោះគម្រោង | C7: លេខ PIP | D7: តម្លៃ គម្រោង ស្នើសុំថ្មី | E7: តម្លៃគម្រោង​កំពុងដំណើរការ​ | F7: ចំណាយប៉ាន់ស្មានសរុប | J7: ហិរញ្ញប្បទានបានសន្យាផ្ដល់ | O7: តម្រូវការហិរញ្ញប្បទានបំពេញបន្ថែម
F8: 2019 | G8: 2020 | H8: 2021 | I8: សរុប​ ២០១៩-២០២១ | J8: ប្រភព ហិរញ្ញប្បទាន | K8: 2019 | L8: 2020 | M8: 2021 | N8: សរុប​ ២០១៩-២០២១ | O8: 2019 | P8: 2020 | Q8: 2021 | R8: សរុប​ ២០១៩-២០២១
B9: 1 | C9: 2 | D9: 3 | E9: 4 | F9: 5 | G9: 6 | H9: 7 | I9: 8=5+6+7 | J9: 9 | K9: 10 | L9: 11 | M9: 12 | N9: 13=10+11+12 | O9: 14=5-10 | P9: 15=6-11 | Q9: 16=7-12 | R9: 17=14+15+16
B10: សរុបរួមក្រសួងសេដ្ឋកិច្ចនិងហិរញ្ញវត្ថុ | D10: =D46 -> 29117 | E10: =E13 -> 17487.8 | F10: =F11+F12 -> 31758.3 | G10: =G11+G12 -> 9924.5 | H10: =H11+H12 -> 4922 | I10: =SUM(F10:H10) -> 46604.8 | J10: សរុប | K10: =K11+K12 -> 3050 | L10: =L11+L12 -> 3050 | M10: =M11+M12 -> 0 | N10: =SUM(K10:M10) -> 6100 | O10: =O11+O12 -> 28708.3 | P10: =P11+P12 -> 6874.5 | Q10: =Q11+Q12 -> 4922 | R10: =SUM(O10:Q10) -> 40504.8 | S10: =IF(SUM(F10:I10,K10:R10)<>0, "OK", "-") -> OK
F11: =F14+F47 -> 30258.3 | G11: =G14+G47 -> 8424.5 | H11: =H14+H47 -> 3922 | I11: =SUM(F11:H11) -> 42604.8 | J11: រាជរដ្ឋាភិបាល | K11: =K14+K47 -> 3050 | L11: =L14+L47 -> 3050 | M11: =M14+M47 -> 0 | N11: =SUM(K11:M11) -> 6100 | O11: =O14+O47 -> 27208.3 | P11: =P14+P47 -> 5374.5 | Q11: =Q14+Q47 -> 3922 | R11: =SUM(O11:Q11) -> 36504.8 | S11: =IF(SUM(F11:I11,K11:R11)<>0, "OK", "-") -> OK
F12: =F15+F48 -> 1500 | G12: =G15+G48 -> 1500 | H12: =H15+H48 -> 1000 | I12: =SUM(F12:H12) -> 4000 | J12: ដៃគូអភិវឌ្ឍន៍ | K12: =K15+K48 -> 0 | L12: =L15+L48 -> 0 | M12: =M15+M48 -> 0 | N12: =SUM(K12:M12) -> 0 | O12: =O15+O48 -> 1500 | P12: =P15+P48 -> 1500 | Q12: =Q15+Q48 -> 1000 | R12: =SUM(O12:Q12) -> 4000 | S12: =IF(SUM(F12:I12,K12:R12)<>0, "OK", "-") -> OK
B13: ​I.សរុបគម្រោងកំពុងដំណើរការ | D13: =SUM(D16+D37) -> 0 | E13: =SUM(E16+E37) -> 17487.8 | F13: =F14+F15 -> 11237.8 | G13: =G14+G15 -> 4900 | H13: =H14+H15 -> 1350 | I13: =SUM(F13:H13) -> 17487.8 | J13: សរុប | K13: =K14+K15 -> 3050 | L13: =L14+L15 -> 3050 | M13: =M14+M15 -> 0 | N13: =SUM(K13:M13) -> 6100 | O13: =O14+O15 -> 8187.8 | P13: =P14+P15 -> 1850 | Q13: =Q14+Q15 -> 1350 | R13: =SUM(O13:Q13) -> 11387.8 | S13: =IF(SUM(F13:I13,K13:R13)<>0, "OK", "-") -> OK
F14: =F17+F38 -> 9737.8 | G14: =G17+G38 -> 3400 | H14: =H17+H38 -> 350 | I14: =SUM(F14:H14) -> 13487.8 | J14: រាជរដ្ឋាភិបាល | K14: =K17+K38 -> 3050 | L14: =L17+L38 -> 3050 | M14: =M17+M38 -> 0 | N14: =SUM(K14:M14) -> 6100 | O14: =F14-K14 -> 6687.8 | P14: =G14-L14 -> 350 | Q14: =H14-M14 -> 350 | R14: =SUM(O14:Q14) -> 7387.8 | S14: =IF(SUM(F14:I14,K14:R14)<>0, "OK", "-") -> OK
F15: =F18+F39 -> 1500 | G15: =G18+G39 -> 1500 | H15: =H18+H39 -> 1000 | I15: =SUM(F15:H15) -> 4000 | J15: ដៃគូអភិវឌ្ឍន៍ | K15: =K18+K39 -> 0 | L15: =L18+L39 -> 0 | M15: =M18+M39 -> 0 | N15: =SUM(K15:M15) -> 0 | O15: =F15-K15 -> 1500 | P15: =G15-L15 -> 1500 | Q15: =H15-M15 -> 1000 | R15: =SUM(O15:Q15) -> 4000 | S15: =IF(SUM(F15:I15,K15:R15)<>0, "OK", "-") -> OK
B16: ​-សរុបគម្រោងវិនិយោគទុន | D16: =SUM(D19:D36) -> 0 | E16: =SUM(E19:E36) -> 17487.8 | F16: =F17+F18 -> 11237.8 | G16: =G17+G18 -> 4900 | H16: =H17+H18 -> 1350 | I16: =SUM(F16:H16) -> 17487.8 | J16: សរុប | K16: =K17+K18 -> 3050 | L16: =L17+L18 -> 3050 | M16: =M17+M18 -> 0 | N16: =SUM(K16:M16) -> 6100 | O16: =O17+O18 -> 8187.8 | P16: =P17+P18 -> 1850 | Q16: =Q17+Q18 -> 1350 | R16: =SUM(O16:Q16) -> 11387.8 | S16: =IF(SUM(F16:I16,K16:R16)<>0, "OK", "-") -> OK
F17: =F20+F23+F26+F29+F32+F35 -> 9737.8 | G17: =G20+G23+G26+G29+G32+G35 -> 3400 | H17: =H20+H23+H26+H29+H32+H35 -> 350 | I17: =SUM(F17:H17) -> 13487.8 | J17: រាជរដ្ឋាភិបាល | K17: =K20+K23+K26+K29+K32+K35 -> 3050 | L17: =L20+L23+L26+L29+L32+L35 -> 3050 | M17: =M20+M23+M26+M29+M32+M35 -> 0 | N17: =SUM(K17:M17) -> 6100 | O17: =O20+O23+O26+O29+O32+O35 -> 6687.8 | P17: =P20+P23+P26+P29+P32+P35 -> 350 | Q17: =Q20+Q23+Q26+Q29+Q32+Q35 -> 350 | R17: =SUM(O17:Q17) -> 7387.8 | S17: =IF(SUM(F17:I17,K17:R17)<>0, "OK", "-") -> OK
F18: =F21+F24+F27+F30+F33+F36 -> 1500 | G18: =G21+G24+G27+G30+G33+G36 -> 1500 | H18: =H21+H24+H27+H30+H33+H36 -> 1000 | I18: =SUM(F18:H18) -> 4000 | J18: ដៃគូអភិវឌ្ឍន៍ | K18: =K21+K24+K27+K30+K33+K36 -> 0 | L18: =L21+L24+L27+L30+L33+L36 -> 0 | M18: =M21+M24+M27+M30+M33+M36 -> 0 | N18: =SUM(K18:M18) -> 0 | O18: =O21+O24+O27+O30+O33+O36 -> 1500 | P18: =P21+P24+P27+P30+P33+P36 -> 1500 | Q18: =Q21+Q24+Q27+Q30+Q33+Q36 -> 1000 | R18: =SUM(O18:Q18) -> 4000 | S18: =IF(SUM(F18:I18,K18:R18)<>0, "OK", "-") -> OK
B19: ១.គម្រោងលើកកម្ពស់ហេដ្ឋារចនាសម្ព័ន្ធ សាធារណៈរបស់អគ្គនាយកដ្ឋានគយ និងរដ្ឋាករកម្ពុជា | C19: 509 | E19: =I19 -> 6100 | F19: =F20+F21 -> 3050 | G19: =G20+G21 -> 3050 | H19: =H20+H21 -> 0 | I19: =SUM(F19:H19) -> 6100 | J19: សរុប | K19: =K20+K21 -> 3050 | L19: =L20+L21 -> 3050 | M19: =M20+M21 -> 0 | N19: =SUM(K19:M19) -> 6100 | O19: =O20+O21 -> 0 | P19: =P20+P21 -> 0 | Q19: =Q20+Q21 -> 0 | R19: =SUM(O19:Q19) -> 0 | S19: =IF(SUM(F19:I19,K19:R19)<>0, "OK", "-") -> OK
F20: 3050 | G20: 3050 | I20: =SUM(F20:H20) -> 6100 | J20: រាជរដ្ឋាភិបាល | K20: 3050 | L20: 3050 | N20: =SUM(K20:M20) -> 6100 | O20: =F20-K20 -> 0 | P20: =G20-L20 -> 0 | Q20: =H20-M20 -> 0 | R20: =SUM(O20:Q20) -> 0 | S20: =IF(SUM(F20:I20,K20:R20)<>0, "OK", "-") -> OK
I21: =SUM(F21:H21) -> 0 | J21: ដៃគូអភិវឌ្ឍន៍ | N21: =SUM(K21:M21) -> 0 | O21: =F21-K21 -> 0 | P21: =G21-L21 -> 0 | Q21: =H21-M21 -> 0 | R21: =SUM(O21:Q21) -> 0
B22: ២. គម្រោងប្រព័ន្ធបញ្ជរតែមួយជាតិ | C22: 659 | E22: =I22 -> 2250 | F22: =F23+F24 -> 1550 | G22: =G23+G24 -> 350 | H22: =H23+H24 -> 350 | I22: =SUM(F22:H22) -> 2250 | J22: សរុប | K22: =K23+K24 -> 0 | L22: =L23+L24 -> 0 | M22: =M23+M24 -> 0 | N22: =SUM(K22:M22) -> 0 | O22: =O23+O24 -> 1550 | P22: =P23+P24 -> 350 | Q22: =Q23+Q24 -> 350 | R22: =SUM(O22:Q22) -> 2250 | S22: =IF(SUM(F22:I22,K22:R22)<>0, "OK", "-") -> OK
F23: 1550 | G23: 350 | H23: 350 | I23: =SUM(F23:H23) -> 2250 | J23: រាជរដ្ឋាភិបាល | N23: =SUM(K23:M23) -> 0 | O23: =F23-K23 -> 1550 | P23: =G23-L23 -> 350 | Q23: =H23-M23 -> 350 | R23: =SUM(O23:Q23) -> 2250 | S23: =IF(SUM(F23:I23,K23:R23)<>0, "OK", "-") -> OK
I24: =SUM(F24:H24) -> 0 | J24: ដៃគូអភិវឌ្ឍន៍ | N24: =SUM(K24:M24) -> 0 | O24: =F24-K24 -> 0 | P24: =G24-L24 -> 0 | Q24: =H24-M24 -> 0 | R24: =SUM(O24:Q24) -> 0
B25: ៣.គម្រោងសាងសង់អគារចំណតរថយន្តក្រោមដី Implemented by GDICDM | C25: 655 | E25: =I25 -> 3200 | F25: =F26+F27 -> 3200 | G25: =G26+G27 -> 0 | H25: =H26+H27 -> 0 | I25: =SUM(F25:H25) -> 3200 | J25: សរុប | K25: =K26+K27 -> 0 | L25: =L26+L27 -> 0 | M25: =M26+M27 -> 0 | N25: =SUM(K25:M25) -> 0 | O25: =O26+O27 -> 3200 | P25: =P26+P27 -> 0 | Q25: =Q26+Q27 -> 0 | R25: =SUM(O25:Q25) -> 3200 | S25: =IF(SUM(F25:I25,K25:R25)<>0, "OK", "-") -> OK
F26: 3200 | G26: 0 | H26: 0 | I26: =SUM(F26:H26) -> 3200 | J26: រាជរដ្ឋាភិបាល | N26: =SUM(K26:M26) -> 0 | O26: =F26-K26 -> 3200 | P26: =G26-L26 -> 0 | Q26: =H26-M26 -> 0 | R26: =SUM(O26:Q26) -> 3200 | S26: =IF(SUM(F26:I26,K26:R26)<>0, "OK", "-") -> OK
I27: =SUM(F27:H27) -> 0 | J27: ដៃគូអភិវឌ្ឍន៍ | N27: =SUM(K27:M27) -> 0 | O27: =F27-K27 -> 0 | P27: =G27-L27 -> 0 | Q27: =H27-M27 -> 0 | R27: =SUM(O27:Q27) -> 0
B28: ៤. គម្រោងជួសជុលនិងកែលម្អអគារធំ | C28: 793 | E28: =I28 -> 1937.8 | F28: =F29+F30 -> 1937.8 | G28: =G29+G30 -> 0 | H28: =H29+H30 -> 0 | I28: =SUM(F28:H28) -> 1937.8 | J28: សរុប | K28: =K29+K30 -> 0 | L28: =L29+L30 -> 0 | M28: =M29+M30 -> 0 | N28: =SUM(K28:M28) -> 0 | O28: =O29+O30 -> 1937.8 | P28: =P29+P30 -> 0 | Q28: =Q29+Q30 -> 0 | R28: =SUM(O28:Q28) -> 1937.8 | S28: =IF(SUM(F28:I28,K28:R28)<>0, "OK", "-") -> OK
F29: 1937.8 | G29: 0 | H29: 0 | I29: =SUM(F29:H29) -> 1937.8 | J29: រាជរដ្ឋាភិបាល | N29: =SUM(K29:M29) -> 0 | O29: =F29-K29 -> 1937.8 | P29: =G29-L29 -> 0 | Q29: =H29-M29 -> 0 | R29: =SUM(O29:Q29) -> 1937.8 | S29: =IF(SUM(F29:I29,K29:R29)<>0, "OK", "-") -> OK
I30: =SUM(F30:H30) -> 0 | J30: ដៃគូអភិវឌ្ឍន៍ | N30: =SUM(K30:M30) -> 0 | O30: =F30-K30 -> 0 | P30: =G30-L30 -> 0 | Q30: =H30-M30 -> 0 | R30: =SUM(O30:Q30) -> 0
B31: ៥. គម្រោងសាងសង់អគារមូលបត្រកម្ពុជា | C31: 491 | E31: =I31 -> 4000 | F31: =F32+F33 -> 1500 | G31: =G32+G33 -> 1500 | H31: =H32+H33 -> 1000 | I31: =SUM(F31:H31) -> 4000 | J31: សរុប | K31: =K32+K33 -> 0 | L31: =L32+L33 -> 0 | M31: =M32+M33 -> 0 | N31: =SUM(K31:M31) -> 0 | O31: =O32+O33 -> 1500 | P31: =P32+P33 -> 1500 | Q31: =Q32+Q33 -> 1000 | R31: =SUM(O31:Q31) -> 4000 | S31: =IF(SUM(F31:I31,K31:R31)<>0, "OK", "-") -> OK
I32: =SUM(F32:H32) -> 0 | J32: រាជរដ្ឋាភិបាល | N32: =SUM(K32:M32) -> 0 | O32: =F32-K32 -> 0 | P32: =G32-L32 -> 0 | Q32: =H32-M32 -> 0 | R32: =SUM(O32:Q32) -> 0
F33: 1500 | G33: 1500 | H33: 1000 | I33: =SUM(F33:H33) -> 4000 | J33: ដៃគូអភិវឌ្ឍន៍ | N33: =SUM(K33:M33) -> 0 | O33: =F33-K33 -> 1500 | P33: =G33-L33 -> 1500 | Q33: =H33-M33 -> 1000 | R33: =SUM(O33:Q33) -> 4000 | S33: =IF(SUM(F33:I33,K33:R33)<>0, "OK", "-") -> OK
E34: =I34 -> 0 | F34: =F35+F36 -> 0 | G34: =G35+G36 -> 0 | H34: =H35+H36 -> 0 | I34: =SUM(F34:H34) -> 0 | J34: សរុប | K34: =K35+K36 -> 0 | L34: =L35+L36 -> 0 | M34: =M35+M36 -> 0 | N34: =SUM(K34:M34) -> 0 | O34: =O35+O36 -> 0 | P34: =P35+P36 -> 0 | Q34: =Q35+Q36 -> 0 | R34: =SUM(O34:Q34) -> 0 | S34: =IF(SUM(F34:I34,K34:R34)<>0, "OK", "-") -> -
I35: =SUM(F35:H35) -> 0 | J35: រាជរដ្ឋាភិបាល | N35: =SUM(K35:M35) -> 0 | O35: =F35-K35 -> 0 | P35: =G35-L35 -> 0 | Q35: =H35-M35 -> 0 | R35: =SUM(O35:Q35) -> 0 | S35: =IF(SUM(F35:I35,K35:R35)<>0, "OK", "-") -> -
I36: =SUM(F36:H36) -> 0 | J36: ដៃគូអភិវឌ្ឍន៍ | N36: =SUM(K36:M36) -> 0 | O36: =F36-K36 -> 0 | P36: =G36-L36 -> 0 | Q36: =H36-M36 -> 0 | R36: =SUM(O36:Q36) -> 0 | S36: =IF(SUM(F36:I36,K36:R36)<>0, "OK", "-") -> -
B37: ​-សរុបគម្រោងជំនួយបច្ចេកទេស | D37: =D40+D43 -> 0 | E37: =E40 -> 0 | F37: =F38+F39 -> 0 | G37: =G38+G39 -> 0 | H37: =H38+H39 -> 0 | I37: =SUM(F37:H37) -> 0 | J37: សរុប | K37: =K38+K39 -> 0 | L37: =L38+L39 -> 0 | M37: =M38+M39 -> 0 | N37: =SUM(K37:M37) -> 0 | O37: =O38+O39 -> 0 | P37: =P38+P39 -> 0 | Q37: =Q38+Q39 -> 0 | R37: =SUM(O37:Q37) -> 0 | S37: =IF(SUM(F37:I37,K37:R37)<>0, "OK", "-") -> -
F38: =F41+F44 -> 0 | G38: =G41+G44 -> 0 | H38: =H41+H44 -> 0 | I38: =SUM(F38:H38) -> 0 | J38: រាជរដ្ឋាភិបាល | K38: =K41+K44 -> 0 | L38: =L41+L44 -> 0 | M38: =M41+M44 -> 0 | N38: =SUM(K38:M38) -> 0 | O38: =O41+O44 -> 0 | P38: =P41+P44 -> 0 | Q38: =Q41+Q44 -> 0 | R38: =SUM(O38:Q38) -> 0 | S38: =IF(SUM(F38:I38,K38:R38)<>0, "OK", "-") -> -
F39: =F42+F45 -> 0 | G39: =G42+G45 -> 0 | H39: =H42+H45 -> 0 | I39: =SUM(F39:H39) -> 0 | J39: ដៃគូអភិវឌ្ឍន៍ | K39: =K42+K45 -> 0 | L39: =L42+L45 -> 0 | M39: =M42+M45 -> 0 | N39: =SUM(K39:M39) -> 0 | O39: =O42+O45 -> 0 | P39: =P42+P45 -> 0 | Q39: =Q42+Q45 -> 0 | R39: =SUM(O39:Q39) -> 0 | S39: =IF(SUM(F39:I39,K39:R39)<>0, "OK", "-") -> -
S40: =IF(SUM(F40:I40,K40:R40)<>0, "OK", "-") -> -
S41: =IF(SUM(F41:I41,K41:R41)<>0, "OK", "-") -> -
S42: =IF(SUM(F42:I42,K42:R42)<>0, "OK", "-") -> -
B43: ២. គម្រោង................ | F43: =F44+F45 -> 0 | G43: =G44+G45 -> 0 | H43: =H44+H45 -> 0 | I43: =SUM(F43:H43) -> 0 | J43: សរុប | K43: =K44+K45 -> 0 | L43: =L44+L45 -> 0 | M43: =M44+M45 -> 0 | N43: =SUM(K43:M43) -> 0 | O43: =O44+O45 -> 0 | P43: =P44+P45 -> 0 | Q43: =Q44+Q45 -> 0 | R43: =SUM(O43:Q43) -> 0 | S43: =IF(SUM(F43:I43,K43:R43)<>0, "OK", "-") -> -
I44: =SUM(F44:H44) -> 0 | J44: រាជរដ្ឋាភិបាល | N44: =SUM(K44:M44) -> 0 | O44: =F44-K44 -> 0 | P44: =G44-L44 -> 0 | Q44: =H44-M44 -> 0 | R44: =SUM(O44:Q44) -> 0 | S44: =IF(SUM(F44:I44,K44:R44)<>0, "OK", "-") -> -
...

Sheet PIP 2019-2021 by BEs
A4: ឧបសម្ព័ន្ធទី២៖ តារាងសរុបគម្រោងវិនិយោគរបស់ក្រសួងសេដ្ឋកិច្ចនិងហិរញ្ញវត្ថុ សម្រាប់ដាក់បញ្ជូលក្នុង ក.វ.ស ៣ឆ្នាំរកិល ២០១៩-២០២១ (តាមអង្គភាពថវិកា)
R5: ឯកតា៖ពាន់ដុល្លារអាមេរិក
B6: ឈ្មោះកម្មវិធី/ ឈ្មោះអនុកម្មវិធី /ឈ្មោះគម្រោង | C6: លេខ PIP | D6: ស្ថានភាពគម្រោង | E6: ប្រភេទគម្រោង | F6: ចំណាយប៉ាន់ស្មានសរុប | J6: ហិរញ្ញប្បទានសន្យាផ្តល់ | N6: តម្រូវការហិរញ្ញប្បទានបំពេញបន្ថែម | R6: ប្រភព ហិរញ្ញប្បទាន
F7: 2019 | G7: 2020 | H7: 2021 | I7: សរុប​៣ឆ្នាំ | J7: 2019 | K7: 2020 | L7: 2021 | M7: សរុប​៣ឆ្នាំ | N7: 2019 | O7: 2020 | P7: 2021 | Q7: សរុប​៣ឆ្នាំ
B9: សរុបរួម ក្រសួង​សេដ្ឋ​កិច្ច​និង​ហិរញ្ញវត្ថុ | F9: =F10+F17+F24+F36+F48 -> 31758.3 | G9: =G10+G17+G24+G36+G48 -> 9924.5 | H9: =H10+H17+H24+H36+H48 -> 4922 | I9: =SUM(F9:H9) -> 46604.8 | J9: =J10+J17+J24+J36+J48 -> 3050 | K9: =K10+K17+K24+K36+K48 -> 3050 | L9: =L10+L17+L24+L36+L48 -> 0 | M9: =SUM(J9:L9) -> 6100 | N9: =N10+N17+N24+N36+N48 -> 28708.3 | O9: =O10+O17+O24+O36+O48 -> 6874.5 | P9: =P10+P17+P24+P36+P48 -> 4922 | Q9: =SUM(N9:P9) -> 40504.8
B10: កម្មវិធីទី១៖ ពង្រឹងនិងបង្កើនប្រសិទ្ធភាពនៃការគ្រប់គ្រងសេដ្ឋកិច្ច | F10: =F11+F13+F15 -> 0 | G10: =G11+G13+G15 -> 0 | H10: =H11+H13+H15 -> 0 | I10: =I11+I13+I15 -> 0 | J10: =J11+J13+J15 -> 0 | K10: =K11+K13+K15 -> 0 | L10: =L11+L13+L15 -> 0 | M10: =M11+M13+M15 -> 0 | ... Q10: =Q11+Q13+Q15 -> 0 | S10: =IF(SUM(I10,Q10), "OK ", "-") -> -
B11: អនុកម្មវិធី ១.១ ៖ អគ្គនាយកដ្ឋានគោលនយោបាយសេដ្ឋកិច្ច និងហិរញ្ញវត្ថុសាធារណៈ | S11: =IF(SUM(I11,Q11), "OK ", "-") -> -
B12: ១. គម្រោង................ | S12: =IF(SUM(I12,Q12), "OK ", "-") -> -
B13: អនុកម្មវិធី ១.២ ៖ គណៈកម្មាធិការផលិតភាពកម្ពុជា | S13: =IF(SUM(I13,Q13), "OK ", "-") -> -
B14: ១. គម្រោង................ | S14: =IF(SUM(I14,Q14), "OK ", "-") -> -
B15: អនុកម្មវិធី ១.៣ ៖ ឧត្តមក្រុមប្រឹក្សាសេដ្ឋកិច្ចកម្ពុជា | S15: =IF(SUM(I15,Q15), "OK ", "-") -> -
B16: ១. គម្រោង................ | S16: =IF(SUM(I16,Q16), "OK ", "-") -> -
B17: កម្មវិធីទី២៖ ពង្រឹងនិងបង្កើនប្រសិទ្ធភាពនៃការគ្រប់គ្រងការត្រួតពិនិត្យ និងការអភិវឌ្ឍន៍វិស័យហិរញ្ញវត្ថុ | F17: =F18+F20+F22 -> 1500 | G17: =G18+G20+G22 -> 1500 | H17: =H18+H20+H22 -> 1000 | I17: =I18+I20+I22 -> 4000 | J17: =J18+J20+J22 -> 0 | K17: =K18+K20+K22 -> 0 | L17: =L18+L20+L22 -> 0 | M17: =M18+M20+M22 -> 0 | ... Q17: =Q18+Q20+Q22 -> 4000 | S17: =IF(SUM(I17,Q17), "OK ", "-") -> OK
B18: អនុកម្មវិធី ២.១ ៖ អគ្គនាយកដ្ឋានឧស្សាហកម្មហិរញ្ញវត្ថុ | S18: =IF(SUM(I18,Q18), "OK ", "-") -> -
B19: ១. គម្រោង................ | S19: =IF(SUM(I19,Q19), "OK ", "-") -> -
B20: អនុកម្មវិធី ២.២ ៖ ក្រុមប្រឹក្សាជាតិគណនេយ្យ | S20: =IF(SUM(I20,Q20), "OK ", "-") -> -
B21: ១. គម្រោង................ | S21: =IF(SUM(I21,Q21), "OK ", "-") -> -
B22: អនុកម្មវិធី ២.៣ ៖ គណៈកម្មការមូលបត្រកម្ពុជា | F22: =SUM(F23) -> 1500 | G22: =SUM(G23) -> 1500 | H22: =SUM(H23) -> 1000 | I22: =SUM(F22:H22) -> 4000 | J22: =SUM(J23) -> 0 | K22: =SUM(K23) -> 0 | L22: =SUM(L23) -> 0 | M22: =SUM(J22:L22) -> 0 | N22: =SUM(N23) -> 1500 | O22: =SUM(O23) -> 1500 | P22: =SUM(P23) -> 1000 | Q22: =SUM(N22:P22) -> 4000 | S22: =IF(SUM(I22,Q22), "OK ", "-") -> OK
B23: ១. គម្រោងសាងសង់អគារគណៈកម្មការមូលបត្រកម្ពុជា | C23: 491 | D23: គម្រោងកំពុងដំណើរការ | E23: វិនិយោគជាទុន | F23: 1500 | G23: 1500 | H23: 1000 | I23: =SUM(F23:H23) -> 4000 | J23: 0 | K23: 0 | L23: 0 | M23: =SUM(J23:L23) -> 0 | N23: =F23-J23 -> 1500 | O23: =G23-K23 -> 1500 | P23: =H23-L23 -> 1000 | Q23: =SUM(N23:P23) -> 4000 | R23: ហិ.រ ក្រៅប្រទេស ADB | S23: =IF(SUM(I23,Q23), "OK ", "-") -> OK
B24: កម្មវិធីទី៣៖ ពង្រឹងនិងបង្កើនស័ក្តិសិទ្ធភាពនិងប្រសិទ្ធភាព នៃការគ្រប់គ្រងការកៀរគរចំណូលថវិកាជាតិ និងទ្រព្យសម្បត្តិរដ្ឋ | F24: =F25+F29+F34 -> 17464 | G24: =G25+G29+G34 -> 4437 | H24: =H25+H29+H34 -> 1387 | I24: =I25+I29+I34 -> 23288 | J24: =J25+J29+J34 -> 3050 | K24: =K25+K29+K34 -> 3050 | L24: =L25+L29+L34 -> 0 | M24: =M25+M29+M34 -> 6100 | ... Q24: =Q25+Q29+Q34 -> 17188 | S24: =IF(SUM(I24,Q24), "OK ", "-") -> OK
B25: អនុកម្មវិធី ៣.១ ៖ អគ្គនាយកដ្ឋានគយ និងរដ្ឋាករកម្ពុជា | F25: =SUM(F26:F28) -> 7180 | G25: =SUM(G26:G28) -> 3400 | H25: =SUM(H26:H28) -> 350 | I25: =SUM(F25:H25) -> 10930 | J25: =SUM(J26:J28) -> 3050 | K25: =SUM(K26:K28) -> 3050 | L25: =SUM(L26:L28) -> 0 | M25: =SUM(J25:L25) -> 6100 | N25: =SUM(N26:N28) -> 4130 | O25: =SUM(O26:O28) -> 350 | P25: =SUM(P26:P28) -> 350 | Q25: =SUM(N25:P25) -> 4830 | S25: =IF(SUM(I25,Q25), "OK ", "-") -> OK
B26: ១. គម្រោងលើកកម្ពស់ហេដ្ឋារចនាសម្ព័ន្ធសាធារណៈ របស់អគ្គនាយកដ្ឋានគយ និងរដ្ឋាករកម្ពុជា | C26: 509 | D26: គម្រោងកំពុងអនុវត្ត | E26: វិនិយោគជាទុន | F26: 3050 | G26: 3050 | I26: =SUM(F26:H26) -> 6100 | J26: 3050 | K26: 3050 | M26: =SUM(J26:L26) -> 6100 | N26: =F26-J26 -> 0 | O26: =G26-K26 -> 0 | P26: =H26-L26 -> 0 | Q26: =SUM(N26:P26) -> 0 | R26: ហិ.រ ក្នុងប្រ/ទ | S26: =IF(SUM(I26,Q26), "OK ", "-") -> OK
B27: ២. គម្រោងប្រព័ន្ធបញ្ជរតែមួយជាតិ | C27: 659 | D27: គម្រោងកំពុងអនុវត្ត | E27: វិនិយោគជាទុន | F27: 1550 | G27: 350 | H27: 350 | I27: =SUM(F27:H27) -> 2250 | M27: =SUM(J27:L27) -> 0 | N27: =F27-J27 -> 1550 | O27: =G27-K27 -> 350 | P27: =H27-L27 -> 350 | Q27: =SUM(N27:P27) -> 2250 | R27: ហិ.រ ក្នុងប្រ/ទ | S27: =IF(SUM(I27,Q27), "OK ", "-") -> OK
B28: ៣. គម្រោងលើកកម្ពស់ប្រសិទ្ធភាពការងារទប់ស្កាត់ និងបង្ក្រាបអំពើរត់គេចពន្ធ និងបទល្មើសឆ្លងដែនពាក់ព័ន្ធគយ | C28: 510 | D28: គម្រោងស្នើសុំថ្មី | E28: វិនិយោគជាទុន | F28: 2580 | I28: =SUM(F28:H28) -> 2580 | M28: =SUM(J28:L28) -> 0 | N28: =F28-J28 -> 2580 | O28: =G28-K28 -> 0 | P28: =H28-L28 -> 0 | Q28: =SUM(N28:P28) -> 2580 | R28: ហិ.រ ក្នុងប្រ/ទ | S28: =IF(SUM(I28,Q28), "OK ", "-") -> OK
B29: អនុកម្មវិធី ៣.២ ៖ អគ្គនាយកដ្ឋានពន្ធដារ | F29: =SUM(F30:F33) -> 10284 | G29: =SUM(G30:G33) -> 1037 | H29: =SUM(H30:H33) -> 1037 | I29: =SUM(F29:H29) -> 12358 | J29: =SUM(J30:J33) -> 0 | K29: =SUM(K30:K33) -> 0 | L29: =SUM(L30:L33) -> 0 | M29: =SUM(J29:L29) -> 0 | N29: =SUM(N30:N33) -> 10284 | O29: =SUM(O30:O33) -> 1037 | P29: =SUM(P30:P33) -> 1037 | Q29: =SUM(N29:P29) -> 12358 | S29: =IF(SUM(I29,Q29), "OK ", "-") -> OK
B30: ១. គម្រោងសាងសង់អគារសាខាពន្ធដារខណ្ឌចំនួន១ ខេត្តចំនួន៦, ការិយាល័យពន្ធដារ១,សាលាជាតិពន្ធដារនិងអគារសាលប្រជុំចំនួន១ | C30: 492 | D30: គម្រោងស្នើសុំថ្មី | E30: វិនិយោគជាទុន | F30: 4456.8 | G30: 888.9 | H30: 444.4 | I30: =SUM(F30:H30) -> 5790.1 | M30: =SUM(J30:L30) -> 0 | N30: =F30-J30 -> 4456.8 | O30: =G30-K30 -> 888.9 | P30: =H30-L30 -> 444.4 | Q30: =SUM(N30:P30) -> 5790.1 | R30: ហិ.រ ក្នុងប្រ/ទ | S30: =IF(SUM(I30,Q30), "OK ", "-") -> OK
B31: ២. គម្រោងទិញដីសម្រាប់សាងសង់អគារសាខាពន្ធដារខណ្ឌពោធិ៍សែនជ័យ | C31: 653 | D31: គម្រោងស្នើសុំថ្មី | E31: វិនិយោគជាទុន | F31: 2370.4 | I31: =SUM(F31:H31) -> 2370.4 | M31: =SUM(J31:L31) -> 0 | N31: =F31-J31 -> 2370.4 | O31: =G31-K31 -> 0 | P31: =H31-L31 -> 0 | Q31: =SUM(N31:P31) -> 2370.4 | R31: ហិ.រ ក្នុងប្រ/ទ | S31: =IF(SUM(I31,Q31), "OK ", "-") -> OK
B32: ៣. គម្រោងជួសជុល និងកែលម្អសាខាពន្ធដារខេត្តចំនួន ០៧, សាខាពន្ធដារ ខណ្ឌចំនួន ៧ និងការិយាល័យពន្ធដារ ចំនួន ២ | C32: 652 | D32: គម្រោងស្នើសុំថ្មី | E32: វិនិយោគជាទុន | G32: 148.1 | H32: 592.6 | I32: =SUM(F32:H32) -> 740.7 | M32: =SUM(J32:L32) -> 0 | N32: =F32-J32 -> 0 | O32: =G32-K32 -> 148.1 | P32: =H32-L32 -> 592.6 | Q32: =SUM(N32:P32) -> 740.7 | R32: ហិ.រ ក្នុងប្រ/ទ | S32: =IF(SUM(I32,Q32), "OK ", "-") -> OK
B33: ៤. គម្រោងអភិវឌ្ឍហេដ្ឋារចនាសម្ព័ន្ធ​ប្រព័ន្ធបច្ចេកវិទ្យាព័ត៌មានដំណាក់កាល​ទី២ | C33: 792 | D33: គម្រោងស្នើសុំថ្មី | E33: វិនិយោគជាទុន | F33: 3456.8 | I33: =SUM(F33:H33) -> 3456.8 | M33: =SUM(J33:L33) -> 0 | N33: =F33-J33 -> 3456.8 | O33: =G33-K33 -> 0 | P33: =H33-L33 -> 0 | Q33: =SUM(N33:P33) -> 3456.8 | R33: ហិ.រ ក្នុងប្រ/ទ | S33: =IF(SUM(I33,Q33), "OK ", "-") -> OK
B34: អនុកម្មវិធី ៣.៣ ៖ អគ្គនាយកដ្ឋានទ្រព្យសម្បត្តិរដ្ឋ និងចំណូលមិនមែនសារពើពន្ធ | S34: =IF(SUM(I34,Q34), "OK ", "-") -> -
B35: ១. គម្រោង................ | S35: =IF(SUM(I35,Q35), "OK ", "-") -> -
B36: កម្មវិធីទី៤៖ ពង្រឹងនិងបង្កើនស័ក្តិសិទ្ធភាពនិងប្រសិទ្ធភាព នៃការគ្រប់គ្រងចំណាយសាធារណៈ | F36: =F37+F39+F41+F43+F45 -> 6737.8 | G36: =G37+G39+G41+G43+G45 -> 1600 | H36: =H37+H39+H41+H43+H45 -> 1400 | I36: =I37+I39+I41+I43+I45 -> 9737.8 | J36: =J37+J39+J41+J43+J45 -> 0 | K36: =K37+K39+K41+K43+K45 -> 0 | L36: =L37+L39+L41+L43+L45 -> 0 | M36: =M37+M39+M41+M43+M45 -> 0 | ... Q36: =Q37+Q39+Q41+Q43+Q45 -> 9737.8 | S36: =IF(SUM(I36,Q36), "OK ", "-") -> OK
B37: អនុកម្មវិធី ៤.១ ៖ អគ្គនាយកដ្ឋានថវិកា | S37: =IF(SUM(I37,Q37), "OK ", "-") -> -
B38: ១. គម្រោង................ | S38: =IF(SUM(I38,Q38), "OK ", "-") -> -
B39: អនុកម្មវិធី ៤.២ ៖ អគ្គនាយកដ្ឋានហិរញ្ញវត្ថុរដ្ឋបាលថ្នាក់ក្រោមជាតិ | S39: =IF(SUM(I39,Q39), "OK ", "-") -> -
B40: ១. គម្រោង................ | S40: =IF(SUM(I40,Q40), "OK ", "-") -> -
B41: អនុកម្មវិធី ៤.៣ ៖ អគ្គនាយកដ្ឋានលទ្ធកម្មសាធារណៈ | S41: =IF(SUM(I41,Q41), "OK ", "-") -> -
B42: ១. គម្រោង................ | S42: =IF(SUM(I42,Q42), "OK ", "-") -> -
B43: អនុកម្មវិធី ៤.៤ ៖ អគ្គនាយកដ្ឋានរតនាគារជាតិ | F43: =F44 -> 1600 | G43: =G44 -> 1600 | H43: =H44 -> 1400 | I43: =SUM(F43:H43) -> 4600 | J43: =J44 -> 0 | K43: =K44 -> 0 | L43: =L44 -> 0 | M43: =SUM(J43:L43) -> 0 | N43: =N44 -> 1600 | O43: =O44 -> 1600 | P43: =P44 -> 1400 | Q43: =SUM(N43:P43) -> 4600 | S43: =IF(SUM(I43,Q43), "OK ", "-") -> OK
B44: ១. គម្រោងសាង់សង់ហេដ្ឋារចនាសម្ព័ន្ធរបស់រតនាគាររាជធានី-ខេត្ត ទាំង២២​និងឃ្លាំងរក្សាទុកឯកសាររបស់អគ្គនាយកដ្ឋានរតនាគារជាតិ | C44: 651 | D44: គម្រោងស្នើសុំថ្មី | E44: វិនិយោគជាទុន | F44: 1600 | G44: 1600 | H44: 1400 | I44: =SUM(F44:H44) -> 4600 | M44: =SUM(J44:L44) -> 0 | N44: =F44-J44 -> 1600 | O44: =G44-K44 -> 1600 | P44: =H44-L44 -> 1400 | Q44: =SUM(N44:P44) -> 4600 | R44: ហិ.រ ក្នុងប្រ/ទ | S44: =IF(SUM(I44,Q44), "OK ", "-") -> OK
...

Sheet pip_project (2)
A4: ឧបសម្ព័ន្ធទី២៖ តារាងសរុបគម្រោងវិនិយោគរបស់ក្រសួងសេដ្ឋកិច្ចនិងហិរញ្ញវត្ថុ សម្រាប់ដាក់បញ្ជូលក្នុង ក.វ.ស ៣ឆ្នាំរំកិល ២០២៣-២០២៥ (តាមអង្គភាពថវិកា)
A5: id | B5: pip_inv_id | C5: program_id | D5: sub_program_id | E5: entity_id | F5: project_name_en | G5: project_name_kh | H5: structure_sub_program | I5: structure_sub_program | J5: structure_sub_program | K5: pip_no | L5: project_status | M5: project_type | N5: project_status_ | O5: project_type_ | P5: est_costing_year_0 | Q5: est_costing_year_1 | R5: est_costing_year_2 | T5: s_fin_year_0 | U5: s_fin_year_1 | V5: s_fin_year_2 | X5: add_req_fin_year_0 | Y5: add_req_fin_year_1 | Z5: add_req_fin_year_2 | AB5: finance_resource_id | AC5: finance_resource
C6: =MATCH(H6,[1]កម្មវិធី!$E$2:$E$6) -> 2 | G6: កម្មវិធីទី៣៖ ការគ្រប់គ្រងចំណូលសាធារណៈ និងទ្រព្យសម្បត្តិរដ្ឋ | H6: កម្មវិធីទី៣ | I6: ការគ្រប់គ្រងចំណូលសាធារណៈនិងទ្រព្យសម្បត្តិរដ្ឋ | J6: =RIGHT(G6,LEN(G6)-SEARCH("៖",G6)) -> ការគ្រប់គ្រងចំណូលសាធារណៈ និងទ្រព្យសម្បត្តិរដ្ឋ | P6: =P7+P9 -> 3400 | Q6: =Q7+Q9 -> 1050 | R6: =R7+R9 -> 100 | S6: =S7+S9 -> 4550 | T6: =T7+T9 -> 0 | U6: =U7+U9 -> 0 | V6: =V7+V9 -> 0 | W6: =W7+W9 -> 0 | ... AA6: =AA7+AA9 -> 4550 | AD6: =IF(SUM(S6,AA6), "OK ", "-") -> OK | AH6: =800000000/4000 -> 200000
D7: =MATCH(H7,[2]អនុកម្មវិធី!$E$2:$E$33,0) -> 13 | E7: 6 | G7: អនុកម្មវិធី ៣.១ ៖ អគ្គនាយកដ្ឋានគយនិងរដ្ឋាករកម្ពុជា | H7: អនុកម្មវិធីទី៣.១ | I7: អគ្គនាយកដ្ឋានគយនិងរដ្ឋាករកម្ពុជា | J7: =TRIM(RIGHT(G7,LEN(G7)-SEARCH("៖",G7))) -> អគ្គនាយកដ្ឋានគយនិងរដ្ឋាករកម្ពុជា | P7: =SUM(P8:P8) -> 2000 | Q7: =SUM(Q8:Q8) -> 1000 | R7: =SUM(R8:R8) -> 0 | S7: =SUM(P7:R7) -> 3000 | T7: =SUM(T8:T8) -> 0 | U7: =SUM(U8:U8) -> 0 | V7: =SUM(V8:V8) -> 0 | W7: =SUM(T7:V7) -> 0 | X7: =SUM(X8:X8) -> 2000 | Y7: =SUM(Y8:Y8) -> 1000 | Z7: =SUM(Z8:Z8) -> 0 | AA7: =SUM(X7:Z7) -> 3000 | AD7: =IF(SUM(S7,AA7), "OK ", "-") -> OK
A8: 1 | C8: 2 | D8: 13 | E8: 6 | F8: ១. គម្រោងប្រព័ន្ធបញ្ជរតែមួយជាតិ (ដំណាក់កាលទី៣) | G8: ១. គម្រោងប្រព័ន្ធបញ្ជរតែមួយជាតិ (ដំណាក់កាលទី៣) | K8: 659 | L8: 4 | M8: 1 | N8: គម្រោងស្នើសុំថ្មី | O8: វិនិយោគជាទុន | P8: 2000 | Q8: 1000 | R8: 0 | S8: =SUM(P8:R8) -> 3000 | W8: =SUM(T8:V8) -> 0 | X8: =P8-T8 -> 2000 | Y8: =Q8-U8 -> 1000 | Z8: =R8-V8 -> 0 | AA8: =SUM(X8:Z8) -> 3000 | AB8: 8 | AC8: ហិ.រ ក្នុងប្រ/ទ | AD8: =IF(SUM(S8,AA8), "OK ", "-") -> OK
D9: =MATCH(H9,[2]អនុកម្មវិធី!$E$2:$E$33,0) -> 14 | E9: 7 | G9: អនុកម្មវិធី ៣.២ ៖ អគ្គនាយកដ្ឋានពន្ធដារ | H9: អនុកម្មវិធីទី៣.២ | I9: អគ្គនាយកដ្ឋានពន្ធដារ | J9: =TRIM(RIGHT(G9,LEN(G9)-SEARCH("៖",G9))) -> អគ្គនាយកដ្ឋានពន្ធដារ | P9: =SUM(P10:P11) -> 1400 | Q9: =SUM(Q10:Q11) -> 50 | R9: =SUM(R10:R11) -> 100 | S9: =SUM(P9:R9) -> 1550 | T9: =SUM(T10:T11) -> 0 | U9: =SUM(U10:U11) -> 0 | V9: =SUM(V10:V11) -> 0 | W9: =SUM(T9:V9) -> 0 | X9: =SUM(X10:X11) -> 1400 | Y9: =SUM(Y10:Y11) -> 50 | Z9: =SUM(Z10:Z11) -> 100 | AA9: =SUM(X9:Z9) -> 1550 | AD9: =IF(SUM(S9,AA9), "OK ", "-") -> OK
A10: 2 | C10: 2 | D10: 14 | E10: 7 | F10: ១. គម្រោងសាងសង់អគារសាខាពន្ធដារខណ្ឌចំនួន០១ និងអគារការិយាល័យពន្ធដារស្រុកស្ទឹងហាវ ០១ | G10: ១. គម្រោងសាងសង់អគារសាខាពន្ធដារខណ្ឌចំនួន០១ និងអគារការិយាល័យពន្ធដារស្រុកស្ទឹងហាវ ០១ | K10: 492 | L10: 4 | M10: 1 | N10: គម្រោងស្នើសុំថ្មី | O10: វិនិយោគជាទុន | P10: 900 | Q10: 0 | R10: 100 | S10: =SUM(P10:R10) -> 1000 | W10: =SUM(T10:V10) -> 0 | X10: =P10-T10 -> 900 | Y10: =Q10-U10 -> 0 | Z10: =R10-V10 -> 100 | AA10: =SUM(X10:Z10) -> 1000 | AB10: 8 | AC10: ហិ.រ ក្នុងប្រ/ទ | AD10: =IF(SUM(S10,AA10), "OK ", "-") -> OK
A11: 3 | C11: 2 | D11: 14 | E11: 7 | F11: ២. គម្រោងជួសជុលនិងកែលម្អអគារសាខាពន្ធដារខណ្ឌចំនួន០១ ការិយាល័យពន្ធដារក្រុងចំនួន០១ និងស្រុកចំនួន ០១ | G11: ២. គម្រោងជួសជុលនិងកែលម្អអគារសាខាពន្ធដារខណ្ឌចំនួន០១ ការិយាល័យពន្ធដារក្រុងចំនួន០១ និងស្រុកចំនួន ០១ | K11: 652 | L11: 4 | M11: 1 | N11: គម្រោងស្នើសុំថ្មី | O11: វិនិយោគជាទុន | P11: 500 | Q11: 50 | R11: 0 | S11: =SUM(P11:R11) -> 550 | W11: =SUM(T11:V11) -> 0 | X11: =P11-T11 -> 500 | Y11: =Q11-U11 -> 50 | Z11: =R11-V11 -> 0 | AA11: =SUM(X11:Z11) -> 550 | AB11: 8 | AC11: ហិ.រ ក្នុងប្រ/ទ | AD11: =IF(SUM(S11,AA11), "OK ", "-") -> OK
C12: =MATCH(H12,[1]កម្មវិធី!$E$2:$E$6) -> 3 | G12: កម្មវិធីទី៤៖ ការគ្រប់គ្រងចំណាយសាធារណៈ និងប្រព័ន្ធហិរញ្ញវត្ថុសាធារណៈ | H12: កម្មវិធីទី៤ | I12: ការគ្រប់គ្រងចំណាយសាធារណៈ និងប្រព័ន្ធហិរញ្ញវត្ថុសាធារណៈ | J12: =RIGHT(G12,LEN(G12)-SEARCH("៖",G12)) -> ការគ្រប់គ្រងចំណាយសាធារណៈ និងប្រព័ន្ធហិរញ្ញវត្ថុសាធារណៈ | P12: =P13 -> 2400 | Q12: =Q13 -> 2400 | R12: =R13 -> 1800 | S12: =S13 -> 6600 | T12: =T13 -> 0 | U12: =U13 -> 0 | V12: =V13 -> 0 | W12: =W13 -> 0 | ... AA12: =AA13 -> 6600 | AD12: =IF(SUM(S12,AA12), "OK ", "-") -> OK
D13: =MATCH(H13,[2]អនុកម្មវិធី!$E$2:$E$33,0) -> 21 | E13: 9 | G13: អនុកម្មវិធី ៤.៤ ៖ អគ្គនាយកដ្ឋានរតនាគារជាតិ | H13: អនុកម្មវិធីទី៤.៤ | I13: អគ្គនាយកដ្ឋានរតនាគារជាតិ | J13: =TRIM(RIGHT(G13,LEN(G13)-SEARCH("៖",G13))) -> អគ្គនាយកដ្ឋានរតនាគារជាតិ | P13: =P14 -> 2400 | Q13: =Q14 -> 2400 | R13: =R14 -> 1800 | S13: =SUM(P13:R13) -> 6600 | T13: =T14 -> 0 | U13: =U14 -> 0 | V13: =V14 -> 0 | W13: =SUM(T13:V13) -> 0 | X13: =X14 -> 2400 | Y13: =Y14 -> 2400 | Z13: =Z14 -> 1800 | AA13: =SUM(X13:Z13) -> 6600 | AD13: =IF(SUM(S13,AA13), "OK ", "-") -> OK
A14: 4 | C14: 3 | D14: 21 | E14: 9 | F14: ១. គម្រោងសាងសង់ហេដ្ឋារចនាសម្ព័ន្ធរបស់រតនាគារខេត្ត ចំនួន ២២​ | G14: ១. គម្រោងសាងសង់ហេដ្ឋារចនាសម្ព័ន្ធរបស់រតនាគារខេត្ត ចំនួន ២២​ | K14: 651 | L14: 4 | M14: 1 | N14: គម្រោងស្នើសុំថ្មី | O14: វិនិយោគជាទុន | P14: 2400 | Q14: 2400 | R14: 1800 | S14: =SUM(P14:R14) -> 6600 | W14: =SUM(T14:V14) -> 0 | X14: =P14-T14 -> 2400 | Y14: =Q14-U14 -> 2400 | Z14: =R14-V14 -> 1800 | AA14: =SUM(X14:Z14) -> 6600 | AB14: 8 | AC14: ហិ.រ ក្នុងប្រ/ទ | AD14: =IF(SUM(S14,AA14), "OK ", "-") -> OK
C15: =MATCH(H15,[1]កម្មវិធី!$E$2:$E$6) -> 4 | G15: កម្មវិធីទី៥៖ កិច្ចការរដ្ឋបាលនិងអភិវឌ្ឍស្ថាប័ន | H15: កម្មវិធីទី៥ | I15: កិច្ចការរដ្ឋបាលនិងអភិវឌ្ឍស្ថាប័ន | J15: =RIGHT(G15,LEN(G15)-SEARCH("៖",G15)) -> កិច្ចការរដ្ឋបាលនិងអភិវឌ្ឍស្ថាប័ន | P15: =P16 -> 4232.5 | Q15: =Q16 -> 1862.5 | R15: =R16 -> 562.5 | S15: =S16 -> 6657.5 | T15: =T16 -> 0 | U15: =U16 -> 0 | V15: =V16 -> 0 | W15: =W16 -> 0 | ... AA15: =AA16 -> 6657.5 | AD15: =IF(SUM(S15,AA15), "OK ", "-") -> OK
D16: =MATCH(H16,[2]អនុកម្មវិធី!$E$2:$E$33,0) -> 30 | E16: 28 | G16: អនុកម្មវិធី ៥.៣ ៖មន្ទីរសេដ្ឋកិច្ចនិងហិរញ្ញវត្ថុរាជធានី ខេត្ត | H16: អនុកម្មវិធីទី៥.៣ | I16: មន្ទីរសេដ្ឋកិច្ច​និងហិរញ្ញវត្ថុ​ រាជធានី ខេត្ត | J16: =TRIM(RIGHT(G16,LEN(G16)-SEARCH("៖",G16))) -> មន្ទីរសេដ្ឋកិច្ចនិងហិរញ្ញវត្ថុរាជធានី ខេត្ត | P16: =P17+P24 -> 4232.5 | Q16: =Q17+Q24 -> 1862.5 | R16: =R17+R24 -> 562.5 | S16: =S17+S24 -> 6657.5 | T16: =T17+T24 -> 0 | U16: =U17+U24 -> 0 | V16: =V17+V24 -> 0 | W16: =W17+W24 -> 0 | ... AA16: =AA17+AA24 -> 6657.5 | AD16: =IF(SUM(S16,AA16), "OK ", "-") -> OK
A17: 5 | C17: 4 | D17: 30 | E17: 28 | F17: ១.គម្រោងសាងសង់ហេដ្ឋារចនាសម្ព័ន្ធរូបវ័ន្តរបស់មន្ទីរសេដ្ឋកិច្ចនិងហិរញ្ញវត្ថុខេត្តចំនួន៥ | G17: ១.គម្រោងសាងសង់ហេដ្ឋារចនាសម្ព័ន្ធរូបវ័ន្តរបស់មន្ទីរសេដ្ឋកិច្ចនិងហិរញ្ញវត្ថុខេត្តចំនួន៥ | K17: 641 | L17: 4 | M17: 1 | N17: គម្រោងស្នើសុំថ្មី | O17: វិនិយោគជាទុន | P17: =SUM(P18:P23) -> 1232.5 | Q17: =SUM(Q18:Q23) -> 362.5 | R17: =SUM(R18:R23) -> 62.5 | S17: =SUM(S18:S23) -> 1657.5 | T17: =SUM(T18:T23) -> 0 | U17: =SUM(U18:U23) -> 0 | V17: =SUM(V18:V23) -> 0 | W17: =SUM(W18:W23) -> 0 | ... AA17: =SUM(AA18:AA23) -> 1657.5 | AB17: 8 | AC17: ហិ.រ ក្នុងប្រ/ទ | AD17: =IF(SUM(S17,AA17), "OK ", "-") -> OK
B18: 5 | E18: 1 | G18: - សាងសង់អគាររដ្ឋបាល | K18: មសហវ ខេត្តបន្ទាយមានជ័យ | P18: 62.5 | Q18: 62.5 | R18: 62.5 | S18: =SUM(P18:R18) -> 187.5 | T18: 0 | U18: 0 | V18: 0 | W18: =SUM(T18:V18) -> 0 | X18: =P18-T18 -> 62.5 | Y18: =Q18-U18 -> 62.5 | Z18: =R18-V18 -> 62.5 | AA18: =SUM(X18:Z18) -> 187.5 | AD18: =IF(SUM(S18,AA18), "OK ", "-") -> OK | AH18: =62500*3 -> 187500
B19: 5 | E19: 2 | G19: - សាងសង់អគាររដ្ឋបាលថ្មីកម្ពស់១ជាន់ (E1) | K19: មសហវ.ខេត្តបាត់ដំបង | P19: 300 | Q19: 300 | S19: =SUM(P19:R19) -> 600 | W19: =SUM(T19:V19) -> 0 | X19: =P19-T19 -> 300 | Y19: =Q19-U19 -> 300 | Z19: =R19-V19 -> 0 | AA19: =SUM(X19:Z19) -> 600 | AD19: =IF(SUM(S19,AA19), "OK ", "-") -> OK
B20: 5 | E20: 3 | G20: - សាងសង់អគារថ្មី | K20: មសហវ. ខេត្តកំពង់ស្ពឺ | P20: 235 | S20: =SUM(P20:R20) -> 235 | W20: =SUM(T20:V20) -> 0 | X20: =P20-T20 -> 235 | Y20: =Q20-U20 -> 0 | Z20: =R20-V20 -> 0 | AA20: =SUM(X20:Z20) -> 235 | AD20: =IF(SUM(S20,AA20), "OK ", "-") -> OK
B21: 5 | E21: 4 | G21: - សាងសង់របងជុំវិញមន្ទីរ | P21: 135 | S21: =SUM(P21:R21) -> 135 | W21: =SUM(T21:V21) -> 0 | X21: =P21-T21 -> 135 | Y21: =Q21-U21 -> 0 | Z21: =R21-V21 -> 0 | AA21: =SUM(X21:Z21) -> 135 | AD21: =IF(SUM(S21,AA21), "OK ", "-") -> OK
B22: 5 | E22: 5 | G22: - សាងសង់របង | K22: មសហវ ខេត្តព្រះវិហារ | P22: 125 | S22: =SUM(P22:R22) -> 125 | W22: =SUM(T22:V22) -> 0 | X22: =P22-T22 -> 125 | Y22: =Q22-U22 -> 0 | Z22: =R22-V22 -> 0 | AA22: =SUM(X22:Z22) -> 125 | AD22: =IF(SUM(S22,AA22), "OK ", "-") -> OK
B23: 5 | E23: 6 | G23: - សាងសង់អគាររដ្ឋបាលថ្មី | K23: មសហវ ខេត្តឧត្តរមានជ័យ | P23: 375 | S23: =SUM(P23:R23) -> 375 | W23: =SUM(T23:V23) -> 0 | X23: =P23-T23 -> 375 | Y23: =Q23-U23 -> 0 | Z23: =R23-V23 -> 0 | AA23: =SUM(X23:Z23) -> 375 | AD23: =IF(SUM(S23,AA23), "OK ", "-") -> OK
A24: 6 | C24: 4 | D24: 30 | E24: 28 | F24: ២.គម្រោងទិញដីសម្រាប់មន្ទីរសេដ្ឋកិច្ចខេត្តកណ្តាលនិងសាងសង់អគារ មន្ទីរសេដ្ឋកិច្ចនិងហិរញ្ញវត្ថុខេត្តកណ្តាល និងអគារមន្ទីរសេដ្ឋកិច្ចនិងហិរញ្ញវត្ថុ រាជធានីភ្នំពេញ | G24: ២.គម្រោងទិញដីសម្រាប់មន្ទីរសេដ្ឋកិច្ចខេត្តកណ្តាលនិងសាងសង់អគារ មន្ទីរសេដ្ឋកិច្ចនិងហិរញ្ញវត្ថុខេត្តកណ្តាល និងអគារមន្ទីរសេដ្ឋកិច្ចនិងហិរញ្ញវត្ថុ រាជធានីភ្នំពេញ | K24: 507 | N24: គម្រោងស្នើសុំថ្មី | O24: វិនិយោគជាទុន | P24: =SUM(P25:P26) -> 3000 | Q24: =SUM(Q25:Q26) -> 1500 | R24: =SUM(R25:R26) -> 500 | S24: =SUM(S25:S26) -> 5000 | T24: =SUM(T25:T26) -> 0 | U24: =SUM(U25:U26) -> 0 | V24: =SUM(V25:V26) -> 0 | W24: =SUM(W25:W26) -> 0 | ... AA24: =SUM(AA25:AA26) -> 5000 | AB24: 8 | AC24: ហិ.រ ក្នុងប្រ/ទ | AD24: =IF(SUM(S24,AA24), "OK ", "-") -> OK
B25: 6 | E25: 1 | G25: - ទិញដី និងសាងសង់អគាររដ្ឋបាល មន្ទីរ | K25: មសហវ ខេត្តកណ្តាល | P25: 2500 | Q25: 1000 | R25: 500 | S25: =SUM(P25:R25) -> 4000 | W25: =SUM(T25:V25) -> 0 | X25: =P25-T25 -> 2500 | Y25: =Q25-U25 -> 1000 | Z25: =R25-V25 -> 500 | AA25: =SUM(X25:Z25) -> 4000 | AD25: =IF(SUM(S25,AA25), "OK ", "-") -> OK
B26: 6 | E26: 2 | G26: - សាងសង់អគារមន្ទីរសេដ្ឋកិច្ចនិងហិរញ្ញវត្ថុរាជធានី និងបំពាក់បរិក្ខារ | K26: មសហវ រាជធានីភ្នំពេញ | P26: 500 | Q26: 500 | S26: =SUM(P26:R26) -> 1000 | W26: =SUM(T26:V26) -> 0 | X26: =P26-T26 -> 500 | Y26: =Q26-U26 -> 500 | Z26: =R26-V26 -> 0 | AA26: =SUM(X26:Z26) -> 1000 | AD26: =IF(SUM(S26,AA26), "OK ", "-") -> OK

Sheet pip_project (3)
A1: id | B1: pip_inv_id | C1: program_id | D1: sub_program_id | E1: entity_id | F1: project_name_en | G1: project_name_kh | H1: structure_sub_program | I1: structure_sub_program | J1: pip_no | K1: project_status | L1: project_type | M1: project_status_ | N1: project_type_ | O1: est_costing_year_0 | P1: est_costing_year_1 | Q1: est_costing_year_2 | S1: s_fin_year_0 | T1: s_fin_year_1 | U1: s_fin_year_2 | W1: add_req_fin_year_0 | X1: add_req_fin_year_1 | Y1: add_req_fin_year_2 | AA1: finance_resource_id | AB1: finance_resource
C2: =MATCH(H2,[1]កម្មវិធី!$E$2:$E$6) -> 2 | G2: កម្មវិធីទី៣៖ ការគ្រប់គ្រងចំណូលសាធារណៈ និងទ្រព្យសម្បត្តិរដ្ឋ | H2: កម្មវិធីទី៣ | I2: =RIGHT(G2,LEN(G2)-SEARCH("៖",G2)) -> ការគ្រប់គ្រងចំណូលសាធារណៈ និងទ្រព្យសម្បត្តិរដ្ឋ | O2: =O3+O5 -> 3400 | P2: =P3+P5 -> 1050 | Q2: =Q3+Q5 -> 100 | R2: =R3+R5 -> 4550 | S2: =S3+S5 -> 0 | T2: =T3+T5 -> 0 | U2: =U3+U5 -> 0 | V2: =V3+V5 -> 0 | ... Z2: =Z3+Z5 -> 4550 | AC2: =IF(SUM(R2,Z2), "OK ", "-") -> OK | AG2: =800000000/4000 -> 200000
