Workbook
Name a: #REF!
Name aa: #REF!
Name b: #REF!
Name br: #REF!
Name condition: [1]Data!$B:$C
Name Monthdata: [2]!Month_Table[Monthlist]
Name pop: #REF!
Name tc: #REF!
Name ល.រ: '[3]Costing(ដំបូង)'!$B$283:$B$1048576
Name សរុប: '[3]Costing(ដំបូង)'!$K$283:$K$1048576
Name អនុគណនី: '[3]Costing(ដំបូង)'!$E$283:$E$1048576

Sheet BSP2_Indicator
B1: id | C1: subprog_to_entity_id | D1: cluster_act_to_entity_id | E1: activity_id | F1: code | H1: kpi_name_kh
F2: 10101 | G2: =[4]Costing!$G$11 -> 10101 | H2: =VLOOKUP($G2,[4]BSP1!$B$12:$D$207,3) -> ១.១. អនុកម្មវិធីទី១.១ : ការគ្រប់គ្រងគោលនយោបាយសេដ្ឋកិច្ច ហិរញ្ញវត្ថុ និងគោលនយោបាយតាមវិស័យផ្សេងៗ | J2: =J8+J15+J22+J27+J34+J43+J50+J57+J64+J71+J78+J85+J92+J99+J106 -> 3639 | Q2: =IF(OR(J2>0,K2<>0,L2<>0,M2<>0),"ok","-") -> ok
B3: 1 | C3: 1 | H3: -សូចនាករទី១ : គោលនយោបាយម៉ាក្រូសេដ្ឋកិច្ច និងសារពើពន្ធ និងលទ្ធផលការងារពាក់ព័ន្ធ | I3: PI-1011 | K3: ១. របាយការណ៍ពិនិត្យតាមដាន និងវាយតម្លៃស្ថានភាពសេដ្ឋកិច្ច និងហិរញ្ញវត្ថុសាធារណៈ ប្រចាំឆ្នាំ២០២០ និងពាក់កណ្តាលឆ្នាំ២០២១ ត្រូវបានរៀបចំ ២.ក្របខ័ណ្ឌគោលនយោបាយម៉ាក្រូសេដ្ឋកិច្ច និងគោលនយោបាយហិរញ្ញវត្ថុសាធារណៈ សម្រាប់ការរៀបចំសេចក្ដីព្រាងច្បាប់ស្តីពីហិរញ្ញវត្ថុសម្រាប់ការគ្រប់គ្រងឆ្នាំ ២០២២ ត្រូវបានរៀបចំ ដោយមានការគិតគូរពីបរិកាណ៍ជំងឺកូវីដ-១៩ ៣.ការសិក្សាស្រាវជ្រាវលើប្រធានបទ ០៣ ត្រូវបានបញ្ចប់រួមមាន៖ (១). ការជំរុញវិស័យកែច្នៃផលិតផលកសិកម្មនៅកម្ពុជា, (២). ការសិក្សាស្រាវជ្រាវស្តីពីការត្រួតពិនិត្យហានិភ័យលើវិស័យអចលនទ្រព្យនៅកម្ពុជា និង (៣).ក្របខណ្ឌវិធានការក្របខណ្ឌជំរុញវិស័យកសិកម្ម និងកសិ-ឧស្សាហកម្មនៅកម្ពុជា ២០២១-២០២៣ ខណៈឯកសារពាក់ព័ន្ធ ដើម្បីចុះប្រមូលទិន្នន័យសំខាន់ៗសម្រាប់ការសិក្សាស្រាវជ្រាវស្តីពី ការលើកកម្ពស់ដំណើរការផ្សារភ្ជាប់រវាងកសិផលកែច្នៃ និងវិស័យទេសចរណ៍នៅកម្ពុជា ត្រូវបានរៀបចំរួចរាល់ ។ ៤.របាយការណ៍ស្តីពីការអនុវត្តគម្រោងមូលនិធិអភិវឌ្ឍន៍ជំនាញត្រូវបានរៀបចំ ។ ៥.របាយការណ៍ស្តីពីការអនុវត្តគម្រោងមូលនិធិអភិវឌ្ឍន៍សហគ្រិន ភាពត្រូវបានរៀបចំ ។ | L3: ១.១. ការសិក្សាលើប្រធានបទទាក់ទងវិស័យសេដ្ឋកិច្ច និងហិរញ្ញវត្ថុគន្លឹះ និងរបបលើកទឹកចិត្តពន្ធសម្រាប់វិស័យអាទិភាពចំនួន០៧ ដើម្បីជាធាតុចូលសម្រាប់ការរៀបចំគោលនយោបាយ។ ១.២. ក្របខ័ណ្ឌហិរញ្ញវត្ថុសាធារណៈរយៈពេលមធ្យម (MTFF) ឆ្នាំ ២០២៣-២០២៥ ត្រូវបានរៀបចំ និងដាក់ឱ្យប្រើប្រាស់។ ១.៣. របាយការណ៍វិភាគ, តាមដាន និងវាយតម្លៃការអនុវត្តគោលនយោបាយម៉ាក្រូសេដ្ឋកិច្ច និងហិរញ្ញវត្ថុសាធារណៈប្រចាំំឆ្នាំ២០២១ ប្រចាំត្រីមាសនិងពាក់កណ្តាលឆ្នាំ២០២២ត្រូវបានរៀបចំ។ ១.៤.របាយការណ៍ត្រួតពិនិត្យការអនុវត្តយុទ្ធ សាស្ត្រកៀរគរចំណូល២០១៩-២០២៣ប្រចាំឆ្នាំនិងពាក់កណ្តាលអាណត្តិ។ ១.៥.របាយការណ៍ស្តីពីការអនុវត្តគម្រោង “មូលនិធិអភិវឌ្ឍន៍ជំនាញ (EDF)”, “មូលនិធិអភិវឌ្ឍជំនាញ (SDF)” និង “ផែនការមេអភិវឌ្ឍខេត្តព្រះសីហនុ” ត្រូវបានរៀបចំ។ | M3: ១. ឯកសារស្រាវជ្រាវឬរបាយការណ៍សិក្ខាសាលាស្តីពីកិច្ចពិភាក្សាលើប្រធានបទទាក់ទងវិស័យសេដ្ឋកិច្ច និងហិរញ្ញវត្ថុចំនួន ៣ ត្រូវបានរៀបចំ ២. ក្របខ័ណ្ឌហិរញ្ញវត្ថុសាធារណៈរយៈពេលមធ្យម ឆ្នាំ ២០២៤-២០២៦ ដែលមានការវាយតម្លៃពីហានិភ័យហិរញ្ញវត្ថុសាធារណៈ ត្រូវបានរៀបចំ ៣. របាយការណ៍ត្រួតពិនិត្យការអនុវត្តយុទ្ធសាស្រ្តកៀរគរចំណូល ២០១៩-២០២៣ ប្រចាំឆ្នាំ ២០២២ និងពាក់កណ្ដាលឆ្នាំ ២០២៣, ៤. របាយការណ៍ពិនិត្យតាមដាន និងវាយតម្លៃសេដ្ឋកិច្ច និងហិរញ្ញវត្ថុសាធារណៈ ប្រចាំឆ្នាំ ២០២២ និងពាក់កណ្តាលឆ្នាំ២០២៣ត្រូវបានរៀបចំ ៥. របាយការណ៍តាមដាន និងវាយតម្លៃសកម្មភាព ដែលបានកំណត់ក្នុងកម្មវិធីកែទម្រង់ការគ្រប់គ្រង ហិរញ្ញវត្ថុសាធារណៈ។ | N3: ស្នើសុំដកចេញនូវសូចនាករលើផ្នែកៈ ១.របាយការណ៍វឌ្ឍនភាពស្តីការរៀបចំផែនការមេ​ ដើម្បីប្រែក្លាយខេត្តព្រះសីហនុទៅជាតំបន់សេដ្ឋកិច្ចពិសេសគំរូពហុបំណង ។ ២.របាយការណ៍ស្តីពីការអនុវត្តគម្រោងមូលនិធិអភិវឌ្ឍន៍ជំនាញ (SDF) និង “មូលនិធិអភិវឌ្ឍន៍សហគ្រិនភាព (EDF)” ប្រចាំឆ្នាំ ២០២១។ មូលហេតុៈ សកម្មភាពនេះ ជាលក្ខណៈ (one off) ដោយប្រើប្រាស់ថវិកាផ្ទេរពីជំពូក​៦៩មក ដូចនេះសុំដាក់ចំណុចទី១ តែសូចនាករក្នុងចង្កោមសកម្មភាពទី២ និងចំណុចទី២ ក្នុងចង្កោមសកម្មភាពទី ៥។ | O3: ១. ឯកសារស្រាវជ្រាវឬរបាយការណ៍សិក្ខាសាលាស្តីពីកិច្ចពិភាក្សាលើប្រធានបទគន្លឹះទាក់ទងវិស័យសេដ្ឋកិច្ច និងហិរញ្ញវត្ថុត្រូវបានរៀបចំ ២. ក្របខ័ណ្ឌហិរញ្ញវត្ថុសាធារណៈរយៈពេលមធ្យម ឆ្នាំ ២០២៥-២០២៧ ដែលមានការវាយតម្លៃពីហានិភ័យហិរញ្ញវត្ថុសាធារណៈ ត្រូវបានរៀបចំ ៣. របាយការណ៍ត្រួតពិនិត្យការអនុវត្តយុទ្ធសាស្រ្តកៀរគរចំណូល ២០១៩-២០២៣ ប្រចាំឆ្នាំ ២០២៣, ៤. របាយការណ៍ពិនិត្យតាមដាន និងវាយតម្លៃសេដ្ឋកិច្ច និងហិរញ្ញវត្ថុសាធារណៈ ប្រចាំឆ្នាំ ២០២៣ និងពាក់កណ្តាលឆ្នាំ២០២៤ត្រូវបានរៀបចំ ៥. របាយការណ៍តាមដាន និងវាយតម្លៃសកម្មភាព ដែលបានកំណត់ក្នុងកម្មវិធីកែទម្រង់ការគ្រប់គ្រង ហិរញ្ញវត្ថុសាធារណៈ។ | P3: ១. ឯកសារស្រាវជ្រាវឬរបាយការណ៍សិក្ខាសាលាស្តីពីកិច្ចពិភាក្សាលើប្រធានបទគន្លឹះទាក់ទងវិស័យសេដ្ឋកិច្ច និងហិរញ្ញវត្ថុត្រូវបានរៀបចំ ២. ក្របខ័ណ្ឌហិរញ្ញវត្ថុសាធារណៈរយៈពេលមធ្យម ឆ្នាំ ២០២៦-២០២៨ ដែលមានការវាយតម្លៃពីហានិភ័យហិរញ្ញវត្ថុសាធារណៈ ត្រូវបានរៀបចំ ៣. របាយការណ៍ត្រួតពិនិត្យចំណូលសារពើពន្ធ និងមិនមែនសារពើពន្ធត្រូវបានរៀបចំ ៤. របាយការណ៍ពិនិត្យតាមដាន និងវាយតម្លៃសេដ្ឋកិច្ច និងហិរញ្ញវត្ថុសាធារណៈ ប្រចាំឆ្នាំ ២០២៤ និងពាក់កណ្តាលឆ្នាំ២០២៥ ត្រូវបានរៀបចំ ៥. របាយការណ៍តាមដាន និងវាយតម្លៃសកម្មភាព ដែលបានកំណត់ក្នុងកម្មវិធីកែទម្រង់ការគ្រប់គ្រង ហិរញ្ញវត្ថុសាធារណៈ។ | Q3: =IF(OR(J3>0,K3<>0,L3<>0,M3<>0),"ok","-") -> ok
B4: 2 | C4: 1 | H4: -សូចនាករទី២ : លទ្ធផលការងារស្ថិតិ | K4: ៦.របាយការណ៍តាមដាននិន្នាការសេដ្ឋកិច្ច និងហិរញ្ញវត្ថុ ចំនួន៣៣ និងកម្រងទិន្នន័យស្ថិតិចំនួន ១១៩ (សេដ្ឋកិច្ច និងហិរញ្ញវត្ថុ, និន្នាការថ្លៃទំនិញក្នុងស្រុកនិងអន្តរជាតិ,ទិន្នន័យថ្លៃប្រេងនាំចូលប្រេងលក់រាយ)ត្រូវបានរៀបចំ ។ | L4: ២.របាយការណ៍ និង ផលិតផលស្ថិតិសេដ្ឋកិច្ច និង ហិរញ្ញវត្ថុ ប្រចាំឆ្នាំ២០២១ និងប្រចាំខែ, ប្រចាំត្រីមាស ឆ្នាំ២០២២ ត្រូវបានរៀបចំ។ | M4: ២.របាយការណ៍ និង ផលិតផលស្ថិតិសេដ្ឋកិច្ច និង ហិរញ្ញវត្ថុ ប្រចាំឆ្នាំ២០២២ និងប្រចាំខែ, ប្រចាំត្រីមាស ឆ្នាំ២០២៣ ត្រូវបានរៀបចំ។ | O4: ២.របាយការណ៍ និង ផលិតផលស្ថិតិសេដ្ឋកិច្ច និង ហិរញ្ញវត្ថុ ប្រចាំឆ្នាំ២០២៣ និងប្រចាំខែ, ប្រចាំត្រីមាស ឆ្នាំ២០២៤ ត្រូវបានរៀបចំ។ | P4: ២.របាយការណ៍ និង ផលិតផលស្ថិតិសេដ្ឋកិច្ច និង ហិរញ្ញវត្ថុ ប្រចាំឆ្នាំ២០២៤ និងប្រចាំខែ, ប្រចាំត្រីមាស ឆ្នាំ២០២៥ ត្រូវបានរៀបចំ។ | Q4: =IF(OR(J4>0,K4<>0,L4<>0,M4<>0),"ok","-") -> ok
B5: 3 | C5: 1 | H5: -សូចនាករទី៣ : លទ្ធផលការងារសមាហរណកម្មសេដ្ឋកិច្ច និងសហប្រតិបត្តិហិរញ្ញវត្ថុ និងរូបិយវត្ថុអាស៊ាន និងជាមួយប្រទេសដៃគូ | K5: ៧.របាយការណ៍ស្តីពីការតាមដាន សម្របសម្រួល និងអនុវត្តយន្តការសហប្រតិបត្តិការហិរញ្ញវត្ថុ និងរូបិយវត្ថុអាស៊ាននិងជាមួយប្រទេសដៃគូ, កិច្ចព្រមព្រៀងពាណិជ្ជកម្មសេរីអាស៊ាន និងជាមួយប្រទេសដៃគូ,គណៈកម្មាធិកាជាតិសម្រាប់វិធានការមិនមែនពន្ធ និងនិហិតដ្ឋានជាតិព័ត៌មានពាក់ព័ន្ធនឹងពាណិជ្ជកម្ម ត្រូវបានរៀប ចំរួចរាល់ ។ | L5: ៣.របាយការណ៏ស្តីពីការតាមដាន សម្របសម្រួល និងអនុវត្តយន្តការសមាហរណកម្មសេដ្ឋកិច្ចនិងសហប្រតិបត្តិហិរញ្ញវត្ថុ និងរូបិយវត្ថុអាស៊ាន និងជាមួយប្រទេសដៃគូប្រចាំឆ្នាំ ២០២២ ត្រូវបានរៀបចំ។ | M5: ៣.របាយការណ៏ស្តីពីការតាមដាន សម្របសម្រួល និងអនុវត្តយន្តការសមាហរណកម្មសេដ្ឋកិច្ចនិងសហប្រតិបត្តិហិរញ្ញវត្ថុ និងរូបិយវត្ថុអាស៊ាន និងជាមួយប្រទេសដៃគូ ប្រចាំឆ្នាំ ២០២៣ ត្រូវបានរៀបចំ។ | N5: បន្ថែមពាក្យ ការតានដាន សម្របសម្រួល និងអនុវត្តយន្តការ និងពាក្យរូបិយវត្ថុអាស៊ាន និងជាមួយប្រទេសដៃគូ ដើម្បីរំលេចពីការងាររួមរបស់នាយកដ្ឋាន | O5: ៣.របាយការណ៏ស្តីពីការតាមដាន សម្របសម្រួល និងអនុវត្តយន្តការសមាហរណកម្មសេដ្ឋកិច្ចនិងសហប្រតិបត្តិហិរញ្ញវត្ថុ និងរូបិយវត្ថុអាស៊ាន និងជាមួយប្រទេសដៃគូ ប្រចាំឆ្នាំ ២០២៤ ត្រូវបានរៀបចំ។ | P5: ៣.របាយការណ៏ស្តីពីការតាមដាន សម្របសម្រួល និងអនុវត្តយន្តការសមាហរណកម្មសេដ្ឋកិច្ចនិងសហប្រតិបត្តិហិរញ្ញវត្ថុ និងរូបិយវត្ថុអាស៊ាន និងជាមួយប្រទេសដៃគូ ប្រចាំឆ្នាំ ២០២៥ ត្រូវបានរៀបចំ។ | Q5: =IF(OR(J5>0,K5<>0,L5<>0,M5<>0),"ok","-") -> ok
B6: 4 | C6: 1 | H6: -សូចនាករទី៤ : គោលនយោបាយលើវិស័យសេដ្ឋកិច្ចថ្មី និងលទ្ធផលការងារពាក់ព័ន្ធ | K6: គ្មាន | L6: គ្មាន | M6: ១. របាយការណ៍លទ្ធផលសិក្សាពាក់ព័ន្ធការកំណត់ និងការលើកកម្ពស់ប្រភពកំណើនថ្មី និងការគិតគូរជាយុទ្ធសាស្ត្ររយៈពេលវែង ត្រូវបានរៀបចំ ២. របាយការណ៍លទ្ធផលសិក្សាពាក់ព័ន្ធសេដ្ឋកិច្ចបៃតង និង ការលើកកម្ពស់ការប្រើប្រាស់ថាមពលបៃតង និងប្រសិទ្ធភាពថាមពល ត្រូវបានរៀបចំ ៣. របាយការណ៍លទ្ធផលសិក្សាពាក់ព័ន្ធនឹងសេដ្ឋកិច្ចឌីជីថល និងការជំរុញការអនុវត្ត​បរិវត្តកម្មឌីជីថល ត្រូវបានរៀបចំ ៤. របាយការណ៍ស្តីពីការតាមដានការអនុវត្តគោលនយោបាយនិងយុទ្ធសាស្ត្រពាក់ព័ន្ធ​​នឹងការលើកទឹកចិត្តសារពើពន្ធ និងមិនមែនសារពើពន្ធដើម្បីជំរុញកំណើនសេដ្ឋកិច្ច ត្រូវបានរៀបចំ | O6: ១. របាយការណ៍លទ្ធផលសិក្សាពាក់ព័ន្ធការកំណត់ និងការលើកកម្ពស់ប្រភពកំណើនថ្មី និងការគិតគូរជាយុទ្ធសាស្ត្ររយៈពេលវែង ត្រូវបានរៀបចំ ២. របាយការណ៍លទ្ធផលសិក្សាពាក់ព័ន្ធសេដ្ឋកិច្ចបៃតង និង ការលើកកម្ពស់ការប្រើប្រាស់ថាមពលបៃតង និងប្រសិទ្ធភាពថាមពល ត្រូវបានរៀបចំ ៣. របាយការណ៍លទ្ធផលសិក្សាពាក់ព័ន្ធនឹងសេដ្ឋកិច្ចឌីជីថល និងការជំរុញការអនុវត្ត​បរិវត្តកម្មឌីជីថល ត្រូវបានរៀបចំ ៤. របាយការណ៍ស្តីពីការតាមដានការអនុវត្តគោលនយោបាយនិងយុទ្ធសាស្ត្រពាក់ព័ន្ធ​​នឹងការលើកទឹកចិត្តសារពើពន្ធ និងមិនមែនសារពើពន្ធដើម្បីជំរុញកំណើនសេដ្ឋកិច្ច ត្រូវបានរៀបចំ | P6: ១. របាយការណ៍លទ្ធផលសិក្សាពាក់ព័ន្ធការកំណត់ និងការលើកកម្ពស់ប្រភពកំណើនថ្មី និងការគិតគូរជាយុទ្ធសាស្ត្ររយៈពេលវែង ត្រូវបានរៀបចំ ២. របាយការណ៍លទ្ធផលសិក្សាពាក់ព័ន្ធសេដ្ឋកិច្ចបៃតង និង ការលើកកម្ពស់ការប្រើប្រាស់ថាមពលបៃតង និងប្រសិទ្ធភាពថាមពល ត្រូវបានរៀបចំ ៣. របាយការណ៍លទ្ធផលសិក្សាពាក់ព័ន្ធនឹងសេដ្ឋកិច្ចឌីជីថល និងការជំរុញការអនុវត្ត​បរិវត្តកម្មឌីជីថល ត្រូវបានរៀបចំ ៤.របាយការណ៍ស្តីពីការតាមដានការអនុវត្តគោលនយោបាយនិងយុទ្ធសាស្ត្រពាក់ព័ន្ធ​​នឹងការលើកទឹកចិត្តសារពើពន្ធ និងមិនមែនសារពើពន្ធដើម្បីជំរុញកំណើនសេដ្ឋកិច្ច ត្រូវបានរៀបចំ
B7: 5 | C7: 1 | H7: -សូចនាករទី៥៖ លទ្ធផលការងារពង្រឹងប្រសិទ្ធភាពចំណាយសាធារណៈ និងការងារពាក់ព័ន្ធ | K7: គ្មាន | L7: គ្មាន | M7: ១.ស្តង់ដារថ្លៃទំនិញនិងសេវា សម្រាប់ប្រើប្រាស់ក្នុងចំណាយសាធារណៈ ត្រូវបាន ការរៀបចំ ចងក្រង តាមដាន វិភាគនិងផ្សព្វផ្សាយ ចំនួន ២ គឺ ១. កម្រងទិន្នន័យតាមដានថ្លៃទំនិញ និងសេវា នៅលើទីផ្សាររាជធានីភ្នំពេញប្រចាំត្រីមាស ចំនួន ០៣ ច្បាប់ និង ២. កម្រងទិន្នន័យតាមដានថ្លៃទំនិញនិងសេវាតាមខេត្ត (១២ខេត្ត) ប្រចាំឆមាសទី ១ ឆ្នាំ ២០២៣ ត្រូវបានរៀបចំ។ ២. ​ ក្របខណ្ឌតាមដាន និងវាយតម្លៃគម្រោងវិនិយោគសាធារណៈ ចំនួន ០១ ត្រូវបានរៀបចំ ដើម្បីធានាប្រសិទ្ធភាពចំណាយវិនិយោគ | O7: ១.ស្តង់ដារថ្លៃទំនិញនិងសេវា សម្រាប់ប្រើប្រាស់ក្នុងចំណាយសាធារណៈ ត្រូវបាន ការរៀបចំ ចងក្រង តាមដាន វិភាគនិងផ្សព្វផ្សាយ ចំនួន ២ គឺ ១. កម្រងទិន្នន័យតាមដានថ្លៃទំនិញ និងសេវា នៅលើទីផ្សាររាជធានីភ្នំពេញប្រចាំត្រីមាស ចំនួន ០៤ ច្បាប់ និង ២. កម្រងទិន្នន័យតាមដានថ្លៃទំនិញនិងសេវាតាមខេត្ត (១២ខេត្ត) ប្រចាំឆមាសទី ២ ឆ្នាំ ២០២៣ និងឆមាសទី ១ ឆ្នាំ ២០២៤ ត្រូវបានរៀបចំ។ ២. ​ របាយការណ៍វិភាគ, តាមដាន និងវាយតម្លៃ គម្រោងវិនិយោគសាធារណៈ ប្រចាំឆ្នាំ ២០២៣ ត្រូវបានរៀបចំដោយ ផ្អែកលើប្រសិទ្ធភាពសេដ្ឋកិច្ច | P7: ១.ស្តង់ដារថ្លៃទំនិញនិងសេវា សម្រាប់ប្រើប្រាស់ក្នុងចំណាយសាធារណៈ ត្រូវបាន ការរៀបចំ ចងក្រង តាមដាន វិភាគនិងផ្សព្វផ្សាយ ចំនួន ២ គឺ ១. កម្រងទិន្នន័យតាមដានថ្លៃទំនិញ និងសេវា នៅលើទីផ្សាររាជធានីភ្នំពេញប្រចាំត្រីមាស ចំនួន ០៤ ច្បាប់ និង ២. កម្រងទិន្នន័យតាមដានថ្លៃទំនិញនិងសេវាតាមខេត្ត (១២ខេត្ត) ប្រចាំឆមាសទី ២ ឆ្នាំ ២០២៤ និងឆមាសទី ១ ឆ្នាំ ២០២៥ ត្រូវបានរៀបចំ។ ២. ​ របាយការណ៍វិភាគ, តាមដាន និងវាយតម្លៃ គម្រោងវិនិយោគសាធារណៈ ប្រចាំឆ្នាំ ២០២៤ ត្រូវបានរៀបចំដោយ ផ្អែកលើប្រសិទ្ធភាពសេដ្ឋកិច្ច
D8: 1 | F8: 1010101 | G8: =$G$2&"01" -> 1010101 | H8: =VLOOKUP($G8,'[5]BSP-Table1A'!$B$12:$D$42,3) -> ១.១.១. ចង្កោមសកម្មភាពទី១ : គាំទ្រ សម្របសម្រួល និងគ្រប់គ្រងការងាររដ្ឋបាលរបស់អគ្គនាយកដ្ឋាន | J8: =VLOOKUP($G8,[4]BSP4!$B$12:$F$187,5,FALSE) -> 1341.6 | Q8: =IF(OR(J8>0,K8<>0,L8<>0,M8<>0),"ok","-") -> ok
B9: 1 | D9: 1 | H9: -សូចនាករទី១ : កិច្ចការងារនានារបស់អគ្គនាយកដ្ឋានត្រូវបានពង្រឹង និងសម្របសម្រួលប្រកបដោយប្រសិទ្ធភាព។ | I9: PI-101011 | K9: ១. បានរៀបចំកិច្ចប្រជុំសំខាន់ៗចំនួន៣ លើក រួមមាន៖ (១). កិច្ចប្រជុំត្រួតពិនិត្យ និងតាមដានចំណូលក្នុងបរិការណ៍កូវីដ-១៩, (២). កិច្ចប្រជុំថ្នាក់ដឹកនាំក្រសួងសេដ្ឋកិច្ច និងហិរញ្ញវត្ថុស្តីពីក្រប ខ័ណ្ឌគោលនយោបាយម៉ាក្រូសេដ្ឋ-កិច្ចនិងគោលនយោបាយហិរញ្ញវត្ថុសាធារណៈឆ្នាំ២០២២។ | L9: ១. របាយការណ៍កិច្ចប្រជុំគណៈកម្មាធិការគោលនយោបាយ និងរដ្ឋបាលប្រមូលចំណូល (ចំណូលសារពើពន្ធ និងចំណូលមិនមែនសារពើពន្ធ) នីមួយៗត្រូវបានរៀបចំ | M9: ១. របាយការណ៍កិច្ចប្រជុំគណៈកម្មាធិការគោលនយោបាយ​ និងរដ្ឋបាលប្រមូលចំណូល (ចំណូលសារពើពន្ធ និងចំណូលមិនមែនសារពើពន្ធ) នីមួយៗត្រូវបានរៀបចំ | O9: ១. របាយការណ៍កិច្ចប្រជុំគណៈកម្មាធិការគោលនយោបាយ​ និងរដ្ឋបាលប្រមូលចំណូល (ចំណូលសារពើពន្ធ និងចំណូលមិនមែនសារពើពន្ធ) នីមួយៗត្រូវបានរៀបចំ | P9: ១. របាយការណ៍កិច្ចប្រជុំគណៈកម្មាធិការគោលនយោបាយ​ និងរដ្ឋបាលប្រមូលចំណូល (ចំណូលសារពើពន្ធ និងចំណូលមិនមែនសារពើពន្ធ) នីមួយៗត្រូវបានរៀបចំ | Q9: =IF(OR(J9>0,K9<>0,L9<>0,M9<>0),"ok","-") -> ok
B10: 2 | D10: 1 | H10: -សូចនាករទី២ : កិច្ចប្រជុំផ្សេងៗ ក្នុងនិងក្រៅប្រទេសរបស់ឯកឧត្តមអគ្គនាយក ត្រូវបានសម្របសម្រួល | K10: ២. របាយការណ៍ចូលរួមកិច្ចប្រជុំសេដ្ឋកិច្ច និង ហិរញ្ញវត្ថុសាធារណៈក្នុង និងក្រៅប្រទេសត្រូវបានរៀបចំ។ | L10: ២. របាយការណ៍ចូលរួមកិច្ចប្រជុំសេដ្ឋកិច្ច និង ហិរញ្ញវត្ថុសាធារណៈក្នុង និងក្រៅប្រទេស ត្រូវបានរៀបចំ។ | M10: ២. របាយការណ៍ចូលរួមកិច្ចប្រជុំសេដ្ឋកិច្ច និង ហិរញ្ញវត្ថុសាធារណៈក្នុង និងក្រៅប្រទេសត្រូវបានរៀបចំ។ | O10: ២. របាយការណ៍ចូលរួមកិច្ចប្រជុំសេដ្ឋកិច្ច និង ហិរញ្ញវត្ថុសាធារណៈក្នុង និងក្រៅប្រទេសត្រូវបានរៀបចំ | P10: ២. របាយការណ៍ចូលរួមកិច្ចប្រជុំសេដ្ឋកិច្ច និង ហិរញ្ញវត្ថុសាធារណៈក្នុង និងក្រៅប្រទេសត្រូវបានរៀបចំ | Q10: =IF(OR(J10>0,K10<>0,L10<>0,M10<>0),"ok","-") -> ok
B11: 3 | H11: -សូចនាករទី៣ : ... | Q11: =IF(OR(J11>0,K11<>0,L11<>0,M11<>0),"ok","-") -> -
B12: 4 | H12: -សូចនាករទី៤ : ... | Q12: =IF(OR(J12>0,K12<>0,L12<>0,M12<>0),"ok","-") -> -
B13: 5 | H13: -សូចនាករទី៥ : ... | Q13: =IF(OR(J13>0,K13<>0,L13<>0,M13<>0),"ok","-") -> -
B14: 6 | H14: -សូចនាករទី៦ : ... | Q14: =IF(OR(J14>0,K14<>0,L14<>0,M14<>0),"ok","-") -> -
D15: 2 | F15: 1010102 | G15: =$G$2&"02" -> 1010102 | H15: =VLOOKUP($G15,'[5]BSP-Table1A'!$B$12:$D$42,3) -> ១.១.២. ចង្កោមសកម្មភាពទី២ : រៀបចំ កែលម្អ ត្រួតពិនិត្យ និងវាយតម្លៃគោលនយោបាយម៉ាក្រូសេដ្ឋកិច្ច និងសារពើពន្ធ | J15: =VLOOKUP($G15,[4]BSP4!$B$12:$F$187,5,FALSE) -> 405.6 | Q15: =IF(OR(J15>0,K15<>0,L15<>0,M15<>0),"ok","-") -> ok
B16: 3 | D16: 2 | H16: -សូចនាករទី១ : ការសិក្សាស្រាវជ្រាវ ទៅលើឥរិយាបថ និន្នាការ កាលានុវត្តភាព និង​ទស្សនវិស័យពាក់ព័ន្ធវិស័យសំខាន់ៗដូចជាសេដ្ឋកិច្ច ហិរញ្ញវត្ថុ និងសង្គមត្រូវបានពង្រឹង | K16: ១.ការសិក្សាស្រាវជ្រាវលើប្រធានបទ ០៣ ត្រូវបានបញ្ចប់រួមមាន៖ (១).ការ ជំរុញវិស័យកែច្នៃផលិតផលកសិកម្មនៅកម្ពុជា, (២). ការសិក្សាស្រាវជ្រាវស្តីពីការត្រួតពិនិត្យហានិភ័យលើវិស័យអចលនទ្រព្យនៅកម្ពុជា និង (៣).ក្របខណ្ឌវិធានការក្របខណ្ឌជំរុញវិស័យកសិកម្ម និងកសិ-ឧស្សាហកម្មនៅកម្ពុជា ២០២១-២០២៣ ខណៈឯកសារពាក់ព័ន្ធ ដើម្បីចុះប្រមូលទិន្នន័យសំខាន់ៗសម្រាប់ការសិក្សាស្រាវជ្រាវស្តីពី ការលើកកម្ពស់ដំណើរការផ្សារភ្ជាប់រវាងកសិផលកែច្នៃ និងវិស័យទេសចរណ៍នៅកម្ពុជា ត្រូវបានរៀបចំរួចរាល់។ | L16: ឯកសារស្រាវជ្រាវឬរបាយការណ៍សិក្ខាសាលាស្តីពីកិច្ចពិភាក្សាលើប្រធានបទទាក់ទងវិស័យសេដ្ឋកិច្ច និងហិរញ្ញវត្ថុចំនួន ៦ ត្រូវបានរៀបចំ៖ (១) ការត្រួតពិនិត្យហានិភ័យលើវិស័យអចលនទ្រព្យនៅកម្ពុជា, (២) ការលើកកម្ពស់ដំណើរការផ្សារភ្ជាប់រវាងកសិផលកែច្នៃ និងវិស័យទេសចរណ៍នៅកម្ពុជា (៣) ក្របខ័ណ្ឌជំរុញវិស័យកសិកម្ម និងកសិឧស្សាហកម្មកម្ពុជា ២០២១-២០២២ (៤) ការសិក្សាលម្អិតពីខ្សែច្រវាក់ផ្គត់ផ្គង់ត្រី:វិធានការរយៈពេលមធ្យម (៥) ការសិក្សាលម្អិតពីខ្សែច្រវាក់ផ្គត់ផ្គង់សាច់ជ្រូក:វិធានការរយៈពេលមធ្យម (៦) ការរៀបចំយន្តការពិនិត្យ តាមដាន និងវាយតម្លៃ: ការអនុវត្តគម្រោងសហហិរញ្ញប្បទានទ្រទ្រង់សហគ្រាសធុនតូច និងមធ្យមនៅកម្ពុជា (ដំណាក់កាលទី ២) និងការផ្តល់ហិរញ្ញប្បទានរបស់ធនាគារសហគ្រាសធុនតូច និងមធ្យមកម្ពុជា | M16: ឯកសារស្រាវជ្រាវឬរបាយការណ៍សិក្ខាសាលាស្តីពីកិច្ចពិភាក្សាលើប្រធានបទទាក់ទងវិស័យសេដ្ឋកិច្ច និងហិរញ្ញវត្ថុចំនួន ៣ ត្រូវបានរៀបចំ | N16: ការកំណត់ប្រធានបទអាទិភាពថ្មី | O16: ឯកសារស្រាវជ្រាវឬរបាយការណ៍សិក្ខាសាលាស្តីពីកិច្ចពិភាក្សាលើប្រធានបទទាក់ទងវិស័យសេដ្ឋកិច្ច និងហិរញ្ញវត្ថុចំនួន ៣ ត្រូវបានរៀបចំ | P16: ឯកសារស្រាវជ្រាវឬរបាយការណ៍សិក្ខាសាលាស្តីពីកិច្ចពិភាក្សាលើប្រធានបទទាក់ទងវិស័យសេដ្ឋកិច្ច និងហិរញ្ញវត្ថុចំនួន ៣ ត្រូវបានរៀបចំ | Q16: =IF(OR(J16>0,K16<>0,L16<>0,M16<>0),"ok","-") -> ok
B17: 4 | D17: 2 | H17: -សូចនាករទី២ : វឌ្ឍនភាពស្តីពីការតាមដាន ពិនិត្យ វាយតម្លៃការអនុវត្តគោលនយោបាយសារពើពន្ធ អនុលោមតាមគោលដៅយុទ្ធសាស្រ្តជាតិ | K17: ១. របាយការណ៍ត្រួតពិនិត្យ និងវាយតម្លៃវឌ្ឍនភាពគោលនយោបាយសារពើពន្ធ ប្រចាំឆ្នាំ ២០២១ ត្រូវបានរៀបចំ ។ ២.ក្របខ័ណ្ឌគោលនយោបាយហិរញ្ញវត្ថុសាធារណៈ សម្រាប់ការរៀបចំសេចក្តីព្រាងច្បាប់ស្តីពីហិរញ្ញវត្ថុសម្រាប់ការគ្រប់គ្រងឆ្នាំ ២០២២ ត្រូវបានរៀបចំ ។ ៣. របាយការណ៍ពិនិត្យ និងវាយតម្លៃ ការអនុវត្តយុទ្ធសាស្ត្រកៀរគរចំណូល ២០១៩-២០២៣ ផ្នែកចំណូលមិនមែនសារពើពន្ធ ប្រចាំឆ្នាំ ត្រូវបានរៀបចំ ។ | L17: ១. របាយការណ៍ពិនិត្យតាមដានការអនុវត្តនយោបាយសារពើពន្ធប្រកបដោយប្រសិទ្ធភាព និងស័ក្តិសិទ្ធិភាពត្រូវបានរៀបចំ ២. ក្របខ័ណ្ឌហិរញ្ញវត្ថុសារធារណៈរយៈពេលមធ្យម ២០២៣-២០២៥ប្រកបដោយប្រសិទ្ធភាព និងស័ក្តិសិទ្ធិភាពត្រូវបានរៀបចំ ៣. របាយការណ៍ពិនិត្យ និងវាយតម្លៃ ការអនុវត្តយុទ្ធសាស្ត្រកៀរគរចំណូល ២០១៩-២០២៣ ផ្នែកចំណូលមិនមែនសារពើពន្ធ ត្រូវបានរៀប។ | M17: ១. ក្របខណ្ឌហិរញ្ញវត្ថុសារធារណៈរយៈពេលមធ្យម ២០២៤-២០២៦ ដែលមានការវាយតម្លៃពីហានិភ័យហិរញ្ញវត្ថុសាធារណៈ ត្រូវបានរៀបចំ, ២. របាយការណ៍វិភាគ និងវាយតម្លៃការអនុវត្តហិរញ្ញវត្ថុសាធារណៈពាក់កណ្ដាលឆ្នាំ ត្រូវបានរៀបចំ, ៣. របាយការណ៍តាមកម្រិតលម្អៀងការព្យាករចំណូលឆ្នាំ ២០២២ ត្រូវបានរៀបចំ, ៤. របាយការណ៍វាយតម្លៃការអនុវត្តចំណាយសាធារណៈតាមវិស័យទាំង ៤ ឆ្នាំ ២០២២ ត្រូវបានរៀបចំ ។ | O17: ១. ក្របខណ្ឌហិរញ្ញវត្ថុសារធារណៈរយៈពេលមធ្យម ដែលមានការវាយតម្លៃពីហានិភ័យហិរញ្ញវត្ថុសាធារណៈ ត្រូវបានរៀបចំ, ២. របាយការណ៍វិភាគ និងវាយតម្លៃការអនុវត្តហិរញ្ញវត្ថុសាធារណៈពាក់កណ្ដាលឆ្នាំ ត្រូវបានរៀបចំ, ៣. របាយការណ៍តាមកម្រិតលម្អៀងការព្យាករចំណូលឆ្នាំ (N-1) ត្រូវបានរៀបចំ, ៤. របាយការណ៍វាយតម្លៃការអនុវត្តចំណាយសាធារណៈតាមវិស័យទាំង ៤ ឆ្នាំ (N-1) ត្រូវបានរៀបចំ ។ | P17: ១. ក្របខណ្ឌហិរញ្ញវត្ថុសារធារណៈរយៈពេលមធ្យម ដែលមានការវាយតម្លៃពីហានិភ័យហិរញ្ញវត្ថុសាធារណៈ ត្រូវបានរៀបចំ, ២. របាយការណ៍វិភាគ និងវាយតម្លៃការអនុវត្តហិរញ្ញវត្ថុសាធារណៈពាក់កណ្ដាលឆ្នាំ ត្រូវបានរៀបចំ, ៣. របាយការណ៍តាមកម្រិតលម្អៀងការព្យាករចំណូលឆ្នាំ (N-1) ត្រូវបានរៀបចំ, ៤. របាយការណ៍វាយតម្លៃការអនុវត្តចំណាយសាធារណៈតាមវិស័យទាំង ៤ ឆ្នាំ (N-1) ត្រូវបានរៀបចំ ។ | Q17: =IF(OR(J17>0,K17<>0,L17<>0,M17<>0),"ok","-") -> ok
B18: 5 | D18: 2 | H18: -សូចនាករទី៣ : ការអនុវត្តយុទ្ធសាស្ត្រ និងគោលនយោបាយពាក់ព័ន្ធនឹងវិស័យសេដ្ឋកិច្ច-សង្គម ត្រូវបាន​ពិនិត្យ និងវាយតម្លៃឱ្យ អនុលោមតាមគោលដៅ​នៃយុទ្ធសាស្ត្រ និងគោលនយោបាយ | K18: ១. យុទ្ធសាស្រ្តកៀរគរចំណូល២០១៩-២០២៣ ត្រូវបានរៀបចំរួចរាល់ និងដាក់ឱ្យអនុវត្ត, ២. របាយការណ៍ត្រួតពិនិត្យការអនុវត្តយុទ្ធសាស្រ្តកៀរគរចំណូល ២០១៩-២០២៣ ប្រចាំឆ្នាំ ២០២០ និងប្រចាំឆមាសទី១ ឆ្នាំ២០២១ ត្រូវបានរៀបចំ, ៣. សេចក្ដីព្រាងគោលនយោបាយស្តីពីការលើកទឹកចិត្តពន្ធលើការដំឡើងទោចក្រយាន និងត្រីចក្រយានត្រូវបានរៀបចំ ៤. របាយការណ៍វឌ្ឍនភាពនៃការអនុវត្តគម្រោងមូលនិធិអភិវឌ្ឍជំនាញ ប្រចាំឆ្នាំ២០២១ ត្រូវបានរៀបចំ | L18: ១. របាយការណ៍ពិនិត្យប្រចាំឆ្នាំ និងពាក់កណ្ដាលអាណត្តិ នៃការអនុវត្តយុទ្ធសាស្រ្តកៀរគរចំណូល ២០១៩-២០២៣ ត្រូវបានរៀបចំ ២. ការសិក្សា​ និងរៀបចំរបបលើកទឹកពន្ធសម្រាប់វិស័យអាទិភាព ត្រូវបានរៀបចំ ៣. របាយការណ៍វឌ្ឍនភាពនៃការអនុវត្តគម្រោងមូលនិធិអភិវឌ្ឍជំនាញ ត្រូវបានរៀបចំ | M18: ១. របាយការណ៍ពិនិត្យប្រចាំឆ្នាំ ២០២២ និងពាក់កណ្តាលឆ្នាំ ២០២៣ នៃការអនុវត្តយុទ្ធសាស្រ្តកៀរគរចំណូល ២០១៩-២០២៣ ត្រូវបានរៀបចំ ២. ការសិក្សា​ និងរៀបចំរបបលើកទឹកពន្ធសម្រាប់វិស័យអាទិភាព ត្រូវបានរៀបចំ | O18: ១. របាយការណ៍ពិនិត្យប្រចាំឆ្នាំ និងបញ្ចប់អាណត្តិ នៃការអនុវត្តយុទ្ធសាស្រ្តកៀរគរចំណូល ២០១៩-២០២៣ ត្រូវបានរៀបចំ ២. ការសិក្សា​ និងរៀបចំរបបលើកទឹកពន្ធសម្រាប់វិស័យអាទិភាព ត្រូវបានរៀបចំ | P18: ១. របាយការណ៍ការអនុវត្តចំណូលសារពើពន្ធ និងចំណូលមិនមែនសារពើពន្ធ ២. ការសិក្សា​ និងរៀបចំរបបលើកទឹកពន្ធសម្រាប់វិស័យអាទិភាព ត្រូវបានរៀបចំ | Q18: =IF(OR(J18>0,K18<>0,L18<>0,M18<>0),"ok","-") -> ok
B19: 6 | D19: 2 | H19: -សូចនាករទី៤ : ស្ថានភាពសេដ្ឋកិច្ចត្រូវបានពិនិត្យ,តាមដាន និង វាយតម្លៃ, និងក្របខ័ណ្ឌម៉ាក្រូសេដ្ឋកិច្ចរយៈពេលមធ្យមត្រូវបានរៀបចំ | K19: ១. របាយការណ៍ពិនិត្យតាមដាន និងវាយតម្លៃសេដ្ឋកិច្ចប្រចាំឆ្នាំ២០២០ និងពាក់កណ្តាលឆ្នាំ២០២១​ ត្រូវបានរៀបចំ ២. របាយការណ៍ និងលទ្ធផលនៃការព្យាករ និងក្របខ័ណ្ឌគោលនយោបាយម៉ាក្រូសេដ្ឋកិច្ចឆ្នាំ២០២២ និងរយៈពេលមធ្យម ត្រូវបានរៀបចំ ៣. របាយកាណ៍ពិគ្រោះយោបល់ជាមួយអ្នកអនុវត្តផ្ទាល់ និងភាគីពាក់ព័ន្ឋសម្រាប់ធ្វើការវាយតម្លៃ និងព្យាករសេដ្ឋកិច្ច ត្រូវបានរៀបចំ | L19: ១. ក្របខ័ណ្ឌគោលនយោបាយម៉ាក្រូសេដ្ឋកិច្ចដើម្បីដាក់បញ្ចូលក្នុងការ ក្របខ័ណ្ឌហិរញ្ញវត្ថុសាធារណៈរយៈពេលមធ្យម ឆ្នាំ ២០២៣-២០២៥ ត្រូវបានរៀបចំ ២.របាយការណ៍ពិនិត្យតាមដាន និងវាយតម្លៃសេដ្ឋកិច្ចប្រចាំឆ្នាំ ២០២១ និងពាក់កណ្តាលឆ្នាំ ២០២២ ត្រូវបានរៀបចំ ៣. របាយការណ៍ឃ្លាំមើលសេដ្ឋកិច្ចប្រចាំត្រីមាសត្រូវបានរៀបចំ ៤. របាយកាណ៍ពិគ្រោះយោបល់ជាមួយអ្នកអនុវត្តផ្ទាល់ និងភាគីពាក់ព័ន្ឋសម្រាប់ធ្វើការវាយតម្លៃ និងព្យាករសេដ្ឋកិច្ច ត្រូវបានរៀបចំ ៥. របាយការណ៍តាមដានសេដ្ឋកិច្ចប្រចាំខែត្រូវបានរៀបចំ | M19: ១. ក្របខ័ណ្ឌគោលនយោបាយម៉ាក្រូសេដ្ឋកិច្ចដើម្បីដាក់បញ្ចូលក្នុង ក្របខ័ណ្ឌហិរញ្ញវត្ថុសាធារណៈរយៈពេលមធ្យម ឆ្នាំ ២០២៤-២០២៦ ត្រូវបានរៀបចំ ២.របាយការណ៍ពិនិត្យតាមដាន និងវាយតម្លៃសេដ្ឋកិច្ចប្រចាំឆ្នាំ ២០២២ និងពាក់កណ្តាលឆ្នាំ ២០២៣ ត្រូវបានរៀបចំ ៣. របាយការណ៍ឃ្លាំមើលសេដ្ឋកិច្ចប្រចាំត្រីមាសត្រូវបានរៀបចំ ៤. របាយកាណ៍ពិគ្រោះយោបល់ជាមួយអ្នកអនុវត្តផ្ទាល់ និងភាគីពាក់ព័ទ្ធសម្រាប់ធ្វើការវាយតម្លៃ និងព្យាករសេដ្ឋកិច្ច ត្រូវបានរៀបចំ ៥. របាយការណ៍តាមដានសេដ្ឋកិច្ចប្រចាំខែត្រូវបានរៀបចំ | O19: ១. ក្របខ័ណ្ឌគោលនយោបាយម៉ាក្រូសេដ្ឋកិច្ចដើម្បីដាក់បញ្ចូលក្នុង ក្របខ័ណ្ឌហិរញ្ញវត្ថុសាធារណៈរយៈពេលមធ្យម ឆ្នាំ ២០២៥-២០២៧ ត្រូវបានរៀបចំ ២.របាយការណ៍ពិនិត្យតាមដាន និងវាយតម្លៃសេដ្ឋកិច្ចប្រចាំឆ្នាំ ២០២៣ និងពាក់កណ្តាលឆ្នាំ ២០២៤ ត្រូវបានរៀបចំ ៣. របាយការណ៍ឃ្លាំមើលសេដ្ឋកិច្ចប្រចាំត្រីមាសត្រូវបានរៀបចំ ៤. របាយការណ៍តាមដានសេដ្ឋកិច្ចប្រចាំខែត្រូវបានរៀបចំ | P19: ១. ក្របខ័ណ្ឌគោលនយោបាយម៉ាក្រូសេដ្ឋកិច្ចដើម្បីដាក់បញ្ចូលក្នុង ក្របខ័ណ្ឌហិរញ្ញវត្ថុសាធារណៈរយៈពេលមធ្យម ឆ្នាំ ២០២៦-២០២៨ ត្រូវបានរៀបចំ ២.របាយការណ៍ពិនិត្យតាមដាន និងវាយតម្លៃសេដ្ឋកិច្ចប្រចាំឆ្នាំ ២០២៤ និងពាក់កណ្តាលឆ្នាំ ២០២៥ ត្រូវបានរៀបចំ ៣. របាយការណ៍ឃ្លាំមើលសេដ្ឋកិច្ចប្រចាំត្រីមាសត្រូវបានរៀបចំ ៤. របាយការណ៍តាមដានសេដ្ឋកិច្ចប្រចាំខែត្រូវបានរៀបចំ | Q19: =IF(OR(J19>0,K19<>0,L19<>0,M19<>0),"ok","-") -> ok
B20: 7 | D20: 2 | H20: -សូចនាករទី៥ : គោលនយោបាយហិរញ្ញវត្ថុសាធារណៈត្រូវបានរៀបចំឡើងប្រកបដោយសង្គតិភាពនិងផ្សារភ្ជាប់ទៅនឹងគោលនយោបាយអាទិភាពរបស់រាជរដ្ឋាភិបាល។ | K20: ១. របាយការណ៍ត្រួតពិនិត្យ និងវាយតម្លៃ ការអនុវត្តយុទ្ធសាស្រ្តកៀរគរចំណូល ២០១៩ -២០២៣ ឆ្នាំ ២០២០ និង ពាកើកណ្តាលឆ្នាំ ២០២១ ផ្នែក អ.គ.រ និង គោលនយោបាយសារពើពន្ធ ត្រូវបានរៀបចំ ២. របាយការណ៍តាមដាន និងវាយតម្លៃសកម្មភាពដែលបានកំណត់ក្នុងកម្មវិធីកែទម្រង់ការគ្រប់គ្រងហិរញ្ញវត្ថុសាធារណៈរបស់នាយកដ្ឋានគោលនយោបាយម៉ាក្រូសេដ្ឋកិច្ច និងសារពើពន្ធ ៣. ការសិក្សាលើធាតុចូលសម្រាប់ការវាយតម្លៃការផ្សារភ្ជាប់ថវិកាទៅនឹងគោលនយោបាយអាទិភាពរបស់រាជរដ្ឋាភិបាល សម្រាប់វិស័យអប់រំ និងសុខាភិបាល ត្រូវបានរៀបចំ ៤. សេចក្តីព្រាងគោលនយោបាយសារពើពន្ធជំរុញការប្រើប្រាស់រថយន្តភាគបរិស្ថាន ២០២១-២០៣០ ត្រូវបានរៀបចំ បន្ទាប់ពីទទួលបានមតិយោបល់អគ្គនាយកដ្ឋានពាក់ព័ន្ធ ៥. របាយការណ៍វឌ្ឍនភាព ស្តីពីការអនុវត្តការរៀបចំផែនការមេ​ ដើម្បីប្រែក្លាយខេត្តព្រះសីហនុទៅជាតំបន់សេដ្ឋកិច្ចពិសេសគំរូពហុបំណង ៦. របាយការណ៍វឌ្ឍនភាពនៃការអនុវត្តគម្រោងមូលនិធិសហគ្រិនភាព (EDF) ប្រចាំឆ្នាំ ២០២០ ត្រូវបានរៀបចំ | L20: ១. របាយការណ៍ត្រួតពិនិត្យ និងវាយតម្លៃ ការអនុវត្តយុទ្ធសាស្រ្តកៀរគរចំណូល ២០១៩ -២០២៣ ពាក់កណ្ដាលអាណត្តិ ផ្នែក អ.គ.រ ត្រូវបានរៀបចំ ២. របាយការណ៍តាមដាន និងវាយតម្លៃសកម្មភាពដែលបានកំណត់ក្នុងកម្មវិធីកែទម្រង់ការគ្រប់គ្រងហិរញ្ញវត្ថុសាធារណៈរបស់នាយកដ្ឋានគោលនយោបាយម៉ាក្រូសេដ្ឋកិច្ច និងសារពើពន្ធ ៣. ការសិក្សាលើធាតុចូលសម្រាប់ការវាយតម្លៃការផ្សារភ្ជាប់ថវិកា ទៅនឹងគោលនយោបាយអាទិភាពរបស់រាជរដ្ឋាភិបាល ត្រូវបានរៀបចំ ៤. របាយការណ៍សិក្សាស្រាវជ្រាវ​ ស្តីពីការរៀបចំ​ និងការអនុវត្តគោលនយោបាយ​សារពើពន្ធសំខាន់ ត្រូវបានរៀបចំ ៥. របាយការណ៍វឌ្ឍនភាព ស្តីពីការអនុវត្តការរៀបចំផែនការមេ​ ដើម្បីប្រែក្លាយខេត្តព្រះសីហនុទៅជាតំបន់សេដ្ឋកិច្ចពិសេសគំរូពហុបំណង ៦. របាយការណ៍វឌ្ឍនភាពនៃការអនុវត្តគម្រោងមូលនិធិសហគ្រិនភាព (EDF) ប្រចាំឆ្នាំ ២០២១ ត្រូវបានរៀបចំ | M20: ១. របាយការណ៍តាមដាន និងវាយតម្លៃសកម្មភាពដែលបានកំណត់ក្នុងកម្មវិធីកែទម្រង់ការគ្រប់គ្រងហិរញ្ញវត្ថុសាធារណៈរបស់នាយកដ្ឋានគោលនយោបាយម៉ាក្រូសេដ្ឋកិច្ច និងសារពើពន្ធ ២. ការសិក្សាលើធាតុចូលសម្រាប់ការវាយតម្លៃការផ្សារភ្ជាប់ថវិកា ទៅនឹងគោលនយោបាយអាទិភាពរបស់រាជរដ្ឋាភិបាល ត្រូវបានរៀបចំ ៣. របាយការណ៍សិក្សាស្រាវជ្រាវ​ ស្តីពីការរៀបចំ​ និងការអនុវត្តគោលនយោបាយ​សារពើពន្ធសំខាន់ ត្រូវបានរៀបចំ ៤. របាយការណ៍វឌ្ឍនភាព ស្តីពីការអនុវត្តការរៀបចំផែនការមេ​ ដើម្បីប្រែក្លាយខេត្តព្រះសីហនុទៅជាតំបន់សេដ្ឋកិច្ចពិសេសគំរូពហុបំណង | O20: ១. របាយការណ៍តាមដាន និងវាយតម្លៃសកម្មភាពដែលបានកំណត់ក្នុងកម្មវិធីកែទម្រង់ការគ្រប់គ្រងហិរញ្ញវត្ថុសាធារណៈរបស់នាយកដ្ឋានគោលនយោបាយម៉ាក្រូសេដ្ឋកិច្ច និងសារពើពន្ធ ២. ការសិក្សាលើធាតុចូលសម្រាប់ការវាយតម្លៃការផ្សារភ្ជាប់ថវិកា ទៅនឹងគោលនយោបាយអាទិភាពរបស់រាជរដ្ឋាភិបាល ត្រូវបានរៀបចំ ៣. របាយការណ៍សិក្សាស្រាវជ្រាវ​ ស្តីពីការរៀបចំ​ និងការអនុវត្តគោលនយោបាយ​សារពើពន្ធសំខាន់ ត្រូវបានរៀបចំ | P20: ១. របាយការណ៍តាមដាន និងវាយតម្លៃសកម្មភាពដែលបានកំណត់ក្នុងកម្មវិធីកែទម្រង់ការគ្រប់គ្រងហិរញ្ញវត្ថុសាធារណៈរបស់នាយកដ្ឋានគោលនយោបាយម៉ាក្រូសេដ្ឋកិច្ច និងសារពើពន្ធ ២. ការសិក្សាលើធាតុចូលសម្រាប់ការវាយតម្លៃការផ្សារភ្ជាប់ថវិកា ទៅនឹងគោលនយោបាយអាទិភាពរបស់រាជរដ្ឋាភិបាល ត្រូវបានរៀបចំ ៣. របាយការណ៍សិក្សាស្រាវជ្រាវ​ ស្តីពីការរៀបចំ​ និងការអនុវត្តគោលនយោបាយ​សារពើពន្ធសំខាន់ ត្រូវបានរៀបចំ
B21: 8 | D21: 2 | H21: -សកម្មភាពទី៦ : ពង្រឹងសេវាគាំទ្រកិច្ចប្រតិបត្តិការ និងការងារសម្របសម្រួលសម្រាប់នាយកដ្ឋានគោលនយោបាយ ម៉ាក្រូសេដ្ឋកិច្ច និងសារពើពន្ធ | K21: សេវាគាំទ្រកិច្ចប្រតិបត្តិការ និងការងារ សម្របសម្រួល សម្រាប់នាយកដ្ឋានគោលនយោបាយម៉ាក្រូសេដ្ឋកិច្ច និងសារពើពន្ធត្រូវបានពង្រឹង | L21: ១.រៀបចំរបាយការណ៍លទ្ធផលការងាររបស់នាយកដ្ឋាន ២.រៀបចំផែនការសកម្មភាព និងថវិកា រួមជាមួយរបាយការណ៍វឌ្ឍភាពការអនុវត្តថវិកាកម្មវិធី ៣.រៀបចំ និងសម្របសម្រួលកិច្ចប្រជុំ និងសិក្ខាសាលាពាក់ព័ន្ធរបស់នាយកដ្ឋាន | M21: ១.រៀបចំសេវាគាំទ្រកិច្ចប្រតិបត្តិការ និងការងារ សម្របសម្រួល សម្រាប់នាយកដ្ឋានគោល នយោបាយម៉ាក្រូសេដ្ឋកិច្ច និងសារពើពន្ធ ២.របាយការលទ្ធផលការងាររបស់នាយកដ្ឋានត្រូវរៀបចំ ប្រកបដោយតម្លាភាព និងគណនេយ្យភាព ៣.ផែនការសកម្មភាព និងថវិកាដើម្បីគាំទ្រ និងធានានូវប្រសិទ្ធភាពនៃប្រតិបត្តិការ រួមជាមួយ របាយការណ៍វឌ្ឍភាពការអនុវត្តថវិកាកម្មវិធីនឹងត្រូវរៀបចំ | N21: រៀបចំសកម្មភាពលម្អិតជាងមុន | O21: ១.រៀបចំរបាយការណ៍ហិរញ្ញវត្ថុ និងរបាយការណ៍សមិទ្ធកម្ម នៃការអនុវត្តថវិកាកម្មវិធី ២.រៀបចំរបាយការណ៍ពាក់ព័ន្ធ និងកិច្ចបញ្ជិការគណនេយ្យប្រចាំខែ ប្រចាំឆមាស និងប្រចាំឆ្នាំ ៣.រៀបចំផែនការគ្រោងចំណូល-ចំណាយថវិកាប្រចាំត្រីមាស ៤.បូកសរុបផែនការយុទ្ធសាស្ត្រថវិកា BSP និង ផែនការថវិកា ៥.. រៀបចំទូទាត់ប្រាក់បៀវត្សប្រចាំខែជូនមន្រ្តីរាជការថ្នាក់ដឹកនាំនិងមន្រ្តីជាប់កិច្ចសន្យាដែលបម្រើការងារនៅអគ្គនាយកដ្ឋានគោលនយោបាយ ៦. កិច្ចការរដ្ឋបាលផ្សេងៗរបស់នាយកដ្ឋានត្រូវសម្របសម្រួលប្រកបដោយគុណភាព និងទាន់ពេលវេលា ។ | P21: ១.រៀបចំរបាយការណ៍ហិរញ្ញវត្ថុ និងរបាយការណ៍សមិទ្ធកម្ម នៃការអនុវត្តថវិកាកម្មវិធី ២.រៀបចំរបាយការណ៍ពាក់ព័ន្ធ និងកិច្ចបញ្ជិការគណនេយ្យប្រចាំខែ ប្រចាំឆមាស និងប្រចាំឆ្នាំ ៣.រៀបចំផែនការគ្រោងចំណូល-ចំណាយថវិកាប្រចាំត្រីមាស ៤.បូកសរុបផែនការយុទ្ធសាស្ត្រថវិកា BSP និង ផែនការថវិកា ៥.. រៀបចំទូទាត់ប្រាក់បៀវត្សប្រចាំខែជូនមន្រ្តីរាជការថ្នាក់ដឹកនាំនិងមន្រ្តីជាប់កិច្ចសន្យាដែលបម្រើការងារនៅអគ្គនាយកដ្ឋានគោលនយោបាយ ៦. កិច្ចការរដ្ឋបាលផ្សេងៗរបស់នាយកដ្ឋានត្រូវសម្របសម្រួលប្រកបដោយគុណភាព និងទាន់ពេលវេលា ។ | Q21: =IF(OR(J21>0,K21<>0,L21<>0,M21<>0),"ok","-") -> ok
D22: 3 | F22: 1010103 | G22: =$G$2&"03" -> 1010103 | H22: =VLOOKUP($G22,[4]BSP1!$B$12:$D$207,3) -> ១.១.៣. ចង្កោមសកម្មភាពទី៣ : លើកកម្ពស់ការងារស្ថិតិសេដ្ឋកិច្ចនិងហិរញ្ញវត្ថុសាធារណៈ | J22: =VLOOKUP($G22,[4]BSP4!$B$12:$F$187,5,FALSE) -> 492.2 | Q22: =IF(OR(J22>0,K22<>0,L22<>0,M22<>0),"ok","-") -> ok
B23: 9 | D23: 3 | H23: សូចនាករទី១៖ ការរៀបចំចងក្រងស្ថិតិ និងការតាមដានស្ថិតិត្រូវបានពង្រឹង | K23: ១.របាយការណ៍តាមដាននិន្នាការសេដ្ឋកិច្ច និងហិរញ្ញវត្ថុសាធារណៈនិងកម្រងស្ថិតិចំនួន៦៧ ត្រូវបានរៀបចំនិងពង្រីកវិសាលភាព | L23: ១. របាយការណ៍តាមដាននិន្នាការហិរញ្ញវត្ថុសាធារណៈ (រយៈពេលខ្លី)​ ចំនួន ២៨ ក្នុង១ឆ្នាំ​ ត្រូវបានរៀបចំ | M23: ១. របាយការណ៍និងកម្រងស្ថិតិតាមដាននិន្នាការហិរញ្ញវត្ថុសាធារណៈ (រយៈពេលខ្លី)​ ចំនួន ២៨ ក្នុង១ឆ្នាំ​ ត្រូវបានរៀបចំ | O23: ១. របាយការណ៍និងកម្រងស្ថិតិតាមដាននិន្នាការហិរញ្ញវត្ថុសាធារណៈ (រយៈពេលខ្លី)​ ចំនួន ២៨ ក្នុង១ឆ្នាំ​ ត្រូវបានរៀបចំ | P23: ១. របាយការណ៍និងកម្រងស្ថិតិតាមដាននិន្នាការហិរញ្ញវត្ថុសាធារណៈ (រយៈពេលខ្លី)​ ចំនួន ២៨ ក្នុង១ឆ្នាំ​ ត្រូវបានរៀបចំ | Q23: =IF(OR(J23>0,K23<>0,L23<>0,M23<>0),"ok","-") -> ok
B24: 10 | D24: 3 | H24: សូចនាករទី២៖ ការរៀបចំចងក្រងស្ថិតិ និងការតាមដានស្ថិតិត្រូវបានពង្រឹង | K24: ២.កម្រង/តារាងស្ថិតិតាមដាននិន្នាការថ្លៃទំនិញក្នុងស្រុកនិងអន្តរជាតិ ចំនួន៤ ត្រូវបានរៀបចំ | L24: ២. របាយការណ៍​និងកម្រងស្ថិតិតាមដាននិន្នាការសេដ្ឋកិច្ចនិងពាណិជ្ជកម្ម (រយៈពេលខ្លី) ចំនួន ៣៩ ត្រូវបានរៀបចំ | M24: ២. របាយការណ៍​និងកម្រងស្ថិតិតាមដាននិន្នាការសេដ្ឋកិច្ចនិងពាណិជ្ជកម្ម (រយៈពេលខ្លី) ចំនួន ៣៩ ត្រូវបានរៀបចំ | O24: ២. របាយការណ៍​និងកម្រងស្ថិតិតាមដាននិន្នាការសេដ្ឋកិច្ចនិងពាណិជ្ជកម្ម (រយៈពេលខ្លី) ចំនួន ៣៩ ត្រូវបានរៀបចំ | P24: ២. របាយការណ៍​និងកម្រងស្ថិតិតាមដាននិន្នាការសេដ្ឋកិច្ចនិងពាណិជ្ជកម្ម (រយៈពេលខ្លី) ចំនួន ៣៩ ត្រូវបានរៀបចំ | Q24: =IF(OR(J24>0,K24<>0,L24<>0,M24<>0),"ok","-") -> ok
B25: 11 | D25: 3 | H25: សូចនាករទី៣៖ ការរៀបចំចងក្រងស្ថិតិ និងការតាមដានស្ថិតិត្រូវបានពង្រឹង | L25: ៣. របាយការណ៍តាមដាននិន្នាការថ្លៃទំនិញ និងសេវាក្នុងស្រុក​ចំនួន៦ ( ប្រចាំត្រីមាស និងឆមាស) និងរបាយការណ៍អង្កេតថ្លៃសំបុត្រយន្តហោះ ចំនួន ៤ ត្រូវបានរៀបចំ | M25: ៣. របាយការណ៍តាមដាននិន្នាការថ្លៃទំនិញ និងសេវាក្នុងស្រុក​ចំនួន៦ ( ប្រចាំត្រីមាស និងឆមាស) និងរបាយការណ៍អង្កេតថ្លៃសំបុត្រយន្តហោះ ចំនួន ៤ ត្រូវបានរៀបចំ | O25: ៣. របាយការណ៍តាមដាននិន្នាការថ្លៃទំនិញ និងសេវាក្នុងស្រុក​ចំនួន៦ ( ប្រចាំត្រីមាស និងឆមាស) និងរបាយការណ៍អង្កេតថ្លៃសំបុត្រយន្តហោះ ចំនួន ៤ ត្រូវបានរៀបចំ | P25: ៣. របាយការណ៍តាមដាននិន្នាការថ្លៃទំនិញ និងសេវាក្នុងស្រុក​ចំនួន៦ ( ប្រចាំត្រីមាស និងឆមាស) និងរបាយការណ៍អង្កេតថ្លៃសំបុត្រយន្តហោះ ចំនួន ៤ ត្រូវបានរៀបចំ | Q25: =IF(OR(J25>0,K25<>0,L25<>0,M25<>0),"ok","-") -> ok
B26: 12 | D26: 3 | H26: សូចនាករទី៤៖ ការរៀបចំចងក្រងស្ថិតិ និងការតាមដានស្ថិតិត្រូវបានពង្រឹង | L26: ៤.ផលិតផលទិន្នន័យស្ថិតិសេដ្ឋកិច្ច,ហិរញ្ញវត្ថុ និងថ្លៃទំនិញ (តារាង/កម្រង/ព្រឹត្តប័ត្រ) ចំនួន ៩៤ ត្រូវបានរៀបចំ | M26: ៤.ផលិតផលទិន្នន័យស្ថិតិសេដ្ឋកិច្ច,ហិរញ្ញវត្ថុ និងថ្លៃទំនិញ (តារាង/កម្រង/ព្រឹត្តប័ត្រ) ចំនួន ៩៤ ត្រូវបានរៀបចំ | O26: ៤.ផលិតផលទិន្នន័យស្ថិតិសេដ្ឋកិច្ច,ហិរញ្ញវត្ថុ និងថ្លៃទំនិញ (តារាង/កម្រង/ព្រឹត្តប័ត្រ) ចំនួន ៩៤ ត្រូវបានរៀបចំ | P26: ៤.ផលិតផលទិន្នន័យស្ថិតិសេដ្ឋកិច្ច,ហិរញ្ញវត្ថុ និងថ្លៃទំនិញ (តារាង/កម្រង/ព្រឹត្តប័ត្រ) ចំនួន ៩៤ ត្រូវបានរៀបចំ | Q26: =IF(OR(J26>0,K26<>0,L26<>0,M26<>0),"ok","-") -> ok
D27: 4 | F27: 1010104 | G27: =$G$2&"04" -> 1010104 | H27: =VLOOKUP($G27,[4]BSP1!$B$12:$D$207,3) -> ១.១.៤. ចង្កោមសកម្មភាពទី៤ : លើកកម្ពស់កិច្ចការសមាហរណកម្មសេដ្ឋកិច្ច និងសហប្រតិបត្តិការហិរញ្ញវត្ថុនិងរូបិយវត្ថុ | J27: =VLOOKUP($G27,[4]BSP4!$B$12:$F$187,5,FALSE) -> 899.6 | Q27: =IF(OR(J27>0,K27<>0,L27<>0,M27<>0),"ok","-") -> ok
B28: 13 | D28: 4 | H28: សូចនាករទី១៖ វឌ្ឍនភាពស្តីពីការតាមដាន សម្របសម្រួល និងអនុវត្តយន្តការសហប្រតិបត្តិការហិរញ្ញវត្ថុ និងរូបិយវត្ថុអាស៊ាន និងជាមួយប្រទេសដៃគូប្រចាំឆ្នាំ ត្រូវបានវាយតម្លៃ | K28: ១. របាយការណ៏ស្តីពីសមាហរណកម្មសេដ្ឋកិច្ចនិងសហប្រតិបត្តិហិរញ្ញវត្ថុ និងរូបិយវត្ថុប្រចាំឆ្នាំ ២០២១ ត្រូវបានរៀបចំ | L28: ១. របាយការណ៍ស្តីពីសហប្រតិបត្តិការហិរញ្ញវត្ថុនិងរូបិយវត្ថុអាស៊ាននិងជាមួយប្រទេសដៃគូសម្រាប់ឆមាសទី១ ត្រូវបានរៀបចំ | M28: ១. របាយការណ៏ស្តីពីសមាហរណកម្មសេដ្ឋកិច្ចនិងសហប្រតិបត្តិហិរញ្ញវត្ថុ និងរូបិយវត្ថុប្រចាំឆ្នាំ ២០២៣ ត្រូវបានរៀបចំ | O28: ១.របាយការណ៍ស្តីពីសហប្រតិបត្តិការហិរញ្ញវត្ថុនិងរូបិយវត្ថុអាស៊ាននិងជាមួយប្រទេសដៃគូប្រចាំឆ្នាំ ២០២៤ ត្រូវបានរៀបចំ | P28: ១.របាយការណ៍ស្តីពីសហប្រតិបត្តិការហិរញ្ញវត្ថុនិងរូបិយវត្ថុអាស៊ាននិងជាមួយប្រទេសដៃគូប្រចាំឆ្នាំ ២០២៥ ត្រូវបានរៀបចំ | Q28: =IF(OR(J28>0,K28<>0,L28<>0,M28<>0),"ok","-") -> ok
K29: ២. របាយការណ៏រួមស្តីពីការតាមដាន សម្របសម្រួល និង អនុវត្តកិច្ចព្រមព្រៀងពាណិជ្ជកម្មសេរីអាស៊ាននិងជាមួយប្រទេសដៃគូប្រចាំឆ្នាំ ២០២១ ត្រូវបានរៀបចំ | L29: ២. របាយការណ៍ស្តីពីកិច្ចព្រមព្រៀងពាណិជ្ជកម្មសេរី អាស៊ាននិងជាមួយប្រទេសដៃគូសម្រាប់ឆមាសទី១ ត្រូវបានរៀបចំ | M29: ២. របាយការណ៏រួមស្តីពីការតាមដាន សម្របសម្រួល និង អនុវត្តកិច្ចព្រមព្រៀងពាណិជ្ជកម្មសេរីអាស៊ាននិងជាមួយប្រទេសដៃគូប្រចាំឆ្នាំ ២០២៣ ត្រូវបានរៀបចំ | O29: ២.របាយការណ៍ស្តីពីកិច្ចព្រមព្រៀងពាណិជ្ជកម្មសេរី អាស៊ាននិងជាមួយប្រទេសដៃគូប្រចាំឆ្នាំ ២០២៤ ត្រូវបានរៀបចំ | P29: ២.របាយការណ៍ស្តីពីកិច្ចព្រមព្រៀងពាណិជ្ជកម្មសេរី អាស៊ាននិងជាមួយប្រទេសដៃគូប្រចាំឆ្នាំ ២០២៥ ត្រូវបានរៀបចំ | Q29: =IF(OR(J29>0,K29<>0,L29<>0,M29<>0),"ok","-") -> ok
K30: ៣. របាយការណ៏រួមស្តីពីការតាមដាន សម្របសម្រួល និងអនុវត្តការងារពាក់ព័ន្ធនានាក្នុងនាមជាលេខាធិការ ដ្ឋានរបស់គណៈកម្មាធិការជាតិសម្រាប់វិធានការមិនមែនពន្ធនិងនិហិតដ្ឋានជាតិ ពត៌មានពាក់ព័ន្ធនឹងពាណិជ្ជកម្មប្រចាំឆ្នាំ ២០២១ ត្រូវបានរៀបចំ | L30: ៣. របាយការណ៍ស្តីពីការងារពាក់ព័ន្ធនានាក្នុងនាមជាលេខាធិការដ្ឋានរបស់គណៈកម្មាធិការជាតិសម្រាប់វិធានការមិនមែនពន្ធ និងនិហិតដ្ឋានជាតិពត៌មានពាក់ព័ន្ធនឹងពាណិជ្ជកម្មសម្រាប់ឆមាសទី១ បានបញ្ចប់សេចក្តីព្រាង | M30: ៣. របាយការណ៏រួមស្តីពីការតាមដាន សម្របសម្រួល និងអនុវត្តការងារពាក់ព័ន្ធនានាក្នុងនាមជាលេខាធិការដ្ឋានរបស់គណៈកម្មាធិការជាតិសម្រាប់វិធានការមិនមែនពន្ធនិងនិហិត ដ្ឋានជាតិ ពត៌មានពាក់ព័ន្ធនឹងពាណិជ្ជកម្មប្រចាំឆ្នាំ ២០២៣ ត្រូវបានរៀបចំ | O30: ៣.របាយការណ៍ស្តីពីការងារពាក់ព័ន្ធនានាក្នុងនាមជាលេខាធិការដ្ឋានរបស់គណៈកម្មាធិការជាតិសម្រាប់វិធានការមិនមែនពន្ធ និងនិហិតដ្ឋានជាតិពត៌មានពាក់ព័ន្ធនឹងពាណិជ្ជកម្មប្រចាំឆ្នាំ២០២៤ បានរៀបចំ | P30: ៣.របាយការណ៍ស្តីពីការងារពាក់ព័ន្ធនានាក្នុងនាមជាលេខាធិការដ្ឋានរបស់គណៈកម្មាធិការជាតិសម្រាប់វិធានការមិនមែនពន្ធ និងនិហិតដ្ឋានជាតិពត៌មានពាក់ព័ន្ធនឹងពាណិជ្ជកម្មប្រចាំឆ្នាំ២០២៥ បានរៀបចំ | Q30: =IF(OR(J30>0,K30<>0,L30<>0,M30<>0),"ok","-") -> ok
K31: ៤. របាយការណ៏ស្តីពី (១)សិក្ខាសាលាផ្សព្វផ្សាយ ស្តីពីការអនុវត្តកិច្ចព្រមព្រៀងពាណិជ្ជកម្មសេរីអាស៊ាន និងអាស៊ានជាមួយដៃគូ និង (២)សិក្ខាសាលាជាតិស្តីពីការងារពាក់ព័ន្ធនឹគណៈ កម្មាធិការជាតិសម្រាប់វិធានការមិនមែនពន្ធនិងនិហិតដ្ឋានជាតិពត៌មានពាក់ព័ន្ធនឹងពាណិជ្ជកម្ម មិនត្រូវបានរៀបចំ | L31: ៤. កិច្ចប្រជុំអនុគណៈកម្មាការវិធានអាស៊ានស្តីពីដើមកំណើត (SCA-ROO) និងសិក្ខាសាលាជាតិស្តីពីការងារពាក់ព័ន្ធនឹងគណៈកម្មាធិការជាតិសម្រាប់វិធានការមិនមែនពន្ធនិងនិហិតដ្ឋានជាតិព័ត៌មានពាក់ព័ន្ធនឹងពាណិជ្ជកម្ម សម្រាប់ឆមាសទី១ មិនទាន់ត្រូវបានរៀបចំ | M31: ៤. បាយការណ៏ស្តីពី (១)សិក្ខាសាលាផ្សព្វផ្សាយស្តីពីការអនុវត្តកិច្ចព្រមព្រៀងពាណិជ្ជកម្មសេរីអាស៊ាន និងអាស៊ានជាមួយដៃគូ និង (២)សិក្ខាសាលាជាតិស្តីពីការងារពាក់ព័ន្ធនឹគណៈ កម្មាធិការជាតិសម្រាប់វិធានការមិនមែនពន្ធនិងនិហិតដ្ឋានជាតិពត៌មានពាក់ព័ន្ធនឹងពាណិជ្ជកម្ម ប្រចាំឆ្នាំ ២០២៣ ត្រូវបានរៀបចំ | O31: ៤.របាយការណ៏ស្តីពី (១)សិក្ខាសាលាផ្សព្វផ្សាយស្តីពីការអនុវត្តកិច្ចព្រមព្រៀងពាណិជ្ជកម្មសេរីអាស៊ាន និងអាស៊ានជាមួយដៃគូ និង (២)សិក្ខាសាលាជាតិស្តីពីការងារពាក់ព័ន្ធនឹគណៈ កម្មាធិការជាតិសម្រាប់វិធានការមិនមែនពន្ធនិងនិហិតដ្ឋានជាតិពត៌មានពាក់ព័ន្ធនឹងពាណិជ្ជកម្ម ប្រចាំឆ្នាំ២០២៤ ត្រូវបានរៀបចំ។ | P31: ៤.របាយការណ៏ស្តីពី (១)សិក្ខាសាលាផ្សព្វផ្សាយស្តីពីការអនុវត្តកិច្ចព្រមព្រៀងពាណិជ្ជកម្មសេរីអាស៊ាន និងអាស៊ានជាមួយដៃគូ និង (២)សិក្ខាសាលាជាតិស្តីពីការងារពាក់ព័ន្ធនឹគណៈ កម្មាធិការជាតិសម្រាប់វិធានការមិនមែនពន្ធនិងនិហិតដ្ឋានជាតិពត៌មានពាក់ព័ន្ធនឹងពាណិជ្ជកម្ម ប្រចាំឆ្នាំ២០២៥ ត្រូវបានរៀបចំ។ | Q31: =IF(OR(J31>0,K31<>0,L31<>0,M31<>0),"ok","-") -> ok
H32: -សូចនាករទី៥ : ... | Q32: =IF(OR(J32>0,K32<>0,L32<>0,M32<>0),"ok","-") -> -
H33: -សូចនាករទី៦ : ... | Q33: =IF(OR(J33>0,K33<>0,L33<>0,M33<>0),"ok","-") -> -
D34: 5 | F34: 1010105 | G34: =$G$2&"05" -> 1010105 | H34: =VLOOKUP($G34,[4]BSP1!$B$12:$D$207,3) -> ១.១.៥. ចង្កោមសកម្មភាពទី ៥ : លើកកម្ពស់គោលនយោបាយលើវិស័យសេដ្ឋកិច្ចថ្មី | J34: =VLOOKUP($G34,[4]BSP4!$B$12:$F$187,5,FALSE) -> 250 | Q34: =IF(OR(J34>0,K34<>0,L34<>0,M34<>0),"ok","-") -> ok
B35: 14 | D35: 5 | H35: -សូចនាករទី១ : លទ្ធផលសិក្សាពាក់ព័ន្ធការកំណត់ និងការលើកកម្ពស់ប្រភពកំណើនថ្មី និងការគិតគូរជាយុទ្ធសាស្ត្ររយៈពេលវែង ត្រូវបានរៀបចំ | K35: គ្មាន | L35: គ្មាន | M35: ១. របាយការណ៍លទ្ធផលសិក្សាពាក់ព័ន្ធការកំណត់ និងការលើកកម្ពស់ប្រភពកំណើនថ្មី និងការគិតគូរជាយុទ្ធសាស្ត្ររយៈពេលវែង ត្រូវបានរៀបចំ | O35: ១. របាយការណ៍លទ្ធផលសិក្សាពាក់ព័ន្ធការកំណត់ និងការលើកកម្ពស់ប្រភពកំណើនថ្មី និងការគិតគូរជាយុទ្ធសាស្ត្ររយៈពេលវែង ត្រូវបានរៀបចំ | P35: ១. របាយការណ៍លទ្ធផលសិក្សាពាក់ព័ន្ធការកំណត់ និងការលើកកម្ពស់ប្រភពកំណើនថ្មី និងការគិតគូរជាយុទ្ធសាស្ត្ររយៈពេលវែង ត្រូវបានរៀបចំ | Q35: =IF(OR(J35>0,K35<>0,L35<>0,M35<>0),"ok","-") -> ok
B36: 15 | D36: 5 | H36: -សូចនាករទី២ : លទ្ធផលសិក្សាពាក់ព័ន្ធសេដ្ឋកិច្ចបៃតង, ការលើកកម្ពស់ការប្រើប្រាស់ថាមពលបៃតង, សេដ្ឋកិច្ចឌីជីថល និងការជំរុញការអនុវត្ត​បរិវត្តកម្មឌីជីថល ត្រូវបានរៀបចំ | K36: គ្មាន | L36: គ្មាន | M36: ២. របាយការណ៍លទ្ធផលសិក្សាពាក់ព័ន្ធសេដ្ឋកិច្ចបៃតង និង ការលើកកម្ពស់ការប្រើប្រាស់ថាមពលបៃតង និងប្រសិទ្ធភាពថាមពល ត្រូវបានរៀបចំ | O36: ២. របាយការណ៍លទ្ធផលសិក្សាពាក់ព័ន្ធសេដ្ឋកិច្ចបៃតង និង ការលើកកម្ពស់ការប្រើប្រាស់ថាមពលបៃតង និងប្រសិទ្ធភាពថាមពល ត្រូវបានរៀបចំ | P36: ២. របាយការណ៍លទ្ធផលសិក្សាពាក់ព័ន្ធសេដ្ឋកិច្ចបៃតង និង ការលើកកម្ពស់ការប្រើប្រាស់ថាមពលបៃតង និងប្រសិទ្ធភាពថាមពល ត្រូវបានរៀបចំ | Q36: =IF(OR(J36>0,K36<>0,L36<>0,M36<>0),"ok","-") -> ok
B37: 16 | D37: 5 | K37: គ្មាន | L37: គ្មាន | M37: ៣. របាយការណ៍លទ្ធផលសិក្សាពាក់ព័ន្ធនឹងសេដ្ឋកិច្ចឌីជីថល និងការជំរុញការអនុវត្ត​បរិវត្តកម្មឌីជីថល ត្រូវបានរៀបចំ | O37: ៣. របាយការណ៍លទ្ធផលសិក្សាពាក់ព័ន្ធនឹងសេដ្ឋកិច្ចឌីជីថល និងការជំរុញការអនុវត្ត​បរិវត្តកម្មឌីជីថល ត្រូវបានរៀបចំ | P37: ៣. របាយការណ៍លទ្ធផលសិក្សាពាក់ព័ន្ធនឹងសេដ្ឋកិច្ចឌីជីថល និងការជំរុញការអនុវត្ត​បរិវត្តកម្មឌីជីថល ត្រូវបានរៀបចំ
B38: 17 | D38: 5 | H38: -សូចនាករទី៣ : របាយការណ៍ស្តីពីការអនុវត្តគម្រោងមូលនិធិអភិវឌ្ឍន៍ជំនាញ (SDF) និង “មូលនិធិអភិវឌ្ឍន៍សហគ្រិនភាព (EDF)” ប្រចាំឆ្នាំ ២០២២​ និងពាក់កណ្តាលឆ្នាំ ២០២៣ ត្រូវបានរៀបចំ | K38: គ្មាន | L38: គ្មាន | M38: ៤. របាយការណ៍ស្តីពីការអនុវត្តគម្រោងមូលនិធិអភិវឌ្ឍន៍ជំនាញ (SDF) និង “មូលនិធិអភិវឌ្ឍន៍សហគ្រិនភាព (EDF)” ប្រចាំឆ្នាំ ២០២២​ និងពាក់កណ្តាលឆ្នាំ ២០២៣ ត្រូវបានរៀបចំ | O38: ៤. របាយការណ៍ស្តីពីការអនុវត្តគម្រោងមូលនិធិអភិវឌ្ឍន៍ជំនាញ (SDF) និង “មូលនិធិអភិវឌ្ឍន៍សហគ្រិនភាព (EDF)” ប្រចាំឆ្នាំ ២០២២៣ និងពាក់កណ្តាលឆ្នាំ ២០២៤ ត្រូវបានរៀបចំ | P38: ៤. របាយការណ៍ស្តីពីការអនុវត្តគម្រោងមូលនិធិអភិវឌ្ឍន៍ជំនាញ (SDF) និង “មូលនិធិអភិវឌ្ឍន៍សហគ្រិនភាព (EDF)” ប្រចាំឆ្នាំ ២០២២៤ និងពាក់កណ្តាលឆ្នាំ ២០២៥ ត្រូវបានរៀបចំ
B39: 18 | D39: 5 | H39: '-សូចនាករទី៤ : ការតាមដានការអនុវត្តគោលនយោបាយនិងយុទ្ធសាស្ត្រពាក់ព័ន្ធ​​នឹងការលើកទឹកចិត្តសារពើពន្ធ និងមិនមែនសារពើពន្ធដើម្បីជំរុញកំណើនសេដ្ឋកិច្ច ត្រូវបានពង្រឹង | K39: គ្មាន | L39: គ្មាន | M39: ៥. របាយការណ៍ស្តីពីការតាមដានការអនុវត្តគោលនយោបាយនិងយុទ្ធសាស្ត្រពាក់ព័ន្ធ​​នឹងការលើកទឹកចិត្តសារពើពន្ធ និងមិនមែនសារពើពន្ធដើម្បីជំរុញកំណើនសេដ្ឋកិច្ច ត្រូវបានរៀបចំ | O39: ៥. របាយការណ៍ស្តីពីការតាមដានការអនុវត្តគោលនយោបាយនិងយុទ្ធសាស្ត្រពាក់ព័ន្ធ​​នឹងការលើកទឹកចិត្តសារពើពន្ធ និងមិនមែនសារពើពន្ធដើម្បីជំរុញកំណើនសេដ្ឋកិច្ច ត្រូវបានរៀបចំ | P39: ៥. របាយការណ៍ស្តីពីការតាមដានការអនុវត្តគោលនយោបាយនិងយុទ្ធសាស្ត្រពាក់ព័ន្ធ​​នឹងការលើកទឹកចិត្តសារពើពន្ធ និងមិនមែនសារពើពន្ធដើម្បីជំរុញកំណើនសេដ្ឋកិច្ច ត្រូវបានរៀបចំ | Q39: =IF(OR(J39>0,K39<>0,L39<>0,M39<>0),"ok","-") -> ok
H40: -សូចនាករទី៤ : ... | Q40: =IF(OR(J40>0,K40<>0,L40<>0,M40<>0),"ok","-") -> -
...

Sheet BSP1_Cluster_Act_2_Entity
A1: id | B1: subprog_to_entity_id | E1: planning_id | F1: sub_program_id | G1: cluster_activity_id | H1: activity_id | I1: entity_id | J1: entity_member_id
C2: Check | D2: កូដកម្មវិធី | K2: ឈ្នោះកម្មវិធី និងអនុកម្មវិធី | M2: អ្នកគ្រប់គ្រង | N2: អង្គភាពទទួលខុសត្រូវ
D3: 101 | K3: កម្មវិធីទី១ : ការគ្រប់គ្រងវិស័យសេដ្ឋកិច្ច | M3: ឯកឧត្តម/លោកជំទាវ... | O3: =IF(AND(K3<>"",M3<>""),"ok","-") -> ok
C4: 101 | D4: 10101 | E4: 4 | F4: 1 | I4: 1 | J4: 1 | K4: ១.១. អនុកម្មវិធីទី១.១ : ការគ្រប់គ្រងគោលនយោបាយសេដ្ឋកិច្ច ហិរញ្ញវត្ថុ និងគោលនយោបាយតាមវិស័យផ្សេងៗ | L4: =RIGHT(M4,LEN(M4)-SEARCH(" ",M4)) -> ឈាង វណ្ណារិទ្ធ | M4: ឯកឧត្តម ឈាង វណ្ណារិទ្ធ | N4: អគ្គនាយកដ្ឋានគោលនយោបាយ | O4: =IF(AND(K4<>"",M4<>""),"ok","-") -> ok
A5: 1 | B5: 1 | C5: 10101 | D5: 1010101 | E5: 4 | F5: 1 | G5: 2 | I5: 29 | J5: 2 | K5: ១.១.១. ចង្កោមសកម្មភាពទី១ : គាំទ្រ សម្របសម្រួល និងគ្រប់គ្រងការងាររដ្ឋបាលរបស់អគ្គនាយកដ្ឋាន | L5: =RIGHT(M6,LEN(M6)-SEARCH(" ",M6)) -> ស្រ៊ន មុនីនាត | M5: លោក ស្រ៊ន មុនីនាត | N5: លេខាធិការដ្ឋាន | O5: =IF(AND(K5<>"",M5<>""),"ok","-") -> ok
C6: 1010101 | D6: 101010101 | E6: 4 | G6: 2 | H6: 1 | I6: 29 | J6: 2 | K6: ១.១.១.១. សកម្មភាពទី១ : បំពេញមុខជាលេខាធិការដ្ឋាន | L6: =RIGHT(M6,LEN(M6)-SEARCH(" ",M6)) -> ស្រ៊ន មុនីនាត | M6: លោក ស្រ៊ន មុនីនាត | N6: លេខាធិការដ្ឋាន | O6: =IF(AND(K6<>"",M6<>""),"ok","-") -> ok
C7: 1010101 | D7: 101010102 | E7: 4 | G7: 2 | H7: 2 | I7: 29 | J7: 2 | K7: ១.១.១.២. សកម្មភាពទី២ : ​ចូលរួមកិច្ចប្រជុំផ្សេងៗ ក្នុងនិងក្រៅប្រទេសរបស់ឯកឧត្តមអគ្គនាយក | L7: =RIGHT(M7,LEN(M7)-SEARCH(" ",M7)) -> ស្រ៊ន មុនីនាត | M7: លោក ស្រ៊ន មុនីនាត | N7: លេខាធិការដ្ឋាន | O7: =IF(AND(K7<>"",M7<>""),"ok","-") -> ok
C8: 1010101 | D8: 101010103 | H8: 3 | K8: ១.១.១.៣. សកម្មភាពទី៣ : | O8: =IF(AND(K8<>"",M8<>""),"ok","-") -> -
C9: 1010101 | D9: 101010104 | H9: 4 | K9: ១.១.១.៤. សកម្មភាពទី៤ : | O9: =IF(AND(K9<>"",M9<>""),"ok","-") -> -
C10: 1010101 | D10: 101010105 | H10: 5 | K10: ១.១.១.៥. សកម្មភាពទី៥ : | O10: =IF(AND(K10<>"",M10<>""),"ok","-") -> -
C11: 1010101 | D11: 101010106 | H11: 6 | K11: ១.១.១.៦. សកម្មភាពទី៦ : | O11: =IF(AND(K11<>"",M11<>""),"ok","-") -> -
C12: 1010101 | D12: 101010107 | H12: 7 | K12: ១.១.១.៧. សកម្មភាពទី៧ : | O12: =IF(AND(K12<>"",M12<>""),"ok","-") -> -
C13: 1010101 | D13: 101010108 | H13: 8 | K13: ១.១.១.៨. សកម្មភាពទី៨ : ​ | O13: =IF(AND(K13<>"",M13<>""),"ok","-") -> -
C14: 1010101 | D14: 101010109 | H14: 9 | K14: ១.១.១.៩. សកម្មភាពទី៩ : | O14: =IF(AND(K14<>"",M14<>""),"ok","-") -> -
C15: 1010101 | D15: 101010110 | H15: 10 | K15: ១.១.១.១០. សកម្មភាពទី១០ : ​ | O15: =IF(AND(K15<>"",M15<>""),"ok","-") -> -
C16: 1010101 | D16: 101010111 | H16: 11 | K16: ១.១.១.១១. សកម្មភាពទី១១ : | O16: =IF(AND(K16<>"",M16<>""),"ok","-") -> -
C17: 1010101 | D17: 101010112 | H17: 12 | K17: ១.១.១.១២. សកម្មភាពទី១២ : ​ | O17: =IF(AND(K17<>"",M17<>""),"ok","-") -> -
A18: 2 | B18: 1 | C18: 10101 | D18: 1010102 | E18: 4 | F18: 1 | G18: 3 | I18: 30 | J18: 7 | K18: ១.១.២. ចង្កោមសកម្មភាពទី២ : រៀបចំ កែលម្អ ត្រួតពិនិត្យ និងវាយតម្លៃគោលនយោបាយម៉ាក្រូសេដ្ឋកិច្ច និងសារពើពន្ធ | L18: =RIGHT(M18,LEN(M18)-SEARCH(" ",M18)) -> សែម សុភា | M18: លោកស្រី សែម សុភា | N18: នាយកដ្ឋានគោលនយោ​បាយ​ម៉ាក្រូសេដ្ឋកិច្ចនិងសារពើពន្ធ | O18: =IF(AND(K18<>"",M18<>""),"ok","-") -> ok
C19: 1010102 | D19: 101010201 | E19: 4 | G19: 2 | H19: 13 | I19: 172 | J19: 6 | K19: ១.១.២.១. សកម្មភាពទី១ : ធ្វើការស្រាវជ្រាវលើវឌ្ឍនភាព និងបញ្ហា អភិវឌ្ឍន៍សេដ្ឋកិច្ច ហិរញ្ញវត្ថុ និងវិស័យសំខាន់ៗ | L19: =RIGHT(M19,LEN(M19)-SEARCH(" ",M19)) -> ស៊ីន ស៊ីប | M19: លោក ស៊ីន ស៊ីប | N19: ការិយាល័យស្រាវជ្រាវ | O19: =IF(AND(K19<>"",M19<>""),"ok","-") -> ok
C20: 1010102 | D20: 101010202 | E20: 4 | G20: 2 | H20: 14 | I20: 173 | J20: 7 | K20: ១.១.២.២. សកម្មភាពទី២ : តាមដាន និងវាយតម្លៃការអនុវត្តគោលនយោបាយសារពើពន្ធ អនុលោមតាមគោលដៅយុទ្ធសាស្រ្តជាតិ | L20: =RIGHT(M20,LEN(M20)-SEARCH(" ",M20)) -> សែម សុភា | M20: កញ្ញា សែម សុភា | N20: ការិយាល័យវិភាគនិងព្យាករណ៍សារពើពន្ធ | O20: =IF(AND(K20<>"",M20<>""),"ok","-") -> ok
C21: 1010102 | D21: 101010203 | E21: 4 | G21: 2 | H21: 15 | I21: 174 | J21: 8 | K21: ១.១.២.៣. សកម្មភាពទី៣ : តាមដាន និងវាយតម្លៃការអនុវត្តយុទ្ធសាស្រ្ត និងគោលនយោបាយពាក់ព័ន្ធនឹងវិស័យសេដ្ឋកិច្ច-សង្គម | L21: =RIGHT(M21,LEN(M21)-SEARCH(" ",M21)) -> ឌី សេរីវិរៈ | M21: លោក ឌី សេរីវិរៈ | N21: ការិយាល័យគោលនយោបាយសេដ្ឋកិច្ច | O21: =IF(AND(K21<>"",M21<>""),"ok","-") -> ok
C22: 1010102 | D22: 101010204 | E22: 4 | G22: 2 | H22: 16 | I22: 175 | J22: 9 | K22: ១.១.២.៤. សកម្មភាពទី៤ : ពិនិត្យ តាមដាន និងវាយតម្លៃស្ថានភាពសេដ្ឋកិច្ច និងក្របខ័ណ្ឌម៉ាក្រូសេដ្ឋកិច្ចរយៈពេលមធ្យម | L22: =RIGHT(M22,LEN(M22)-SEARCH(" ",M22)) -> តាន់ ទ្បានីន | M22: លោកស្រី តាន់ ទ្បានីន | N22: ការិយាល័យវិភាគនិងព្យាករណ៍សេដ្ឋកិច្ច | O22: =IF(AND(K22<>"",M22<>""),"ok","-") -> ok
C23: 1010102 | D23: 101010205 | E23: 4 | G23: 2 | H23: 17 | I23: 176 | J23: 10 | K23: ១.១.២.៥. សកម្មភាពទី៥ : តាមដាន និងវិភាគគោលនយោបាយហិរញ្ញវត្ថុសាធារណៈ | L23: =RIGHT(M23,LEN(M23)-SEARCH(" ",M23)) -> ម៉ក់ វិចិត្រសក្កដា | M23: លោក ម៉ក់ វិចិត្រសក្កដា | N23: ការិយាល័យគោលនយោបាយហិរញ្ញវត្ថុសាធារណៈ | O23: =IF(AND(K23<>"",M23<>""),"ok","-") -> ok
C24: 1010102 | D24: 101010206 | E24: 4 | G24: 2 | H24: 18 | I24: 177 | J24: 11 | K24: ១.១.២.៦. សកម្មភាពទី៦ : ពង្រឹងសេវាគាំទ្រកិច្ចប្រតិបត្តិការ និងការងារសម្របសម្រួលសម្រាប់នាយកដ្ឋានគោលនយោបាយម៉ាក្រូសេដ្ឋកិច្ច និងសារពើពន្ធ | L24: =RIGHT(M24,LEN(M24)-SEARCH(" ",M24)) -> ស៊ាង ពីសី | M24: លោកស្រី ស៊ាង ពីសី | N24: ការិយាល័យកិច្ចការទូទៅនិងសម្របសម្រួល | O24: =IF(AND(K24<>"",M24<>""),"ok","-") -> ok
C25: 1010102 | D25: 101010207 | J25: #N/A | K25: ១.១.២.៧. សកម្មភាពទី៧ : | O25: =IF(AND(K25<>"",M25<>""),"ok","-") -> -
C26: 1010102 | D26: 101010208 | J26: #N/A | K26: ១.១.២.៨. សកម្មភាពទី៨ : ​ | O26: =IF(AND(K26<>"",M26<>""),"ok","-") -> -
C27: 1010102 | D27: 101010209 | J27: #N/A | K27: ១.១.២.៩. សកម្មភាពទី៩ : | O27: =IF(AND(K27<>"",M27<>""),"ok","-") -> -
C28: 1010102 | D28: 101010210 | J28: #N/A | K28: ១.១.២.១០. សកម្មភាពទី១០ : ​ | O28: =IF(AND(K28<>"",M28<>""),"ok","-") -> -
C29: 1010102 | D29: 101010211 | J29: #N/A | K29: ១.១.២.១១. សកម្មភាពទី១១ : | O29: =IF(AND(K29<>"",M29<>""),"ok","-") -> -
C30: 1010102 | D30: 101010212 | J30: #N/A | K30: ១.១.២.១២. សកម្មភាពទី១២ : ​ | O30: =IF(AND(K30<>"",M30<>""),"ok","-") -> -
A31: 3 | B31: 1 | C31: 10101 | D31: 1010103 | E31: 4 | F31: 1 | G31: 4 | I31: 31 | J31: 12 | K31: ១.១.៣. ចង្កោមសកម្មភាពទី៣ : លើកកម្ពស់ការងារស្ថិតិសេដ្ឋកិច្ចនិងហិរញ្ញវត្ថុសាធារណៈ | L31: សុខ ខន | M31: លោក សុខ ខន | N31: នាយកដ្ឋានស្ថិតិ និងវិភាគសេដ្ឋកិច្ច | O31: =IF(AND(K31<>"",M31<>""),"ok","-") -> ok
C32: 1010103 | D32: 101010301 | E32: 4 | G32: 4 | H32: 19 | I32: 177 | J32: 13 | K32: ១.‌១.៣.១.សកម្មភាពទី១៖ពង្រឹងការគ្រប់គ្រងកិច្ចការទូទៅ និងការសម្របសម្រួលផ្ទៃក្នុងនិងអន្តរទំនាក់ទំនង ដើម្បីបុរេសកម្មការងារ | L32: =RIGHT(M32,LEN(M32)-SEARCH(" ",M32)) -> កូយ សុចាន់ | M32: កញ្ញា កូយ សុចាន់ | N32: ការិយាល័យកិច្ចការទូទៅនិងសម្របសម្រួល | O32: =IF(AND(K32<>"",M32<>""),"ok","-") -> ok
C33: 1010103 | D33: 101010302 | E33: 4 | G33: 4 | H33: 20 | I33: 178 | J33: 14 | K33: ១.‌១.៣.២.សកម្មភាពទី២៖ ពង្រឹងការរៀបចំចងក្រង តាមដាន វិភាគនិងផ្សព្វផ្សាយស្ថិតិប្រតិបត្តិការហិរញ្ញវត្ថុ (TOFE) និងស្តង់ដារស្ថិតិហិរញ្ញវត្ថុរដ្ឋាភិបាល (GFS) | L33: =RIGHT(M33,LEN(M33)-SEARCH(" ",M33)) -> សែម សំណាង | M33: លោក​ស្រី សែម សំណាង | N33: ការិយាល័យស្ថិតិហិរញ្ញវត្ថុសាធារណៈ | O33: =IF(AND(K33<>"",M33<>""),"ok","-") -> ok
C34: 1010103 | D34: 101010303 | E34: 4 | G34: 4 | H34: 21 | I34: 179 | J34: 15 | K34: ១.១.៣.៣.សកម្មភាពទី៣៖​ ពង្រឹងការរៀបចំចងក្រង តាមដាន វិភាគនិងផ្សព្វផ្សាយស្ថិតិម៉ាក្រូសេដ្ឋកិច្ច | L34: =RIGHT(M34,LEN(M34)-SEARCH(" ",M34)) -> បាន ​កុសល | M34: លោក បាន ​កុសល | N34: ការិយាល័យស្ថិតិនិងវិភាគម៉ាក្រូសេដ្ឋកិច្ច | O34: =IF(AND(K34<>"",M34<>""),"ok","-") -> ok
C35: 1010103 | D35: 101010304 | E35: 4 | G35: 4 | H35: 22 | I35: 180 | J35: 16 | K35: ១.‌១.៣.៤.សកម្មភាពទី៤៖ ពង្រឹងការរៀបចំចងក្រង តាមដាន វិភាគនិងផ្សព្វផ្សាយស្ថិតិសេដ្ឋកិច្ចតាមវិស័យ | L35: =RIGHT(M35,LEN(M35)-SEARCH(" ",M35)) -> ស្រៀង ចន្ធី | M35: លោក ស្រៀង ចន្ធី | N35: ការិយាល័យស្ថិតិនិងវិភាគសេដ្ឋកិច្ចតាមវិស័យ | O35: =IF(AND(K35<>"",M35<>""),"ok","-") -> ok
C36: 1010103 | D36: 101010305 | E36: 4 | G36: 4 | H36: 23 | I36: 181 | J36: 17 | K36: ១.១.៣.៥.សកម្មភាពទី៥៖​ ពង្រឹងការរៀបចំចងក្រង តាមដាន វិភាគនិងផ្សព្វផ្សាយស្ថិតិថ្លៃទំនិញនិងសេវា | L36: =RIGHT(M36,LEN(M36)-SEARCH(" ",M36)) -> ជា សុខឃីមរាជ | M36: លោក ជា សុខឃីមរាជ | N36: ការិយាល័យតាមដានថ្លៃទំនិញ និងសេវា | O36: =IF(AND(K36<>"",M36<>""),"ok","-") -> ok
C37: 1010103 | D37: 101010306 | E37: 4 | G37: 4 | H37: 24 | I37: 182 | J37: 15 | K37: ១.‌១.៣.៦.សកម្មភាពទី៦៖ ពង្រឹងការតាមដាន និងវិភាគនិន្នាការសេដ្ឋកិច្ច | L37: =RIGHT(M37,LEN(M37)-SEARCH(" ",M37)) -> បាន ​កុសល | M37: លោក បាន ​កុសល | N37: ការិយាល័យតាមដាននិងវិភាគនិន្នាការសេដ្ឋកិច្ច | O37: =IF(AND(K37<>"",M37<>""),"ok","-") -> ok
C38: 1010103 | D38: 101010307 | K38: ១.១.៣.៧. សកម្មភាពទី៧ : | O38: =IF(AND(K38<>"",M38<>""),"ok","-") -> -
C39: 1010103 | D39: 101010308 | K39: ១.១.៣.៨. សកម្មភាពទី៨ : ​ | O39: =IF(AND(K39<>"",M39<>""),"ok","-") -> -
C40: 1010103 | D40: 101010309 | K40: ១.១.៣.៩. សកម្មភាពទី៩ : | O40: =IF(AND(K40<>"",M40<>""),"ok","-") -> -
...

Sheet BSP1_Subpro_2_Entity
A1: id | D1: sub_prog_to_entity_id | E1: planning_id | F1: sub_program_id | G1: cluster_activity_id | H1: activity_id | I1: entity_id | J1: entity_member_id
B2: Check | C2: កូដកម្មវិធី | K2: ឈ្នោះកម្មវិធី និងអនុកម្មវិធី | M2: អ្នកគ្រប់គ្រង | N2: អង្គភាពទទួលខុសត្រូវ
C3: 101 | K3: កម្មវិធីទី១ : ការគ្រប់គ្រងវិស័យសេដ្ឋកិច្ច | M3: ឯកឧត្តម/លោកជំទាវ... | O3: =IF(AND(K3<>"",M3<>""),"ok","-") -> ok
A4: 1 | B4: 101 | C4: 10101 | E4: 4 | F4: 1 | I4: 1 | J4: 1 | K4: ១.១. អនុកម្មវិធីទី១.១ : ការគ្រប់គ្រងគោលនយោបាយសេដ្ឋកិច្ច ហិរញ្ញវត្ថុ និងគោលនយោបាយតាមវិស័យផ្សេងៗ | L4: =RIGHT(M4,LEN(M4)-SEARCH(" ",M4)) -> ឈាង វណ្ណារិទ្ធ | M4: ឯកឧត្តម ឈាង វណ្ណារិទ្ធ | N4: អគ្គនាយកដ្ឋានគោលនយោបាយ | O4: =IF(AND(K4<>"",M4<>""),"ok","-") -> ok
A5: 1 | B5: 10101 | C5: 1010101 | D5: 1 | E5: 4 | F5: 1 | G5: 2 | I5: 29 | J5: 2 | K5: ១.១.១. ចង្កោមសកម្មភាពទី១ : គាំទ្រ សម្របសម្រួល និងគ្រប់គ្រងការងាររដ្ឋបាលរបស់អគ្គនាយកដ្ឋាន | L5: =RIGHT(M6,LEN(M6)-SEARCH(" ",M6)) -> ស្រ៊ន មុនីនាត | M5: លោក ស្រ៊ន មុនីនាត | N5: លេខាធិការដ្ឋាន | O5: =IF(AND(K5<>"",M5<>""),"ok","-") -> ok
A6: 1 | B6: 1010101 | C6: 101010101 | E6: 4 | G6: 2 | H6: 1 | I6: 29 | J6: 2 | K6: ១.១.១.១. សកម្មភាពទី១ : បំពេញមុខជាលេខាធិការដ្ឋាន | L6: =RIGHT(M6,LEN(M6)-SEARCH(" ",M6)) -> ស្រ៊ន មុនីនាត | M6: លោក ស្រ៊ន មុនីនាត | N6: លេខាធិការដ្ឋាន | O6: =IF(AND(K6<>"",M6<>""),"ok","-") -> ok
A7: 2 | B7: 1010101 | C7: 101010102 | E7: 4 | G7: 2 | H7: 2 | I7: 29 | J7: 2 | K7: ១.១.១.២. សកម្មភាពទី២ : ​ចូលរួមកិច្ចប្រជុំផ្សេងៗ ក្នុងនិងក្រៅប្រទេសរបស់ឯកឧត្តមអគ្គនាយក | L7: =RIGHT(M7,LEN(M7)-SEARCH(" ",M7)) -> ស្រ៊ន មុនីនាត | M7: លោក ស្រ៊ន មុនីនាត | N7: លេខាធិការដ្ឋាន | O7: =IF(AND(K7<>"",M7<>""),"ok","-") -> ok
B8: 1010101 | C8: 101010103 | H8: 3 | K8: ១.១.១.៣. សកម្មភាពទី៣ : | O8: =IF(AND(K8<>"",M8<>""),"ok","-") -> -
B9: 1010101 | C9: 101010104 | H9: 4 | K9: ១.១.១.៤. សកម្មភាពទី៤ : | O9: =IF(AND(K9<>"",M9<>""),"ok","-") -> -
B10: 1010101 | C10: 101010105 | H10: 5 | K10: ១.១.១.៥. សកម្មភាពទី៥ : | O10: =IF(AND(K10<>"",M10<>""),"ok","-") -> -
B11: 1010101 | C11: 101010106 | H11: 6 | K11: ១.១.១.៦. សកម្មភាពទី៦ : | O11: =IF(AND(K11<>"",M11<>""),"ok","-") -> -
B12: 1010101 | C12: 101010107 | H12: 7 | K12: ១.១.១.៧. សកម្មភាពទី៧ : | O12: =IF(AND(K12<>"",M12<>""),"ok","-") -> -
B13: 1010101 | C13: 101010108 | H13: 8 | K13: ១.១.១.៨. សកម្មភាពទី៨ : ​ | O13: =IF(AND(K13<>"",M13<>""),"ok","-") -> -
B14: 1010101 | C14: 101010109 | H14: 9 | K14: ១.១.១.៩. សកម្មភាពទី៩ : | O14: =IF(AND(K14<>"",M14<>""),"ok","-") -> -
B15: 1010101 | C15: 101010110 | H15: 10 | K15: ១.១.១.១០. សកម្មភាពទី១០ : ​ | O15: =IF(AND(K15<>"",M15<>""),"ok","-") -> -
B16: 1010101 | C16: 101010111 | H16: 11 | K16: ១.១.១.១១. សកម្មភាពទី១១ : | O16: =IF(AND(K16<>"",M16<>""),"ok","-") -> -
B17: 1010101 | C17: 101010112 | H17: 12 | K17: ១.១.១.១២. សកម្មភាពទី១២ : ​ | O17: =IF(AND(K17<>"",M17<>""),"ok","-") -> -
A18: 2 | B18: 10101 | C18: 1010102 | D18: 1 | E18: 4 | F18: 1 | G18: 3 | I18: 30 | J18: 7 | K18: ១.១.២. ចង្កោមសកម្មភាពទី២ : រៀបចំ កែលម្អ ត្រួតពិនិត្យ និងវាយតម្លៃគោលនយោបាយម៉ាក្រូសេដ្ឋកិច្ច និងសារពើពន្ធ | L18: =RIGHT(M18,LEN(M18)-SEARCH(" ",M18)) -> សែម សុភា | M18: លោកស្រី សែម សុភា | N18: នាយកដ្ឋានគោលនយោ​បាយ​ម៉ាក្រូសេដ្ឋកិច្ចនិងសារពើពន្ធ | O18: =IF(AND(K18<>"",M18<>""),"ok","-") -> ok
A19: 3 | B19: 1010102 | C19: 101010201 | E19: 4 | G19: 2 | H19: 13 | I19: 172 | J19: 6 | K19: ១.១.២.១. សកម្មភាពទី១ : ធ្វើការស្រាវជ្រាវលើវឌ្ឍនភាព និងបញ្ហា អភិវឌ្ឍន៍សេដ្ឋកិច្ច ហិរញ្ញវត្ថុ និងវិស័យសំខាន់ៗ | L19: =RIGHT(M19,LEN(M19)-SEARCH(" ",M19)) -> ស៊ីន ស៊ីប | M19: លោក ស៊ីន ស៊ីប | N19: ការិយាល័យស្រាវជ្រាវ | O19: =IF(AND(K19<>"",M19<>""),"ok","-") -> ok
A20: 4 | B20: 1010102 | C20: 101010202 | E20: 4 | G20: 2 | H20: 14 | I20: 173 | J20: 7 | K20: ១.១.២.២. សកម្មភាពទី២ : តាមដាន និងវាយតម្លៃការអនុវត្តគោលនយោបាយសារពើពន្ធ អនុលោមតាមគោលដៅយុទ្ធសាស្រ្តជាតិ | L20: =RIGHT(M20,LEN(M20)-SEARCH(" ",M20)) -> សែម សុភា | M20: កញ្ញា សែម សុភា | N20: ការិយាល័យវិភាគនិងព្យាករណ៍សារពើពន្ធ | O20: =IF(AND(K20<>"",M20<>""),"ok","-") -> ok
A21: 5 | B21: 1010102 | C21: 101010203 | E21: 4 | G21: 2 | H21: 15 | I21: 174 | J21: 8 | K21: ១.១.២.៣. សកម្មភាពទី៣ : តាមដាន និងវាយតម្លៃការអនុវត្តយុទ្ធសាស្រ្ត និងគោលនយោបាយពាក់ព័ន្ធនឹងវិស័យសេដ្ឋកិច្ច-សង្គម | L21: =RIGHT(M21,LEN(M21)-SEARCH(" ",M21)) -> ឌី សេរីវិរៈ | M21: លោក ឌី សេរីវិរៈ | N21: ការិយាល័យគោលនយោបាយសេដ្ឋកិច្ច | O21: =IF(AND(K21<>"",M21<>""),"ok","-") -> ok
A22: 6 | B22: 1010102 | C22: 101010204 | E22: 4 | G22: 2 | H22: 16 | I22: 175 | J22: 9 | K22: ១.១.២.៤. សកម្មភាពទី៤ : ពិនិត្យ តាមដាន និងវាយតម្លៃស្ថានភាពសេដ្ឋកិច្ច និងក្របខ័ណ្ឌម៉ាក្រូសេដ្ឋកិច្ចរយៈពេលមធ្យម | L22: =RIGHT(M22,LEN(M22)-SEARCH(" ",M22)) -> តាន់ ទ្បានីន | M22: លោកស្រី តាន់ ទ្បានីន | N22: ការិយាល័យវិភាគនិងព្យាករណ៍សេដ្ឋកិច្ច | O22: =IF(AND(K22<>"",M22<>""),"ok","-") -> ok
A23: 7 | B23: 1010102 | C23: 101010205 | E23: 4 | G23: 2 | H23: 17 | I23: 176 | J23: 10 | K23: ១.១.២.៥. សកម្មភាពទី៥ : តាមដាន និងវិភាគគោលនយោបាយហិរញ្ញវត្ថុសាធារណៈ | L23: =RIGHT(M23,LEN(M23)-SEARCH(" ",M23)) -> ម៉ក់ វិចិត្រសក្កដា | M23: លោក ម៉ក់ វិចិត្រសក្កដា | N23: ការិយាល័យគោលនយោបាយហិរញ្ញវត្ថុសាធារណៈ | O23: =IF(AND(K23<>"",M23<>""),"ok","-") -> ok
A24: 8 | B24: 1010102 | C24: 101010206 | E24: 4 | G24: 2 | H24: 18 | I24: 177 | J24: 11 | K24: ១.១.២.៦. សកម្មភាពទី៦ : ពង្រឹងសេវាគាំទ្រកិច្ចប្រតិបត្តិការ និងការងារសម្របសម្រួលសម្រាប់នាយកដ្ឋានគោលនយោបាយម៉ាក្រូសេដ្ឋកិច្ច និងសារពើពន្ធ | L24: =RIGHT(M24,LEN(M24)-SEARCH(" ",M24)) -> ស៊ាង ពីសី | M24: លោកស្រី ស៊ាង ពីសី | N24: ការិយាល័យកិច្ចការទូទៅនិងសម្របសម្រួល | O24: =IF(AND(K24<>"",M24<>""),"ok","-") -> ok
B25: 1010102 | C25: 101010207 | J25: #N/A | K25: ១.១.២.៧. សកម្មភាពទី៧ : | O25: =IF(AND(K25<>"",M25<>""),"ok","-") -> -
B26: 1010102 | C26: 101010208 | J26: #N/A | K26: ១.១.២.៨. សកម្មភាពទី៨ : ​ | O26: =IF(AND(K26<>"",M26<>""),"ok","-") -> -
B27: 1010102 | C27: 101010209 | J27: #N/A | K27: ១.១.២.៩. សកម្មភាពទី៩ : | O27: =IF(AND(K27<>"",M27<>""),"ok","-") -> -
B28: 1010102 | C28: 101010210 | J28: #N/A | K28: ១.១.២.១០. សកម្មភាពទី១០ : ​ | O28: =IF(AND(K28<>"",M28<>""),"ok","-") -> -
B29: 1010102 | C29: 101010211 | J29: #N/A | K29: ១.១.២.១១. សកម្មភាពទី១១ : | O29: =IF(AND(K29<>"",M29<>""),"ok","-") -> -
B30: 1010102 | C30: 101010212 | J30: #N/A | K30: ១.១.២.១២. សកម្មភាពទី១២ : ​ | O30: =IF(AND(K30<>"",M30<>""),"ok","-") -> -
A31: 3 | B31: 10101 | C31: 1010103 | D31: 1 | E31: 4 | F31: 1 | G31: 4 | I31: 31 | J31: 12 | K31: ១.១.៣. ចង្កោមសកម្មភាពទី៣ : លើកកម្ពស់ការងារស្ថិតិសេដ្ឋកិច្ចនិងហិរញ្ញវត្ថុសាធារណៈ | L31: សុខ ខន | M31: លោក សុខ ខន | N31: នាយកដ្ឋានស្ថិតិ និងវិភាគសេដ្ឋកិច្ច | O31: =IF(AND(K31<>"",M31<>""),"ok","-") -> ok
A32: 9 | B32: 1010103 | C32: 101010301 | E32: 4 | G32: 4 | H32: 19 | I32: 177 | J32: 13 | K32: ១.‌១.៣.១.សកម្មភាពទី១៖ពង្រឹងការគ្រប់គ្រងកិច្ចការទូទៅ និងការសម្របសម្រួលផ្ទៃក្នុងនិងអន្តរទំនាក់ទំនង ដើម្បីបុរេសកម្មការងារ | L32: =RIGHT(M32,LEN(M32)-SEARCH(" ",M32)) -> កូយ សុចាន់ | M32: កញ្ញា កូយ សុចាន់ | N32: ការិយាល័យកិច្ចការទូទៅនិងសម្របសម្រួល | O32: =IF(AND(K32<>"",M32<>""),"ok","-") -> ok
A33: 10 | B33: 1010103 | C33: 101010302 | E33: 4 | G33: 4 | H33: 20 | I33: 178 | J33: 14 | K33: ១.‌១.៣.២.សកម្មភាពទី២៖ ពង្រឹងការរៀបចំចងក្រង តាមដាន វិភាគនិងផ្សព្វផ្សាយស្ថិតិប្រតិបត្តិការហិរញ្ញវត្ថុ (TOFE) និងស្តង់ដារស្ថិតិហិរញ្ញវត្ថុរដ្ឋាភិបាល (GFS) | L33: =RIGHT(M33,LEN(M33)-SEARCH(" ",M33)) -> សែម សំណាង | M33: លោក​ស្រី សែម សំណាង | N33: ការិយាល័យស្ថិតិហិរញ្ញវត្ថុសាធារណៈ | O33: =IF(AND(K33<>"",M33<>""),"ok","-") -> ok
A34: 11 | B34: 1010103 | C34: 101010303 | E34: 4 | G34: 4 | H34: 21 | I34: 179 | J34: 15 | K34: ១.១.៣.៣.សកម្មភាពទី៣៖​ ពង្រឹងការរៀបចំចងក្រង តាមដាន វិភាគនិងផ្សព្វផ្សាយស្ថិតិម៉ាក្រូសេដ្ឋកិច្ច | L34: =RIGHT(M34,LEN(M34)-SEARCH(" ",M34)) -> បាន ​កុសល | M34: លោក បាន ​កុសល | N34: ការិយាល័យស្ថិតិនិងវិភាគម៉ាក្រូសេដ្ឋកិច្ច | O34: =IF(AND(K34<>"",M34<>""),"ok","-") -> ok
A35: 12 | B35: 1010103 | C35: 101010304 | E35: 4 | G35: 4 | H35: 22 | I35: 180 | J35: 16 | K35: ១.‌១.៣.៤.សកម្មភាពទី៤៖ ពង្រឹងការរៀបចំចងក្រង តាមដាន វិភាគនិងផ្សព្វផ្សាយស្ថិតិសេដ្ឋកិច្ចតាមវិស័យ | L35: =RIGHT(M35,LEN(M35)-SEARCH(" ",M35)) -> ស្រៀង ចន្ធី | M35: លោក ស្រៀង ចន្ធី | N35: ការិយាល័យស្ថិតិនិងវិភាគសេដ្ឋកិច្ចតាមវិស័យ | O35: =IF(AND(K35<>"",M35<>""),"ok","-") -> ok
A36: 13 | B36: 1010103 | C36: 101010305 | E36: 4 | G36: 4 | H36: 23 | I36: 181 | J36: 17 | K36: ១.១.៣.៥.សកម្មភាពទី៥៖​ ពង្រឹងការរៀបចំចងក្រង តាមដាន វិភាគនិងផ្សព្វផ្សាយស្ថិតិថ្លៃទំនិញនិងសេវា | L36: =RIGHT(M36,LEN(M36)-SEARCH(" ",M36)) -> ជា សុខឃីមរាជ | M36: លោក ជា សុខឃីមរាជ | N36: ការិយាល័យតាមដានថ្លៃទំនិញ និងសេវា | O36: =IF(AND(K36<>"",M36<>""),"ok","-") -> ok
A37: 14 | B37: 1010103 | C37: 101010306 | E37: 4 | G37: 4 | H37: 24 | I37: 182 | J37: 15 | K37: ១.‌១.៣.៦.សកម្មភាពទី៦៖ ពង្រឹងការតាមដាន និងវិភាគនិន្នាការសេដ្ឋកិច្ច | L37: =RIGHT(M37,LEN(M37)-SEARCH(" ",M37)) -> បាន ​កុសល | M37: លោក បាន ​កុសល | N37: ការិយាល័យតាមដាននិងវិភាគនិន្នាការសេដ្ឋកិច្ច | O37: =IF(AND(K37<>"",M37<>""),"ok","-") -> ok
B38: 1010103 | C38: 101010307 | K38: ១.១.៣.៧. សកម្មភាពទី៧ : | O38: =IF(AND(K38<>"",M38<>""),"ok","-") -> -
B39: 1010103 | C39: 101010308 | K39: ១.១.៣.៨. សកម្មភាពទី៨ : ​ | O39: =IF(AND(K39<>"",M39<>""),"ok","-") -> -
B40: 1010103 | C40: 101010309 | K40: ១.១.៣.៩. សកម្មភាពទី៩ : | O40: =IF(AND(K40<>"",M40<>""),"ok","-") -> -
...

Sheet BSP1
C5: តារាង ១ : អនុកម្មវិធី អ្នកគ្រប់គ្រង និងអង្គភាពទទួលខុសត្រូវ
F6: តារាង ១"ក"
F7: ឯកតា៖ លានរៀល
C8: ជំពូក | D8: ជំពូក | E8: ជំពូក | F8: ជំពូក
A10: Check | B10: កូដកម្មវិធី | C10: ឈ្មោះគោលបំណងគោលនយោបាយ | D10: ឈ្នោះកម្មវិធី និងអនុកម្មវិធី | E10: អ្នកគ្រប់គ្រង | F10: អង្គភាពទទួលខុសត្រូវ
B11: =A12 -> #REF! | C11: គោលបំណងគោលនយោបាយទី១: ការគ្រប់គ្រងសេដ្ឋកិច្ច និងវិស័យ ហិរញ្ញវត្ថុ | D11: កម្មវិធីទី១ : ការគ្រប់គ្រងវិស័យសេដ្ឋកិច្ច | E11: ឯកឧត្តម/លោកជំទាវ... | G11: =IF(AND(D11<>"",E11<>""),"ok","-") -> ok
A12: =LEFT(B12,3) -> #REF! | B12: =#REF! -> #REF! | D12: ១.១. អនុកម្មវិធីទី១.១ : ការគ្រប់គ្រងគោលនយោបាយសេដ្ឋកិច្ច ហិរញ្ញវត្ថុ និងគោលនយោបាយតាមវិស័យផ្សេងៗ | E12: ឯកឧត្តម ឈាង វណ្ណារិទ្ធ | F12: អគ្គនាយកដ្ឋានគោលនយោបាយ | G12: =IF(AND(D12<>"",E12<>""),"ok","-") -> ok
A13: =LEFT(B13,5) -> #REF! | B13: =$B$12&"01" -> #REF! | D13: ១.១.១. ចង្កោមសកម្មភាពទី១ : គាំទ្រ សម្របសម្រួល និងគ្រប់គ្រងការងាររដ្ឋបាលរបស់អគ្គនាយកដ្ឋាន | E13: លោក ស្រ៊ន មុនីនាត | F13: លេខាធិការដ្ឋាន | G13: =IF(AND(D13<>"",E13<>""),"ok","-") -> ok
A14: =LEFT(B14,7) -> #REF! | B14: =B13&"01" -> #REF! | D14: ១.១.១.១. សកម្មភាពទី១ : បំពេញមុខជាលេខាធិការដ្ឋាន | E14: លោក ស្រ៊ន មុនីនាត | F14: លេខាធិការដ្ឋាន | G14: =IF(AND(D14<>"",E14<>""),"ok","-") -> ok
A15: =LEFT(B15,7) -> #REF! | B15: =B13&"02" -> #REF! | D15: ១.១.១.២. សកម្មភាពទី២ : ​ចូលរួមកិច្ចប្រជុំផ្សេងៗ ក្នុងនិងក្រៅប្រទេសរបស់ឯកឧត្តមអគ្គនាយក | E15: លោក ស្រ៊ន មុនីនាត | F15: លេខាធិការដ្ឋាន | G15: =IF(AND(D15<>"",E15<>""),"ok","-") -> ok
A16: =LEFT(B16,7) -> #REF! | B16: =B13&"03" -> #REF! | D16: ១.១.១.៣. សកម្មភាពទី៣ : | G16: =IF(AND(D16<>"",E16<>""),"ok","-") -> -
A17: =LEFT(B17,7) -> #REF! | B17: =B13&"04" -> #REF! | D17: ១.១.១.៤. សកម្មភាពទី៤ : | G17: =IF(AND(D17<>"",E17<>""),"ok","-") -> -
A18: =LEFT(B18,7) -> #REF! | B18: =B13&"05" -> #REF! | D18: ១.១.១.៥. សកម្មភាពទី៥ : | G18: =IF(AND(D18<>"",E18<>""),"ok","-") -> -
A19: =LEFT(B19,7) -> #REF! | B19: =B13&"06" -> #REF! | D19: ១.១.១.៦. សកម្មភាពទី៦ : | G19: =IF(AND(D19<>"",E19<>""),"ok","-") -> -
A20: =LEFT(B20,7) -> #REF! | B20: =B13&"07" -> #REF! | D20: ១.១.១.៧. សកម្មភាពទី៧ : | G20: =IF(AND(D20<>"",E20<>""),"ok","-") -> -
A21: =LEFT(B21,7) -> #REF! | B21: =B13&"08" -> #REF! | D21: ១.១.១.៨. សកម្មភាពទី៨ : ​ | G21: =IF(AND(D21<>"",E21<>""),"ok","-") -> -
A22: =LEFT(B22,7) -> #REF! | B22: =B13&"09" -> #REF! | D22: ១.១.១.៩. សកម្មភាពទី៩ : | G22: =IF(AND(D22<>"",E22<>""),"ok","-") -> -
A23: =LEFT(B23,7) -> #REF! | B23: =B13&"10" -> #REF! | D23: ១.១.១.១០. សកម្មភាពទី១០ : ​ | G23: =IF(AND(D23<>"",E23<>""),"ok","-") -> -
A24: =LEFT(B24,7) -> #REF! | B24: =B13&"11" -> #REF! | D24: ១.១.១.១១. សកម្មភាពទី១១ : | G24: =IF(AND(D24<>"",E24<>""),"ok","-") -> -
A25: =LEFT(B25,7) -> #REF! | B25: =B13&"12" -> #REF! | D25: ១.១.១.១២. សកម្មភាពទី១២ : ​ | G25: =IF(AND(D25<>"",E25<>""),"ok","-") -> -
A26: =LEFT(B26,5) -> #REF! | B26: =$B$12&"02" -> #REF! | D26: ១.១.២. ចង្កោមសកម្មភាពទី២ : រៀបចំ កែលម្អ ត្រួតពិនិត្យ និងវាយតម្លៃគោលនយោបាយម៉ាក្រូសេដ្ឋកិច្ច និងសារពើពន្ធ | E26: លោកស្រី សែម សុភា | F26: នាយកដ្ឋានគោលនយោ​បាយ​ម៉ាក្រូសេដ្ឋកិច្ច និងសារពើពន្ធ | G26: =IF(AND(D26<>"",E26<>""),"ok","-") -> ok
A27: =LEFT(B27,7) -> #REF! | B27: =B26&"01" -> #REF! | D27: ១.១.២.១. សកម្មភាពទី១ : ធ្វើការស្រាវជ្រាវលើវឌ្ឍនភាព និងបញ្ហា អភិវឌ្ឍន៍សេដ្ឋកិច្ច ហិរញ្ញវត្ថុ និងវិស័យសំខាន់ៗ | E27: លោក ស៊ីន ស៊ីប | F27: ការិយាល័យស្រាវជ្រាវ | G27: =IF(AND(D27<>"",E27<>""),"ok","-") -> ok
A28: =LEFT(B28,7) -> #REF! | B28: =B26&"02" -> #REF! | D28: ១.១.២.២. សកម្មភាពទី២ : តាមដាន និងវាយតម្លៃការអនុវត្តគោលនយោបាយសារពើពន្ធ អនុលោមតាមគោលដៅយុទ្ធសាស្រ្តជាតិ | E28: កញ្ញា សែម សុភា | F28: ការិយាល័យវិភាគ និងព្យាករណ៍សារពើពន្ធ | G28: =IF(AND(D28<>"",E28<>""),"ok","-") -> ok
A29: =LEFT(B29,7) -> #REF! | B29: =B26&"03" -> #REF! | D29: ១.១.២.៣. សកម្មភាពទី៣ : តាមដាន និងវាយតម្លៃការអនុវត្តយុទ្ធសាស្រ្ត និងគោលនយោបាយពាក់ព័ន្ធនឹងវិស័យសេដ្ឋកិច្ច-សង្គម | E29: លោក ឌី សេរីវិរៈ | F29: ការិយាល័យគោលនយោបាយសេដ្ឋកិច្ច | G29: =IF(AND(D29<>"",E29<>""),"ok","-") -> ok
A30: =LEFT(B30,7) -> #REF! | B30: =B26&"04" -> #REF! | D30: ១.១.២.៤. សកម្មភាពទី៤ : ពិនិត្យ តាមដាន និងវាយតម្លៃស្ថានភាពសេដ្ឋកិច្ច និងក្របខ័ណ្ឌម៉ាក្រូសេដ្ឋកិច្ចរយៈពេលមធ្យម | E30: លោកស្រី តាន់ ទ្បានីន | F30: ការិយាល័យវិភាគ និងព្យាករណ៍សេដ្ឋកិច្ច | G30: =IF(AND(D30<>"",E30<>""),"ok","-") -> ok
A31: =LEFT(B31,7) -> #REF! | B31: =B26&"05" -> #REF! | D31: ១.១.២.៥. សកម្មភាពទី៥ : តាមដាន និងវិភាគគោលនយោបាយហិរញ្ញវត្ថុសាធារណៈ | E31: លោក ម៉ក់ វិចិត្រសក្កដា | F31: ការិយាល័យគោលនយោបាយហិរញ្ញវត្ថុសាធារណៈ | G31: =IF(AND(D31<>"",E31<>""),"ok","-") -> ok
A32: =LEFT(B32,7) -> #REF! | B32: =B26&"06" -> #REF! | D32: ១.១.២.៦. សកម្មភាពទី៦ : ពង្រឹងសេវាគាំទ្រកិច្ចប្រតិបត្តិការ និងការងារសម្របសម្រួលសម្រាប់នាយកដ្ឋានគោលនយោបាយម៉ាក្រូសេដ្ឋកិច្ច និងសារពើពន្ធ | E32: លោកស្រី ស៊ាង ពីសី | F32: ការិយាល័យកិច្ចការទូទៅ និងសម្របសម្រួល | G32: =IF(AND(D32<>"",E32<>""),"ok","-") -> ok
A33: =LEFT(B33,7) -> #REF! | B33: =B26&"07" -> #REF! | D33: ១.១.២.៧. សកម្មភាពទី៧ : | G33: =IF(AND(D33<>"",E33<>""),"ok","-") -> -
A34: =LEFT(B34,7) -> #REF! | B34: =B26&"08" -> #REF! | D34: ១.១.២.៨. សកម្មភាពទី៨ : ​ | G34: =IF(AND(D34<>"",E34<>""),"ok","-") -> -
A35: =LEFT(B35,7) -> #REF! | B35: =B26&"09" -> #REF! | D35: ១.១.២.៩. សកម្មភាពទី៩ : | G35: =IF(AND(D35<>"",E35<>""),"ok","-") -> -
A36: =LEFT(B36,7) -> #REF! | B36: =B26&"10" -> #REF! | D36: ១.១.២.១០. សកម្មភាពទី១០ : ​ | G36: =IF(AND(D36<>"",E36<>""),"ok","-") -> -
A37: =LEFT(B37,7) -> #REF! | B37: =B26&"11" -> #REF! | D37: ១.១.២.១១. សកម្មភាពទី១១ : | G37: =IF(AND(D37<>"",E37<>""),"ok","-") -> -
A38: =LEFT(B38,7) -> #REF! | B38: =B26&"12" -> #REF! | D38: ១.១.២.១២. សកម្មភាពទី១២ : ​ | G38: =IF(AND(D38<>"",E38<>""),"ok","-") -> -
A39: =LEFT(B39,5) -> #REF! | B39: =$B$12&"03" -> #REF! | D39: ១.១.៣. ចង្កោមសកម្មភាពទី៣ : លើកកម្ពស់ការងារស្ថិតិសេដ្ឋកិច្ចនិងហិរញ្ញវត្ថុសាធារណៈ | E39: លោក សុខ ខន | F39: នាយកដ្ឋានស្ថិតិ និងវិភាគសេដ្ឋកិច្ច | G39: =IF(AND(D39<>"",E39<>""),"ok","-") -> ok
A40: =LEFT(B40,7) -> #REF! | B40: =B39&"01" -> #REF! | D40: ១.‌១.៣.១.សកម្មភាពទី១៖ពង្រឹងការគ្រប់គ្រងកិច្ចការទូទៅ និងការសម្របសម្រួលផ្ទៃក្នុងនិងអន្តរទំនាក់ទំនង ដើម្បីបុរេសកម្មការងារ | E40: កញ្ញា កូយ សុចាន់ | F40: ការិយាល័យកិច្ចការទូទៅ និងសម្របសម្រួល | G40: =IF(AND(D40<>"",E40<>""),"ok","-") -> ok
